Workbook

Sheet Sheet1
A1: object_id | B1: Huis | C1: Postcode | D1: Huur p/m | E1: Ontv. Huur p/w incl | F1: Eigenaar | G1: Contactpersoon | H1: Adres | I1: Postcode | J1: Woonplaats | K1: Telefoon | L1: Mail | M1: Rekeningnr | N1: Bedden | O1: Kamers | P1: Tekening | Q1: Lijst meters | R1: Energie Gas | S1: Leverancier Gas | T1: Tarief Gas | U1: Energie Electra | V1: Leverancier Electra | W1: Tarief E Enkel | X1: Tarief E Hoog | Y1: Tarief E Laag | Z1: Energie Water | AA1: Leverancier Water | AB1: Contractduur | AC1: Begindatum contract | AD1: Einddatum contract | AE1: voorschot glw | AF1: G/L/W verbruik | AG1: Belastingen p/m | AH1: Container | AI1: Tarief container | AJ1: container info | AK1: Internet | AL1: Tarief internet | AM1: contract | AN1: borg | AO1: Begin huur | AP1: Eind Huur | AQ1: Opzegtermijn | AR1: opmerking
A2: 0280 | B2: Bovendijk, 59 , Kwintsheul | C2: 2295 RW | D2: 1375 | E2: 119 | F2: M. Nottet | G2: M. Nottet | H2: Kapittelland 16 | I2: 3151 ZB | J2: Hoek van Holland | K2: 06-50502637 | L2: mnottet@caiway.nl | M2: NL60RABO0323282903 | N2: 5 | O2: 3 | P2: ja | Q2: ja | R2: ComCam | S2: Engie | T2: 1.46 | U2: ComCam | V2: Engie | W2: 0 | X2: 0.1145 | Y2: 0.11013 | Z2: Exclusief | AA2: Evides | AB2: 4 | AC2: 44835 | AD2: 46082 | AE2: =10.97+13.65+25.39+25.32+47.09 -> 122.42 | AF2: 0 | AG2: 66.36 | AH2: MSN | AI2: 115.76 | AJ2: 1x 500 ltr / 1x pw / vrijdag | AK2: BICT | AL2: 79 | AM2: ja | AO2: 41791 | AP2: nb | AQ2: 2 maanden
A3: 0281 | B3: Bovendijk,61, Kwintsheul | C3: 2295 RW | D3: 2625 | E3: 119 | F3: M. Nottet | G3: M. Nottet | H3: Kapittelland 16 | I3: 3151 ZB | J3: Hoek van Holland | K3: 06-50502637 | L3: mnottet@caiway.nl | M3: NL60RABO0323282903 | N3: 8 | O3: 5 | P3: ja | Q3: ja | R3: ComCam | S3: Engie | T3: 1.46 | U3: ComCam | V3: Engie | W3: 0 | X3: 0.1145 | Y3: 0.11013 | Z3: Exclusief | AA3: Evides | AB3: 4 | AC3: 44835 | AD3: 46082 | AE3: =10.97+30.1+5.04+28.1+55.98+46.04+85.64 -> 261.87 | AF3: 0 | AG3: 66.36 | AK3: BICT | AL3: 79 | AM3: ja | AO3: 41791 | AP3: nb | AQ3: 2 maanden
A4: 0276 | B4: Burgemeester Cramerlaan, 82, De Lier | C4: 2678 AN | D4: 1450 | E4: 119 | F4: P. van den Berg | G4: Piet van den Berg | H4: Burgemeester Cramerlaan 17 | I4: 2678 AL | J4: De Lier | K4: 06-38765032 | L4: info@vandenbergdelier.nl | M4: NL29ABNA0472271989 | N4: 6 | O4: 4 | P4: ja | Q4: ja | R4: ComCam | S4: Engie | T4: 0.80162 | U4: ComCam | V4: Engie | W4: 0 | X4: 0.29319 | Y4: 0.16794 | Z4: Exclusief | AA4: Evides | AB4: 4 | AC4: 44621 | AD4: 46082 | AE4: =34.33+437.42+34.58+41.63+41.63 -> 589.59 | AF4: 0 | AG4: 36.24 | AH4: Renewi / Gemeente | AI4: =407.55/3 -> 135.85 | AJ4: 1x 660 ltr 1x pw di // Grijs (OW) groen ( EW) donderdag | AK4: BICT | AL4: 79 | AM4: ja | AN4: 1200 | AO4: 43466 | AP4: 44196 | AQ4: 3 maanden | AR4: stroom via tuin eigenaar
A5: 0275 | B5: Burgemeester Crezeelaan, 76, De Lier | C5: 2678 KZ | D5: 1400 | E5: 119 | F5: K. Zuidgeest | G5: K. Zuidgeest | H5: Oudecampsweg 7 | I5: 2678 NN | J5: De Lier | K5: 06-26146636 | L5: KoosZuidgeest@zuidkoop.nl / k.zuidgeest@hetnet.nl | M5: NL05RABO0336208367 | N5: 8 | O5: 4 | P5: ja | Q5: ja | R5: ComCam | S5: Engie | T5: 0.80162 | U5: ComCam | V5: Engie | W5: 0 | X5: 0.29319 | Y5: 0.16794 | Z5: Exclusief | AA5: Evides | AB5: 4 | AC5: 44621 | AD5: 46082 | AE5: =32.66+235.17+186.52+101.06+346.93 -> 902.34 | AF5: 0 | AG5: 99.53 | AH5: MSN | AI5: 173.26 | AJ5: 1x 1100 ltr / 1x pw / woensdag | AK5: BICT | AL5: 0 | AN5: 2300 | AO5: 41239 | AP5: nb | AQ5: 2 maanden
A6: 0273 | B6: Fenacoliuslaan, 56b, Maassluis | C6: 3143AB | D6: 2227 | E6: 119 | F6: P.H. Jagt | G6: Peter Jagt | H6: Haakweg 33 | I6: 3151 XD | J6: Hoek van Holland | K6: 06-51609632 | L6: peter@westhoekmakelaars.nl | M6: NL60KNAB0257738010 | N6: 8 | O6: 4 | P6: ja | Q6: ja | R6: ComCam | S6: Engie | T6: 0.80162 | U6: ComCam | V6: Engie | W6: 0 | X6: 0.29319 | Y6: 0.16794 | Z6: Exclusief | AA6: Evides | AB6: 4 | AC6: 44621 | AD6: 46082 | AE6: =6.98+30.3+93.93+26.62+56.36+174.71 -> 388.9 | AF6: 0 | AG6: 0 | AH6: Gemeente | AI6: 0 | AJ6: ondergrondse containers | AK6: BICT | AL6: 79 | AM6: ja | AN6: 2150 | AO6: 43896 | AP6: 44261 | AQ6: 6maanden | AR6: 15 april ipv 5 maart aangevangen
A7: 0279 | B7: Haagkamp, 11, Honselersdijk | C7: 2675 SK | D7: 1950 | E7: 119 | F7: v.o.f. J.C. Mulder | G7: Jan Mulder | H7: Nieuwe Tuinen 7B | I7: 2675 SE | J7: Honselersdijk | K7: 06-53690859 | L7: janmul54@gmail.com | M7: NL08RABO0343659077 | N7: 6 | O7: 3 | P7: ja | Q7: ja | R7: ComCam | S7: Engie | T7: 0.80162 | U7: Inclusief met VS | V7: Inclusief met VS | W7: 0 | X7: 0 | Y7: 0 | Z7: Inclusief | AA7: Inclusief | AB7: 1 | AC7: 44621 | AD7: 46082 | AE7: =2592.78-2163.42 -> 429.36 | AF7: 0 | AG7: 53.34 | AH7: Gemeente & Renewi | AI7: 134.88 | AJ7: Grijs (OW), Groen (EW) / Dinsdag (1x pw), Blauw laatste maandag vd maand / 1x 660 ltr 1x pw dinsdag | AK7: incl | AL7: 0 | AM7: ja | AO7: 41239 | AP7: 44197 | AQ7: 3 maanden
A8: 0274 | B8: Karel Doormanlaan, 21a, De Lier | C8: 2678 EX | D8: 1150 | E8: 119 | F8: De Rembrandt B.V. | G8: Flip van Adrichem | H8: Langestraat 48 | I8: 2691 BH | J8: s-Gravenzande | K8: 06-41372342 | L8: flip@eetcafedewitte.nl | M8: NL21RABO0156104105 | N8: 4 | O8: 2 | P8: ja | Q8: nee | R8: Inclusief | S8: Inclusief | T8: 0 | U8: Inclusief | V8: Inclusief | W8: 0 | X8: 0 | Y8: 0 | Z8: Inclusief | AA8: Inclusief | AE8: 0 | AF8: 0 | AG8: 95.43 | AH8: MSN | AI8: 134.88 | AJ8: 1 X 660 ltr/ 1x pw / woensdag | AK8: incl | AL8: 0 | AM8: ja | AN8: 1000 | AO8: 43160 | AP8: OT | AQ8: 1 maand
A9: 0291 | B9: Koperwerf, 28, Den Haag (kamers) | C9: 2544 EN | D9: 41710 | E9: 119 | F9: Lammertink Projecten B.V. | G9: Hans Lammertink | H9: Schietlood 2 | I9: 2495 AN | J9: Den Haag | K9: 085-2739900 | L9: Dennis Baak 06-24313837 (schoonzoon) / dbaak@l-groep.nl | M9: NL83INGB0677182783 | N9: 150 | O9: 86 | P9: ja | Q9: ja | R9: ComCam | S9: Engie | U9: ComCam | V9: Engie | W9: 0 | X9: 0.15779 | Y9: 0.12237 | Z9: Exclusief | AA9: dunea | AB9: 4 | AC9: 44621 | AD9: 46082 | AE9: =85654.07-71675.57 -> 13978.5 | AF9: 0 | AG9: 207.61 | AH9: Omega | AI9: 845.56 | AJ9: Omega 4x 1000ltr 2x p/w | AK9: BICT | AL9: 237 | AO9: 43591 | AP9: 45396 | AR9: Dennis Baak 06-24313837 (schoonzoon)
A10: 0291 | B10: Koperwerf, 28, Den Haag (trefpunt) | C10: 2544 EN | D10: 1500 | E10: 119 | F10: Lammertink Projecten B.V. | G10: Hans Lammertink | H10: Schietlood 2 | I10: 2495 AN | J10: Den Haag | K10: 085-2739900 | M10: NL83INGB0677182783 | P10: ja | Q10: ja | R10: ComCam | S10: Engie | U10: ComCam | V10: Engie | W10: 0 | X10: 0.15779 | Y10: 0.12237 | Z10: Exclusief | AA10: dunea | AB10: 4 | AC10: gedurende jaar | AD10: 46082 | AE10: 0 | AF10: 0 | AG10: 0 | AH10: incl. | AK10: BICT | AL10: 395 | AO10: 43891 | AP10: 45396
A11: 0278 | B11: Lange Broekweg, 46, Naaldwijk | C11: 2671 DV | D11: 1825 | E11: 119 | F11: G. Hofland | G11: Goos Hofland | H11: Lange Broekweg 46 | I11: 2671 DV | J11: Naaldwijk | K11: 0174-625887 | L11: goos@hoflandfloweringplants.nl | M11: NL27RABO0343661063 | N11: 8 | O11: 5 | P11: ja | Q11: nee | R11: Inclusief | S11: Inclusief | T11: 0 | U11: Inclusief | V11: Inclusief | W11: 0 | X11: 0 | Y11: 0 | Z11: Inclusief | AA11: Inclusief | AE11: 0 | AF11: 0 | AG11: 22.83 | AH11: Renewi | AI11: =377.66/3 -> 125.88667 | AJ11: 1x 500 ltr / 1x pw / dinsdag | AK11: BICT | AL11: 79 | AM11: ja | AN11: 1750 | AO11: 43079 | AP11: nb | AQ11: per maand | AR11: 2022 € 5.200,- huur vermindering
A12: 0284 | B12: Molenweg,3A, Monster | C12: 2681 RD | D12: 1800 | E12: 119 | F12: M.J.W. van den Enden & B.M. van den Enden | G12: Barbara van den Enden | H12: Bospolder 4a | I12: 2675 BL | J12: Honselersdijk | K12: 06-51611737 Barbara / 06-54398790 Maup | L12: endem3@caiway.nl | M12: NL81INGB0112509347 | N12: 7 | O12: 4 | P12: ja | Q12: ja | R12: ComCam | S12: Engie | T12: 0.80162 | U12: ComCam | V12: Engie | W12: 0 | X12: 0.29319 | Y12: 0.16794 | Z12: Exclusief | AA12: Evides | AB12: 4 | AC12: 44621 | AD12: 46082 | AE12: =3780.09-3170.42 -> 609.67 | AF12: 0 | AG12: 97.4 | AH12: Renewi / Gemeente | AI12: =188.85/3 -> 62.95 | AJ12: Grijs (EW), Groen (OW) / dinsdag, Blauw 1e woensdag vd maand / Rol 500ltr dinsdag (OW) | AK12: BICT | AL12: 79 | AM12: ja | AO12: 41239 | AP12: nb
A13: 0335 | B13: Molenweg, 3 B, Monster | C13: 2681 RD | D13: 1800 | E13: 119 | F13: M.J.W. van den Enden & B.M. van den Enden | G13: Barbara van den Enden | H13: Bospolder 4a | I13: 2675 BL | J13: Honselersdijk | K13: 06-51611737 Barbara / 06-54398790 Maup | L13: endem3@caiway.nl | M13: NL81INGB0112509347 | N13: 5 | O13: 3 | R13: Inclusief | U13: Inclusief met VS | V13: Inclusief met VS | AC13: 45659 | AE13: 200 | AH13: Renewi / Gemeente | AI13: =188.85/3 -> 62.95 | AK13: BICT | AL13: 79 | AM13: ja | AN13: 3600 | AO13: 45659
A14: 0282 | B14: Madeweg, 25 C, Monster | C14: 2681 PJ | D14: 2600 | E14: 119 | F14: H. van Leeuwen | G14: Petra | H14: Postbus 170 | I14: 2680 AD | J14: Monster | K14: 06-51262904 / 0174-248804 | L14: petra@huubvanleeuwen.nl | M14: NL96RABO0375644504 | N14: 8 | O14: 4 | P14: ja | Q14: nee | R14: Inclusief | S14: Inclusief | T14: 0 | U14: Inclusief | V14: Inclusief | W14: 0 | X14: 0 | Y14: 0 | Z14: Inclusief | AA14: Inclusief | AE14: 0 | AF14: 0 | AG14: 77.46 | AH14: Renewi | AI14: =377.66/3 -> 125.88667 | AJ14: 1x 500 ltr / 1x pw / maandag | AK14: BICT | AL14: 79 | AO14: 42826 | AP14: nb
A15: 0283 | B15: Madeweg, 35 A, Monster | C15: 2681 PK | D15: 2020 | E15: 119 | F15: J.S. Vink Vastgoed | G15: Denise Vink | H15: Boomaweg 27 | I15: 2681 RH | J15: Monster | K15: 06-23615767 (denise) 06-53505331 (jan) | L15: info@jsvink.nl / d.j.vink@hotmail.com | M15: NL14RABO3291687140 en NL20RABO0129949140 | N15: 7 | O15: 4 | P15: ja | Q15: ja | R15: ComCam | S15: Engie | T15: 0.80162 | U15: ComCam | V15: Engie | W15: 0 | X15: 0.29319 | Y15: 0.16794 | Z15: Inclusief | AA15: Inclusief | AB15: 4 | AC15: 44621 | AD15: 46082 | AE15: =6129.86-5496.99 -> 632.87 | AF15: 0 | AG15: =32.11+15.37 -> 47.48 | AH15: Renewi | AI15: =377.66/3 -> 125.88667 | AJ15: 1x 500 ltr / 1x pw / donderdag | AL15: 79 | AO15: 44256
A16: 0285 | B16: Poeldijkseweg, 27, Monster | C16: 2681 LT | D16: 850 | E16: 119 | F16: P.C. Vijverberg | G16: Piet Vijverberg | H16: Van Koppenweg 24 | I16: 2672 EH | J16: Naaldwijk | K16: 06-53299575 | L16: piet@pietvijverberg.nl | M16: NL95RABO0142277460 | AI16: 138.2 | AJ16: 1x 660 ltr / 1x pw / donderdag | AO16: 45231 | AP16: 45961 | AQ16: 1 maand
A17: 0378 | B17: Poeldijkseweg, 29, Monster | C17: 2681 LT | D17: 1500 | E17: 119 | F17: P.C. Vijverberg | G17: Piet Vijverberg | H17: Van Koppenweg 24 | I17: 2672 EH | J17: Naaldwijk | K17: 06-53299575 | L17: piet@pietvijverberg.nl | M17: NL95RABO0142277460 | AE17: 0 | AH17: MSN | AO17: 45108 | AP17: 46568 | AQ17: 1 maand | AR17: Contract van 2 jaar is inmiddels verlengd voor 2e keer
A18: 0363 | B18: Rietdijkstraat, 56a, Hoek van Holland | C18: 3151 GJ | D18: 1300 | E18: 119 | F18: S.A. van Bergen Vastgoed B.V. | G18: S.A. van Bergen | H18: Strandweg 25 | I18: 3151 HV | J18: Hoek van holland | K18: 06-30412153 | L18: bas.vanbergen@aubvanbergen.nl | M18: NL11RABO0318502364 | N18: 4 | O18: 2 | P18: ja | R18: ComCam | S18: Engie | T18: 1.48249 | U18: ComCam | V18: Engie | W18: 0 | X18: 0.28378 | Y18: 0.24836 | Z18: Exclusief | AA18: Evides | AB18: 4 | AC18: 44958 | AD18: 46082 | AE18: 6.7 | AF18: 0 | AG18: 0 | AI18: 0 | AM18: ja | AN18: 1300 | AO18: 44927 | AP18: 45291 | AQ18: 1 maand
A19: 0364 | B19: Rietdijkstraat, 56b, Hoek van Holland | C19: 3151 GJ | D19: 1950 | E19: 119 | F19: S.A. van Bergen Vastgoed B.V. | G19: S.A. van Bergen | H19: Strandweg 25 | I19: 3151 HV | J19: Hoek van holland | K19: 06-30412153 | L19: bas.vanbergen@aubvanbergen.nl | M19: NL11RABO0318502364 | N19: 6 | O19: 3 | P19: ja | R19: ComCam | S19: Engie | T19: 1.48249 | U19: ComCam | V19: Engie | W19: 0 | X19: 0.28378 | Y19: 0.24836 | Z19: Exclusief | AA19: Evides | AB19: 4 | AC19: 44958 | AD19: 46082 | AE19: 6.7 | AF19: 0 | AG19: 0 | AI19: 0 | AM19: ja | AN19: 1950 | AO19: 44927 | AP19: 45291 | AQ19: 1 maand
A20: 0377 | B20: Rijpstraat, 24, Hoek van Holland | C20: 3151 BV | D20: 1733.33 | E20: 119 | F20: F.A.S. van Bergen | G20: J. v. Bergen | H20: Rijpstraat 22 | I20: 3151 BV | J20: Hoek van Holland | K20: 06-53739975 | L20: jetvbergen@gmail.com | M20: NL44ABNA0620327766 | N20: 4 | O20: 2 | P20: ja | Q20: ja | R20: Exclusief | S20: Total | T20: 0.17602 | U20: Exclusief | V20: Total | W20: 0.0483 | X20: 0.05403 | Y20: 0.04201 | Z20: Exclusief | AA20: Evides | AB20: 5 | AC20: 44197 | AD20: 46022 | AE20: 0 | AF20: 0 | AG20: 43.58 | AH20: Renewi / Gemeente | AI20: =166.43/3 -> 55.476667 | AJ20: 1x 660 ltr / 1x2 pw / donderdag/ O-W | AK20: incl. | AL20: 0 | AO20: 43600 | AP20: 44695 | AQ20: 1 maand
A21: 0286 | B21: Waellandweg, 12, Monster | C21: 2681 LV | D21: 2000 | E21: 119 | F21: T. Olsthoorn | G21: Ton Olsthoorn | H21: Ravellaan 8 | I21: 2671 VT | J21: Naaldwijk | K21: 06-22413459 | L21: tonolsthoorn@kpnmail.nl | M21: NL92RABO0342957031 | N21: 7 | O21: 4 | P21: ja | Q21: ja | R21: ComCam | S21: Engie | T21: 0.80162 | U21: ComCam | V21: Engie | W21: 0 | X21: 0.29319 | Y21: 0.16794 | Z21: Exclusief | AA21: Evides | AB21: 4 | AC21: 44621 | AD21: 46082 | AE21: =3800.87-3167.11 -> 633.76 | AF21: 0 | AG21: =26.79+65.44 -> 92.23 | AH21: Renewi | AI21: 377.66 | AJ21: 1x 500 ltr / 1x pw / maandag | AK21: BICT | AL21: 79 | AN21: 1400 | AO21: 41239 | AP21: nb
A22: 0288 | B22: Zekkenstraat,33 A, Hoek van Holland | C22: 3151 XP | D22: 2500 | E22: 119 | F22: Stichting MCM | G22: J. v. Bergen | H22: Rijpstraat 22 | I22: 3151 BV | J22: Hoek van Holland | K22: 06-53739975 | L22: jetvbergen@gmail.com | M22: NL39RABO0334435080 | N22: 7 | O22: 4 | P22: ja | Q22: nee | R22: Inclusief | S22: Inclusief | T22: 0 | U22: Inclusief | V22: Inclusief | W22: 0 | X22: 0 | Y22: 0 | Z22: Exclusief | AA22: Evides | AB22: 5 | AC22: 44197 | AD22: 46022 | AE22: 48.21 | AF22: 0 | AG22: 63.99 | AI22: 373.6 | AL22: 0 | AO22: 44927 | AP22: 46022 | AR22: In P4F bekend onder 31A en 31B
A23: 0289 | B23: Zekkenstraat, 33 B, Hoek van Holland | C23: 3151 XP | D23: 2500 | E23: 119 | F23: Stichting MCM | G23: J. v. Bergen | H23: Rijpstraat 22 | I23: 3151 BV | J23: Hoek van Holland | K23: 06-53739975 | L23: jetvbergen@gmail.com | M23: NL39RABO0334435080 | N23: 8 | O23: 4 | P23: ja | Q23: nee | R23: Inclusief | S23: Inclusief | T23: 0 | U23: Inclusief | V23: Inclusief | W23: 0 | X23: 0 | Y23: 0 | Z23: Exclusief | AA23: Evides | AB23: 5 | AC23: 44197 | AD23: 46022 | AE23: 0 | AF23: 0 | AG23: 0 | AL23: 0 | AO23: 44927 | AP23: 46022

Sheet info
A1: object_id | B1: gwe_voorschot | C1: Eigenaar | D1: Contactpersoon | E1: Adres | F1: Postcode | G1: Woonplaats | H1: Telefoon | I1: Mail | J1: Rekeningnr
A2: 280 | B2: {=_xlfn.XLOOKUP($A2,1*Sheet1!$A:$A,Sheet1!AE:AE,"",0)} -> 122.42 | C2: {=_xlfn.XLOOKUP($A2,1*Sheet1!$A:$A,Sheet1!F:F,"",0)} -> M. Nottet | D2: {=_xlfn.XLOOKUP($A2,1*Sheet1!$A:$A,Sheet1!G:G,"",0)} -> M. Nottet | E2: {=_xlfn.XLOOKUP($A2,1*Sheet1!$A:$A,Sheet1!H:H,"",0)} -> Kapittelland 16 | F2: {=_xlfn.XLOOKUP($A2,1*Sheet1!$A:$A,Sheet1!I:I,"",0)} -> 3151 ZB | G2: {=_xlfn.XLOOKUP($A2,1*Sheet1!$A:$A,Sheet1!J:J,"",0)} -> Hoek van Holland | H2: {=_xlfn.XLOOKUP($A2,1*Sheet1!$A:$A,Sheet1!K:K,"",0)} -> 06-50502637 | I2: {=_xlfn.XLOOKUP($A2,1*Sheet1!$A:$A,Sheet1!L:L,"",0)} -> mnottet@caiway.nl | J2: {=_xlfn.XLOOKUP($A2,1*Sheet1!$A:$A,Sheet1!M:M,"",0)} -> NL60RABO0323282903
A3: 281 | B3: {=_xlfn.XLOOKUP($A3,1*Sheet1!$A:$A,Sheet1!AE:AE,"",0)} -> 261.87 | C3: {=_xlfn.XLOOKUP($A3,1*Sheet1!$A:$A,Sheet1!F:F,"",0)} -> M. Nottet | D3: {=_xlfn.XLOOKUP($A3,1*Sheet1!$A:$A,Sheet1!G:G,"",0)} -> M. Nottet | E3: {=_xlfn.XLOOKUP($A3,1*Sheet1!$A:$A,Sheet1!H:H,"",0)} -> Kapittelland 16 | F3: {=_xlfn.XLOOKUP($A3,1*Sheet1!$A:$A,Sheet1!I:I,"",0)} -> 3151 ZB | G3: {=_xlfn.XLOOKUP($A3,1*Sheet1!$A:$A,Sheet1!J:J,"",0)} -> Hoek van Holland | H3: {=_xlfn.XLOOKUP($A3,1*Sheet1!$A:$A,Sheet1!K:K,"",0)} -> 06-50502637 | I3: {=_xlfn.XLOOKUP($A3,1*Sheet1!$A:$A,Sheet1!L:L,"",0)} -> mnottet@caiway.nl | J3: {=_xlfn.XLOOKUP($A3,1*Sheet1!$A:$A,Sheet1!M:M,"",0)} -> NL60RABO0323282903
A4: 276 | B4: {=_xlfn.XLOOKUP($A4,1*Sheet1!$A:$A,Sheet1!AE:AE,"",0)} -> 589.59 | C4: {=_xlfn.XLOOKUP($A4,1*Sheet1!$A:$A,Sheet1!F:F,"",0)} -> P. van den Berg | D4: {=_xlfn.XLOOKUP($A4,1*Sheet1!$A:$A,Sheet1!G:G,"",0)} -> Piet van den Berg | E4: {=_xlfn.XLOOKUP($A4,1*Sheet1!$A:$A,Sheet1!H:H,"",0)} -> Burgemeester Cramerlaan 17 | F4: {=_xlfn.XLOOKUP($A4,1*Sheet1!$A:$A,Sheet1!I:I,"",0)} -> 2678 AL | G4: {=_xlfn.XLOOKUP($A4,1*Sheet1!$A:$A,Sheet1!J:J,"",0)} -> De Lier | H4: {=_xlfn.XLOOKUP($A4,1*Sheet1!$A:$A,Sheet1!K:K,"",0)} -> 06-38765032 | I4: {=_xlfn.XLOOKUP($A4,1*Sheet1!$A:$A,Sheet1!L:L,"",0)} -> info@vandenbergdelier.nl | J4: {=_xlfn.XLOOKUP($A4,1*Sheet1!$A:$A,Sheet1!M:M,"",0)} -> NL29ABNA0472271989
A5: 275 | B5: {=_xlfn.XLOOKUP($A5,1*Sheet1!$A:$A,Sheet1!AE:AE,"",0)} -> 902.34 | C5: {=_xlfn.XLOOKUP($A5,1*Sheet1!$A:$A,Sheet1!F:F,"",0)} -> K. Zuidgeest | D5: {=_xlfn.XLOOKUP($A5,1*Sheet1!$A:$A,Sheet1!G:G,"",0)} -> K. Zuidgeest | E5: {=_xlfn.XLOOKUP($A5,1*Sheet1!$A:$A,Sheet1!H:H,"",0)} -> Oudecampsweg 7 | F5: {=_xlfn.XLOOKUP($A5,1*Sheet1!$A:$A,Sheet1!I:I,"",0)} -> 2678 NN | G5: {=_xlfn.XLOOKUP($A5,1*Sheet1!$A:$A,Sheet1!J:J,"",0)} -> De Lier | H5: {=_xlfn.XLOOKUP($A5,1*Sheet1!$A:$A,Sheet1!K:K,"",0)} -> 06-26146636 | I5: {=_xlfn.XLOOKUP($A5,1*Sheet1!$A:$A,Sheet1!L:L,"",0)} -> KoosZuidgeest@zuidkoop.nl / k.zuidgeest@hetnet.nl | J5: {=_xlfn.XLOOKUP($A5,1*Sheet1!$A:$A,Sheet1!M:M,"",0)} -> NL05RABO0336208367
A6: 273 | B6: {=_xlfn.XLOOKUP($A6,1*Sheet1!$A:$A,Sheet1!AE:AE,"",0)} -> 388.9 | C6: {=_xlfn.XLOOKUP($A6,1*Sheet1!$A:$A,Sheet1!F:F,"",0)} -> P.H. Jagt | D6: {=_xlfn.XLOOKUP($A6,1*Sheet1!$A:$A,Sheet1!G:G,"",0)} -> Peter Jagt | E6: {=_xlfn.XLOOKUP($A6,1*Sheet1!$A:$A,Sheet1!H:H,"",0)} -> Haakweg 33 | F6: {=_xlfn.XLOOKUP($A6,1*Sheet1!$A:$A,Sheet1!I:I,"",0)} -> 3151 XD | G6: {=_xlfn.XLOOKUP($A6,1*Sheet1!$A:$A,Sheet1!J:J,"",0)} -> Hoek van Holland | H6: {=_xlfn.XLOOKUP($A6,1*Sheet1!$A:$A,Sheet1!K:K,"",0)} -> 06-51609632 | I6: {=_xlfn.XLOOKUP($A6,1*Sheet1!$A:$A,Sheet1!L:L,"",0)} -> peter@westhoekmakelaars.nl | J6: {=_xlfn.XLOOKUP($A6,1*Sheet1!$A:$A,Sheet1!M:M,"",0)} -> NL60KNAB0257738010
A7: 279 | B7: {=_xlfn.XLOOKUP($A7,1*Sheet1!$A:$A,Sheet1!AE:AE,"",0)} -> 429.36 | C7: {=_xlfn.XLOOKUP($A7,1*Sheet1!$A:$A,Sheet1!F:F,"",0)} -> v.o.f. J.C. Mulder | D7: {=_xlfn.XLOOKUP($A7,1*Sheet1!$A:$A,Sheet1!G:G,"",0)} -> Jan Mulder | E7: {=_xlfn.XLOOKUP($A7,1*Sheet1!$A:$A,Sheet1!H:H,"",0)} -> Nieuwe Tuinen 7B | F7: {=_xlfn.XLOOKUP($A7,1*Sheet1!$A:$A,Sheet1!I:I,"",0)} -> 2675 SE | G7: {=_xlfn.XLOOKUP($A7,1*Sheet1!$A:$A,Sheet1!J:J,"",0)} -> Honselersdijk | H7: {=_xlfn.XLOOKUP($A7,1*Sheet1!$A:$A,Sheet1!K:K,"",0)} -> 06-53690859 | I7: {=_xlfn.XLOOKUP($A7,1*Sheet1!$A:$A,Sheet1!L:L,"",0)} -> janmul54@gmail.com | J7: {=_xlfn.XLOOKUP($A7,1*Sheet1!$A:$A,Sheet1!M:M,"",0)} -> NL08RABO0343659077
A8: 274 | B8: {=_xlfn.XLOOKUP($A8,1*Sheet1!$A:$A,Sheet1!AE:AE,"",0)} -> 0 | C8: {=_xlfn.XLOOKUP($A8,1*Sheet1!$A:$A,Sheet1!F:F,"",0)} -> De Rembrandt B.V. | D8: {=_xlfn.XLOOKUP($A8,1*Sheet1!$A:$A,Sheet1!G:G,"",0)} -> Flip van Adrichem | E8: {=_xlfn.XLOOKUP($A8,1*Sheet1!$A:$A,Sheet1!H:H,"",0)} -> Langestraat 48 | F8: {=_xlfn.XLOOKUP($A8,1*Sheet1!$A:$A,Sheet1!I:I,"",0)} -> 2691 BH | G8: {=_xlfn.XLOOKUP($A8,1*Sheet1!$A:$A,Sheet1!J:J,"",0)} -> s-Gravenzande | H8: {=_xlfn.XLOOKUP($A8,1*Sheet1!$A:$A,Sheet1!K:K,"",0)} -> 06-41372342 | I8: {=_xlfn.XLOOKUP($A8,1*Sheet1!$A:$A,Sheet1!L:L,"",0)} -> flip@eetcafedewitte.nl | J8: {=_xlfn.XLOOKUP($A8,1*Sheet1!$A:$A,Sheet1!M:M,"",0)} -> NL21RABO0156104105
A9: 291 | B9: {=_xlfn.XLOOKUP($A9,1*Sheet1!$A:$A,Sheet1!AE:AE,"",0)} -> 13978.5 | C9: {=_xlfn.XLOOKUP($A9,1*Sheet1!$A:$A,Sheet1!F:F,"",0)} -> Lammertink Projecten B.V. | D9: {=_xlfn.XLOOKUP($A9,1*Sheet1!$A:$A,Sheet1!G:G,"",0)} -> Hans Lammertink | E9: {=_xlfn.XLOOKUP($A9,1*Sheet1!$A:$A,Sheet1!H:H,"",0)} -> Schietlood 2 | F9: {=_xlfn.XLOOKUP($A9,1*Sheet1!$A:$A,Sheet1!I:I,"",0)} -> 2495 AN | G9: {=_xlfn.XLOOKUP($A9,1*Sheet1!$A:$A,Sheet1!J:J,"",0)} -> Den Haag | H9: {=_xlfn.XLOOKUP($A9,1*Sheet1!$A:$A,Sheet1!K:K,"",0)} -> 085-2739900 | I9: {=_xlfn.XLOOKUP($A9,1*Sheet1!$A:$A,Sheet1!L:L,"",0)} -> Dennis Baak 06-24313837 (schoonzoon) / dbaak@l-groep.nl | J9: {=_xlfn.XLOOKUP($A9,1*Sheet1!$A:$A,Sheet1!M:M,"",0)} -> NL83INGB0677182783
A10: 291 | B10: {=_xlfn.XLOOKUP($A10,1*Sheet1!$A:$A,Sheet1!AE:AE,"",0)} -> 13978.5 | C10: {=_xlfn.XLOOKUP($A10,1*Sheet1!$A:$A,Sheet1!F:F,"",0)} -> Lammertink Projecten B.V. | D10: {=_xlfn.XLOOKUP($A10,1*Sheet1!$A:$A,Sheet1!G:G,"",0)} -> Hans Lammertink | E10: {=_xlfn.XLOOKUP($A10,1*Sheet1!$A:$A,Sheet1!H:H,"",0)} -> Schietlood 2 | F10: {=_xlfn.XLOOKUP($A10,1*Sheet1!$A:$A,Sheet1!I:I,"",0)} -> 2495 AN | G10: {=_xlfn.XLOOKUP($A10,1*Sheet1!$A:$A,Sheet1!J:J,"",0)} -> Den Haag | H10: {=_xlfn.XLOOKUP($A10,1*Sheet1!$A:$A,Sheet1!K:K,"",0)} -> 085-2739900 | I10: {=_xlfn.XLOOKUP($A10,1*Sheet1!$A:$A,Sheet1!L:L,"",0)} -> Dennis Baak 06-24313837 (schoonzoon) / dbaak@l-groep.nl | J10: {=_xlfn.XLOOKUP($A10,1*Sheet1!$A:$A,Sheet1!M:M,"",0)} -> NL83INGB0677182783
A11: 278 | B11: {=_xlfn.XLOOKUP($A11,1*Sheet1!$A:$A,Sheet1!AE:AE,"",0)} -> 0 | C11: {=_xlfn.XLOOKUP($A11,1*Sheet1!$A:$A,Sheet1!F:F,"",0)} -> G. Hofland | D11: {=_xlfn.XLOOKUP($A11,1*Sheet1!$A:$A,Sheet1!G:G,"",0)} -> Goos Hofland | E11: {=_xlfn.XLOOKUP($A11,1*Sheet1!$A:$A,Sheet1!H:H,"",0)} -> Lange Broekweg 46 | F11: {=_xlfn.XLOOKUP($A11,1*Sheet1!$A:$A,Sheet1!I:I,"",0)} -> 2671 DV | G11: {=_xlfn.XLOOKUP($A11,1*Sheet1!$A:$A,Sheet1!J:J,"",0)} -> Naaldwijk | H11: {=_xlfn.XLOOKUP($A11,1*Sheet1!$A:$A,Sheet1!K:K,"",0)} -> 0174-625887 | I11: {=_xlfn.XLOOKUP($A11,1*Sheet1!$A:$A,Sheet1!L:L,"",0)} -> goos@hoflandfloweringplants.nl | J11: {=_xlfn.XLOOKUP($A11,1*Sheet1!$A:$A,Sheet1!M:M,"",0)} -> NL27RABO0343661063
A12: 284 | B12: {=_xlfn.XLOOKUP($A12,1*Sheet1!$A:$A,Sheet1!AE:AE,"",0)} -> 609.67 | C12: {=_xlfn.XLOOKUP($A12,1*Sheet1!$A:$A,Sheet1!F:F,"",0)} -> M.J.W. van den Enden & B.M. van den Enden | D12: {=_xlfn.XLOOKUP($A12,1*Sheet1!$A:$A,Sheet1!G:G,"",0)} -> Barbara van den Enden | E12: {=_xlfn.XLOOKUP($A12,1*Sheet1!$A:$A,Sheet1!H:H,"",0)} -> Bospolder 4a | F12: {=_xlfn.XLOOKUP($A12,1*Sheet1!$A:$A,Sheet1!I:I,"",0)} -> 2675 BL | G12: {=_xlfn.XLOOKUP($A12,1*Sheet1!$A:$A,Sheet1!J:J,"",0)} -> Honselersdijk | H12: {=_xlfn.XLOOKUP($A12,1*Sheet1!$A:$A,Sheet1!K:K,"",0)} -> 06-51611737 Barbara / 06-54398790 Maup | I12: {=_xlfn.XLOOKUP($A12,1*Sheet1!$A:$A,Sheet1!L:L,"",0)} -> endem3@caiway.nl | J12: {=_xlfn.XLOOKUP($A12,1*Sheet1!$A:$A,Sheet1!M:M,"",0)} -> NL81INGB0112509347
A13: 335 | B13: {=_xlfn.XLOOKUP($A13,1*Sheet1!$A:$A,Sheet1!AE:AE,"",0)} -> 200 | C13: {=_xlfn.XLOOKUP($A13,1*Sheet1!$A:$A,Sheet1!F:F,"",0)} -> M.J.W. van den Enden & B.M. van den Enden | D13: {=_xlfn.XLOOKUP($A13,1*Sheet1!$A:$A,Sheet1!G:G,"",0)} -> Barbara van den Enden | E13: {=_xlfn.XLOOKUP($A13,1*Sheet1!$A:$A,Sheet1!H:H,"",0)} -> Bospolder 4a | F13: {=_xlfn.XLOOKUP($A13,1*Sheet1!$A:$A,Sheet1!I:I,"",0)} -> 2675 BL | G13: {=_xlfn.XLOOKUP($A13,1*Sheet1!$A:$A,Sheet1!J:J,"",0)} -> Honselersdijk | H13: {=_xlfn.XLOOKUP($A13,1*Sheet1!$A:$A,Sheet1!K:K,"",0)} -> 06-51611737 Barbara / 06-54398790 Maup | I13: {=_xlfn.XLOOKUP($A13,1*Sheet1!$A:$A,Sheet1!L:L,"",0)} -> endem3@caiway.nl | J13: {=_xlfn.XLOOKUP($A13,1*Sheet1!$A:$A,Sheet1!M:M,"",0)} -> NL81INGB0112509347
... A23: 289 | B23: {=_xlfn.XLOOKUP($A23,1*Sheet1!$A:$A,Sheet1!AE:AE,"",0)} -> 0 | C23: {=_xlfn.XLOOKUP($A23,1*Sheet1!$A:$A,Sheet1!F:F,"",0)} -> Stichting MCM | D23: {=_xlfn.XLOOKUP($A23,1*Sheet1!$A:$A,Sheet1!G:G,"",0)} -> J. v. Bergen | E23: {=_xlfn.XLOOKUP($A23,1*Sheet1!$A:$A,Sheet1!H:H,"",0)} -> Rijpstraat 22 | F23: {=_xlfn.XLOOKUP($A23,1*Sheet1!$A:$A,Sheet1!I:I,"",0)} -> 3151 BV | G23: {=_xlfn.XLOOKUP($A23,1*Sheet1!$A:$A,Sheet1!J:J,"",0)} -> Hoek van Holland | H23: {=_xlfn.XLOOKUP($A23,1*Sheet1!$A:$A,Sheet1!K:K,"",0)} -> 06-53739975 | I23: {=_xlfn.XLOOKUP($A23,1*Sheet1!$A:$A,Sheet1!L:L,"",0)} -> jetvbergen@gmail.com | J23: {=_xlfn.XLOOKUP($A23,1*Sheet1!$A:$A,Sheet1!M:M,"",0)} -> NL39RABO0334435080

Sheet none
A1: object_id | B1: Omschrijving | C1: Huur | D1: Max. of Debet | E1: Max. of Credit | G1: Average of Debet | H1: Average of Credit | I1: verschil avg-max | J1: max of niet
A2: 0 | B2: Algemeen woningen | C2: =IF(J2=1,D2,"") | D2: 13043.23 | E2: 90 | G2: 2142.3474 | H2: 1.125 | I2: 10900.883
A3: 2 | B3: Allard Piersonlaan 142 Den Haag | C3: =IF(J3=1,D3,"") -> 1416.85 | D3: 1416.85 | E3: 0 | G3: 1393.9333 | H3: 0 | I3: 22.916667 | J3: 1
A4: 4 | B4: Broekweg 25 Vlaardingen | C4: =IF(J4=1,D4,"") -> 1708.41 | D4: 1708.41 | E4: 0 | G4: 1674.765 | H4: 0 | I4: 33.645 | J4: 1
A5: 9 | B5: Galgeweg 48A, 's-Gravenzande | C5: =IF(J5=1,D5,"") -> 3643.5 | D5: 3643.5 | E5: 0 | G5: 3643.5 | H5: 0 | I5: 0 | J5: 1
A6: 10 | B6: Kethelweg 1B Vlaardingen | C6: =IF(J6=1,D6,"") -> 1708.41 | D6: 1708.41 | E6: 0 | G6: 1674.765 | H6: 0 | I6: 33.645 | J6: 1
A7: 11 | B7: Kethelweg 1C Vlaardingen | C7: =IF(J7=1,D7,"") -> 1708.41 | D7: 1708.41 | E7: 0 | G7: 1674.765 | H7: 0 | I7: 33.645 | J7: 1
A8: 15 | B8: Maasdijk 69 | C8: =IF(J8=1,D8,"") -> 3400 | D8: 3400 | E8: 0 | G8: 3400 | H8: 0 | I8: 0 | J8: 1
A9: 16 | B9: van Scorelstraat 73 Maassluis | C9: =IF(J9=1,D9,"") -> 2364.3 | D9: 2364.3 | E9: 0 | G9: 2317.74 | H9: 0 | I9: 46.56 | J9: 1
A10: 17 | B10: G.A. Brederolaan 75B Maassluis | C10: =IF(J10=1,D10,"") -> 1677.89 | D10: 1677.89 | E10: 0 | G10: 1644.85 | H10: 0 | I10: 33.04 | J10: 1
A11: 20 | B11: Mr. Troelstrastraat 37 Vlaardingen | C11: =IF(J11=1,D11,"") -> 1723.44 | D11: 1723.44 | E11: 0 | G11: 1689.5 | H11: 0 | I11: 33.94 | J11: 1
A12: 21 | B12: Vaartweg 106C Vlaardingen | C12: =IF(J12=1,D12,"") -> 1830.43 | D12: 1830.43 | E12: 0 | G12: 1794.385 | H12: 0 | I12: 36.045 | J12: 1
A13: 22 | B13: 2e van Leyden Gaelstraat 6, Vlaardingen | C13: =IF(J13=1,D13,"") -> 2930.56 | D13: 2930.56 | E13: 2930.56 | G13: 2705.1323 | H13: 225.42769 | I13: 225.42769 | J13: 1
A14: 25 | B14: Groenelaan 30B Schiedam | C14: =IF(J14=1,D14,"") -> 1625 | D14: 1625 | E14: 1625 | G14: 1209.7282 | H14: 147.72727 | I14: 415.27182 | J14: 1
... A29: 88 | B29: Kethelweg 66A, Vlaardingen | C29: =IF(J29=1,D29,"") -> 2593.81 | D29: 2593.81 | E29: 2491.65 | G29: 2311.7692 | H29: 207.6375 | I29: 282.04083 | J29: 1
A30: 95 | B30: Engelsestraat 16L01 Rotterdam | C30: =IF(J30=1,D30,"") | D30: 1993.32 | E30: 0 | G30: 948.79385 | H30: 0 | I30: 1044.5262
A31: 95 | B31: Engelsestraat 16L3, Rotterdam | C31: =IF(J31=1,D31,"") | D31: 3435.06 | E31: 1750 | G31: 1906.8017 | H31: 145.83333 | I31: 1528.2583
A32: 97 | B32: Burchstraat 16A, Oostburg | C32: =IF(J32=1,D32,"") -> 3550 | D32: 3550 | E32: 0 | G32: 3094.4983 | H32: 0 | I32: 455.50167 | J32: 1
A33: 99 | B33: Steenen Dijck 87, Maassluis | C33: =IF(J33=1,D33,"") -> 3383.25 | D33: 3383.25 | E33: 0 | G33: 3316.625 | H33: 0 | I33: 66.625 | J33: 1
A34: 103 | B34: Narcissenstraat 23 Rozenburg | C34: =IF(J34=1,D34,"") -> 1700 | D34: 1700 | E34: 0 | G34: 1680.7043 | H34: 0 | I34: 19.295714 | J34: 1
A35: 106 | B35: Prinses Wilhelminastraat 9, Hekendorp | C35: =IF(J35=1,D35,"") | D35: 3200 | E35: 3200 | G35: 1920 | H35: 1280 | I35: 1280
A36: 120 | B36: Plaats 10, Montfoort | C36: =IF(J36=1,D36,"") -> 2300 | D36: 2300 | E36: 0 | G36: 2300 | H36: 0 | I36: 0 | J36: 1
A37: 122 | B37: Kethelweg 66B, Vlaardingen | C37: =IF(J37=1,D37,"") -> 2593.81 | D37: 2593.81 | E37: 0 | G37: 2542.73 | H37: 0 | I37: 51.08 | J37: 1
A38: 131 | B38: Chopinstraat 35A, Vlaardingen | C38: =IF(J38=1,D38,"") -> 2165.26 | D38: 2165.26 | E38: 0 | G38: 2122.62 | H38: 0 | I38: 42.64 | J38: 1
A39: 133 | B39: Herenpad 20A, Schiedam | C39: =IF(J39=1,D39,"") -> 2075.05 | D39: 2075.05 | E39: 0 | G39: 2034.185 | H39: 0 | I39: 40.865 | J39: 1
A40: 134 | B40: Herenpad 20B, Schiedam | C40: =IF(J40=1,D40,"") -> 992.34 | D40: 992.34 | E40: 0 | G40: 972.8 | H40: 0 | I40: 19.54 | J40: 1
A41: 135 | B41: Amperestraat 36A, Schiedam | C41: =IF(J41=1,D41,"") -> 1691.63 | D41: 1691.63 | E41: 0 | G41: 1658.315 | H41: 0 | I41: 33.315 | J41: 1
A42: 148 | B42: 2e Maasbosstraat 2A Vlaardingen | C42: =IF(J42=1,D42,"") -> 1570.24 | D42: 1570.24 | E42: 0 | G42: 1430.1377 | H42: 0 | I42: 140.10231 | J42: 1
A43: 149 | B43: 2e Maasbosstraat 2B Vlaardingen | C43: =IF(J43=1,D43,"") -> 1570.24 | D43: 1570.24 | E43: 0 | G43: 1534.1667 | H43: 0 | I43: 36.073333 | J43: 1
A44: 150 | B44: 2e Maasbosstraat 2C Vlaardingen | C44: =IF(J44=1,D44,"") -> 1475.31 | D44: 1475.31 | E44: 0 | G44: 1441.4125 | H44: 0 | I44: 33.8975 | J44: 1
A45: 154 | B45: Rubensplein 6B3 Schiedam | C45: =IF(J45=1,D45,"") -> 2238.15 | D45: 2238.15 | E45: 0 | G45: 2198.0818 | H45: 0 | I45: 40.068182 | J45: 1
A46: 156 | B46: Broersvest 74c Schiedam | C46: =IF(J46=1,D46,"") -> 2051.51 | D46: 2051.51 | E46: 0 | G46: 2024.51 | H46: 0 | I46: 27 | J46: 1
A47: 160 | B47: Chopinstraat 33c Vlaardingen | C47: =IF(J47=1,D47,"") -> 1300 | D47: 1300 | E47: 0 | G47: 1300 | H47: 0 | I47: 0 | J47: 1
... A63: 191 | B63: Jan van Arkelstraat 118 Vlaardingen | C63: =IF(J63=1,D63,"") -> 895 | D63: 895 | E63: 0 | G63: 895 | H63: 0 | I63: 0 | J63: 1
A64: 192 | B64: Kaapsebos 11 Maasdijk | C64: =IF(J64=1,D64,"") | D64: 8370 | E64: 0 | G64: 6654.8 | H64: 0 | I64: 1715.2
A65: 193 | B65: Kapershoek 11 Rotterdam | C65: =IF(J65=1,D65,"") -> 1400.53 | D65: 1400.53 | E65: 0 | G65: 1372.95 | H65: 0 | I65: 27.58 | J65: 1
A66: 194 | B66: Keesomstraat 22 Vlaardingen | C66: =IF(J66=1,D66,"") -> 2336 | D66: 2336 | E66: 0 | G66: 2257.3077 | H66: 0 | I66: 78.692308 | J66: 1
A67: 195 | B67: Keesomstraat 50 Vlaardingen | C67: =IF(J67=1,D67,"") -> 895 | D67: 895 | E67: 0 | G67: 895 | H67: 0 | I67: 0 | J67: 1
A68: 196 | B68: Keesomstraat 54 Vlaardingen | C68: =IF(J68=1,D68,"") -> 1405 | D68: 1405 | E68: 0 | G68: 1368.3333 | H68: 0 | I68: 36.666667 | J68: 1
A69: 199 | B69: Kerstendijk 125 Rotterdam | C69: =IF(J69=1,D69,"") -> 1200 | D69: 1200 | E69: 0 | G69: 1200 | H69: 0 | I69: 0 | J69: 1
...

Sheet Tradiro huur
A1: object_id | B1: Omschrijving | C1: Huur
A2: 0 | B2: Algemeen woningen
A3: 2 | B3: Allard Piersonlaan 142 Den Haag | C3: 1416.85
A4: 4 | B4: Broekweg 25 Vlaardingen | C4: 1708.41
A5: 9 | B5: Galgeweg 48A, 's-Gravenzande | C5: 3643.5
A6: 10 | B6: Kethelweg 1B Vlaardingen | C6: 1708.41
A7: 11 | B7: Kethelweg 1C Vlaardingen | C7: 1708.41
A8: 15 | B8: Maasdijk 69 | C8: 3400
A9: 16 | B9: van Scorelstraat 73 Maassluis | C9: 2364.3
A10: 17 | B10: G.A. Brederolaan 75B Maassluis | C10: 1677.89
A11: 20 | B11: Mr. Troelstrastraat 37 Vlaardingen | C11: 1723.44
A12: 21 | B12: Vaartweg 106C Vlaardingen | C12: 1830.43
A13: 22 | B13: 2e van Leyden Gaelstraat 6, Vlaardingen | C13: 2930.56
A14: 25 | B14: Groenelaan 30B Schiedam | C14: 1625
... A29: 88 | B29: Kethelweg 66A, Vlaardingen | C29: 2593.81
A30: 95 | B30: Engelsestraat 16L01 Rotterdam
A31: 95 | B31: Engelsestraat 16L3, Rotterdam
A32: 97 | B32: Burchstraat 16A, Oostburg | C32: 3550
A33: 99 | B33: Steenen Dijck 87, Maassluis | C33: 3383.25
A34: 103 | B34: Narcissenstraat 23 Rozenburg | C34: 1700
A35: 106 | B35: Prinses Wilhelminastraat 9, Hekendorp
A36: 120 | B36: Plaats 10, Montfoort | C36: 2300
A37: 122 | B37: Kethelweg 66B, Vlaardingen | C37: 2593.81
A38: 131 | B38: Chopinstraat 35A, Vlaardingen | C38: 2165.26
A39: 133 | B39: Herenpad 20A, Schiedam | C39: 2075.05
A40: 134 | B40: Herenpad 20B, Schiedam | C40: 992.34
A41: 135 | B41: Amperestraat 36A, Schiedam | C41: 1691.63
A42: 148 | B42: 2e Maasbosstraat 2A Vlaardingen | C42: 1570.24
A43: 149 | B43: 2e Maasbosstraat 2B Vlaardingen | C43: 1570.24
A44: 150 | B44: 2e Maasbosstraat 2C Vlaardingen | C44: 1475.31
A45: 154 | B45: Rubensplein 6B3 Schiedam | C45: 2238.15
A46: 156 | B46: Broersvest 74c Schiedam | C46: 2051.51
A47: 160 | B47: Chopinstraat 33c Vlaardingen | C47: 1300
... A63: 191 | B63: Jan van Arkelstraat 118 Vlaardingen | C63: 895
A64: 192 | B64: Kaapsebos 11 Maasdijk
A65: 193 | B65: Kapershoek 11 Rotterdam | C65: 1400.53
A66: 194 | B66: Keesomstraat 22 Vlaardingen | C66: 2336
A67: 195 | B67: Keesomstraat 50 Vlaardingen | C67: 895
A68: 196 | B68: Keesomstraat 54 Vlaardingen | C68: 1405
A69: 199 | B69: Kerstendijk 125 Rotterdam | C69: 1200
...

Sheet Tradiro Gwe
A1: object_id | B1: Omschrijving | C1: Per. | D1: Max. of Debet
A2: 0 | B2: Algemeen woningen | D2: 19375.27
A3: 4 | B3: Broekweg 25 Vlaardingen | D3: 260.15
A4: 9 | B4: Galgeweg 48A, 's-Gravenzande | D4: 773.78
A5: 10 | B5: Kethelweg 1B Vlaardingen | D5: 85.24
A6: 11 | B6: Kethelweg 1C Vlaardingen | D6: 32.11
A7: 15 | B7: Maasdijk 69 | D7: 2470.8
A8: 16 | B8: van Scorelstraat 73 Maassluis | D8: 218.11
A9: 17 | B9: G.A. Brederolaan 75B Maassluis | D9: 208.85
A10: 20 | B10: Mr. Troelstrastraat 37 Vlaardingen | D10: 181.36
A11: 21 | B11: Vaartweg 106C Vlaardingen | D11: 256.89
A12: 22 | B12: 2e van Leyden Gaelstraat 6, Vlaardingen | D12: 482.84
A13: 25 | B13: Groenelaan 30B Schiedam | D13: 190.22
... A165: 111 | B165: Oosterstraat 89 Vlaardingen | D165: 315.48

Sheet Tradiro VVE
A1: object_id | B1: Omschrijving | C1: Per. | D1: Max. of Debet
A2: 0 | B2: Algemeen woningen | D2: 0
A3: 30 | B3: Curacaolaan 88 Vlaardingen | D3: 329.66
A4: 183 | B4: Hugo de Vriesstraat 54 Vlaardingen | D4: 300
A5: 191 | B5: Jan van Arkelstraat 118 Vlaardingen | D5: 185
A6: 195 | B6: Keesomstraat 50 Vlaardingen | D6: 205.35
A7: 208 | B7: L.A. Kesperweg 31a Vlaardingen | D7: 186.34
A8: 213 | B8: Mr. Troelstrastraat 11 Vlaardingen | D8: 150
A9: 228 | B9: Parallelweg 122a Vlaardingen | D9: 110
A10: 234 | B10: Rotterdamsedijk 154b Schiedam | D10: 50
A11: 236 | B11: Schalkeroord 389 Rotterdam | D11: 95.64
A12: 238 | B12: Van der Werffstraat 370 Vlaardingen | D12: 726.26
A13: 245 | B13: Van der Werffstraat 240 Vlaardingen | D13: 185.9
... A17: 470 | B17: v.d. Waalstraat 16 Vlaardingen | D17: 1077.81

Sheet Tradiro internet
A1: object_id | B1: Omschrijving | C1: Per. | D1: Max. of Debet
A2: 0 | B2: Algemeen woningen | D2: 5187.65
A3: 1 | B3: Nunspeetlaan 14 | D3: 22.82
A4: 2 | B4: Allard Piersonlaan 142 Den Haag | D4: 25.1
A5: 4 | B5: Broekweg 25 Vlaardingen | D5: 25.2
A6: 9 | B6: Galgeweg 48A, 's-Gravenzande | D6: 50.37
A7: 10 | B7: Kethelweg 1B Vlaardingen | D7: 25.1
A8: 11 | B8: Kethelweg 1C Vlaardingen | D8: 25.1
A9: 16 | B9: van Scorelstraat 73 Maassluis | D9: 67.36
A10: 17 | B10: G.A. Brederolaan 75B Maassluis | D10: 33.06
A11: 20 | B11: Mr. Troelstrastraat 37 Vlaardingen | D11: 25.1
A12: 21 | B12: Vaartweg 106C Vlaardingen | D12: 25.1
A13: 22 | B13: 2e van Leyden Gaelstraat 6, Vlaardingen | D13: 25.1
... A112: 42 | B112: Parallelweg 110A Vlaardingen | D112: 22.82
