Workbook

Sheet pivot 
B3: Column Labels
B4: 01 | D4: 02 | F4: 03 | H4: 04 | J4: 05 | L4: 06 | N4: 07 | P4: 08 | R4: 09 | T4: 10 | V4: 11 | X4: 12 | Z4: (blank) | AB4: Total Sum of c | AC4: Total Sum of d
A5: Row Labels | B5: Sum of c | C5: Sum of d | D5: Sum of c | E5: Sum of d | F5: Sum of c | G5: Sum of d | H5: Sum of c | I5: Sum of d | J5: Sum of c | K5: Sum of d | L5: Sum of c | M5: Sum of d | N5: Sum of c | O5: Sum of d | P5: Sum of c | Q5: Sum of d | R5: Sum of c | S5: Sum of d | T5: Sum of c | U5: Sum of d | V5: Sum of c | W5: Sum of d | X5: Sum of c | Y5: Sum of d | Z5: Sum of c | AA5: Sum of d
A6: 00088 - L. Keizer | B6: 1837.5 | C6: 1837.5 | AB6: 1837.5 | AC6: 1837.5
A7: (blank) | B7: 1837.5 | C7: 1837.5 | AB7: 1837.5 | AC7: 1837.5
A8: 100089 - Uitzendbureau Bakker B.V. | B8: 12000 | C8: 8000 | D8: 20107.12 | E8: 10450 | F8: 25302.33 | G8: 17000 | H8: 23650 | I8: 21100 | J8: 19650 | K8: 13100 | L8: 19650 | M8: 13100 | N8: 19650 | O8: 13100 | P8: 19650 | Q8: 13100 | R8: 19650 | S8: 13100 | T8: 32676.01 | U8: 19869.44 | V8: 46353.78 | W8: 30550.67 | X8: 42600 | Y8: 28400 | AB8: 300939.24 | AC8: 200870.11
A9: 0082 - Kanaal van Steenenhoek z z 10 Gorinchem | F9: 9952.33 | G9: 4100 | H9: 12300 | I9: 8200 | J9: 12300 | K9: 8200 | L9: 12300 | M9: 8200 | N9: 12300 | O9: 8200 | P9: 12300 | Q9: 8200 | R9: 12300 | S9: 8200 | T9: 12300 | U9: 8200 | V9: 12300 | W9: 8200 | X9: 12300 | Y9: 8200 | AB9: 120652.33 | AC9: 77900
A10: Huur | F10: 5852.33 | H10: 4100 | J10: 4100 | L10: 4100 | N10: 4100 | P10: 4100 | R10: 4100 | T10: 4100 | V10: 4100 | X10: 4100 | AB10: 42752.33
A11: 8105 - Omzet laag | F11: 5852.33 | H11: 4100 | J11: 4100 | L11: 4100 | N11: 4100 | P11: 4100 | R11: 4100 | T11: 4100 | V11: 4100 | X11: 4100 | AB11: 42752.33
A12: Huur (01-01-2026 - 31-01-2026) | X12: 4100 | Y12: 4100 | AB12: 4100 | AC12: 4100
A13: 1370 - Transitoria debet | X13: 4100 | AB13: 4100
A14: 8105 - Omzet laag | Y14: 4100 | AC14: 4100
A15: Huur (01-04-2025 - 30-04-2025) | F15: 4100 | G15: 4100 | H15: 4100 | I15: 4100 | AB15: 8200 | AC15: 8200
A16: 1370 - Transitoria debet | F16: 4100 | I16: 4100 | AB16: 4100 | AC16: 4100
A17: 8105 - Omzet laag | G17: 4100 | H17: 4100 | AB17: 4100 | AC17: 4100
A18: Huur (01-05-2025 - 31-05-2025) | H18: 4100 | I18: 4100 | J18: 4100 | K18: 4100 | AB18: 8200 | AC18: 8200
A19: 1370 - Transitoria debet | H19: 4100 | K19: 4100 | AB19: 4100 | AC19: 4100
A20: 8105 - Omzet laag | I20: 4100 | J20: 4100 | AB20: 4100 | AC20: 4100
A21: Huur (01-06-2025 - 30-06-2025) | J21: 4100 | K21: 4100 | L21: 4100 | M21: 4100 | AB21: 8200 | AC21: 8200
A22: 1370 - Transitoria debet | J22: 4100 | M22: 4100 | AB22: 4100 | AC22: 4100
A23: 8105 - Omzet laag | K23: 4100 | L23: 4100 | AB23: 4100 | AC23: 4100
A24: Huur (01-07-2025 - 31-07-2025) | L24: 4100 | M24: 4100 | N24: 4100 | O24: 4100 | AB24: 8200 | AC24: 8200
A25: 1370 - Transitoria debet | L25: 4100 | O25: 4100 | AB25: 4100 | AC25: 4100
A26: 8105 - Omzet laag | M26: 4100 | N26: 4100 | AB26: 4100 | AC26: 4100
A27: Huur (01-08-2025 - 31-08-2025) | N27: 4100 | O27: 4100 | P27: 4100 | Q27: 4100 | AB27: 8200 | AC27: 8200
A28: 1370 - Transitoria debet | N28: 4100 | Q28: 4100 | AB28: 4100 | AC28: 4100
A29: 8105 - Omzet laag | O29: 4100 | P29: 4100 | AB29: 4100 | AC29: 4100
A30: Huur (01-09-2025 - 30-09-2025) | P30: 4100 | Q30: 4100 | R30: 4100 | S30: 4100 | AB30: 8200 | AC30: 8200
A31: 1370 - Transitoria debet | P31: 4100 | S31: 4100 | AB31: 4100 | AC31: 4100
A32: 8105 - Omzet laag | Q32: 4100 | R32: 4100 | AB32: 4100 | AC32: 4100
A33: Huur (01-10-2025 - 31-10-2025) | R33: 4100 | S33: 4100 | T33: 4100 | U33: 4100 | AB33: 8200 | AC33: 8200
A34: 1370 - Transitoria debet | R34: 4100 | U34: 4100 | AB34: 4100 | AC34: 4100
A35: 8105 - Omzet laag | S35: 4100 | T35: 4100 | AB35: 4100 | AC35: 4100
A36: Huur (01-11-2025 - 30-11-2025) | T36: 4100 | U36: 4100 | V36: 4100 | W36: 4100 | AB36: 8200 | AC36: 8200
A37: 1370 - Transitoria debet | T37: 4100 | W37: 4100 | AB37: 4100 | AC37: 4100
A38: 8105 - Omzet laag | U38: 4100 | V38: 4100 | AB38: 4100 | AC38: 4100
A39: Huur (01-12-2025 - 31-12-2025) | V39: 4100 | W39: 4100 | X39: 4100 | Y39: 4100 | AB39: 8200 | AC39: 8200
A40: 1370 - Transitoria debet | V40: 4100 | Y40: 4100 | AB40: 4100 | AC40: 4100
A41: 8105 - Omzet laag | W41: 4100 | X41: 4100 | AB41: 4100 | AC41: 4100
A42: 0217 - Middelrode 8, ROTTERDAM | T42: 3550.68 | U42: 1775.34 | V42: 6275.34 | W42: 4025.34 | X42: 6750 | Y42: 4500 | AB42: 16576.02 | AC42: 10300.68
...

Sheet Datasheet
A1: Jaar | B1: Periode | C1: Maand pivot | D1: Boekjaar / Periode | E1: Kostendrager | F1: Datum | G1: Bkst.nr. | H1: Grootboekrekening | I1: Omschrijving | J1: Kostenplaats | K1: Relatie | L1: d | M1: c | N1: saldo
A2: {=_xlfn.TEXTSPLIT(D2," - ",TRUE,1)} -> 2025 | B2: 1 | C2: =_xlfn.XLOOKUP(B2*1,List!A:A,List!B:B,"",0) -> 01 | D2: 2025 - 1 | F2: 45688 | G2: 25910187 | H2: 8105 - Omzet laag | I2: Huur (01-01-2025 - 31-01-2025) | J2: 0135 - Amperestraat 36A Schiedam | K2: 20 - Tradiro Services B.V. | M2: 1625 | N2: -1625
A3: {=_xlfn.TEXTSPLIT(D3," - ",TRUE,1)} -> 2025 | B3: 1 | C3: =_xlfn.XLOOKUP(B3*1,List!A:A,List!B:B,"",0) -> 01 | D3: 2025 - 1 | F3: 45672 | G3: 25910555 | H3: 8105 - Omzet laag | I3: Huur (01-02-2025 - 28-02-2025) | J3: 0061 - Dwarsweg 44 , Rozenburg | K3: 50329 - Impianti Industriala S.P.A. NEDERLAND BRANCH | L3: 4568.15 | N3: 4568.15
A4: {=_xlfn.TEXTSPLIT(D4," - ",TRUE,1)} -> 2025 | B4: 1 | C4: =_xlfn.XLOOKUP(B4*1,List!A:A,List!B:B,"",0) -> 01 | D4: 2025 - 1 | F4: 45688 | G4: 25910054 | H4: 8105 - Omzet laag | I4: Huur (01-01-2025 - 31-01-2025) | J4: 0020 - Mr. Troelstrastraat 37 Vlaardingen | K4: 20 - Tradiro Services B.V. | M4: 1655.56 | N4: -1655.56
A5: {=_xlfn.TEXTSPLIT(D5," - ",TRUE,1)} -> 2025 | B5: 1 | C5: =_xlfn.XLOOKUP(B5*1,List!A:A,List!B:B,"",0) -> 01 | D5: 2025 - 1 | F5: 45672 | G5: 25910909 | H5: 8105 - Omzet laag | I5: Huur (01-02-2025 - 28-02-2025) | J5: 0128 - Tesselschadelaan 45, Roosendaal | K5: 50429 - EG Facility & Services BV | L5: 2225 | N5: 2225
A6: {=_xlfn.TEXTSPLIT(D6," - ",TRUE,1)} -> 2025 | B6: 1 | C6: =_xlfn.XLOOKUP(B6*1,List!A:A,List!B:B,"",0) -> 01 | D6: 2025 - 1 | F6: 45672 | G6: 25910699 | H6: 1370 - Transitoria debet | I6: Huur (01-02-2025 - 28-02-2025) | J6: 0033 - Kethelweg 66C Vlaardingen | K6: 20 - Tradiro Services B.V. | M6: 2000 | N6: -2000
A7: {=_xlfn.TEXTSPLIT(D7," - ",TRUE,1)} -> 2025 | B7: 1 | C7: =_xlfn.XLOOKUP(B7*1,List!A:A,List!B:B,"",0) -> 01 | D7: 2025 - 1 | F7: 45672 | G7: 25800193 | H7: 8105 - Omzet laag | I7: Huur | J7: 0018 - Meester G. Groen van Prinsterlaan 313 Amstelveen | K7: 50311 - Labour Housing BV | M7: 1975 | N7: -1975
A8: {=_xlfn.TEXTSPLIT(D8," - ",TRUE,1)} -> 2025 | B8: 1 | C8: =_xlfn.XLOOKUP(B8*1,List!A:A,List!B:B,"",0) -> 01 | D8: 2025 - 1 | F8: 45688 | G8: 25910039 | H8: 1370 - Transitoria debet | I8: Huur (01-01-2025 - 31-01-2025) | J8: 0255 - Middenbaan Noord 20B, Hoogvliet | K8: 50251 - Vastgoed Spijkenisse | L8: 2795 | N8: 2795
A9: {=_xlfn.TEXTSPLIT(D9," - ",TRUE,1)} -> 2025 | B9: 1 | C9: =_xlfn.XLOOKUP(B9*1,List!A:A,List!B:B,"",0) -> 01 | D9: 2025 - 1 | F9: 45672 | G9: 25800146 | H9: 8105 - Omzet laag | I9: Huur | J9: 0170 - Goudestein 30 Rotterdam | K9: 100094 - I.T.S. SR.L. (INDUSTRIAL TECHNICAL SERVICES), BRAN | M9: 0 | N9: 0
A10: {=_xlfn.TEXTSPLIT(D10," - ",TRUE,1)} -> 2025 | B10: 1 | C10: =_xlfn.XLOOKUP(B10*1,List!A:A,List!B:B,"",0) -> 01 | D10: 2025 - 1 | F10: 45688 | G10: 25912716 | H10: 1370 - Transitoria debet | I10: Huur (01-01-2025 - 31-01-2025) | J10: 0130 - Van Langendonckstraat 80 Rotterdam | K10: 16 - United Homes B.V. | L10: 2199.12 | N10: 2199.12
A11: {=_xlfn.TEXTSPLIT(D11," - ",TRUE,1)} -> 2025 | B11: 1 | C11: =_xlfn.XLOOKUP(B11*1,List!A:A,List!B:B,"",0) -> 01 | D11: 2025 - 1 | F11: 45688 | G11: 25910020 | H11: 8105 - Omzet laag | I11: Huur (01-01-2025 - 31-01-2025) | J11: 0092 - Lange Brink 3 Luttelgeest | K11: 50188 - Werckpost Service B.V. | M11: 3500 | N11: -3500
A12: {=_xlfn.TEXTSPLIT(D12," - ",TRUE,1)} -> 2025 | B12: 1 | C12: =_xlfn.XLOOKUP(B12*1,List!A:A,List!B:B,"",0) -> 01 | D12: 2025 - 1 | F12: 45672 | G12: 25800222 | H12: 8105 - Omzet laag | I12: Huur | J12: 0106 - Prinses Wilhelminastraat 9 Hekendorp | K12: 20 - Tradiro Services B.V. | M12: 3200 | N12: -3200
A13: {=_xlfn.TEXTSPLIT(D13," - ",TRUE,1)} -> 2025 | B13: 1 | C13: =_xlfn.XLOOKUP(B13*1,List!A:A,List!B:B,"",0) -> 01 | D13: 2025 - 1 | F13: 45688 | G13: 25700545 | H13: 7100 - Huur woningen | I13: huur januari | J13: 0164 - Sint Annalandstraat 116 Rotterdam | K13: 20 - Tradiro Services B.V. | L13: 307.09 | N13: 307.09
A14: {=_xlfn.TEXTSPLIT(D14," - ",TRUE,1)} -> 2025 | B14: 1 | C14: =_xlfn.XLOOKUP(B14*1,List!A:A,List!B:B,"",0) -> 01 | D14: 2025 - 1 | F14: 45672 | G14: 25800166 | H14: 8105 - Omzet laag | I14: Huur | J14: 0312 - Kerkweg 9a [huis 333] Hensbroek | K14: 50311 - Labour Housing BV | M14: 3275 | N14: -3275
A15: {=_xlfn.TEXTSPLIT(D15," - ",TRUE,1)} -> 2025 | B15: 1 | C15: =_xlfn.XLOOKUP(B15*1,List!A:A,List!B:B,"",0) -> 01 | D15: 2025 - 1 | F15: 45688 | G15: 25910301 | H15: 8105 - Omzet laag | I15: Huur (01-01-2025 - 31-01-2025) | J15: 0010 - Kethelweg 1B Vlaardingen | K15: 20 - Tradiro Services B.V. | M15: 1641.12 | N15: -1641.12
A16: {=_xlfn.TEXTSPLIT(D16," - ",TRUE,1)} -> 2025 | B16: 1 | C16: =_xlfn.XLOOKUP(B16*1,List!A:A,List!B:B,"",0) -> 01 | D16: 2025 - 1 | F16: 45688 | G16: 25910224 | H16: 1370 - Transitoria debet | I16: Huur (01-01-2025 - 31-01-2025) | J16: 0061 - Dwarsweg 44 , Rozenburg | K16: 50329 - Impianti Industriala S.P.A. NEDERLAND BRANCH | L16: 4568.15 | N16: 4568.15
A17: {=_xlfn.TEXTSPLIT(D17," - ",TRUE,1)} -> 2025 | B17: 1 | C17: =_xlfn.XLOOKUP(B17*1,List!A:A,List!B:B,"",0) -> 01 | D17: 2025 - 1 | F17: 45688 | G17: 25910216 | H17: 8105 - Omzet laag | I17: Huur (01-01-2025 - 31-01-2025) | J17: 0024 - Desiree Geeraertstraat 1 C, Baarle-Nassau | K17: 50314 - NL Realty B.V. | M17: 3875 | N17: -3875
A18: {=_xlfn.TEXTSPLIT(D18," - ",TRUE,1)} -> 2025 | B18: 1 | C18: =_xlfn.XLOOKUP(B18*1,List!A:A,List!B:B,"",0) -> 01 | D18: 2025 - 1 | F18: 45688 | G18: 25910103 | H18: 1370 - Transitoria debet | I18: Huur (01-01-2025 - 31-01-2025) | J18: 0144 - Scheepjesbrug 433 Meerkerk | K18: 50402 - Flextalent4u Uitzenden B.V. | L18: 3798 | N18: 3798
A19: {=_xlfn.TEXTSPLIT(D19," - ",TRUE,1)} -> 2025 | B19: 1 | C19: =_xlfn.XLOOKUP(B19*1,List!A:A,List!B:B,"",0) -> 01 | D19: 2025 - 1 | F19: 45688 | G19: 25910119 | H19: 8105 - Omzet laag | I19: Huur (01-01-2025 - 31-01-2025) | J19: 0249 - Tholenstraat 114 Rotterdam | K19: 100109 - Europe-jobs B.V. | M19: 1585 | N19: -1585
A20: {=_xlfn.TEXTSPLIT(D20," - ",TRUE,1)} -> 2025 | B20: 1 | C20: =_xlfn.XLOOKUP(B20*1,List!A:A,List!B:B,"",0) -> 01 | D20: 2025 - 1 | F20: 45688 | G20: 25912828 | H20: 8105 - Omzet laag | I20: Huur (01-01-2025 - 31-01-2025) | J20: 0206 - Kruiningenstraat 152 Rotterdam | K20: 100094 - I.T.S. SR.L. (INDUSTRIAL TECHNICAL SERVICES), BRAN | L20: 1750 | N20: 1750
A21: {=_xlfn.TEXTSPLIT(D21," - ",TRUE,1)} -> 2025 | B21: 1 | C21: =_xlfn.XLOOKUP(B21*1,List!A:A,List!B:B,"",0) -> 01 | D21: 2025 - 1 | F21: 45672 | G21: 25910693 | H21: 8105 - Omzet laag | I21: Huur (01-02-2025 - 28-02-2025) | J21: 0011 - Kethelweg 1C, Vlaardingen | K21: 20 - Tradiro Services B.V. | L21: 1641.12 | N21: 1641.12
A22: {=_xlfn.TEXTSPLIT(D22," - ",TRUE,1)} -> 2025 | B22: 1 | C22: =_xlfn.XLOOKUP(B22*1,List!A:A,List!B:B,"",0) -> 01 | D22: 2025 - 1 | F22: 45672 | G22: 25910711 | H22: 8105 - Omzet laag | I22: Huur (01-02-2025 - 28-02-2025) | J22: A-00335 - Korte Singelstraat 21C Schiedam | K22: 50368 - Transport People B.V. | L22: 2270 | N22: 2270
A23: {=_xlfn.TEXTSPLIT(D23," - ",TRUE,1)} -> 2025 | B23: 1 | C23: =_xlfn.XLOOKUP(B23*1,List!A:A,List!B:B,"",0) -> 01 | D23: 2025 - 1 | F23: 45672 | G23: 25800083 | H23: 8105 - Omzet laag | I23: Huur | J23: 0142 - Wilhelmina Druckerstraat 68 Coevorden | K23: 50446 - C-Flex B.V. | M23: 2300 | N23: -2300
A24: {=_xlfn.TEXTSPLIT(D24," - ",TRUE,1)} -> 2025 | B24: 1 | C24: =_xlfn.XLOOKUP(B24*1,List!A:A,List!B:B,"",0) -> 01 | D24: 2025 - 1 | F24: 45680 | G24: 25910951 | H24: 1370 - Transitoria debet | I24: Huur (01-08-2024 - 31-08-2024) | J24: 0112 - Oudewerfslaan 84 Winschoten | K24: 16 - United Homes B.V. | L24: 2221.06 | N24: 2221.06
A25: {=_xlfn.TEXTSPLIT(D25," - ",TRUE,1)} -> 2025 | B25: 1 | C25: =_xlfn.XLOOKUP(B25*1,List!A:A,List!B:B,"",0) -> 01 | D25: 2025 - 1 | F25: 45688 | G25: 25910113 | H25: 1370 - Transitoria debet | I25: Huur (01-01-2025 - 31-01-2025) | J25: 0200 - Stal 355 Drachten | K25: 50312 - THS B.V. | L25: 2376.92 | N25: 2376.92
A26: {=_xlfn.TEXTSPLIT(D26," - ",TRUE,1)} -> 2025 | B26: 1 | C26: =_xlfn.XLOOKUP(B26*1,List!A:A,List!B:B,"",0) -> 01 | D26: 2025 - 1 | F26: 45642 | G26: 25700022 | H26: 7100 - Huur woningen | I26: Westhavendomein BV huur Januari 2025 | J26: A-00277 - 2e van Leydengaelstraat 6 Vlaardingen | K26: 50425 - Westhavendomein BV | L26: 2645 | N26: 2645
A27: {=_xlfn.TEXTSPLIT(D27," - ",TRUE,1)} -> 2025 | B27: 1 | C27: =_xlfn.XLOOKUP(B27*1,List!A:A,List!B:B,"",0) -> 01 | D27: 2025 - 1 | F27: 45688 | G27: 25910001 | H27: 1370 - Transitoria debet | I27: Huur (01-01-2025 - 31-01-2025) | J27: 0011 - Kethelweg 1C, Vlaardingen | K27: 20 - Tradiro Services B.V. | L27: 1641.12 | N27: 1641.12
A28: {=_xlfn.TEXTSPLIT(D28," - ",TRUE,1)} -> 2025 | B28: 1 | C28: =_xlfn.XLOOKUP(B28*1,List!A:A,List!B:B,"",0) -> 01 | D28: 2025 - 1 | F28: 45672 | G28: 25910369 | H28: 1370 - Transitoria debet | I28: Huur (01-02-2025 - 28-02-2025) | J28: 0239 - Schoonegge 110 Rotterdam | K28: 50182 - dockHolland Huisvesting B.V. | M28: 2468.7 | N28: -2468.7
A29: {=_xlfn.TEXTSPLIT(D29," - ",TRUE,1)} -> 2025 | B29: 1 | C29: =_xlfn.XLOOKUP(B29*1,List!A:A,List!B:B,"",0) -> 01 | D29: 2025 - 1 | F29: 45688 | G29: 25910125 | H29: 1370 - Transitoria debet | I29: Huur (01-01-2025 - 31-01-2025) | J29: 0137 - Venkelstraat 29a Brielle | K29: 50222 - Flexvesting B.V. | L29: 3125 | N29: 3125
A30: {=_xlfn.TEXTSPLIT(D30," - ",TRUE,1)} -> 2025 | B30: 1 | C30: =_xlfn.XLOOKUP(B30*1,List!A:A,List!B:B,"",0) -> 01 | D30: 2025 - 1 | F30: 45674 | G30: 25910945 | H30: 8105 - Omzet laag | I30: Huur (01-02-2025 - 28-02-2025) | J30: 0095 - Engelsestraat 16L3 Rotterdam | K30: 20 - Tradiro Services B.V. | M30: 1750 | N30: -1750
A31: {=_xlfn.TEXTSPLIT(D31," - ",TRUE,1)} -> 2025 | B31: 1 | C31: =_xlfn.XLOOKUP(B31*1,List!A:A,List!B:B,"",0) -> 01 | D31: 2025 - 1 | F31: 45688 | G31: 25910091 | H31: 1370 - Transitoria debet | I31: Huur (01-01-2025 - 31-01-2025) | J31: 0272 - Professor Kamerlingh Onneslaan 134 B3, Schiedam | K31: 50347 - Housing en Transport Facilities B.V. | L31: 1380 | N31: 1380
A32: {=_xlfn.TEXTSPLIT(D32," - ",TRUE,1)} -> 2025 | B32: 1 | C32: =_xlfn.XLOOKUP(B32*1,List!A:A,List!B:B,"",0) -> 01 | D32: 2025 - 1 | F32: 45672 | G32: 25910539 | H32: 8105 - Omzet laag | I32: Huur (01-02-2025 - 28-02-2025) | J32: 0058 - Deugenweerd 18 Borculo | K32: 50188 - Werckpost Service B.V. | L32: 2860 | N32: 2860
A33: {=_xlfn.TEXTSPLIT(D33," - ",TRUE,1)} -> 2025 | B33: 1 | C33: =_xlfn.XLOOKUP(B33*1,List!A:A,List!B:B,"",0) -> 01 | D33: 2025 - 1 | F33: 45672 | G33: 25910819 | H33: 1370 - Transitoria debet | I33: Huur (01-02-2025 - 28-02-2025) | J33: 0113 - Peursumseweg 119 Giessenburg | K33: 50402 - Flextalent4u Uitzenden B.V. | M33: 2954 | N33: -2954
A34: {=_xlfn.TEXTSPLIT(D34," - ",TRUE,1)} -> 2025 | B34: 1 | C34: =_xlfn.XLOOKUP(B34*1,List!A:A,List!B:B,"",0) -> 01 | D34: 2025 - 1 | F34: 45688 | G34: 25910056 | H34: 1370 - Transitoria debet | I34: Huur (01-01-2025 - 31-01-2025) | J34: 0104 - Narcissenstraat 37, Rozenburg | K34: 50157 - AmDor Projecten B.V. | L34: 2564.13 | N34: 2564.13
A35: {=_xlfn.TEXTSPLIT(D35," - ",TRUE,1)} -> 2025 | B35: 1 | C35: =_xlfn.XLOOKUP(B35*1,List!A:A,List!B:B,"",0) -> 01 | D35: 2025 - 1 | F35: 45672 | G35: 25800198 | H35: 8105 - Omzet laag | I35: Huur | J35: 0258 - Middenbaan Noord 22B, Hoogvliet | K35: 50251 - Vastgoed Spijkenisse | M35: 2400.13 | N35: -2400.13
A36: {=_xlfn.TEXTSPLIT(D36," - ",TRUE,1)} -> 2025 | B36: 1 | C36: =_xlfn.XLOOKUP(B36*1,List!A:A,List!B:B,"",0) -> 01 | D36: 2025 - 1 | F36: 45688 | G36: 25910175 | H36: 8105 - Omzet laag | I36: Huur (01-01-2025 - 31-01-2025) | J36: 0293 - Akkerweg 41 [014], Den Oever | K36: 50314 - NL Realty B.V. | M36: 4620.9 | N36: -4620.9
A37: {=_xlfn.TEXTSPLIT(D37," - ",TRUE,1)} -> 2025 | B37: 1 | C37: =_xlfn.XLOOKUP(B37*1,List!A:A,List!B:B,"",0) -> 01 | D37: 2025 - 1 | F37: 45685 | G37: 25910982 | H37: 8105 - Omzet laag | I37: Huur (01-02-2025 - 28-02-2025) | J37: 0164 - Sint Annalandstraat 116 Rotterdam | K37: 100174 - Workforce Housing Holland B.V. | L37: 1900 | N37: 1900
A38: {=_xlfn.TEXTSPLIT(D38," - ",TRUE,1)} -> 2025 | B38: 1 | C38: =_xlfn.XLOOKUP(B38*1,List!A:A,List!B:B,"",0) -> 01 | D38: 2025 - 1 | F38: 45688 | G38: 25910096 | H38: 8105 - Omzet laag | I38: Huur (01-01-2025 - 31-01-2025) | J38: A-00239 - Rivierdijk 794 (onder) Hardinxveld - Giessendam | K38: 35 - Interim Jobs B.V. | M38: 1972.8 | N38: -1972.8
A39: {=_xlfn.TEXTSPLIT(D39," - ",TRUE,1)} -> 2025 | B39: 1 | C39: =_xlfn.XLOOKUP(B39*1,List!A:A,List!B:B,"",0) -> 01 | D39: 2025 - 1 | F39: 45672 | G39: 25910847 | H39: 8105 - Omzet laag | I39: Huur (01-02-2025 - 28-02-2025) | J39: A-00373 - Professor Kamerlingh Onneslaan 134 A Schiedam | K39: 50347 - Housing en Transport Facilities B.V. | L39: 1860 | N39: 1860
A40: {=_xlfn.TEXTSPLIT(D40," - ",TRUE,1)} -> 2025 | B40: 1 | C40: =_xlfn.XLOOKUP(B40*1,List!A:A,List!B:B,"",0) -> 01 | D40: 2025 - 1 | F40: 45672 | G40: 25910567 | H40: 1370 - Transitoria debet | I40: Huur (01-02-2025 - 28-02-2025) | J40: 0006 - Enschotsestraat 163 Tilburg | K40: 50396 - Head Vastgoed B.V. | M40: 5486 | N40: -5486
...

Sheet List
A1: 1 | B1: 01
A2: 2 | B2: 02
A3: 3 | B3: 03
A4: 4 | B4: 04
A5: 5 | B5: 05
A6: 6 | B6: 06
A7: 7 | B7: 07
A8: 8 | B8: 08
A9: 9 | B9: 09
A10: 10 | B10: 10
A11: 11 | B11: 11
A12: 12 | B12: 12
