Workbook

Sheet VVE
A1: Jaar | B1: 2025
A2: Grootboekrekening | B2: Kosten VvE woningen
A4: object_id | B4: Omschrijving | C4: Per. | D4: Max. of Debet | E4: Max. of Credit
A5: 0 | B5: Algemeen woningen | D5: 0 | E5: 20
A6: 30 | B6: Curacaolaan 88 Vlaardingen | D6: 329.66 | E6: 0
A7: 183 | B7: Hugo de Vriesstraat 54 Vlaardingen | D7: 300 | E7: 0
A8: 191 | B8: Jan van Arkelstraat 118 Vlaardingen | D8: 185 | E8: 0
A9: 195 | B9: Keesomstraat 50 Vlaardingen | D9: 205.35 | E9: 0
A10: 208 | B10: L.A. Kesperweg 31a Vlaardingen | D10: 186.34 | E10: 0
A11: 213 | B11: Mr. Troelstrastraat 11 Vlaardingen | D11: 150 | E11: 0
A12: 228 | B12: Parallelweg 122a Vlaardingen | D12: 110 | E12: 0
A13: 234 | B13: Rotterdamsedijk 154b Schiedam | D13: 50 | E13: 0
A14: 236 | B14: Schalkeroord 389 Rotterdam | D14: 95.64 | E14: 0
A15: 238 | B15: Van der Werffstraat 370 Vlaardingen | D15: 726.26 | E15: 0
A16: 245 | B16: Van der Werffstraat 240 Vlaardingen | D16: 185.9 | E16: 0
... A20: 470 | B20: v.d. Waalstraat 16 Vlaardingen | D20: 1077.81 | E20: 0
A21: Grand Total | D21: 1077.81 | E21: 20
F283: =B283/1.09 -> 0
F284: =B284/1.09 -> 0
F285: =B285/1.09 -> 0
F286: =B286/1.09 -> 0
F287: =B287/1.09 -> 0
F288: =B288/1.09 -> 0
F289: =B289/1.09 -> 0
F290: =B290/1.09 -> 0
F291: =B291/1.09 -> 0

Sheet Internet & telefoonkosten
A1: Jaar | B1: 2025
A2: Grootboekrekening | B2: Internet en telefoonkosten woningen
A4: object_id | B4: Omschrijving | C4: Per. | D4: Max. of Debet | E4: Max. of Credit
A5: 0 | B5: Algemeen woningen | D5: 5187.65 | E5: 333.9
A6: 1 | B6: Nunspeetlaan 14 | D6: 22.82 | E6: 5.15
A7: 2 | B7: Allard Piersonlaan 142 Den Haag | D7: 25.1 | E7: 0
A8: 4 | B8: Broekweg 25 Vlaardingen | D8: 25.2 | E8: 20.92
A9: 9 | B9: Galgeweg 48A, 's-Gravenzande | D9: 50.37 | E9: 50.37
A10: 10 | B10: Kethelweg 1B Vlaardingen | D10: 25.1 | E10: 0
A11: 11 | B11: Kethelweg 1C Vlaardingen | D11: 25.1 | E11: 0
A12: 16 | B12: van Scorelstraat 73 Maassluis | D12: 67.36 | E12: 0
A13: 17 | B13: G.A. Brederolaan 75B Maassluis | D13: 33.06 | E13: 0
A14: 20 | B14: Mr. Troelstrastraat 37 Vlaardingen | D14: 25.1 | E14: 23.48
A15: 21 | B15: Vaartweg 106C Vlaardingen | D15: 25.1 | E15: 7.29
A16: 22 | B16: 2e van Leyden Gaelstraat 6, Vlaardingen | D16: 25.1 | E16: 9.2
... A114: 471 | B114: W.M. Bakkerslaan 34, Maasluis | D114: 43.39 | E114: 0
B115: Parallelweg 110A Vlaardingen | D115: 22.82 | E115: 2.94
A116: Grand Total | D116: 5187.65 | E116: 333.9
F283: =B283/1.09 -> 0
F284: =B284/1.09 -> 0
F285: =B285/1.09 -> 0
F286: =B286/1.09 -> 0
F287: =B287/1.09 -> 0
F288: =B288/1.09 -> 0
F289: =B289/1.09 -> 0
F290: =B290/1.09 -> 0
F291: =B291/1.09 -> 0

Sheet GWE woningen
A1: Jaar | B1: 2025
A2: Grootboekrekening | B2: Gas, water en electra woningen
A4: object_id | B4: Omschrijving | C4: Per. | D4: Max. of Debet | E4: Max. of Credit
A5: 0 | B5: Algemeen woningen | D5: 19375.27 | E5: 113.24
A6: 4 | B6: Broekweg 25 Vlaardingen | D6: 260.15 | E6: 0
A7: 9 | B7: Galgeweg 48A, 's-Gravenzande | D7: 773.78 | E7: 0
A8: 10 | B8: Kethelweg 1B Vlaardingen | D8: 85.24 | E8: 0
A9: 11 | B9: Kethelweg 1C Vlaardingen | D9: 32.11 | E9: 0
A10: 15 | B10: Maasdijk 69 | D10: 2470.8 | E10: 0
A11: 16 | B11: van Scorelstraat 73 Maassluis | D11: 218.11 | E11: 0
A12: 17 | B12: G.A. Brederolaan 75B Maassluis | D12: 208.85 | E12: 0
A13: 20 | B13: Mr. Troelstrastraat 37 Vlaardingen | D13: 181.36 | E13: 0
A14: 21 | B14: Vaartweg 106C Vlaardingen | D14: 256.89 | E14: 0
A15: 22 | B15: 2e van Leyden Gaelstraat 6, Vlaardingen | D15: 482.84 | E15: 0
A16: 25 | B16: Groenelaan 30B Schiedam | D16: 190.22 | E16: 467.81
... A167: 488 | B167: Goghlaan 36, Roosendaal | D167: 309.4 | E167: 0
B168: Oosterstraat 89 Vlaardingen | D168: 315.48 | E168: 1.24
A169: Grand Total | D169: 19375.27 | E169: 4543.5
F283: =B283/1.09 -> 0
F284: =B284/1.09 -> 0
F285: =B285/1.09 -> 0
F286: =B286/1.09 -> 0
F287: =B287/1.09 -> 0
F288: =B288/1.09 -> 0
F289: =B289/1.09 -> 0
F290: =B290/1.09 -> 0
F291: =B291/1.09 -> 0

Sheet Huur(belast)woningenavg
A1: Jaar | B1: 2025
A2: Grootboekrekening | B2: Huur (belast) woningen
A4: object_id | B4: Omschrijving | C4: Per. | D4: Max. of Debet | E4: Max. of Credit | G4: Average of Debet | H4: Average of Credit | I4: verschil avg-max | J4: max of niet
A5: 0 | B5: Algemeen woningen | D5: 13043.23 | E5: 90 | G5: 2142.3474 | H5: 1.125 | I5: =D5-G5 -> 10900.883
A6: 2 | B6: Allard Piersonlaan 142 Den Haag | D6: 1416.85 | E6: 0 | G6: 1393.9333 | H6: 0 | I6: =D6-G6 -> 22.916667 | J6: 1
A7: 4 | B7: Broekweg 25 Vlaardingen | D7: 1708.41 | E7: 0 | G7: 1674.765 | H7: 0 | I7: =D7-G7 -> 33.645 | J7: 1
A8: 9 | B8: Galgeweg 48A, 's-Gravenzande | D8: 3643.5 | E8: 0 | G8: 3643.5 | H8: 0 | I8: =D8-G8 -> 0 | J8: 1
A9: 10 | B9: Kethelweg 1B Vlaardingen | D9: 1708.41 | E9: 0 | G9: 1674.765 | H9: 0 | I9: =D9-G9 -> 33.645 | J9: 1
A10: 11 | B10: Kethelweg 1C Vlaardingen | D10: 1708.41 | E10: 0 | G10: 1674.765 | H10: 0 | I10: =D10-G10 -> 33.645 | J10: 1
A11: 15 | B11: Maasdijk 69 | D11: 3400 | E11: 0 | G11: 3400 | H11: 0 | I11: =D11-G11 -> 0 | J11: 1
A12: 16 | B12: van Scorelstraat 73 Maassluis | D12: 2364.3 | E12: 0 | G12: 2317.74 | H12: 0 | I12: =D12-G12 -> 46.56 | J12: 1
A13: 17 | B13: G.A. Brederolaan 75B Maassluis | D13: 1677.89 | E13: 0 | G13: 1644.85 | H13: 0 | I13: =D13-G13 -> 33.04 | J13: 1
A14: 20 | B14: Mr. Troelstrastraat 37 Vlaardingen | D14: 1723.44 | E14: 0 | G14: 1689.5 | H14: 0 | I14: =D14-G14 -> 33.94 | J14: 1
A15: 21 | B15: Vaartweg 106C Vlaardingen | D15: 1830.43 | E15: 0 | G15: 1794.385 | H15: 0 | I15: =D15-G15 -> 36.045 | J15: 1
A16: 22 | B16: 2e van Leyden Gaelstraat 6, Vlaardingen | D16: 2930.56 | E16: 2930.56 | G16: 2705.1323 | H16: 225.42769 | I16: =D16-G16 -> 225.42769 | J16: 1
A17: 25 | B17: Groenelaan 30B Schiedam | D17: 1625 | E17: 1625 | G17: 1209.7282 | H17: 147.72727 | I17: =D17-G17 -> 415.27182 | J17: 1
... A32: 88 | B32: Kethelweg 66A, Vlaardingen | D32: 2593.81 | E32: 2491.65 | G32: 2311.7692 | H32: 207.6375 | I32: =D32-G32 -> 282.04083 | J32: 1
A33: 95 | B33: Engelsestraat 16L01 Rotterdam | D33: 1993.32 | E33: 0 | G33: 948.79385 | H33: 0 | I33: =D33-G33 -> 1044.5262
A34: 95 | B34: Engelsestraat 16L3, Rotterdam | D34: 3435.06 | E34: 1750 | G34: 1906.8017 | H34: 145.83333 | I34: =D34-G34 -> 1528.2583
A35: 97 | B35: Burchstraat 16A, Oostburg | D35: 3550 | E35: 0 | G35: 3094.4983 | H35: 0 | I35: =D35-G35 -> 455.50167 | J35: 1
A36: 99 | B36: Steenen Dijck 87, Maassluis | D36: 3383.25 | E36: 0 | G36: 3316.625 | H36: 0 | I36: =D36-G36 -> 66.625 | J36: 1
A37: 103 | B37: Narcissenstraat 23 Rozenburg | D37: 1700 | E37: 0 | G37: 1680.7043 | H37: 0 | I37: =D37-G37 -> 19.295714 | J37: 1
A38: 106 | B38: Prinses Wilhelminastraat 9, Hekendorp | D38: 3200 | E38: 3200 | G38: 1920 | H38: 1280 | I38: =D38-G38 -> 1280
A39: 120 | B39: Plaats 10, Montfoort | D39: 2300 | E39: 0 | G39: 2300 | H39: 0 | I39: =D39-G39 -> 0 | J39: 1
A40: 122 | B40: Kethelweg 66B, Vlaardingen | D40: 2593.81 | E40: 0 | G40: 2542.73 | H40: 0 | I40: =D40-G40 -> 51.08 | J40: 1
A41: 131 | B41: Chopinstraat 35A, Vlaardingen | D41: 2165.26 | E41: 0 | G41: 2122.62 | H41: 0 | I41: =D41-G41 -> 42.64 | J41: 1
A42: 133 | B42: Herenpad 20A, Schiedam | D42: 2075.05 | E42: 0 | G42: 2034.185 | H42: 0 | I42: =D42-G42 -> 40.865 | J42: 1
A43: 134 | B43: Herenpad 20B, Schiedam | D43: 992.34 | E43: 0 | G43: 972.8 | H43: 0 | I43: =D43-G43 -> 19.54 | J43: 1
A44: 135 | B44: Amperestraat 36A, Schiedam | D44: 1691.63 | E44: 0 | G44: 1658.315 | H44: 0 | I44: =D44-G44 -> 33.315 | J44: 1
A45: 148 | B45: 2e Maasbosstraat 2A Vlaardingen | D45: 1570.24 | E45: 0 | G45: 1430.1377 | H45: 0 | I45: =D45-G45 -> 140.10231 | J45: 1
A46: 149 | B46: 2e Maasbosstraat 2B Vlaardingen | D46: 1570.24 | E46: 0 | G46: 1534.1667 | H46: 0 | I46: =D46-G46 -> 36.073333 | J46: 1
A47: 150 | B47: 2e Maasbosstraat 2C Vlaardingen | D47: 1475.31 | E47: 0 | G47: 1441.4125 | H47: 0 | I47: =D47-G47 -> 33.8975 | J47: 1
A48: 154 | B48: Rubensplein 6B3 Schiedam | D48: 2238.15 | E48: 0 | G48: 2198.0818 | H48: 0 | I48: =D48-G48 -> 40.068182 | J48: 1
A49: 156 | B49: Broersvest 74c Schiedam | D49: 2051.51 | E49: 0 | G49: 2024.51 | H49: 0 | I49: =D49-G49 -> 27 | J49: 1
A50: 160 | B50: Chopinstraat 33c Vlaardingen | D50: 1300 | E50: 0 | G50: 1300 | H50: 0 | I50: =D50-G50 -> 0 | J50: 1
... A66: 191 | B66: Jan van Arkelstraat 118 Vlaardingen | D66: 895 | E66: 0 | G66: 895 | H66: 0 | I66: =D66-G66 -> 0 | J66: 1
A67: 192 | B67: Kaapsebos 11 Maasdijk | D67: 8370 | E67: 0 | G67: 6654.8 | H67: 0 | I67: =D67-G67 -> 1715.2
A68: 193 | B68: Kapershoek 11 Rotterdam | D68: 1400.53 | E68: 0 | G68: 1372.95 | H68: 0 | I68: =D68-G68 -> 27.58 | J68: 1
A69: 194 | B69: Keesomstraat 22 Vlaardingen | D69: 2336 | E69: 0 | G69: 2257.3077 | H69: 0 | I69: =D69-G69 -> 78.692308 | J69: 1
A70: 195 | B70: Keesomstraat 50 Vlaardingen | D70: 895 | E70: 0 | G70: 895 | H70: 0 | I70: =D70-G70 -> 0 | J70: 1
...

Sheet Huur(belast)woningenmax
A1: Jaar | B1: 2025
A2: Grootboekrekening | B2: Huur (belast) woningen
A4: object_id | B4: Omschrijving | C4: Per. | D4: Max. of Debet | E4: Max. of Credit
A5: 0 | B5: Algemeen woningen | D5: 13043.23 | E5: 90
A6: 2 | B6: Allard Piersonlaan 142 Den Haag | D6: 1416.85 | E6: 0
A7: 4 | B7: Broekweg 25 Vlaardingen | D7: 1708.41 | E7: 0
A8: 9 | B8: Galgeweg 48A, 's-Gravenzande | D8: 3643.5 | E8: 0
A9: 10 | B9: Kethelweg 1B Vlaardingen | D9: 1708.41 | E9: 0
A10: 11 | B10: Kethelweg 1C Vlaardingen | D10: 1708.41 | E10: 0
A11: 15 | B11: Maasdijk 69 | D11: 3400 | E11: 0
A12: 16 | B12: van Scorelstraat 73 Maassluis | D12: 2364.3 | E12: 0
A13: 17 | B13: G.A. Brederolaan 75B Maassluis | D13: 1677.89 | E13: 0
A14: 20 | B14: Mr. Troelstrastraat 37 Vlaardingen | D14: 1723.44 | E14: 0
A15: 21 | B15: Vaartweg 106C Vlaardingen | D15: 1830.43 | E15: 0
A16: 22 | B16: 2e van Leyden Gaelstraat 6, Vlaardingen | D16: 2930.56 | E16: 2930.56
... A18: 26 | B18: Chopinstraat 39C Vlaardingen | D18: 1952.46 | E18: 0
A19: 27 | B19: Buizerdstraat 210 Maassluis | D19: 1677.89 | E19: 0 | F19: 430.32 | G19: 456.54
A20: 28 | B20: Lange Kruisweg 12 Maasdijk | D20: 2928.69 | E20: 0
A21: 30 | B21: Curacaolaan 88 Vlaardingen | D21: 895 | E21: 0
A22: 31 | B22: Hogenbanweg 331 Schiedam | D22: 1568.43 | E22: 0
A23: 33 | B23: Kethelweg 66C | D23: 2082 | E23: 0
A24: 34 | B24: Kethelweg 68A | D24: 2269.38 | E24: 0
A25: 35 | B25: Messchaertplein 39, Vlaardingen | D25: 1784.67 | E25: 0
A26: 36 | B26: Messchaertplein 40, Vlaardingen | D26: 2810.7 | E26: 0
A27: 57 | B27: Markt 5 Bovenwoning, Massluis | D27: 1715.6 | E27: 0
A28: 67 | B28: Franz Liszstraat 5, Terneuzen | D28: 3643.5 | E28: 0
A29: 79 | B29: Ploegstraat 2a, Schiedam | D29: 2166.65 | E29: 0
A30: 80 | B30: Voorstraat 25, Vlaardingen | D30: 2170 | E30: 0
A31: 84 | B31: Kerkdreef 42 Axel | D31: 2250 | E31: 0
... A187: 477 | B187: Hotel de Sluiskop | D187: 16986.67 | E187: 0
B188: 1e Verdeligsweg 6 - 821, Putte | D188: 475 | E188: 475
B189: Oosterstraat 89 Vlaardingen | D189: 1569.3 | E189: 0
B190: Parallelweg 110A Vlaardingen | D190: 2082 | E190: 0
F283: =B283/1.09 -> 0
F284: =B284/1.09 -> 0
F285: =B285/1.09 -> 0
F286: =B286/1.09 -> 0
F287: =B287/1.09 -> 0
F288: =B288/1.09 -> 0
F289: =B289/1.09 -> 0
...

Sheet Financiele mutaties uitgebreid
A1: Jaar | B1: Per. | C1: Boekstuk | D1: Jrnpstnr. | E1: Vlgnr. jrnpst. | F1: Rek.nr. | G1: Grootboekrekening | H1: Debet | I1: Credit | J1: Saldo | K1: Verb. 1 | L1: object_id | M1: Omschrijving | N1: Verb. 2 | O1: Omschrijving | P1: Btw | Q1: Boeking | R1: Bkstk.nr. | S1: Fact.nr. | T1: Dagboek | U1: Ltst. wijz. | V1: Gewijzigd door
A2: 2025 | B2: 12 | C2: 46022 | D2: 87488 | E2: 2 | F2: 4230 | G2: Internet en telefoonkosten woningen | H2: 158.84 | I2: 0 | J2: 158.84 | K2: 526 | L2: =_xlfn.XLOOKUP(M2,Sheet6!B:B,Sheet6!A:A,"",0) -> 371 | M2: Zwingel 8B | P2: 4 | Q2: Tot Uw Dienst | R2: 1021507250249 | S2: I255314 | T2: Inkoopdagboek | U2: 46027.625 | V2: 86806.admin
A3: 2025 | B3: 12 | C3: 46022 | D3: 87490 | E3: 2 | F3: 4220 | G3: Kleine inventaris/inrichting woningen | H3: 400 | I3: 0 | J3: 400 | K3: 526 | L3: =_xlfn.XLOOKUP(M3,Sheet6!B:B,Sheet6!A:A,"",0) -> 371 | M3: Zwingel 8B | P3: 4 | Q3: Tot Uw Dienst, wk 52 | R3: 07250248 | S3: I255316 | T3: Inkoopdagboek | U3: 46027.625 | V3: 86806.admin
A4: 2025 | B4: 12 | C4: 46021 | D4: 87425 | E4: 2 | F4: 4270 | G4: Kosten VvE woningen | H4: 0 | I4: 20 | J4: -20 | K4: 999 | L4: =_xlfn.XLOOKUP(M4,Sheet6!B:B,Sheet6!A:A,"",0) -> 0 | M4: Algemeen woningen | Q4: VVE FLATGEBOUW JAN Te veel betaalde VvE bijdrage 2025/2025-12-30 | R4: 25425 | T4: Rabobank betaalrekening | U4: 46029.471 | V4: 86806.1002315
A5: 2025 | B5: 12 | C5: 46020 | D5: 87423 | E5: 97 | F5: 4250 | G5: Gas, water en electra woningen | H5: 24.73 | I5: 0 | J5: 24.73 | K5: 518 | L5: =_xlfn.XLOOKUP(M5,Sheet6!B:B,Sheet6!A:A,"",0) -> 203 | M5: Dorpstraat 48, Aarlanderveen | P5: 5 | Q5: OASEN NV Voorschot dec, BTW 2,23, Dorpsstraat 48, 2445 AN AARLANDERVEEN/2025-12-29 7017893706202501 178937 | R5: 25424 | T5: Rabobank betaalrekening | U5: 46029.581 | V5: 86806.1002315
A6: 2025 | B6: 12 | C6: 46015 | D6: 87374 | E6: 2 | F6: 4250 | G6: Gas, water en electra woningen | H6: 78.85 | I6: 0 | J6: 78.85 | K6: 542 | L6: =_xlfn.XLOOKUP(M6,Sheet6!B:B,Sheet6!A:A,"",0) -> 370 | M6: Cloosterstraat 23A, Kloosterzande | P6: 4 | Q6: Evides september | R6: 111100156488 | S6: I255282 | T6: Inkoopdagboek | U6: 46022.547 | V6: 86806.admin
A7: 2025 | B7: 12 | C7: 46015 | D7: 87493 | E7: 2 | F7: 4250 | G7: Gas, water en electra woningen | H7: 0 | I7: 148.37 | J7: -148.37 | K7: 469 | L7: =_xlfn.XLOOKUP(M7,Sheet6!B:B,Sheet6!A:A,"",0) -> 177 | M7: Hoge Noordweg 27B Naaldwijk | P7: 4 | Q7: Audax Renewables afrekening | R7: 6509100 | S7: I255319 | T7: Inkoopdagboek | U7: 46027.626 | V7: 86806.admin
A8: 2025 | B8: 12 | C8: 46015 | D8: 87493 | E8: 3 | F8: 4250 | G8: Gas, water en electra woningen | H8: 0 | I8: 507.86 | J8: -507.86 | K8: 197 | L8: =_xlfn.XLOOKUP(M8,Sheet6!B:B,Sheet6!A:A,"",0) -> 225 | M8: Kerkwervesingel 127 Rotterdam | P8: 4 | Q8: Audax Renewables afrekening | R8: 6509100 | S8: I255319 | T8: Inkoopdagboek | U8: 46027.626 | V8: 86806.admin
A9: 2025 | B9: 12 | C9: 46015 | D9: 87493 | E9: 4 | F9: 4250 | G9: Gas, water en electra woningen | H9: 0 | I9: 41.56 | J9: -41.56 | K9: 545 | L9: =_xlfn.XLOOKUP(M9,Sheet6!B:B,Sheet6!A:A,"",0) -> 361 | M9: Putsebocht 136 B01 | P9: 4 | Q9: Audax Renewables afrekening | R9: 6509100 | S9: I255319 | T9: Inkoopdagboek | U9: 46027.626 | V9: 86806.admin
A10: 2025 | B10: 12 | C10: 46015 | D10: 87493 | E10: 5 | F10: 4250 | G10: Gas, water en electra woningen | H10: 1806.92 | I10: 0 | J10: 1806.92 | K10: 297 | L10: =_xlfn.XLOOKUP(M10,Sheet6!B:B,Sheet6!A:A,"",0) -> 243 | M10: Sint Liduinastraat 80 A B Schiedam | P10: 4 | Q10: Audax Renewables afrekening | R10: 6509100 | S10: I255319 | T10: Inkoopdagboek | U10: 46027.626 | V10: 86806.admin
A11: 2025 | B11: 12 | C11: 46015 | D11: 87493 | E11: 6 | F11: 4250 | G11: Gas, water en electra woningen | H11: 0 | I11: 299.64 | J11: -299.64 | K11: 477 | L11: =_xlfn.XLOOKUP(M11,Sheet6!B:B,Sheet6!A:A,"",0) -> 88 | M11: Kethelweg 66A, Vlaardingen | P11: 4 | Q11: Audax Renewables afrekening | R11: 6509100 | S11: I255319 | T11: Inkoopdagboek | U11: 46027.626 | V11: 86806.admin
A12: 2025 | B12: 12 | C12: 46014 | D12: 87262 | E12: 2 | F12: 4250 | G12: Gas, water en electra woningen | H12: 0 | I12: 304.71 | J12: -304.71 | K12: 544 | L12: =_xlfn.XLOOKUP(M12,Sheet6!B:B,Sheet6!A:A,"",0) -> 450 | M12: Laan van Zuid 949 | P12: 4 | Q12: ENECO SERVICES Kenmerk 7005642756500011 Omschrijving Restitutie creditsaldo Laan op Zuid 949 ROTTERDAM/2025-12-23 7005642756500011 | R12: 25421 | T12: Rabobank betaalrekening | U12: 46024.649 | V12: 86806.1002315
A13: 2025 | B13: 12 | C13: 46014 | D13: 87362 | E13: 2 | F13: 4220 | G13: Kleine inventaris/inrichting woningen | H13: 918.67 | I13: 0 | J13: 918.67 | K13: 999 | L13: =_xlfn.XLOOKUP(M13,Sheet6!B:B,Sheet6!A:A,"",0) -> 0 | M13: Algemeen woningen | P13: 4 | Q13: Hakzo sleutels 4ekw25 | R13: 231225588 | S13: I255271 | T13: Inkoopdagboek | U13: 46022.546 | V13: 86806.admin
A14: 2025 | B14: 12 | C14: 46014 | D14: 87495 | E14: 2 | F14: 4220 | G14: Kleine inventaris/inrichting woningen | H14: 400 | I14: 0 | J14: 400 | K14: 526 | L14: =_xlfn.XLOOKUP(M14,Sheet6!B:B,Sheet6!A:A,"",0) -> 371 | M14: Zwingel 8B | P14: 4 | Q14: Tot Uw Dienst, wk 51 | R14: 07250246 | S14: I255321 | T14: Inkoopdagboek | U14: 46027.626 | V14: 86806.admin
A15: 2025 | B15: 12 | C15: 46013 | D15: 87340 | E15: 2 | F15: 4220 | G15: Kleine inventaris/inrichting woningen | H15: 400 | I15: 0 | J15: 400 | K15: 526 | L15: =_xlfn.XLOOKUP(M15,Sheet6!B:B,Sheet6!A:A,"",0) -> 371 | M15: Zwingel 8B | P15: 4 | Q15: Tot Uw Dienst, wk 50 | R15: 07250244 | S15: I255249 | T15: Inkoopdagboek | U15: 46021.6 | V15: 86806.admin
A16: 2025 | B16: 12 | C16: 46013 | D16: 87341 | E16: 2 | F16: 4200 | G16: Huur (belast) woningen | H16: 2117.89 | I16: 0 | J16: 2117.89 | K16: 495 | L16: =_xlfn.XLOOKUP(M16,Sheet6!B:B,Sheet6!A:A,"",0) -> 291 | M16: Koperwerf 28 | P16: 5 | Q16: AUB van Bergen Personeelsdiensten; wk 52 | R16: 250155 | S16: I255250 | T16: Inkoopdagboek | U16: 46021.6 | V16: 86806.admin
A17: 2025 | B17: 12 | C17: 46013 | D17: 87341 | E17: 3 | F17: 4200 | G17: Huur (belast) woningen | H17: 111.47 | I17: 0 | J17: 111.47 | K17: 496 | L17: =_xlfn.XLOOKUP(M17,Sheet6!B:B,Sheet6!A:A,"",0) -> 279 | M17: Haagkamp 11 | P17: 5 | Q17: AUB van Bergen Personeelsdiensten; wk 52 | R17: 250155 | S17: I255250 | T17: Inkoopdagboek | U17: 46021.6 | V17: 86806.admin
A18: 2025 | B18: 12 | C18: 46012 | D18: 86962 | E18: 2 | F18: 4250 | G18: Gas, water en electra woningen | H18: 0 | I18: 24.77 | J18: -24.77 | K18: 544 | L18: =_xlfn.XLOOKUP(M18,Sheet6!B:B,Sheet6!A:A,"",0) -> 450 | M18: Laan van Zuid 949 | P18: 5 | Q18: Evides december | R18: 144200006889 | S18: I255071 | T18: Inkoopdagboek | U18: 46002.611 | V18: 86806.admin
A19: 2025 | B19: 12 | C19: 46012 | D19: 86963 | E19: 2 | F19: 4250 | G19: Gas, water en electra woningen | H19: 0 | I19: 22.94 | J19: -22.94 | K19: 545 | L19: =_xlfn.XLOOKUP(M19,Sheet6!B:B,Sheet6!A:A,"",0) -> 361 | M19: Putsebocht 136 B01 | P19: 5 | Q19: Evides december | R19: 142000006282 | S19: I255072 | T19: Inkoopdagboek | U19: 46002.612 | V19: 86806.admin
A20: 2025 | B20: 12 | C20: 46012 | D20: 87046 | E20: 2 | F20: 4250 | G20: Gas, water en electra woningen | H20: 0 | I20: 29.36 | J20: -29.36 | K20: 251 | L20: =_xlfn.XLOOKUP(M20,Sheet6!B:B,Sheet6!A:A,"",0) -> 63 | M20: Energieweg 40 Vlaardingen | P20: 5 | Q20: Evides april | R20: 145300006170 | S20: I255113 | T20: Inkoopdagboek | U20: 46006.665 | V20: 86806.admin
A21: 2025 | B21: 12 | C21: 46012 | D21: 87047 | E21: 2 | F21: 4250 | G21: Gas, water en electra woningen | H21: 0 | I21: 30.28 | J21: -30.28 | K21: 323 | L21: =_xlfn.XLOOKUP(M21,Sheet6!B:B,Sheet6!A:A,"",0) -> 193 | M21: Kapershoek 11 Rotterdam | P21: 5 | Q21: Evides december | R21: 146800006269 | S21: I255114 | T21: Inkoopdagboek | U21: 46006.665 | V21: 86806.admin
A22: 2025 | B22: 12 | C22: 46012 | D22: 87048 | E22: 2 | F22: 4250 | G22: Gas, water en electra woningen | H22: 0 | I22: 30.28 | J22: -30.28 | K22: 318 | L22: =_xlfn.XLOOKUP(M22,Sheet6!B:B,Sheet6!A:A,"",0) -> 37 | M22: Westfrankelandsestraat 108 Schiedam | P22: 5 | Q22: Evides december | R22: 141100006160 | S22: I255115 | T22: Inkoopdagboek | U22: 46006.665 | V22: 86806.admin
A23: 2025 | B23: 12 | C23: 46012 | D23: 87434 | E23: 2 | F23: 4250 | G23: Gas, water en electra woningen | H23: 0 | I23: 76.95 | J23: -76.95 | K23: 415 | L23: =_xlfn.XLOOKUP(M23,Sheet6!B:B,Sheet6!A:A,"",0) -> 241 | M23: Van der Werffstraat 166, Vlaardingen | P23: 5 | Q23: Noord Energie Afrekening 2025 | R23: F0800161 | S23: I255309 | T23: Inkoopdagboek | U23: 46024.662 | V23: 86806.admin
A24: 2025 | B24: 8 | C24: 46010 | D24: 87223 | E24: 2 | F24: 4200 | G24: Huur (belast) woningen | H24: 895 | I24: 0 | J24: 895 | K24: 154 | L24: =_xlfn.XLOOKUP(M24,Sheet6!B:B,Sheet6!A:A,"",0) -> 235 | M24: Rubensplein 3b Schiedam | P24: 6 | Q24: Tradiro Housing 2025-08 | R24: V05250008 | S24: I255202 | T24: Inkoopdagboek | U24: 46010.495 | V24: 86806.1002315
... A631: 2025 | B631: 12 | C631: 45992 | D631: 86591 | E631: 2 | F631: 4250 | G631: Gas, water en electra woningen | H631: 0 | I631: 461.26 | J631: -461.26 | K631: 180 | L631: =_xlfn.XLOOKUP(M631,Sheet6!B:B,Sheet6!A:A,"",0) -> 236 | M631: Schalkeroord 389 Rotterdam | P631: 6 | Q631: Kalmeijer e/o Klootwijk stookkosten 01-07-2024 - 30-06-2025 | R631: S2514 | S631: I254908 | T631: Inkoopdagboek | U631: 45988.389 | V631: 86806.admin
A632: 2025 | B632: 12 | C632: 45992 | D632: 86771 | E632: 1 | F632: 4270 | G632: Kosten VvE woningen | H632: 192.71 | I632: 0 | J632: 192.71 | K632: 222 | L632: =_xlfn.XLOOKUP(M632,Sheet6!B:B,Sheet6!A:A,"",0) -> 238 | M632: Van der Werffstraat 370 Vlaardingen | Q632: Vve van der Werffstraat 254-380 OO9B005161840292 Vve Van der Werffstraat 370/2025-12-01 | R632: 25404 | T632: Rabobank betaalrekening | U632: 46029.582 | V632: 86806.1002315
A633: 2025 | B633: 12 | C633: 45992 | D633: 86771 | E633: 2 | F633: 4270 | G633: Kosten VvE woningen | H633: 300 | I633: 0 | J633: 300 | K633: 226 | L633: =_xlfn.XLOOKUP(M633,Sheet6!B:B,Sheet6!A:A,"",0) -> 183 | M633: Hugo de Vriesstraat 54 Vlaardingen | Q633: Vve Hugo de Vriesstraat 50 tm 64 OO9B005161957968 VvE bijdrage Hugo de Vriesstraat 54 Vlaardingen/2025-12-01 | R633: 25404 | T633: Rabobank betaalrekening | U633: 46029.582 | V633: 86806.1002315
A634: 2025 | B634: 12 | C634: 45992 | D634: 86771 | E634: 3 | F634: 4270 | G634: Kosten VvE woningen | H634: 205.35 | I634: 0 | J634: 205.35 | K634: 229 | L634: =_xlfn.XLOOKUP(M634,Sheet6!B:B,Sheet6!A:A,"",0) -> 195 | M634: Keesomstraat 50 Vlaardingen | Q634: VvE Keesomstraat 2-64, te Vlaardingen OO9B005162138280 VvE bijdrage Keesomstraat 50 Vlaardingen/2025-12-01 | R634: 25404 | T634: Rabobank betaalrekening | U634: 46029.582 | V634: 86806.1002315
A635: 2025 | B635: 12 | C635: 45992 | D635: 86771 | E635: 4 | F635: 4270 | G635: Kosten VvE woningen | H635: 185 | I635: 0 | J635: 185 | K635: 228 | L635: =_xlfn.XLOOKUP(M635,Sheet6!B:B,Sheet6!A:A,"",0) -> 191 | M635: Jan van Arkelstraat 118 Vlaardingen | Q635: Vereniging van eigenaars flatgebouw Jan van Arkelstraat 62 t/m 148 OO9B005162193097 Maandbijdrage Vve Jan van Arkelstraat 118 Vlaardingen/2025-12-01 | R635: 25404 | T635: Rabobank betaalrekening | U635: 46029.582 | V635: 86806.1002315
A636: 2025 | B636: 12 | C636: 45992 | D636: 86771 | E636: 5 | F636: 4270 | G636: Kosten VvE woningen | H636: 186.34 | I636: 0 | J636: 186.34 | K636: 189 | L636: =_xlfn.XLOOKUP(M636,Sheet6!B:B,Sheet6!A:A,"",0) -> 208 | M636: L.A. Kesperweg 31a Vlaardingen | Q636: VvE Mr. L.A. Kesperweg 1-39 Vlaardingen OO9B005162322475 VvE-bijdrage Mr. L.A. Kesperweg 31A/2025-12-01 | R636: 25404 | T636: Rabobank betaalrekening | U636: 46029.582 | V636: 86806.1002315
A637: 2025 | B637: 12 | C637: 45992 | D637: 86771 | E637: 6 | F637: 4270 | G637: Kosten VvE woningen | H637: 185.9 | I637: 0 | J637: 185.9 | K637: 241 | L637: =_xlfn.XLOOKUP(M637,Sheet6!B:B,Sheet6!A:A,"",0) -> 245 | M637: Van der Werffstraat 240 Vlaardingen | Q637: VvE van der Werffstraat 132-252 te Vlaardingen OO9B005162494509 Maandbijdrage Vve Van der Werffstraat 240/2025-12-01 | R637: 25404 | T637: Rabobank betaalrekening | U637: 46029.582 | V637: 86806.1002315
A638: 2025 | B638: 12 | C638: 45992 | D638: 86771 | E638: 7 | F638: 4270 | G638: Kosten VvE woningen | H638: 115 | I638: 0 | J638: 115 | K638: 156 | L638: =_xlfn.XLOOKUP(M638,Sheet6!B:B,Sheet6!A:A,"",0) -> 452 | M638: Nic. Beetsstraat 29 Vlaardingen | Q638: VvE Nicolaas Beetsstraat 25 t/m 35 OO9B005162795473 VvE-bijdrage Nic. Beetsstraat 29/2025-12-01 | R638: 25404 | T638: Rabobank betaalrekening | U638: 46029.582 | V638: 86806.1002315
A639: 2025 | B639: 12 | C639: 45992 | D639: 86771 | E639: 8 | F639: 4270 | G639: Kosten VvE woningen | H639: 110 | I639: 0 | J639: 110 | K639: 193 | L639: =_xlfn.XLOOKUP(M639,Sheet6!B:B,Sheet6!A:A,"",0) -> 228 | M639: Parallelweg 122a Vlaardingen | Q639: Vve Parallelweg 112-134 OO9B005163007651 Maandbijdrage Vve Parallelweg 122a Vlaardingen/2025-12-01 | R639: 25404 | T639: Rabobank betaalrekening | U639: 46029.582 | V639: 86806.1002315
A640: 2025 | B640: 12 | C640: 45992 | D640: 86771 | E640: 10 | F640: 4250 | G640: Gas, water en electra woningen | H640: 131.4 | I640: 0 | J640: 131.4 | K640: 544 | L640: =_xlfn.XLOOKUP(M640,Sheet6!B:B,Sheet6!A:A,"",0) -> 450 | M640: Laan van Zuid 949 | P640: 4 | Q640: ENECO SERVICES Kenmerk 5000011325936612 Omschrijving Klantnummer 56427565-1 Termijnnota Periode 2025-12 Laan op Zuid 949 ROTTERDAM/2025-12-01 5000011325936612 4235176 | R640: 25404 | T640: Rabobank betaalrekening | U640: 46029.582 | V640: 86806.1002315
A641: 2025 | B641: 12 | C641: 45992 | D641: 86774 | E641: 2 | F641: 4210 | G641: Reparatie en onderhoud woningen | H641: 20.59 | I641: 0 | J641: 20.59 | K641: 999 | L641: =_xlfn.XLOOKUP(M641,Sheet6!B:B,Sheet6!A:A,"",0) -> 0 | M641: Algemeen woningen | P641: 4 | Q641: P. Goinski 1-12-2025 decl. action | R641: 220015 1-12-2025 | S641: I254971 | T641: Inkoopdagboek | U641: 45993.45 | V641: 86806.admin
A642: 2025 | B642: 12 | C642: 45992 | D642: 86782 | E642: 2 | F642: 4270 | G642: Kosten VvE woningen | H642: 50 | I642: 0 | J642: 50 | K642: 191 | L642: =_xlfn.XLOOKUP(M642,Sheet6!B:B,Sheet6!A:A,"",0) -> 234 | M642: Rotterdamsedijk 154b Schiedam | Q642: VVE Rotterdamsedijk 154b december | R642: 2025-024 | S642: I254978 | T642: Inkoopdagboek | U642: 45994.367 | V642: 86806.admin
A643: 2025 | B643: 11 | C643: 45992 | D643: 86820 | E643: 2 | F643: 4200 | G643: Huur (belast) woningen | H643: 2187 | I643: 0 | J643: 2187 | K643: 501 | L643: =_xlfn.XLOOKUP(M643,Sheet6!B:B,Sheet6!A:A,"",0) -> 441 | M643: Grimbergen 19 | P643: 6 | Q643: Alvonto Steenbergen B.V. wk 45 tm 48 met huuropslag | R643: V01250086 | S643: I255013 | T643: Inkoopdagboek | U643: 45996.348 | V643: 86806.admin
A644: 2025 | B644: 11 | C644: 45992 | D644: 86820 | E644: 3 | F644: 4200 | G644: Huur (belast) woningen | H644: 972 | I644: 0 | J644: 972 | K644: 511 | L644: =_xlfn.XLOOKUP(M644,Sheet6!B:B,Sheet6!A:A,"",0) -> 454 | M644: Oostene 23 | P644: 6 | Q644: Alvonto Steenbergen B.V. wk 45 tm 48 met huuropslag | R644: V01250086 | S644: I255013 | T644: Inkoopdagboek | U644: 45996.348 | V644: 86806.admin
A645: 2025 | B645: 11 | C645: 45992 | D645: 86820 | E645: 4 | F645: 4200 | G645: Huur (belast) woningen | H645: 5589 | I645: 0 | J645: 5589 | K645: 502 | L645: =_xlfn.XLOOKUP(M645,Sheet6!B:B,Sheet6!A:A,"",0) -> 472 | M645: Westlandse Langeweg 14 | P645: 6 | Q645: Alvonto Steenbergen B.V. wk 45 tm 48 met huuropslag | R645: V01250086 | S645: I255013 | T645: Inkoopdagboek | U645: 45996.348 | V645: 86806.admin
A646: 2025 | B646: 11 | C646: 45992 | D646: 86820 | E646: 5 | F646: 4200 | G646: Huur (belast) woningen | H646: 1620 | I646: 0 | J646: 1620 | K646: 999 | L646: =_xlfn.XLOOKUP(M646,Sheet6!B:B,Sheet6!A:A,"",0) -> 0 | M646: Algemeen woningen | P646: 6 | Q646: Alvonto Steenbergen B.V. wk 45 tm 48 met huuropslag | R646: V01250086 | S646: I255013 | T646: Inkoopdagboek | U646: 45996.348 | V646: 86806.admin
...

Sheet Sheet6
A1: object_id | B1: tradiro_adres
A2: 1 | B2: Nunspeetlaan 14
A3: 2 | B3: Allard Piersonlaan 142 Den Haag
A4: 4 | B4: Broekweg 25 Vlaardingen
A5: 9 | B5: Galgeweg 48A, 's-Gravenzande
A6: 10 | B6: Kethelweg 1B Vlaardingen
A7: 11 | B7: Kethelweg 1C Vlaardingen
A8: 15 | B8: Maasdijk 69
A9: 16 | B9: van Scorelstraat 73 Maassluis
A10: 17 | B10: G.A. Brederolaan 75B Maassluis
A11: 20 | B11: Mr. Troelstrastraat 37 Vlaardingen
A12: 21 | B12: Vaartweg 106C Vlaardingen
A13: 22 | B13: 2e van Leyden Gaelstraat 6, Vlaardingen
... A237: 488 | B237: Goghlaan 36, Roosendaal
B238: Algemeen woningen
