Workbook
Name lst_actie_type: LIJSTEN!$B$2:$B$7
Name lst_bestemming: LIJSTEN!$E$2:$E$3
Name lst_huis_id: HUIZEN_MASTER!#REF!
Name lst_ja_nee_onbekend: LIJSTEN!$C$2:$C$4
Name lst_klant_type: LIJSTEN!$D$2:$D$4
Name lst_sleuteloverdracht_methode: LIJSTEN!$F$2:$F$4
Name lst_status: LIJSTEN!$A$2:$A$12
Name lst_uitvoerder_team: LIJSTEN!$G$2:$G$5
Name lst_uren: LIJSTEN!$H$2:$H$26

Sheet LIJSTEN
A1: status | B1: actie_type | C1: ja_nee_onbekend | D1: klant_type | E1: bestemming | F1: sleuteloverdracht_methode | G1: uitvoerder_team | H1: uren
A2: NIET_GESTART | B2: VOORINSPECTIE | C2: JA | D2: TRADIRO | E2: OPNIEUW_VERHUREN | F2: PERSOONLIJK | G2: INTERN | H2: 0
A3: VOORINSPECTIE_GEPLAND | B3: UITCHECK | C3: NEE | D3: EXTERN | E3: TERUG_NAAR_EIGENAAR | F3: IN_WONING_ACHTERGELATEN | G3: AANNEMER | H3: 0.5
A4: VOORINSPECTIE_UITGEVOERD | B4: SCHOONMAAK | C4: ONBEKEND | D4: EIGENAAR | F4: ANDERS | G4: SCHOONMAAKBEDRIJF | H4: 1
A5: UITCHECK_GEPLAND | B5: INCHECK | G5: EIGENAAR | H5: 1.5
A6: UITCHECK_UITGEVOERD | B6: OVERDRACHT_EIGENAAR | H6: 2
A7: SCHOONMAAK_NODIG | B7: REPARATIE | H7: 2.5
A8: KLAAR_VOOR_INCHECK | H8: 3
A9: INCHECK_GEPLAND | H9: 3.5
A10: INCHECK_UITGEVOERD | H10: 4
A11: TERUG_NAAR_EIGENAAR | H11: 4.5
A12: AFGEROND | H12: 5
H13: 5.5
H14: 6
H15: 6.5
H16: 7
H17: 7.5
H18: 8
H19: 8.5
H20: 9
H21: 9.5
H22: 10
H23: 10.5
H24: 11
... H26: 12

Sheet HUIZEN_MASTER
A1: object_id | B1: adres_weergave | C1: actief | D1: Column1
A2: =_xlfn.XLOOKUP(tbl_huizen[[#This Row],[adres_weergave]],OG_HUIZEN_LIJST!C:C,OG_HUIZEN_LIJST!B:B,"",0) -> 0308 | B2: Kerkweg 9a [135] | C2: JA | D2: Kerkweg 9a [135]
A3: =_xlfn.XLOOKUP(tbl_huizen[[#This Row],[adres_weergave]],OG_HUIZEN_LIJST!C:C,OG_HUIZEN_LIJST!B:B,"",0) -> A-0088 | B3: Jasmijnring 35 | C3: JA | D3: Jasmijnring 35
A4: =_xlfn.XLOOKUP(tbl_huizen[[#This Row],[adres_weergave]],OG_HUIZEN_LIJST!C:C,OG_HUIZEN_LIJST!B:B,"",0) -> 0368 | B4: Wedderweg 3 | C4: JA | D4: Wedderweg 3
A5: =_xlfn.XLOOKUP(tbl_huizen[[#This Row],[adres_weergave]],OG_HUIZEN_LIJST!C:C,OG_HUIZEN_LIJST!B:B,"",0) -> 0358 | B5: Monsterseweg 26A | C5: JA | D5: Monsterseweg 26A
A6: =_xlfn.XLOOKUP(tbl_huizen[[#This Row],[adres_weergave]],OG_HUIZEN_LIJST!C:C,OG_HUIZEN_LIJST!B:B,"",0) -> 0041 | B6: Nunspeetlaan 53 | C6: JA | D6: Nunspeetlaan 53
A7: =_xlfn.XLOOKUP(tbl_huizen[[#This Row],[adres_weergave]],OG_HUIZEN_LIJST!C:C,OG_HUIZEN_LIJST!B:B,"",0) -> 0295 | B7: Akkerweg 41 [018] | C7: JA | D7: Akkerweg 41 [018]
A8: =_xlfn.XLOOKUP(tbl_huizen[[#This Row],[adres_weergave]],OG_HUIZEN_LIJST!C:C,OG_HUIZEN_LIJST!B:B,"",0) -> 0300 | B8: Akkerweg 41 [040] | C8: JA | D8: Akkerweg 41 [040]
A9: =_xlfn.XLOOKUP(tbl_huizen[[#This Row],[adres_weergave]],OG_HUIZEN_LIJST!C:C,OG_HUIZEN_LIJST!B:B,"",0) -> 0357 | B9: Akkerweg 41 [038] | C9: JA | D9: Akkerweg 41 [038]
A10: =_xlfn.XLOOKUP(tbl_huizen[[#This Row],[adres_weergave]],OG_HUIZEN_LIJST!C:C,OG_HUIZEN_LIJST!B:B,"",0) -> 0384 | B10: Akkerweg 41 [058] | C10: JA | D10: Akkerweg 41 [058]
A11: =_xlfn.XLOOKUP(tbl_huizen[[#This Row],[adres_weergave]],OG_HUIZEN_LIJST!C:C,OG_HUIZEN_LIJST!B:B,"",0) -> 0101 | B11: Moureauveld 8 | C11: JA | D11: Moureauveld 8
A12: =_xlfn.XLOOKUP(tbl_huizen[[#This Row],[adres_weergave]],OG_HUIZEN_LIJST!C:C,OG_HUIZEN_LIJST!B:B,"",0) -> 0240 | B12: Schoonegge 84 | C12: JA | D12: Schoonegge 84
A13: =_xlfn.XLOOKUP(tbl_huizen[[#This Row],[adres_weergave]],OG_HUIZEN_LIJST!C:C,OG_HUIZEN_LIJST!B:B,"",0) -> 0193 | B13: Kapershoek 11 | C13: JA | D13: Kapershoek 11
... A48: =_xlfn.XLOOKUP(tbl_huizen[[#This Row],[adres_weergave]],OG_HUIZEN_LIJST!C:C,OG_HUIZEN_LIJST!B:B,"",0) -> 0374 | B48: Vierambachtsstraat 32-B01 | C48: JA | D48: Vierambachtsstraat 32-B01

Sheet WONING_CYCLI
A1: cyclus_id | B1: huis_id | C1: adres_weergave | D1: is_actief | E1: klant_type | F1: bestemming | G1: einddatum_huurder | H1: startdatum_nieuwe_huurder | I1: status | J1: laatst_bijgewerkt | K1: interne_opmerking | L1: sleutel_actief | M1: check_voorinspectie_gepland | N1: check_voorinspectie_uitgevoerd | O1: check_uitcheck_gepland | P1: check_uitcheck_uitgevoerd | Q1: check_schoonmaak | R1: check_incheck_gepland | S1: check_incheck_uitgevoerd | T1: foutmelding | U1: Commentaar
A2: C0001 | B2: 0308 | C2: =_xlfn.XLOOKUP(tbl_cycli[[#This Row],[huis_id]],OG_HUIZEN_LIJST!B:B,OG_HUIZEN_LIJST!C:C,"",0) -> Kerkweg 9a [135] | D2: JA | E2: EXTERN | G2: 45804 | I2: NIET_GESTART | J2: 2025-12-19 15:37 | K2: nan | L2: =B2&"|"&D2 -> 0308|JA | M2: =IF(COUNTIFS(tbl_acties[cyclus_id],A2,tbl_acties[actie_type],"VOORINSPECTIE",tbl_acties[gepland_op],"<>")>0,"OK","MIS") -> MIS | N2: =IF(COUNTIFS(tbl_acties[cyclus_id],A2,tbl_acties[actie_type],"VOORINSPECTIE",tbl_acties[uitgevoerd_op],"<>")>0,"OK","MIS") -> MIS | O2: =IF(COUNTIFS(tbl_acties[cyclus_id],A2,tbl_acties[actie_type],"UITCHECK",tbl_acties[gepland_op],"<>")>0,"OK","MIS") -> MIS | P2: =IF(COUNTIFS(tbl_acties[cyclus_id],A2,tbl_acties[actie_type],"UITCHECK",tbl_acties[uitgevoerd_op],"<>",tbl_acties[verwachte_schoonmaak_uren],"<>")>0,"OK","MIS") -> MIS | Q2: =IF(COUNTIFS(tbl_acties[cyclus_id],A2,tbl_acties[actie_type],"SCHOONMAAK",tbl_acties[uitgevoerd_op],"<>",tbl_acties[werkelijke_schoonmaak_uren],"<>")>0,"OK","MIS") -> MIS | R2: =IF(COUNTIFS(tbl_acties[cyclus_id],A2,tbl_acties[actie_type],"INCHECK",tbl_acties[gepland_op],"<>")>0,"OK","MIS") -> MIS | S2: =IF(COUNTIFS(tbl_acties[cyclus_id],A2,tbl_acties[actie_type],"INCHECK",tbl_acties[uitgevoerd_op],"<>",tbl_acties[sleutels_bevestigd],"JA")>0,"OK","MIS") -> MIS | U2: =IF(I2="UITCHECK_UITGEVOERD",IF(P2="OK","","FOUT: uitcheck mist uitgevoerd_op of verwachte uren"),IF(I2="SCHOONMAAK_NODIG",IF(P2="OK","","FOUT: schoonmaak kan pas na uitcheck"),IF(I2="INCHECK_UITGEVOERD",IF(S2="OK","","FOUT: incheck mist sleutelbevestiging/uitgevoerd"),"")))
A3: C0002 | B3: A-0088 | C3: =_xlfn.XLOOKUP(tbl_cycli[[#This Row],[huis_id]],OG_HUIZEN_LIJST!B:B,OG_HUIZEN_LIJST!C:C,"",0) -> Jasmijnring 35 | D3: JA | E3: EXTERN | G3: 45930 | I3: UITCHECK_GEPLAND | J3: 2025-12-19 15:37 | K3: nan | L3: =B3&"|"&D3 -> A-0088|JA | M3: =IF(COUNTIFS(tbl_acties[cyclus_id],A3,tbl_acties[actie_type],"VOORINSPECTIE",tbl_acties[gepland_op],"<>")>0,"OK","MIS") -> MIS | N3: =IF(COUNTIFS(tbl_acties[cyclus_id],A3,tbl_acties[actie_type],"VOORINSPECTIE",tbl_acties[uitgevoerd_op],"<>")>0,"OK","MIS") -> MIS | O3: =IF(COUNTIFS(tbl_acties[cyclus_id],A3,tbl_acties[actie_type],"UITCHECK",tbl_acties[gepland_op],"<>")>0,"OK","MIS") -> OK | P3: =IF(COUNTIFS(tbl_acties[cyclus_id],A3,tbl_acties[actie_type],"UITCHECK",tbl_acties[uitgevoerd_op],"<>",tbl_acties[verwachte_schoonmaak_uren],"<>")>0,"OK","MIS") -> MIS | Q3: =IF(COUNTIFS(tbl_acties[cyclus_id],A3,tbl_acties[actie_type],"SCHOONMAAK",tbl_acties[uitgevoerd_op],"<>",tbl_acties[werkelijke_schoonmaak_uren],"<>")>0,"OK","MIS") -> MIS | R3: =IF(COUNTIFS(tbl_acties[cyclus_id],A3,tbl_acties[actie_type],"INCHECK",tbl_acties[gepland_op],"<>")>0,"OK","MIS") -> MIS | S3: =IF(COUNTIFS(tbl_acties[cyclus_id],A3,tbl_acties[actie_type],"INCHECK",tbl_acties[uitgevoerd_op],"<>",tbl_acties[sleutels_bevestigd],"JA")>0,"OK","MIS") -> MIS | U3: =IF(I3="UITCHECK_UITGEVOERD",IF(P3="OK","","FOUT: uitcheck mist uitgevoerd_op of verwachte uren"),IF(I3="SCHOONMAAK_NODIG",IF(P3="OK","","FOUT: schoonmaak kan pas na uitcheck"),IF(I3="INCHECK_UITGEVOERD",IF(S3="OK","","FOUT: incheck mist sleutelbevestiging/uitgevoerd"),"")))
A4: C0003 | B4: 0368 | C4: =_xlfn.XLOOKUP(tbl_cycli[[#This Row],[huis_id]],OG_HUIZEN_LIJST!B:B,OG_HUIZEN_LIJST!C:C,"",0) -> Wedderweg 3 | D4: JA | E4: EXTERN | G4: 45961 | H4: 07-11 Ana | I4: INCHECK_GEPLAND | J4: 2025-12-19 15:37 | K4: Woensdag 29-10 avond vertrekken de bewoners | L4: =B4&"|"&D4 -> 0368|JA | M4: =IF(COUNTIFS(tbl_acties[cyclus_id],A4,tbl_acties[actie_type],"VOORINSPECTIE",tbl_acties[gepland_op],"<>")>0,"OK","MIS") -> MIS | N4: =IF(COUNTIFS(tbl_acties[cyclus_id],A4,tbl_acties[actie_type],"VOORINSPECTIE",tbl_acties[uitgevoerd_op],"<>")>0,"OK","MIS") -> MIS | O4: =IF(COUNTIFS(tbl_acties[cyclus_id],A4,tbl_acties[actie_type],"UITCHECK",tbl_acties[gepland_op],"<>")>0,"OK","MIS") -> OK | P4: =IF(COUNTIFS(tbl_acties[cyclus_id],A4,tbl_acties[actie_type],"UITCHECK",tbl_acties[uitgevoerd_op],"<>",tbl_acties[verwachte_schoonmaak_uren],"<>")>0,"OK","MIS") -> MIS | Q4: =IF(COUNTIFS(tbl_acties[cyclus_id],A4,tbl_acties[actie_type],"SCHOONMAAK",tbl_acties[uitgevoerd_op],"<>",tbl_acties[werkelijke_schoonmaak_uren],"<>")>0,"OK","MIS") -> MIS | R4: =IF(COUNTIFS(tbl_acties[cyclus_id],A4,tbl_acties[actie_type],"INCHECK",tbl_acties[gepland_op],"<>")>0,"OK","MIS") -> MIS | S4: =IF(COUNTIFS(tbl_acties[cyclus_id],A4,tbl_acties[actie_type],"INCHECK",tbl_acties[uitgevoerd_op],"<>",tbl_acties[sleutels_bevestigd],"JA")>0,"OK","MIS") -> MIS | U4: =IF(I4="UITCHECK_UITGEVOERD",IF(P4="OK","","FOUT: uitcheck mist uitgevoerd_op of verwachte uren"),IF(I4="SCHOONMAAK_NODIG",IF(P4="OK","","FOUT: schoonmaak kan pas na uitcheck"),IF(I4="INCHECK_UITGEVOERD",IF(S4="OK","","FOUT: incheck mist sleutelbevestiging/uitgevoerd"),"")))
A5: C0004 | B5: 0358 | C5: =_xlfn.XLOOKUP(tbl_cycli[[#This Row],[huis_id]],OG_HUIZEN_LIJST!B:B,OG_HUIZEN_LIJST!C:C,"",0) -> Monsterseweg 26A | D5: JA | E5: TRADIRO | G5: 45967 | I5: UITCHECK_GEPLAND | J5: 2025-12-19 15:37 | K5: Gaat deze woning terug naar Tr of naar eigenaar? Christa | L5: =B5&"|"&D5 -> 0358|JA | M5: =IF(COUNTIFS(tbl_acties[cyclus_id],A5,tbl_acties[actie_type],"VOORINSPECTIE",tbl_acties[gepland_op],"<>")>0,"OK","MIS") -> MIS | N5: =IF(COUNTIFS(tbl_acties[cyclus_id],A5,tbl_acties[actie_type],"VOORINSPECTIE",tbl_acties[uitgevoerd_op],"<>")>0,"OK","MIS") -> MIS | O5: =IF(COUNTIFS(tbl_acties[cyclus_id],A5,tbl_acties[actie_type],"UITCHECK",tbl_acties[gepland_op],"<>")>0,"OK","MIS") -> OK | P5: =IF(COUNTIFS(tbl_acties[cyclus_id],A5,tbl_acties[actie_type],"UITCHECK",tbl_acties[uitgevoerd_op],"<>",tbl_acties[verwachte_schoonmaak_uren],"<>")>0,"OK","MIS") -> MIS | Q5: =IF(COUNTIFS(tbl_acties[cyclus_id],A5,tbl_acties[actie_type],"SCHOONMAAK",tbl_acties[uitgevoerd_op],"<>",tbl_acties[werkelijke_schoonmaak_uren],"<>")>0,"OK","MIS") -> MIS | R5: =IF(COUNTIFS(tbl_acties[cyclus_id],A5,tbl_acties[actie_type],"INCHECK",tbl_acties[gepland_op],"<>")>0,"OK","MIS") -> MIS | S5: =IF(COUNTIFS(tbl_acties[cyclus_id],A5,tbl_acties[actie_type],"INCHECK",tbl_acties[uitgevoerd_op],"<>",tbl_acties[sleutels_bevestigd],"JA")>0,"OK","MIS") -> MIS | U5: =IF(I5="UITCHECK_UITGEVOERD",IF(P5="OK","","FOUT: uitcheck mist uitgevoerd_op of verwachte uren"),IF(I5="SCHOONMAAK_NODIG",IF(P5="OK","","FOUT: schoonmaak kan pas na uitcheck"),IF(I5="INCHECK_UITGEVOERD",IF(S5="OK","","FOUT: incheck mist sleutelbevestiging/uitgevoerd"),"")))
A6: C0005 | B6: 0041 | C6: =_xlfn.XLOOKUP(tbl_cycli[[#This Row],[huis_id]],OG_HUIZEN_LIJST!B:B,OG_HUIZEN_LIJST!C:C,"",0) -> Nunspeetlaan 53 | D6: JA | E6: EXTERN | G6: 45989 | I6: UITCHECK_GEPLAND | J6: 2025-12-19 15:37 | K6: woning moet worden leeggehaald | L6: =B6&"|"&D6 -> 0041|JA | M6: =IF(COUNTIFS(tbl_acties[cyclus_id],A6,tbl_acties[actie_type],"VOORINSPECTIE",tbl_acties[gepland_op],"<>")>0,"OK","MIS") -> MIS | N6: =IF(COUNTIFS(tbl_acties[cyclus_id],A6,tbl_acties[actie_type],"VOORINSPECTIE",tbl_acties[uitgevoerd_op],"<>")>0,"OK","MIS") -> MIS | O6: =IF(COUNTIFS(tbl_acties[cyclus_id],A6,tbl_acties[actie_type],"UITCHECK",tbl_acties[gepland_op],"<>")>0,"OK","MIS") -> MIS | P6: =IF(COUNTIFS(tbl_acties[cyclus_id],A6,tbl_acties[actie_type],"UITCHECK",tbl_acties[uitgevoerd_op],"<>",tbl_acties[verwachte_schoonmaak_uren],"<>")>0,"OK","MIS") -> MIS | Q6: =IF(COUNTIFS(tbl_acties[cyclus_id],A6,tbl_acties[actie_type],"SCHOONMAAK",tbl_acties[uitgevoerd_op],"<>",tbl_acties[werkelijke_schoonmaak_uren],"<>")>0,"OK","MIS") -> MIS | R6: =IF(COUNTIFS(tbl_acties[cyclus_id],A6,tbl_acties[actie_type],"INCHECK",tbl_acties[gepland_op],"<>")>0,"OK","MIS") -> MIS | S6: =IF(COUNTIFS(tbl_acties[cyclus_id],A6,tbl_acties[actie_type],"INCHECK",tbl_acties[uitgevoerd_op],"<>",tbl_acties[sleutels_bevestigd],"JA")>0,"OK","MIS") -> MIS | U6: =IF(I6="UITCHECK_UITGEVOERD",IF(P6="OK","","FOUT: uitcheck mist uitgevoerd_op of verwachte uren"),IF(I6="SCHOONMAAK_NODIG",IF(P6="OK","","FOUT: schoonmaak kan pas na uitcheck"),IF(I6="INCHECK_UITGEVOERD",IF(S6="OK","","FOUT: incheck mist sleutelbevestiging/uitgevoerd"),"")))
A7: C0006 | B7: 0295 | C7: =_xlfn.XLOOKUP(tbl_cycli[[#This Row],[huis_id]],OG_HUIZEN_LIJST!B:B,OG_HUIZEN_LIJST!C:C,"",0) -> Akkerweg 41 [018] | D7: JA | E7: EXTERN | G7: 45962 | I7: UITCHECK_GEPLAND | J7: 2025-12-19 15:37 | K7: nan | L7: =B7&"|"&D7 -> 0295|JA | M7: =IF(COUNTIFS(tbl_acties[cyclus_id],A7,tbl_acties[actie_type],"VOORINSPECTIE",tbl_acties[gepland_op],"<>")>0,"OK","MIS") -> MIS | N7: =IF(COUNTIFS(tbl_acties[cyclus_id],A7,tbl_acties[actie_type],"VOORINSPECTIE",tbl_acties[uitgevoerd_op],"<>")>0,"OK","MIS") -> MIS | O7: =IF(COUNTIFS(tbl_acties[cyclus_id],A7,tbl_acties[actie_type],"UITCHECK",tbl_acties[gepland_op],"<>")>0,"OK","MIS") -> OK | P7: =IF(COUNTIFS(tbl_acties[cyclus_id],A7,tbl_acties[actie_type],"UITCHECK",tbl_acties[uitgevoerd_op],"<>",tbl_acties[verwachte_schoonmaak_uren],"<>")>0,"OK","MIS") -> MIS | Q7: =IF(COUNTIFS(tbl_acties[cyclus_id],A7,tbl_acties[actie_type],"SCHOONMAAK",tbl_acties[uitgevoerd_op],"<>",tbl_acties[werkelijke_schoonmaak_uren],"<>")>0,"OK","MIS") -> MIS | R7: =IF(COUNTIFS(tbl_acties[cyclus_id],A7,tbl_acties[actie_type],"INCHECK",tbl_acties[gepland_op],"<>")>0,"OK","MIS") -> MIS | S7: =IF(COUNTIFS(tbl_acties[cyclus_id],A7,tbl_acties[actie_type],"INCHECK",tbl_acties[uitgevoerd_op],"<>",tbl_acties[sleutels_bevestigd],"JA")>0,"OK","MIS") -> MIS | U7: =IF(I7="UITCHECK_UITGEVOERD",IF(P7="OK","","FOUT: uitcheck mist uitgevoerd_op of verwachte uren"),IF(I7="SCHOONMAAK_NODIG",IF(P7="OK","","FOUT: schoonmaak kan pas na uitcheck"),IF(I7="INCHECK_UITGEVOERD",IF(S7="OK","","FOUT: incheck mist sleutelbevestiging/uitgevoerd"),"")))
A8: C0007 | B8: 0300 | C8: =_xlfn.XLOOKUP(tbl_cycli[[#This Row],[huis_id]],OG_HUIZEN_LIJST!B:B,OG_HUIZEN_LIJST!C:C,"",0) -> Akkerweg 41 [040] | D8: JA | E8: EXTERN | G8: 45991 | I8: UITCHECK_GEPLAND | J8: 2025-12-19 15:37 | K8: nan | L8: =B8&"|"&D8 -> 0300|JA | M8: =IF(COUNTIFS(tbl_acties[cyclus_id],A8,tbl_acties[actie_type],"VOORINSPECTIE",tbl_acties[gepland_op],"<>")>0,"OK","MIS") -> MIS | N8: =IF(COUNTIFS(tbl_acties[cyclus_id],A8,tbl_acties[actie_type],"VOORINSPECTIE",tbl_acties[uitgevoerd_op],"<>")>0,"OK","MIS") -> MIS | O8: =IF(COUNTIFS(tbl_acties[cyclus_id],A8,tbl_acties[actie_type],"UITCHECK",tbl_acties[gepland_op],"<>")>0,"OK","MIS") -> OK | P8: =IF(COUNTIFS(tbl_acties[cyclus_id],A8,tbl_acties[actie_type],"UITCHECK",tbl_acties[uitgevoerd_op],"<>",tbl_acties[verwachte_schoonmaak_uren],"<>")>0,"OK","MIS") -> MIS | Q8: =IF(COUNTIFS(tbl_acties[cyclus_id],A8,tbl_acties[actie_type],"SCHOONMAAK",tbl_acties[uitgevoerd_op],"<>",tbl_acties[werkelijke_schoonmaak_uren],"<>")>0,"OK","MIS") -> MIS | R8: =IF(COUNTIFS(tbl_acties[cyclus_id],A8,tbl_acties[actie_type],"INCHECK",tbl_acties[gepland_op],"<>")>0,"OK","MIS") -> MIS | S8: =IF(COUNTIFS(tbl_acties[cyclus_id],A8,tbl_acties[actie_type],"INCHECK",tbl_acties[uitgevoerd_op],"<>",tbl_acties[sleutels_bevestigd],"JA")>0,"OK","MIS") -> MIS | U8: =IF(I8="UITCHECK_UITGEVOERD",IF(P8="OK","","FOUT: uitcheck mist uitgevoerd_op of verwachte uren"),IF(I8="SCHOONMAAK_NODIG",IF(P8="OK","","FOUT: schoonmaak kan pas na uitcheck"),IF(I8="INCHECK_UITGEVOERD",IF(S8="OK","","FOUT: incheck mist sleutelbevestiging/uitgevoerd"),"")))
A9: C0008 | B9: 0357 | C9: =_xlfn.XLOOKUP(tbl_cycli[[#This Row],[huis_id]],OG_HUIZEN_LIJST!B:B,OG_HUIZEN_LIJST!C:C,"",0) -> Akkerweg 41 [038] | D9: JA | E9: EXTERN | G9: 45962 | I9: NIET_GESTART | J9: 2025-12-19 15:37 | K9: nan | L9: =B9&"|"&D9 -> 0357|JA | M9: =IF(COUNTIFS(tbl_acties[cyclus_id],A9,tbl_acties[actie_type],"VOORINSPECTIE",tbl_acties[gepland_op],"<>")>0,"OK","MIS") -> MIS | N9: =IF(COUNTIFS(tbl_acties[cyclus_id],A9,tbl_acties[actie_type],"VOORINSPECTIE",tbl_acties[uitgevoerd_op],"<>")>0,"OK","MIS") -> MIS | O9: =IF(COUNTIFS(tbl_acties[cyclus_id],A9,tbl_acties[actie_type],"UITCHECK",tbl_acties[gepland_op],"<>")>0,"OK","MIS") -> MIS | P9: =IF(COUNTIFS(tbl_acties[cyclus_id],A9,tbl_acties[actie_type],"UITCHECK",tbl_acties[uitgevoerd_op],"<>",tbl_acties[verwachte_schoonmaak_uren],"<>")>0,"OK","MIS") -> MIS | Q9: =IF(COUNTIFS(tbl_acties[cyclus_id],A9,tbl_acties[actie_type],"SCHOONMAAK",tbl_acties[uitgevoerd_op],"<>",tbl_acties[werkelijke_schoonmaak_uren],"<>")>0,"OK","MIS") -> MIS | R9: =IF(COUNTIFS(tbl_acties[cyclus_id],A9,tbl_acties[actie_type],"INCHECK",tbl_acties[gepland_op],"<>")>0,"OK","MIS") -> MIS | S9: =IF(COUNTIFS(tbl_acties[cyclus_id],A9,tbl_acties[actie_type],"INCHECK",tbl_acties[uitgevoerd_op],"<>",tbl_acties[sleutels_bevestigd],"JA")>0,"OK","MIS") -> MIS | U9: =IF(I9="UITCHECK_UITGEVOERD",IF(P9="OK","","FOUT: uitcheck mist uitgevoerd_op of verwachte uren"),IF(I9="SCHOONMAAK_NODIG",IF(P9="OK","","FOUT: schoonmaak kan pas na uitcheck"),IF(I9="INCHECK_UITGEVOERD",IF(S9="OK","","FOUT: incheck mist sleutelbevestiging/uitgevoerd"),"")))
A10: C0009 | B10: 0384 | C10: =_xlfn.XLOOKUP(tbl_cycli[[#This Row],[huis_id]],OG_HUIZEN_LIJST!B:B,OG_HUIZEN_LIJST!C:C,"",0) -> Akkerweg 41 [058] | D10: JA | E10: EXTERN | G10: 45991 | I10: UITCHECK_GEPLAND | J10: 2025-12-19 15:37 | K10: huis is al leeg 30-10. | L10: =B10&"|"&D10 -> 0384|JA | M10: =IF(COUNTIFS(tbl_acties[cyclus_id],A10,tbl_acties[actie_type],"VOORINSPECTIE",tbl_acties[gepland_op],"<>")>0,"OK","MIS") -> MIS | N10: =IF(COUNTIFS(tbl_acties[cyclus_id],A10,tbl_acties[actie_type],"VOORINSPECTIE",tbl_acties[uitgevoerd_op],"<>")>0,"OK","MIS") -> MIS | O10: =IF(COUNTIFS(tbl_acties[cyclus_id],A10,tbl_acties[actie_type],"UITCHECK",tbl_acties[gepland_op],"<>")>0,"OK","MIS") -> OK | P10: =IF(COUNTIFS(tbl_acties[cyclus_id],A10,tbl_acties[actie_type],"UITCHECK",tbl_acties[uitgevoerd_op],"<>",tbl_acties[verwachte_schoonmaak_uren],"<>")>0,"OK","MIS") -> MIS | Q10: =IF(COUNTIFS(tbl_acties[cyclus_id],A10,tbl_acties[actie_type],"SCHOONMAAK",tbl_acties[uitgevoerd_op],"<>",tbl_acties[werkelijke_schoonmaak_uren],"<>")>0,"OK","MIS") -> MIS | R10: =IF(COUNTIFS(tbl_acties[cyclus_id],A10,tbl_acties[actie_type],"INCHECK",tbl_acties[gepland_op],"<>")>0,"OK","MIS") -> MIS | S10: =IF(COUNTIFS(tbl_acties[cyclus_id],A10,tbl_acties[actie_type],"INCHECK",tbl_acties[uitgevoerd_op],"<>",tbl_acties[sleutels_bevestigd],"JA")>0,"OK","MIS") -> MIS | U10: =IF(I10="UITCHECK_UITGEVOERD",IF(P10="OK","","FOUT: uitcheck mist uitgevoerd_op of verwachte uren"),IF(I10="SCHOONMAAK_NODIG",IF(P10="OK","","FOUT: schoonmaak kan pas na uitcheck"),IF(I10="INCHECK_UITGEVOERD",IF(S10="OK","","FOUT: incheck mist sleutelbevestiging/uitgevoerd"),"")))
A11: C0010 | B11: 0101 | C11: =_xlfn.XLOOKUP(tbl_cycli[[#This Row],[huis_id]],OG_HUIZEN_LIJST!B:B,OG_HUIZEN_LIJST!C:C,"",0) -> Moureauveld 8 | D11: JA | E11: EXTERN | G11: 45991 | H11: 45996 | I11: INCHECK_GEPLAND | J11: 2025-12-19 15:37 | K11: nan | L11: =B11&"|"&D11 -> 0101|JA | M11: =IF(COUNTIFS(tbl_acties[cyclus_id],A11,tbl_acties[actie_type],"VOORINSPECTIE",tbl_acties[gepland_op],"<>")>0,"OK","MIS") -> MIS | N11: =IF(COUNTIFS(tbl_acties[cyclus_id],A11,tbl_acties[actie_type],"VOORINSPECTIE",tbl_acties[uitgevoerd_op],"<>")>0,"OK","MIS") -> MIS | O11: =IF(COUNTIFS(tbl_acties[cyclus_id],A11,tbl_acties[actie_type],"UITCHECK",tbl_acties[gepland_op],"<>")>0,"OK","MIS") -> OK | P11: =IF(COUNTIFS(tbl_acties[cyclus_id],A11,tbl_acties[actie_type],"UITCHECK",tbl_acties[uitgevoerd_op],"<>",tbl_acties[verwachte_schoonmaak_uren],"<>")>0,"OK","MIS") -> MIS | Q11: =IF(COUNTIFS(tbl_acties[cyclus_id],A11,tbl_acties[actie_type],"SCHOONMAAK",tbl_acties[uitgevoerd_op],"<>",tbl_acties[werkelijke_schoonmaak_uren],"<>")>0,"OK","MIS") -> MIS | R11: =IF(COUNTIFS(tbl_acties[cyclus_id],A11,tbl_acties[actie_type],"INCHECK",tbl_acties[gepland_op],"<>")>0,"OK","MIS") -> OK | S11: =IF(COUNTIFS(tbl_acties[cyclus_id],A11,tbl_acties[actie_type],"INCHECK",tbl_acties[uitgevoerd_op],"<>",tbl_acties[sleutels_bevestigd],"JA")>0,"OK","MIS") -> MIS | U11: =IF(I11="UITCHECK_UITGEVOERD",IF(P11="OK","","FOUT: uitcheck mist uitgevoerd_op of verwachte uren"),IF(I11="SCHOONMAAK_NODIG",IF(P11="OK","","FOUT: schoonmaak kan pas na uitcheck"),IF(I11="INCHECK_UITGEVOERD",IF(S11="OK","","FOUT: incheck mist sleutelbevestiging/uitgevoerd"),"")))
A12: C0011 | B12: 0240 | C12: =_xlfn.XLOOKUP(tbl_cycli[[#This Row],[huis_id]],OG_HUIZEN_LIJST!B:B,OG_HUIZEN_LIJST!C:C,"",0) -> Schoonegge 84 | D12: JA | E12: TRADIRO | I12: UITCHECK_GEPLAND | J12: 2025-12-19 15:37 | K12: schoonmaak nodig | L12: =B12&"|"&D12 -> 0240|JA | M12: =IF(COUNTIFS(tbl_acties[cyclus_id],A12,tbl_acties[actie_type],"VOORINSPECTIE",tbl_acties[gepland_op],"<>")>0,"OK","MIS") -> OK | N12: =IF(COUNTIFS(tbl_acties[cyclus_id],A12,tbl_acties[actie_type],"VOORINSPECTIE",tbl_acties[uitgevoerd_op],"<>")>0,"OK","MIS") -> MIS | O12: =IF(COUNTIFS(tbl_acties[cyclus_id],A12,tbl_acties[actie_type],"UITCHECK",tbl_acties[gepland_op],"<>")>0,"OK","MIS") -> OK | P12: =IF(COUNTIFS(tbl_acties[cyclus_id],A12,tbl_acties[actie_type],"UITCHECK",tbl_acties[uitgevoerd_op],"<>",tbl_acties[verwachte_schoonmaak_uren],"<>")>0,"OK","MIS") -> MIS | Q12: =IF(COUNTIFS(tbl_acties[cyclus_id],A12,tbl_acties[actie_type],"SCHOONMAAK",tbl_acties[uitgevoerd_op],"<>",tbl_acties[werkelijke_schoonmaak_uren],"<>")>0,"OK","MIS") -> MIS | R12: =IF(COUNTIFS(tbl_acties[cyclus_id],A12,tbl_acties[actie_type],"INCHECK",tbl_acties[gepland_op],"<>")>0,"OK","MIS") -> MIS | S12: =IF(COUNTIFS(tbl_acties[cyclus_id],A12,tbl_acties[actie_type],"INCHECK",tbl_acties[uitgevoerd_op],"<>",tbl_acties[sleutels_bevestigd],"JA")>0,"OK","MIS") -> MIS | U12: =IF(I12="UITCHECK_UITGEVOERD",IF(P12="OK","","FOUT: uitcheck mist uitgevoerd_op of verwachte uren"),IF(I12="SCHOONMAAK_NODIG",IF(P12="OK","","FOUT: schoonmaak kan pas na uitcheck"),IF(I12="INCHECK_UITGEVOERD",IF(S12="OK","","FOUT: incheck mist sleutelbevestiging/uitgevoerd"),"")))
A13: C0012 | B13: 0193 | C13: =_xlfn.XLOOKUP(tbl_cycli[[#This Row],[huis_id]],OG_HUIZEN_LIJST!B:B,OG_HUIZEN_LIJST!C:C,"",0) -> Kapershoek 11 | D13: JA | E13: TRADIRO | H13: 46003 | I13: INCHECK_GEPLAND | J13: 2025-12-19 15:37 | K13: nan | L13: =B13&"|"&D13 -> 0193|JA | M13: =IF(COUNTIFS(tbl_acties[cyclus_id],A13,tbl_acties[actie_type],"VOORINSPECTIE",tbl_acties[gepland_op],"<>")>0,"OK","MIS") -> MIS | N13: =IF(COUNTIFS(tbl_acties[cyclus_id],A13,tbl_acties[actie_type],"VOORINSPECTIE",tbl_acties[uitgevoerd_op],"<>")>0,"OK","MIS") -> MIS | O13: =IF(COUNTIFS(tbl_acties[cyclus_id],A13,tbl_acties[actie_type],"UITCHECK",tbl_acties[gepland_op],"<>")>0,"OK","MIS") -> MIS | P13: =IF(COUNTIFS(tbl_acties[cyclus_id],A13,tbl_acties[actie_type],"UITCHECK",tbl_acties[uitgevoerd_op],"<>",tbl_acties[verwachte_schoonmaak_uren],"<>")>0,"OK","MIS") -> MIS | Q13: =IF(COUNTIFS(tbl_acties[cyclus_id],A13,tbl_acties[actie_type],"SCHOONMAAK",tbl_acties[uitgevoerd_op],"<>",tbl_acties[werkelijke_schoonmaak_uren],"<>")>0,"OK","MIS") -> MIS | R13: =IF(COUNTIFS(tbl_acties[cyclus_id],A13,tbl_acties[actie_type],"INCHECK",tbl_acties[gepland_op],"<>")>0,"OK","MIS") -> OK | S13: =IF(COUNTIFS(tbl_acties[cyclus_id],A13,tbl_acties[actie_type],"INCHECK",tbl_acties[uitgevoerd_op],"<>",tbl_acties[sleutels_bevestigd],"JA")>0,"OK","MIS") -> MIS | U13: =IF(I13="UITCHECK_UITGEVOERD",IF(P13="OK","","FOUT: uitcheck mist uitgevoerd_op of verwachte uren"),IF(I13="SCHOONMAAK_NODIG",IF(P13="OK","","FOUT: schoonmaak kan pas na uitcheck"),IF(I13="INCHECK_UITGEVOERD",IF(S13="OK","","FOUT: incheck mist sleutelbevestiging/uitgevoerd"),"")))
A14: C0013 | B14: 0341 | C14: =_xlfn.XLOOKUP(tbl_cycli[[#This Row],[huis_id]],OG_HUIZEN_LIJST!B:B,OG_HUIZEN_LIJST!C:C,"",0) -> Akkerweg 41 [010] | D14: JA | E14: EXTERN | G14: 45992 | I14: UITCHECK_GEPLAND | J14: 2025-12-19 15:37 | K14: Samen met Ricky met SNF dag? | L14: =B14&"|"&D14 -> 0341|JA | M14: =IF(COUNTIFS(tbl_acties[cyclus_id],A14,tbl_acties[actie_type],"VOORINSPECTIE",tbl_acties[gepland_op],"<>")>0,"OK","MIS") -> MIS | N14: =IF(COUNTIFS(tbl_acties[cyclus_id],A14,tbl_acties[actie_type],"VOORINSPECTIE",tbl_acties[uitgevoerd_op],"<>")>0,"OK","MIS") -> MIS | O14: =IF(COUNTIFS(tbl_acties[cyclus_id],A14,tbl_acties[actie_type],"UITCHECK",tbl_acties[gepland_op],"<>")>0,"OK","MIS") -> OK | P14: =IF(COUNTIFS(tbl_acties[cyclus_id],A14,tbl_acties[actie_type],"UITCHECK",tbl_acties[uitgevoerd_op],"<>",tbl_acties[verwachte_schoonmaak_uren],"<>")>0,"OK","MIS") -> MIS | Q14: =IF(COUNTIFS(tbl_acties[cyclus_id],A14,tbl_acties[actie_type],"SCHOONMAAK",tbl_acties[uitgevoerd_op],"<>",tbl_acties[werkelijke_schoonmaak_uren],"<>")>0,"OK","MIS") -> MIS | R14: =IF(COUNTIFS(tbl_acties[cyclus_id],A14,tbl_acties[actie_type],"INCHECK",tbl_acties[gepland_op],"<>")>0,"OK","MIS") -> MIS | S14: =IF(COUNTIFS(tbl_acties[cyclus_id],A14,tbl_acties[actie_type],"INCHECK",tbl_acties[uitgevoerd_op],"<>",tbl_acties[sleutels_bevestigd],"JA")>0,"OK","MIS") -> MIS | U14: =IF(I14="UITCHECK_UITGEVOERD",IF(P14="OK","","FOUT: uitcheck mist uitgevoerd_op of verwachte uren"),IF(I14="SCHOONMAAK_NODIG",IF(P14="OK","","FOUT: schoonmaak kan pas na uitcheck"),IF(I14="INCHECK_UITGEVOERD",IF(S14="OK","","FOUT: incheck mist sleutelbevestiging/uitgevoerd"),"")))
A15: C0014 | B15: 0342 | C15: =_xlfn.XLOOKUP(tbl_cycli[[#This Row],[huis_id]],OG_HUIZEN_LIJST!B:B,OG_HUIZEN_LIJST!C:C,"",0) -> Akkerweg 41 [016] | D15: JA | E15: EXTERN | G15: 45992 | I15: UITCHECK_GEPLAND | J15: 2025-12-19 15:37 | K15: Samen met Ricky met SNF dag? | L15: =B15&"|"&D15 -> 0342|JA | M15: =IF(COUNTIFS(tbl_acties[cyclus_id],A15,tbl_acties[actie_type],"VOORINSPECTIE",tbl_acties[gepland_op],"<>")>0,"OK","MIS") -> MIS | N15: =IF(COUNTIFS(tbl_acties[cyclus_id],A15,tbl_acties[actie_type],"VOORINSPECTIE",tbl_acties[uitgevoerd_op],"<>")>0,"OK","MIS") -> MIS | O15: =IF(COUNTIFS(tbl_acties[cyclus_id],A15,tbl_acties[actie_type],"UITCHECK",tbl_acties[gepland_op],"<>")>0,"OK","MIS") -> OK | P15: =IF(COUNTIFS(tbl_acties[cyclus_id],A15,tbl_acties[actie_type],"UITCHECK",tbl_acties[uitgevoerd_op],"<>",tbl_acties[verwachte_schoonmaak_uren],"<>")>0,"OK","MIS") -> MIS | Q15: =IF(COUNTIFS(tbl_acties[cyclus_id],A15,tbl_acties[actie_type],"SCHOONMAAK",tbl_acties[uitgevoerd_op],"<>",tbl_acties[werkelijke_schoonmaak_uren],"<>")>0,"OK","MIS") -> MIS | R15: =IF(COUNTIFS(tbl_acties[cyclus_id],A15,tbl_acties[actie_type],"INCHECK",tbl_acties[gepland_op],"<>")>0,"OK","MIS") -> MIS | S15: =IF(COUNTIFS(tbl_acties[cyclus_id],A15,tbl_acties[actie_type],"INCHECK",tbl_acties[uitgevoerd_op],"<>",tbl_acties[sleutels_bevestigd],"JA")>0,"OK","MIS") -> MIS | U15: =IF(I15="UITCHECK_UITGEVOERD",IF(P15="OK","","FOUT: uitcheck mist uitgevoerd_op of verwachte uren"),IF(I15="SCHOONMAAK_NODIG",IF(P15="OK","","FOUT: schoonmaak kan pas na uitcheck"),IF(I15="INCHECK_UITGEVOERD",IF(S15="OK","","FOUT: incheck mist sleutelbevestiging/uitgevoerd"),"")))
A16: C0015 | B16: 0343 | C16: =_xlfn.XLOOKUP(tbl_cycli[[#This Row],[huis_id]],OG_HUIZEN_LIJST!B:B,OG_HUIZEN_LIJST!C:C,"",0) -> Akkerweg 41 [019] | D16: JA | E16: EXTERN | G16: 45992 | I16: UITCHECK_GEPLAND | J16: 2025-12-19 15:37 | K16: Samen met Ricky met SNF dag? | L16: =B16&"|"&D16 -> 0343|JA | M16: =IF(COUNTIFS(tbl_acties[cyclus_id],A16,tbl_acties[actie_type],"VOORINSPECTIE",tbl_acties[gepland_op],"<>")>0,"OK","MIS") -> MIS | N16: =IF(COUNTIFS(tbl_acties[cyclus_id],A16,tbl_acties[actie_type],"VOORINSPECTIE",tbl_acties[uitgevoerd_op],"<>")>0,"OK","MIS") -> MIS | O16: =IF(COUNTIFS(tbl_acties[cyclus_id],A16,tbl_acties[actie_type],"UITCHECK",tbl_acties[gepland_op],"<>")>0,"OK","MIS") -> OK | P16: =IF(COUNTIFS(tbl_acties[cyclus_id],A16,tbl_acties[actie_type],"UITCHECK",tbl_acties[uitgevoerd_op],"<>",tbl_acties[verwachte_schoonmaak_uren],"<>")>0,"OK","MIS") -> MIS | Q16: =IF(COUNTIFS(tbl_acties[cyclus_id],A16,tbl_acties[actie_type],"SCHOONMAAK",tbl_acties[uitgevoerd_op],"<>",tbl_acties[werkelijke_schoonmaak_uren],"<>")>0,"OK","MIS") -> MIS | R16: =IF(COUNTIFS(tbl_acties[cyclus_id],A16,tbl_acties[actie_type],"INCHECK",tbl_acties[gepland_op],"<>")>0,"OK","MIS") -> MIS | S16: =IF(COUNTIFS(tbl_acties[cyclus_id],A16,tbl_acties[actie_type],"INCHECK",tbl_acties[uitgevoerd_op],"<>",tbl_acties[sleutels_bevestigd],"JA")>0,"OK","MIS") -> MIS | U16: =IF(I16="UITCHECK_UITGEVOERD",IF(P16="OK","","FOUT: uitcheck mist uitgevoerd_op of verwachte uren"),IF(I16="SCHOONMAAK_NODIG",IF(P16="OK","","FOUT: schoonmaak kan pas na uitcheck"),IF(I16="INCHECK_UITGEVOERD",IF(S16="OK","","FOUT: incheck mist sleutelbevestiging/uitgevoerd"),"")))
A17: C0016 | B17: 0303 | C17: =_xlfn.XLOOKUP(tbl_cycli[[#This Row],[huis_id]],OG_HUIZEN_LIJST!B:B,OG_HUIZEN_LIJST!C:C,"",0) -> Akkerweg 41 [055] | D17: JA | E17: EXTERN | G17: 45992 | I17: UITCHECK_GEPLAND | J17: 2025-12-19 15:37 | K17: Samen met Ricky met SNF dag? | L17: =B17&"|"&D17 -> 0303|JA | M17: =IF(COUNTIFS(tbl_acties[cyclus_id],A17,tbl_acties[actie_type],"VOORINSPECTIE",tbl_acties[gepland_op],"<>")>0,"OK","MIS") -> MIS | N17: =IF(COUNTIFS(tbl_acties[cyclus_id],A17,tbl_acties[actie_type],"VOORINSPECTIE",tbl_acties[uitgevoerd_op],"<>")>0,"OK","MIS") -> MIS | O17: =IF(COUNTIFS(tbl_acties[cyclus_id],A17,tbl_acties[actie_type],"UITCHECK",tbl_acties[gepland_op],"<>")>0,"OK","MIS") -> OK | P17: =IF(COUNTIFS(tbl_acties[cyclus_id],A17,tbl_acties[actie_type],"UITCHECK",tbl_acties[uitgevoerd_op],"<>",tbl_acties[verwachte_schoonmaak_uren],"<>")>0,"OK","MIS") -> MIS | Q17: =IF(COUNTIFS(tbl_acties[cyclus_id],A17,tbl_acties[actie_type],"SCHOONMAAK",tbl_acties[uitgevoerd_op],"<>",tbl_acties[werkelijke_schoonmaak_uren],"<>")>0,"OK","MIS") -> MIS | R17: =IF(COUNTIFS(tbl_acties[cyclus_id],A17,tbl_acties[actie_type],"INCHECK",tbl_acties[gepland_op],"<>")>0,"OK","MIS") -> MIS | S17: =IF(COUNTIFS(tbl_acties[cyclus_id],A17,tbl_acties[actie_type],"INCHECK",tbl_acties[uitgevoerd_op],"<>",tbl_acties[sleutels_bevestigd],"JA")>0,"OK","MIS") -> MIS | U17: =IF(I17="UITCHECK_UITGEVOERD",IF(P17="OK","","FOUT: uitcheck mist uitgevoerd_op of verwachte uren"),IF(I17="SCHOONMAAK_NODIG",IF(P17="OK","","FOUT: schoonmaak kan pas na uitcheck"),IF(I17="INCHECK_UITGEVOERD",IF(S17="OK","","FOUT: incheck mist sleutelbevestiging/uitgevoerd"),"")))
A18: C0017 | B18: 0304 | C18: =_xlfn.XLOOKUP(tbl_cycli[[#This Row],[huis_id]],OG_HUIZEN_LIJST!B:B,OG_HUIZEN_LIJST!C:C,"",0) -> Akkerweg 41 [056] | D18: JA | E18: EXTERN | G18: 45992 | I18: UITCHECK_GEPLAND | J18: 2025-12-19 15:37 | K18: Samen met Ricky met SNF dag? | L18: =B18&"|"&D18 -> 0304|JA | M18: =IF(COUNTIFS(tbl_acties[cyclus_id],A18,tbl_acties[actie_type],"VOORINSPECTIE",tbl_acties[gepland_op],"<>")>0,"OK","MIS") -> MIS | N18: =IF(COUNTIFS(tbl_acties[cyclus_id],A18,tbl_acties[actie_type],"VOORINSPECTIE",tbl_acties[uitgevoerd_op],"<>")>0,"OK","MIS") -> MIS | O18: =IF(COUNTIFS(tbl_acties[cyclus_id],A18,tbl_acties[actie_type],"UITCHECK",tbl_acties[gepland_op],"<>")>0,"OK","MIS") -> OK | P18: =IF(COUNTIFS(tbl_acties[cyclus_id],A18,tbl_acties[actie_type],"UITCHECK",tbl_acties[uitgevoerd_op],"<>",tbl_acties[verwachte_schoonmaak_uren],"<>")>0,"OK","MIS") -> MIS | Q18: =IF(COUNTIFS(tbl_acties[cyclus_id],A18,tbl_acties[actie_type],"SCHOONMAAK",tbl_acties[uitgevoerd_op],"<>",tbl_acties[werkelijke_schoonmaak_uren],"<>")>0,"OK","MIS") -> MIS | R18: =IF(COUNTIFS(tbl_acties[cyclus_id],A18,tbl_acties[actie_type],"INCHECK",tbl_acties[gepland_op],"<>")>0,"OK","MIS") -> MIS | S18: =IF(COUNTIFS(tbl_acties[cyclus_id],A18,tbl_acties[actie_type],"INCHECK",tbl_acties[uitgevoerd_op],"<>",tbl_acties[sleutels_bevestigd],"JA")>0,"OK","MIS") -> MIS | U18: =IF(I18="UITCHECK_UITGEVOERD",IF(P18="OK","","FOUT: uitcheck mist uitgevoerd_op of verwachte uren"),IF(I18="SCHOONMAAK_NODIG",IF(P18="OK","","FOUT: schoonmaak kan pas na uitcheck"),IF(I18="INCHECK_UITGEVOERD",IF(S18="OK","","FOUT: incheck mist sleutelbevestiging/uitgevoerd"),"")))
A19: C0018 | B19: 0085 | C19: =_xlfn.XLOOKUP(tbl_cycli[[#This Row],[huis_id]],OG_HUIZEN_LIJST!B:B,OG_HUIZEN_LIJST!C:C,"",0) -> Kierkegaardhof 54 | D19: JA | E19: EXTERN | G19: 45994 | H19: 14-11-2025 Jakub | I19: INCHECK_GEPLAND | J19: 2025-12-19 15:37 | K19: met bedlinnen | L19: =B19&"|"&D19 -> 0085|JA | M19: =IF(COUNTIFS(tbl_acties[cyclus_id],A19,tbl_acties[actie_type],"VOORINSPECTIE",tbl_acties[gepland_op],"<>")>0,"OK","MIS") -> MIS | N19: =IF(COUNTIFS(tbl_acties[cyclus_id],A19,tbl_acties[actie_type],"VOORINSPECTIE",tbl_acties[uitgevoerd_op],"<>")>0,"OK","MIS") -> MIS | O19: =IF(COUNTIFS(tbl_acties[cyclus_id],A19,tbl_acties[actie_type],"UITCHECK",tbl_acties[gepland_op],"<>")>0,"OK","MIS") -> OK | P19: =IF(COUNTIFS(tbl_acties[cyclus_id],A19,tbl_acties[actie_type],"UITCHECK",tbl_acties[uitgevoerd_op],"<>",tbl_acties[verwachte_schoonmaak_uren],"<>")>0,"OK","MIS") -> MIS | Q19: =IF(COUNTIFS(tbl_acties[cyclus_id],A19,tbl_acties[actie_type],"SCHOONMAAK",tbl_acties[uitgevoerd_op],"<>",tbl_acties[werkelijke_schoonmaak_uren],"<>")>0,"OK","MIS") -> MIS | R19: =IF(COUNTIFS(tbl_acties[cyclus_id],A19,tbl_acties[actie_type],"INCHECK",tbl_acties[gepland_op],"<>")>0,"OK","MIS") -> MIS | S19: =IF(COUNTIFS(tbl_acties[cyclus_id],A19,tbl_acties[actie_type],"INCHECK",tbl_acties[uitgevoerd_op],"<>",tbl_acties[sleutels_bevestigd],"JA")>0,"OK","MIS") -> MIS | U19: =IF(I19="UITCHECK_UITGEVOERD",IF(P19="OK","","FOUT: uitcheck mist uitgevoerd_op of verwachte uren"),IF(I19="SCHOONMAAK_NODIG",IF(P19="OK","","FOUT: schoonmaak kan pas na uitcheck"),IF(I19="INCHECK_UITGEVOERD",IF(S19="OK","","FOUT: incheck mist sleutelbevestiging/uitgevoerd"),"")))
A20: C0019 | B20: 0361 | C20: =_xlfn.XLOOKUP(tbl_cycli[[#This Row],[huis_id]],OG_HUIZEN_LIJST!B:B,OG_HUIZEN_LIJST!C:C,"",0) -> Putsebocht 136 B01 | D20: JA | E20: TRADIRO | G20: 45996 | I20: NIET_GESTART | J20: 2025-12-19 15:37 | K20: Dion levert op aan eigenaar 05-12, | L20: =B20&"|"&D20 -> 0361|JA | M20: =IF(COUNTIFS(tbl_acties[cyclus_id],A20,tbl_acties[actie_type],"VOORINSPECTIE",tbl_acties[gepland_op],"<>")>0,"OK","MIS") -> MIS | N20: =IF(COUNTIFS(tbl_acties[cyclus_id],A20,tbl_acties[actie_type],"VOORINSPECTIE",tbl_acties[uitgevoerd_op],"<>")>0,"OK","MIS") -> MIS | O20: =IF(COUNTIFS(tbl_acties[cyclus_id],A20,tbl_acties[actie_type],"UITCHECK",tbl_acties[gepland_op],"<>")>0,"OK","MIS") -> MIS | P20: =IF(COUNTIFS(tbl_acties[cyclus_id],A20,tbl_acties[actie_type],"UITCHECK",tbl_acties[uitgevoerd_op],"<>",tbl_acties[verwachte_schoonmaak_uren],"<>")>0,"OK","MIS") -> MIS | Q20: =IF(COUNTIFS(tbl_acties[cyclus_id],A20,tbl_acties[actie_type],"SCHOONMAAK",tbl_acties[uitgevoerd_op],"<>",tbl_acties[werkelijke_schoonmaak_uren],"<>")>0,"OK","MIS") -> MIS | R20: =IF(COUNTIFS(tbl_acties[cyclus_id],A20,tbl_acties[actie_type],"INCHECK",tbl_acties[gepland_op],"<>")>0,"OK","MIS") -> MIS | S20: =IF(COUNTIFS(tbl_acties[cyclus_id],A20,tbl_acties[actie_type],"INCHECK",tbl_acties[uitgevoerd_op],"<>",tbl_acties[sleutels_bevestigd],"JA")>0,"OK","MIS") -> MIS | U20: =IF(I20="UITCHECK_UITGEVOERD",IF(P20="OK","","FOUT: uitcheck mist uitgevoerd_op of verwachte uren"),IF(I20="SCHOONMAAK_NODIG",IF(P20="OK","","FOUT: schoonmaak kan pas na uitcheck"),IF(I20="INCHECK_UITGEVOERD",IF(S20="OK","","FOUT: incheck mist sleutelbevestiging/uitgevoerd"),"")))
A21: C0020 | B21: 0114 | C21: =_xlfn.XLOOKUP(tbl_cycli[[#This Row],[huis_id]],OG_HUIZEN_LIJST!B:B,OG_HUIZEN_LIJST!C:C,"",0) -> Piersonstraat 8 | D21: JA | E21: EXTERN | G21: 46006 | I21: SCHOONMAAK_NODIG | J21: 2025-12-19 15:37 | K21: met bedlinnen voor 3pers, HTC breng de sleutel naar kantoor | L21: =B21&"|"&D21 -> 0114|JA | M21: =IF(COUNTIFS(tbl_acties[cyclus_id],A21,tbl_acties[actie_type],"VOORINSPECTIE",tbl_acties[gepland_op],"<>")>0,"OK","MIS") -> OK | N21: =IF(COUNTIFS(tbl_acties[cyclus_id],A21,tbl_acties[actie_type],"VOORINSPECTIE",tbl_acties[uitgevoerd_op],"<>")>0,"OK","MIS") -> MIS | O21: =IF(COUNTIFS(tbl_acties[cyclus_id],A21,tbl_acties[actie_type],"UITCHECK",tbl_acties[gepland_op],"<>")>0,"OK","MIS") -> OK | P21: =IF(COUNTIFS(tbl_acties[cyclus_id],A21,tbl_acties[actie_type],"UITCHECK",tbl_acties[uitgevoerd_op],"<>",tbl_acties[verwachte_schoonmaak_uren],"<>")>0,"OK","MIS") -> MIS | Q21: =IF(COUNTIFS(tbl_acties[cyclus_id],A21,tbl_acties[actie_type],"SCHOONMAAK",tbl_acties[uitgevoerd_op],"<>",tbl_acties[werkelijke_schoonmaak_uren],"<>")>0,"OK","MIS") -> MIS | R21: =IF(COUNTIFS(tbl_acties[cyclus_id],A21,tbl_acties[actie_type],"INCHECK",tbl_acties[gepland_op],"<>")>0,"OK","MIS") -> MIS | S21: =IF(COUNTIFS(tbl_acties[cyclus_id],A21,tbl_acties[actie_type],"INCHECK",tbl_acties[uitgevoerd_op],"<>",tbl_acties[sleutels_bevestigd],"JA")>0,"OK","MIS") -> MIS | U21: =IF(I21="UITCHECK_UITGEVOERD",IF(P21="OK","","FOUT: uitcheck mist uitgevoerd_op of verwachte uren"),IF(I21="SCHOONMAAK_NODIG",IF(P21="OK","","FOUT: schoonmaak kan pas na uitcheck"),IF(I21="INCHECK_UITGEVOERD",IF(S21="OK","","FOUT: incheck mist sleutelbevestiging/uitgevoerd"),""))) -> FOUT: schoonmaak kan pas na uitcheck
A22: C0021 | B22: 0225 | C22: =_xlfn.XLOOKUP(tbl_cycli[[#This Row],[huis_id]],OG_HUIZEN_LIJST!B:B,OG_HUIZEN_LIJST!C:C,"",0) -> Kerkwerversingel 127 | D22: JA | E22: EXTERN | G22: 46007 | I22: SCHOONMAAK_NODIG | J22: 2025-12-19 15:37 | K22: outcheck is gedaan. Moet het nog leeg? | L22: =B22&"|"&D22 -> 0225|JA | M22: =IF(COUNTIFS(tbl_acties[cyclus_id],A22,tbl_acties[actie_type],"VOORINSPECTIE",tbl_acties[gepland_op],"<>")>0,"OK","MIS") -> MIS | N22: =IF(COUNTIFS(tbl_acties[cyclus_id],A22,tbl_acties[actie_type],"VOORINSPECTIE",tbl_acties[uitgevoerd_op],"<>")>0,"OK","MIS") -> MIS | O22: =IF(COUNTIFS(tbl_acties[cyclus_id],A22,tbl_acties[actie_type],"UITCHECK",tbl_acties[gepland_op],"<>")>0,"OK","MIS") -> OK | P22: =IF(COUNTIFS(tbl_acties[cyclus_id],A22,tbl_acties[actie_type],"UITCHECK",tbl_acties[uitgevoerd_op],"<>",tbl_acties[verwachte_schoonmaak_uren],"<>")>0,"OK","MIS") -> MIS | Q22: =IF(COUNTIFS(tbl_acties[cyclus_id],A22,tbl_acties[actie_type],"SCHOONMAAK",tbl_acties[uitgevoerd_op],"<>",tbl_acties[werkelijke_schoonmaak_uren],"<>")>0,"OK","MIS") -> MIS | R22: =IF(COUNTIFS(tbl_acties[cyclus_id],A22,tbl_acties[actie_type],"INCHECK",tbl_acties[gepland_op],"<>")>0,"OK","MIS") -> MIS | S22: =IF(COUNTIFS(tbl_acties[cyclus_id],A22,tbl_acties[actie_type],"INCHECK",tbl_acties[uitgevoerd_op],"<>",tbl_acties[sleutels_bevestigd],"JA")>0,"OK","MIS") -> MIS | U22: =IF(I22="UITCHECK_UITGEVOERD",IF(P22="OK","","FOUT: uitcheck mist uitgevoerd_op of verwachte uren"),IF(I22="SCHOONMAAK_NODIG",IF(P22="OK","","FOUT: schoonmaak kan pas na uitcheck"),IF(I22="INCHECK_UITGEVOERD",IF(S22="OK","","FOUT: incheck mist sleutelbevestiging/uitgevoerd"),""))) -> FOUT: schoonmaak kan pas na uitcheck
A23: C0022 | B23: 0293 | C23: =_xlfn.XLOOKUP(tbl_cycli[[#This Row],[huis_id]],OG_HUIZEN_LIJST!B:B,OG_HUIZEN_LIJST!C:C,"",0) -> Akkerweg 41 [014] | D23: JA | E23: EXTERN | G23: 46022 | I23: NIET_GESTART | J23: 2025-12-19 15:37 | K23: Via mail aan Chris gevraagd of hij de outcheck kan doen | L23: =B23&"|"&D23 -> 0293|JA | M23: =IF(COUNTIFS(tbl_acties[cyclus_id],A23,tbl_acties[actie_type],"VOORINSPECTIE",tbl_acties[gepland_op],"<>")>0,"OK","MIS") -> MIS | N23: =IF(COUNTIFS(tbl_acties[cyclus_id],A23,tbl_acties[actie_type],"VOORINSPECTIE",tbl_acties[uitgevoerd_op],"<>")>0,"OK","MIS") -> MIS | O23: =IF(COUNTIFS(tbl_acties[cyclus_id],A23,tbl_acties[actie_type],"UITCHECK",tbl_acties[gepland_op],"<>")>0,"OK","MIS") -> MIS | P23: =IF(COUNTIFS(tbl_acties[cyclus_id],A23,tbl_acties[actie_type],"UITCHECK",tbl_acties[uitgevoerd_op],"<>",tbl_acties[verwachte_schoonmaak_uren],"<>")>0,"OK","MIS") -> MIS | Q23: =IF(COUNTIFS(tbl_acties[cyclus_id],A23,tbl_acties[actie_type],"SCHOONMAAK",tbl_acties[uitgevoerd_op],"<>",tbl_acties[werkelijke_schoonmaak_uren],"<>")>0,"OK","MIS") -> MIS | R23: =IF(COUNTIFS(tbl_acties[cyclus_id],A23,tbl_acties[actie_type],"INCHECK",tbl_acties[gepland_op],"<>")>0,"OK","MIS") -> MIS | S23: =IF(COUNTIFS(tbl_acties[cyclus_id],A23,tbl_acties[actie_type],"INCHECK",tbl_acties[uitgevoerd_op],"<>",tbl_acties[sleutels_bevestigd],"JA")>0,"OK","MIS") -> MIS | U23: =IF(I23="UITCHECK_UITGEVOERD",IF(P23="OK","","FOUT: uitcheck mist uitgevoerd_op of verwachte uren"),IF(I23="SCHOONMAAK_NODIG",IF(P23="OK","","FOUT: schoonmaak kan pas na uitcheck"),IF(I23="INCHECK_UITGEVOERD",IF(S23="OK","","FOUT: incheck mist sleutelbevestiging/uitgevoerd"),"")))
A24: C0023 | B24: 0383 | C24: =_xlfn.XLOOKUP(tbl_cycli[[#This Row],[huis_id]],OG_HUIZEN_LIJST!B:B,OG_HUIZEN_LIJST!C:C,"",0) -> Akkerweg 41 [020] | D24: JA | E24: EXTERN | G24: 46022 | I24: NIET_GESTART | J24: 2025-12-19 15:37 | K24: Via mail aan Chris gevraagd of hij de outcheck kan doen | L24: =B24&"|"&D24 -> 0383|JA | M24: =IF(COUNTIFS(tbl_acties[cyclus_id],A24,tbl_acties[actie_type],"VOORINSPECTIE",tbl_acties[gepland_op],"<>")>0,"OK","MIS") -> MIS | N24: =IF(COUNTIFS(tbl_acties[cyclus_id],A24,tbl_acties[actie_type],"VOORINSPECTIE",tbl_acties[uitgevoerd_op],"<>")>0,"OK","MIS") -> MIS | O24: =IF(COUNTIFS(tbl_acties[cyclus_id],A24,tbl_acties[actie_type],"UITCHECK",tbl_acties[gepland_op],"<>")>0,"OK","MIS") -> MIS | P24: =IF(COUNTIFS(tbl_acties[cyclus_id],A24,tbl_acties[actie_type],"UITCHECK",tbl_acties[uitgevoerd_op],"<>",tbl_acties[verwachte_schoonmaak_uren],"<>")>0,"OK","MIS") -> MIS | Q24: =IF(COUNTIFS(tbl_acties[cyclus_id],A24,tbl_acties[actie_type],"SCHOONMAAK",tbl_acties[uitgevoerd_op],"<>",tbl_acties[werkelijke_schoonmaak_uren],"<>")>0,"OK","MIS") -> MIS | R24: =IF(COUNTIFS(tbl_acties[cyclus_id],A24,tbl_acties[actie_type],"INCHECK",tbl_acties[gepland_op],"<>")>0,"OK","MIS") -> MIS | S24: =IF(COUNTIFS(tbl_acties[cyclus_id],A24,tbl_acties[actie_type],"INCHECK",tbl_acties[uitgevoerd_op],"<>",tbl_acties[sleutels_bevestigd],"JA")>0,"OK","MIS") -> MIS | U24: =IF(I24="UITCHECK_UITGEVOERD",IF(P24="OK","","FOUT: uitcheck mist uitgevoerd_op of verwachte uren"),IF(I24="SCHOONMAAK_NODIG",IF(P24="OK","","FOUT: schoonmaak kan pas na uitcheck"),IF(I24="INCHECK_UITGEVOERD",IF(S24="OK","","FOUT: incheck mist sleutelbevestiging/uitgevoerd"),"")))
A25: C0024 | B25: 0302 | C25: =_xlfn.XLOOKUP(tbl_cycli[[#This Row],[huis_id]],OG_HUIZEN_LIJST!B:B,OG_HUIZEN_LIJST!C:C,"",0) -> Akkerweg 41 [042] | D25: JA | E25: EXTERN | G25: 46022 | I25: NIET_GESTART | J25: 2025-12-19 15:37 | K25: Via mail aan Chris gevraagd of hij de outcheck kan doen | L25: =B25&"|"&D25 -> 0302|JA | M25: =IF(COUNTIFS(tbl_acties[cyclus_id],A25,tbl_acties[actie_type],"VOORINSPECTIE",tbl_acties[gepland_op],"<>")>0,"OK","MIS") -> MIS | N25: =IF(COUNTIFS(tbl_acties[cyclus_id],A25,tbl_acties[actie_type],"VOORINSPECTIE",tbl_acties[uitgevoerd_op],"<>")>0,"OK","MIS") -> MIS | O25: =IF(COUNTIFS(tbl_acties[cyclus_id],A25,tbl_acties[actie_type],"UITCHECK",tbl_acties[gepland_op],"<>")>0,"OK","MIS") -> MIS | P25: =IF(COUNTIFS(tbl_acties[cyclus_id],A25,tbl_acties[actie_type],"UITCHECK",tbl_acties[uitgevoerd_op],"<>",tbl_acties[verwachte_schoonmaak_uren],"<>")>0,"OK","MIS") -> MIS | Q25: =IF(COUNTIFS(tbl_acties[cyclus_id],A25,tbl_acties[actie_type],"SCHOONMAAK",tbl_acties[uitgevoerd_op],"<>",tbl_acties[werkelijke_schoonmaak_uren],"<>")>0,"OK","MIS") -> MIS | R25: =IF(COUNTIFS(tbl_acties[cyclus_id],A25,tbl_acties[actie_type],"INCHECK",tbl_acties[gepland_op],"<>")>0,"OK","MIS") -> MIS | S25: =IF(COUNTIFS(tbl_acties[cyclus_id],A25,tbl_acties[actie_type],"INCHECK",tbl_acties[uitgevoerd_op],"<>",tbl_acties[sleutels_bevestigd],"JA")>0,"OK","MIS") -> MIS | U25: =IF(I25="UITCHECK_UITGEVOERD",IF(P25="OK","","FOUT: uitcheck mist uitgevoerd_op of verwachte uren"),IF(I25="SCHOONMAAK_NODIG",IF(P25="OK","","FOUT: schoonmaak kan pas na uitcheck"),IF(I25="INCHECK_UITGEVOERD",IF(S25="OK","","FOUT: incheck mist sleutelbevestiging/uitgevoerd"),"")))
A26: C0025 | B26: 0089 | C26: =_xlfn.XLOOKUP(tbl_cycli[[#This Row],[huis_id]],OG_HUIZEN_LIJST!B:B,OG_HUIZEN_LIJST!C:C,"",0) -> Van Maanenstraat 14A | D26: JA | E26: EXTERN | G26: 46011 | I26: SCHOONMAAK_NODIG | J26: 2025-12-19 15:37 | K26: Eigenaar is gemaild voor sleutel overdracht | L26: =B26&"|"&D26 -> 0089|JA | M26: =IF(COUNTIFS(tbl_acties[cyclus_id],A26,tbl_acties[actie_type],"VOORINSPECTIE",tbl_acties[gepland_op],"<>")>0,"OK","MIS") -> MIS | N26: =IF(COUNTIFS(tbl_acties[cyclus_id],A26,tbl_acties[actie_type],"VOORINSPECTIE",tbl_acties[uitgevoerd_op],"<>")>0,"OK","MIS") -> MIS | O26: =IF(COUNTIFS(tbl_acties[cyclus_id],A26,tbl_acties[actie_type],"UITCHECK",tbl_acties[gepland_op],"<>")>0,"OK","MIS") -> OK | P26: =IF(COUNTIFS(tbl_acties[cyclus_id],A26,tbl_acties[actie_type],"UITCHECK",tbl_acties[uitgevoerd_op],"<>",tbl_acties[verwachte_schoonmaak_uren],"<>")>0,"OK","MIS") -> MIS | Q26: =IF(COUNTIFS(tbl_acties[cyclus_id],A26,tbl_acties[actie_type],"SCHOONMAAK",tbl_acties[uitgevoerd_op],"<>",tbl_acties[werkelijke_schoonmaak_uren],"<>")>0,"OK","MIS") -> MIS | R26: =IF(COUNTIFS(tbl_acties[cyclus_id],A26,tbl_acties[actie_type],"INCHECK",tbl_acties[gepland_op],"<>")>0,"OK","MIS") -> MIS | S26: =IF(COUNTIFS(tbl_acties[cyclus_id],A26,tbl_acties[actie_type],"INCHECK",tbl_acties[uitgevoerd_op],"<>",tbl_acties[sleutels_bevestigd],"JA")>0,"OK","MIS") -> MIS | U26: =IF(I26="UITCHECK_UITGEVOERD",IF(P26="OK","","FOUT: uitcheck mist uitgevoerd_op of verwachte uren"),IF(I26="SCHOONMAAK_NODIG",IF(P26="OK","","FOUT: schoonmaak kan pas na uitcheck"),IF(I26="INCHECK_UITGEVOERD",IF(S26="OK","","FOUT: incheck mist sleutelbevestiging/uitgevoerd"),""))) -> FOUT: schoonmaak kan pas na uitcheck
A27: C0026 | B27: 0117 | C27: =_xlfn.XLOOKUP(tbl_cycli[[#This Row],[huis_id]],OG_HUIZEN_LIJST!B:B,OG_HUIZEN_LIJST!C:C,"",0) -> Prunuslaan 36 | D27: JA | E27: EXTERN | G27: 46018 | I27: NIET_GESTART | J27: 2025-12-19 15:37 | K27: Christa? | L27: =B27&"|"&D27 -> 0117|JA | M27: =IF(COUNTIFS(tbl_acties[cyclus_id],A27,tbl_acties[actie_type],"VOORINSPECTIE",tbl_acties[gepland_op],"<>")>0,"OK","MIS") -> MIS | N27: =IF(COUNTIFS(tbl_acties[cyclus_id],A27,tbl_acties[actie_type],"VOORINSPECTIE",tbl_acties[uitgevoerd_op],"<>")>0,"OK","MIS") -> MIS | O27: =IF(COUNTIFS(tbl_acties[cyclus_id],A27,tbl_acties[actie_type],"UITCHECK",tbl_acties[gepland_op],"<>")>0,"OK","MIS") -> MIS | P27: =IF(COUNTIFS(tbl_acties[cyclus_id],A27,tbl_acties[actie_type],"UITCHECK",tbl_acties[uitgevoerd_op],"<>",tbl_acties[verwachte_schoonmaak_uren],"<>")>0,"OK","MIS") -> MIS | Q27: =IF(COUNTIFS(tbl_acties[cyclus_id],A27,tbl_acties[actie_type],"SCHOONMAAK",tbl_acties[uitgevoerd_op],"<>",tbl_acties[werkelijke_schoonmaak_uren],"<>")>0,"OK","MIS") -> MIS | R27: =IF(COUNTIFS(tbl_acties[cyclus_id],A27,tbl_acties[actie_type],"INCHECK",tbl_acties[gepland_op],"<>")>0,"OK","MIS") -> MIS | S27: =IF(COUNTIFS(tbl_acties[cyclus_id],A27,tbl_acties[actie_type],"INCHECK",tbl_acties[uitgevoerd_op],"<>",tbl_acties[sleutels_bevestigd],"JA")>0,"OK","MIS") -> MIS | U27: =IF(I27="UITCHECK_UITGEVOERD",IF(P27="OK","","FOUT: uitcheck mist uitgevoerd_op of verwachte uren"),IF(I27="SCHOONMAAK_NODIG",IF(P27="OK","","FOUT: schoonmaak kan pas na uitcheck"),IF(I27="INCHECK_UITGEVOERD",IF(S27="OK","","FOUT: incheck mist sleutelbevestiging/uitgevoerd"),"")))
A28: C0027 | B28: 0322 | C28: =_xlfn.XLOOKUP(tbl_cycli[[#This Row],[huis_id]],OG_HUIZEN_LIJST!B:B,OG_HUIZEN_LIJST!C:C,"",0) -> Bettingeslag 10 | D28: JA | E28: EXTERN | G28: 46019 | I28: NIET_GESTART | J28: 2025-12-19 15:37 | K28: Christa? | L28: =B28&"|"&D28 -> 0322|JA | M28: =IF(COUNTIFS(tbl_acties[cyclus_id],A28,tbl_acties[actie_type],"VOORINSPECTIE",tbl_acties[gepland_op],"<>")>0,"OK","MIS") -> MIS | N28: =IF(COUNTIFS(tbl_acties[cyclus_id],A28,tbl_acties[actie_type],"VOORINSPECTIE",tbl_acties[uitgevoerd_op],"<>")>0,"OK","MIS") -> MIS | O28: =IF(COUNTIFS(tbl_acties[cyclus_id],A28,tbl_acties[actie_type],"UITCHECK",tbl_acties[gepland_op],"<>")>0,"OK","MIS") -> MIS | P28: =IF(COUNTIFS(tbl_acties[cyclus_id],A28,tbl_acties[actie_type],"UITCHECK",tbl_acties[uitgevoerd_op],"<>",tbl_acties[verwachte_schoonmaak_uren],"<>")>0,"OK","MIS") -> MIS | Q28: =IF(COUNTIFS(tbl_acties[cyclus_id],A28,tbl_acties[actie_type],"SCHOONMAAK",tbl_acties[uitgevoerd_op],"<>",tbl_acties[werkelijke_schoonmaak_uren],"<>")>0,"OK","MIS") -> MIS | R28: =IF(COUNTIFS(tbl_acties[cyclus_id],A28,tbl_acties[actie_type],"INCHECK",tbl_acties[gepland_op],"<>")>0,"OK","MIS") -> MIS | S28: =IF(COUNTIFS(tbl_acties[cyclus_id],A28,tbl_acties[actie_type],"INCHECK",tbl_acties[uitgevoerd_op],"<>",tbl_acties[sleutels_bevestigd],"JA")>0,"OK","MIS") -> MIS | U28: =IF(I28="UITCHECK_UITGEVOERD",IF(P28="OK","","FOUT: uitcheck mist uitgevoerd_op of verwachte uren"),IF(I28="SCHOONMAAK_NODIG",IF(P28="OK","","FOUT: schoonmaak kan pas na uitcheck"),IF(I28="INCHECK_UITGEVOERD",IF(S28="OK","","FOUT: incheck mist sleutelbevestiging/uitgevoerd"),"")))
A29: C0028 | B29: 0126 | C29: =_xlfn.XLOOKUP(tbl_cycli[[#This Row],[huis_id]],OG_HUIZEN_LIJST!B:B,OG_HUIZEN_LIJST!C:C,"",0) -> Korte Singelstraat 21-2 | D29: JA | E29: EXTERN | G29: 46022 | I29: SCHOONMAAK_NODIG | J29: 2025-12-19 15:37 | K29: nan | L29: =B29&"|"&D29 -> 0126|JA | M29: =IF(COUNTIFS(tbl_acties[cyclus_id],A29,tbl_acties[actie_type],"VOORINSPECTIE",tbl_acties[gepland_op],"<>")>0,"OK","MIS") -> MIS | N29: =IF(COUNTIFS(tbl_acties[cyclus_id],A29,tbl_acties[actie_type],"VOORINSPECTIE",tbl_acties[uitgevoerd_op],"<>")>0,"OK","MIS") -> MIS | O29: =IF(COUNTIFS(tbl_acties[cyclus_id],A29,tbl_acties[actie_type],"UITCHECK",tbl_acties[gepland_op],"<>")>0,"OK","MIS") -> OK | P29: =IF(COUNTIFS(tbl_acties[cyclus_id],A29,tbl_acties[actie_type],"UITCHECK",tbl_acties[uitgevoerd_op],"<>",tbl_acties[verwachte_schoonmaak_uren],"<>")>0,"OK","MIS") -> MIS | Q29: =IF(COUNTIFS(tbl_acties[cyclus_id],A29,tbl_acties[actie_type],"SCHOONMAAK",tbl_acties[uitgevoerd_op],"<>",tbl_acties[werkelijke_schoonmaak_uren],"<>")>0,"OK","MIS") -> MIS | R29: =IF(COUNTIFS(tbl_acties[cyclus_id],A29,tbl_acties[actie_type],"INCHECK",tbl_acties[gepland_op],"<>")>0,"OK","MIS") -> MIS | S29: =IF(COUNTIFS(tbl_acties[cyclus_id],A29,tbl_acties[actie_type],"INCHECK",tbl_acties[uitgevoerd_op],"<>",tbl_acties[sleutels_bevestigd],"JA")>0,"OK","MIS") -> MIS | U29: =IF(I29="UITCHECK_UITGEVOERD",IF(P29="OK","","FOUT: uitcheck mist uitgevoerd_op of verwachte uren"),IF(I29="SCHOONMAAK_NODIG",IF(P29="OK","","FOUT: schoonmaak kan pas na uitcheck"),IF(I29="INCHECK_UITGEVOERD",IF(S29="OK","","FOUT: incheck mist sleutelbevestiging/uitgevoerd"),""))) -> FOUT: schoonmaak kan pas na uitcheck
A30: C0029 | B30: 0126 | C30: =_xlfn.XLOOKUP(tbl_cycli[[#This Row],[huis_id]],OG_HUIZEN_LIJST!B:B,OG_HUIZEN_LIJST!C:C,"",0) -> Korte Singelstraat 21-2 | D30: JA | E30: EXTERN | G30: 46022 | I30: SCHOONMAAK_NODIG | J30: 2025-12-19 15:37 | L30: =B30&"|"&D30 -> 0126|JA | M30: =IF(COUNTIFS(tbl_acties[cyclus_id],A30,tbl_acties[actie_type],"VOORINSPECTIE",tbl_acties[gepland_op],"<>")>0,"OK","MIS") -> MIS | N30: =IF(COUNTIFS(tbl_acties[cyclus_id],A30,tbl_acties[actie_type],"VOORINSPECTIE",tbl_acties[uitgevoerd_op],"<>")>0,"OK","MIS") -> MIS | O30: =IF(COUNTIFS(tbl_acties[cyclus_id],A30,tbl_acties[actie_type],"UITCHECK",tbl_acties[gepland_op],"<>")>0,"OK","MIS") -> MIS | P30: =IF(COUNTIFS(tbl_acties[cyclus_id],A30,tbl_acties[actie_type],"UITCHECK",tbl_acties[uitgevoerd_op],"<>",tbl_acties[verwachte_schoonmaak_uren],"<>")>0,"OK","MIS") -> MIS | Q30: =IF(COUNTIFS(tbl_acties[cyclus_id],A30,tbl_acties[actie_type],"SCHOONMAAK",tbl_acties[uitgevoerd_op],"<>",tbl_acties[werkelijke_schoonmaak_uren],"<>")>0,"OK","MIS") -> MIS | R30: =IF(COUNTIFS(tbl_acties[cyclus_id],A30,tbl_acties[actie_type],"INCHECK",tbl_acties[gepland_op],"<>")>0,"OK","MIS") -> MIS | S30: =IF(COUNTIFS(tbl_acties[cyclus_id],A30,tbl_acties[actie_type],"INCHECK",tbl_acties[uitgevoerd_op],"<>",tbl_acties[sleutels_bevestigd],"JA")>0,"OK","MIS") -> MIS | U30: =IF(I30="UITCHECK_UITGEVOERD",IF(P30="OK","","FOUT: uitcheck mist uitgevoerd_op of verwachte uren"),IF(I30="SCHOONMAAK_NODIG",IF(P30="OK","","FOUT: schoonmaak kan pas na uitcheck"),IF(I30="INCHECK_UITGEVOERD",IF(S30="OK","","FOUT: incheck mist sleutelbevestiging/uitgevoerd"),""))) -> FOUT: schoonmaak kan pas na uitcheck
A31: C0030 | B31: 0110 | C31: =_xlfn.XLOOKUP(tbl_cycli[[#This Row],[huis_id]],OG_HUIZEN_LIJST!B:B,OG_HUIZEN_LIJST!C:C,"",0) -> Opaal 9 | D31: JA | E31: EXTERN | G31: 46022 | I31: SCHOONMAAK_NODIG | J31: 2025-12-19 15:37 | K31: nan | L31: =B31&"|"&D31 -> 0110|JA | M31: =IF(COUNTIFS(tbl_acties[cyclus_id],A31,tbl_acties[actie_type],"VOORINSPECTIE",tbl_acties[gepland_op],"<>")>0,"OK","MIS") -> MIS | N31: =IF(COUNTIFS(tbl_acties[cyclus_id],A31,tbl_acties[actie_type],"VOORINSPECTIE",tbl_acties[uitgevoerd_op],"<>")>0,"OK","MIS") -> MIS | O31: =IF(COUNTIFS(tbl_acties[cyclus_id],A31,tbl_acties[actie_type],"UITCHECK",tbl_acties[gepland_op],"<>")>0,"OK","MIS") -> OK | P31: =IF(COUNTIFS(tbl_acties[cyclus_id],A31,tbl_acties[actie_type],"UITCHECK",tbl_acties[uitgevoerd_op],"<>",tbl_acties[verwachte_schoonmaak_uren],"<>")>0,"OK","MIS") -> MIS | Q31: =IF(COUNTIFS(tbl_acties[cyclus_id],A31,tbl_acties[actie_type],"SCHOONMAAK",tbl_acties[uitgevoerd_op],"<>",tbl_acties[werkelijke_schoonmaak_uren],"<>")>0,"OK","MIS") -> MIS | R31: =IF(COUNTIFS(tbl_acties[cyclus_id],A31,tbl_acties[actie_type],"INCHECK",tbl_acties[gepland_op],"<>")>0,"OK","MIS") -> MIS | S31: =IF(COUNTIFS(tbl_acties[cyclus_id],A31,tbl_acties[actie_type],"INCHECK",tbl_acties[uitgevoerd_op],"<>",tbl_acties[sleutels_bevestigd],"JA")>0,"OK","MIS") -> MIS | U31: =IF(I31="UITCHECK_UITGEVOERD",IF(P31="OK","","FOUT: uitcheck mist uitgevoerd_op of verwachte uren"),IF(I31="SCHOONMAAK_NODIG",IF(P31="OK","","FOUT: schoonmaak kan pas na uitcheck"),IF(I31="INCHECK_UITGEVOERD",IF(S31="OK","","FOUT: incheck mist sleutelbevestiging/uitgevoerd"),""))) -> FOUT: schoonmaak kan pas na uitcheck
A32: C0031 | B32: 0141 | C32: =_xlfn.XLOOKUP(tbl_cycli[[#This Row],[huis_id]],OG_HUIZEN_LIJST!B:B,OG_HUIZEN_LIJST!C:C,"",0) -> Wilhelminastraat 8 | D32: JA | E32: EXTERN | G32: 46022 | I32: SCHOONMAAK_NODIG | J32: 2025-12-19 15:37 | K32: nan | L32: =B32&"|"&D32 -> 0141|JA | M32: =IF(COUNTIFS(tbl_acties[cyclus_id],A32,tbl_acties[actie_type],"VOORINSPECTIE",tbl_acties[gepland_op],"<>")>0,"OK","MIS") -> MIS | N32: =IF(COUNTIFS(tbl_acties[cyclus_id],A32,tbl_acties[actie_type],"VOORINSPECTIE",tbl_acties[uitgevoerd_op],"<>")>0,"OK","MIS") -> MIS | O32: =IF(COUNTIFS(tbl_acties[cyclus_id],A32,tbl_acties[actie_type],"UITCHECK",tbl_acties[gepland_op],"<>")>0,"OK","MIS") -> OK | P32: =IF(COUNTIFS(tbl_acties[cyclus_id],A32,tbl_acties[actie_type],"UITCHECK",tbl_acties[uitgevoerd_op],"<>",tbl_acties[verwachte_schoonmaak_uren],"<>")>0,"OK","MIS") -> MIS | Q32: =IF(COUNTIFS(tbl_acties[cyclus_id],A32,tbl_acties[actie_type],"SCHOONMAAK",tbl_acties[uitgevoerd_op],"<>",tbl_acties[werkelijke_schoonmaak_uren],"<>")>0,"OK","MIS") -> MIS | R32: =IF(COUNTIFS(tbl_acties[cyclus_id],A32,tbl_acties[actie_type],"INCHECK",tbl_acties[gepland_op],"<>")>0,"OK","MIS") -> MIS | S32: =IF(COUNTIFS(tbl_acties[cyclus_id],A32,tbl_acties[actie_type],"INCHECK",tbl_acties[uitgevoerd_op],"<>",tbl_acties[sleutels_bevestigd],"JA")>0,"OK","MIS") -> MIS | U32: =IF(I32="UITCHECK_UITGEVOERD",IF(P32="OK","","FOUT: uitcheck mist uitgevoerd_op of verwachte uren"),IF(I32="SCHOONMAAK_NODIG",IF(P32="OK","","FOUT: schoonmaak kan pas na uitcheck"),IF(I32="INCHECK_UITGEVOERD",IF(S32="OK","","FOUT: incheck mist sleutelbevestiging/uitgevoerd"),""))) -> FOUT: schoonmaak kan pas na uitcheck
A33: C0032 | B33: 0365 | C33: =_xlfn.XLOOKUP(tbl_cycli[[#This Row],[huis_id]],OG_HUIZEN_LIJST!B:B,OG_HUIZEN_LIJST!C:C,"",0) -> Laan op Zuid 949 | D33: JA | E33: EXTERN | G33: 46022 | I33: SCHOONMAAK_NODIG | J33: 2025-12-19 15:37 | K33: nan | L33: =B33&"|"&D33 -> 0365|JA | M33: =IF(COUNTIFS(tbl_acties[cyclus_id],A33,tbl_acties[actie_type],"VOORINSPECTIE",tbl_acties[gepland_op],"<>")>0,"OK","MIS") -> MIS | N33: =IF(COUNTIFS(tbl_acties[cyclus_id],A33,tbl_acties[actie_type],"VOORINSPECTIE",tbl_acties[uitgevoerd_op],"<>")>0,"OK","MIS") -> MIS | O33: =IF(COUNTIFS(tbl_acties[cyclus_id],A33,tbl_acties[actie_type],"UITCHECK",tbl_acties[gepland_op],"<>")>0,"OK","MIS") -> OK | P33: =IF(COUNTIFS(tbl_acties[cyclus_id],A33,tbl_acties[actie_type],"UITCHECK",tbl_acties[uitgevoerd_op],"<>",tbl_acties[verwachte_schoonmaak_uren],"<>")>0,"OK","MIS") -> MIS | Q33: =IF(COUNTIFS(tbl_acties[cyclus_id],A33,tbl_acties[actie_type],"SCHOONMAAK",tbl_acties[uitgevoerd_op],"<>",tbl_acties[werkelijke_schoonmaak_uren],"<>")>0,"OK","MIS") -> MIS | R33: =IF(COUNTIFS(tbl_acties[cyclus_id],A33,tbl_acties[actie_type],"INCHECK",tbl_acties[gepland_op],"<>")>0,"OK","MIS") -> MIS | S33: =IF(COUNTIFS(tbl_acties[cyclus_id],A33,tbl_acties[actie_type],"INCHECK",tbl_acties[uitgevoerd_op],"<>",tbl_acties[sleutels_bevestigd],"JA")>0,"OK","MIS") -> MIS | U33: =IF(I33="UITCHECK_UITGEVOERD",IF(P33="OK","","FOUT: uitcheck mist uitgevoerd_op of verwachte uren"),IF(I33="SCHOONMAAK_NODIG",IF(P33="OK","","FOUT: schoonmaak kan pas na uitcheck"),IF(I33="INCHECK_UITGEVOERD",IF(S33="OK","","FOUT: incheck mist sleutelbevestiging/uitgevoerd"),""))) -> FOUT: schoonmaak kan pas na uitcheck
A34: C0033 | B34: 0144 | C34: =_xlfn.XLOOKUP(tbl_cycli[[#This Row],[huis_id]],OG_HUIZEN_LIJST!B:B,OG_HUIZEN_LIJST!C:C,"",0) -> Scheepjesbrug 433 | D34: JA | E34: EXTERN | G34: 46022 | I34: SCHOONMAAK_NODIG | J34: 2025-12-19 15:37 | K34: nan | L34: =B34&"|"&D34 -> 0144|JA | M34: =IF(COUNTIFS(tbl_acties[cyclus_id],A34,tbl_acties[actie_type],"VOORINSPECTIE",tbl_acties[gepland_op],"<>")>0,"OK","MIS") -> MIS | N34: =IF(COUNTIFS(tbl_acties[cyclus_id],A34,tbl_acties[actie_type],"VOORINSPECTIE",tbl_acties[uitgevoerd_op],"<>")>0,"OK","MIS") -> MIS | O34: =IF(COUNTIFS(tbl_acties[cyclus_id],A34,tbl_acties[actie_type],"UITCHECK",tbl_acties[gepland_op],"<>")>0,"OK","MIS") -> OK | P34: =IF(COUNTIFS(tbl_acties[cyclus_id],A34,tbl_acties[actie_type],"UITCHECK",tbl_acties[uitgevoerd_op],"<>",tbl_acties[verwachte_schoonmaak_uren],"<>")>0,"OK","MIS") -> MIS | Q34: =IF(COUNTIFS(tbl_acties[cyclus_id],A34,tbl_acties[actie_type],"SCHOONMAAK",tbl_acties[uitgevoerd_op],"<>",tbl_acties[werkelijke_schoonmaak_uren],"<>")>0,"OK","MIS") -> MIS | R34: =IF(COUNTIFS(tbl_acties[cyclus_id],A34,tbl_acties[actie_type],"INCHECK",tbl_acties[gepland_op],"<>")>0,"OK","MIS") -> MIS | S34: =IF(COUNTIFS(tbl_acties[cyclus_id],A34,tbl_acties[actie_type],"INCHECK",tbl_acties[uitgevoerd_op],"<>",tbl_acties[sleutels_bevestigd],"JA")>0,"OK","MIS") -> MIS | U34: =IF(I34="UITCHECK_UITGEVOERD",IF(P34="OK","","FOUT: uitcheck mist uitgevoerd_op of verwachte uren"),IF(I34="SCHOONMAAK_NODIG",IF(P34="OK","","FOUT: schoonmaak kan pas na uitcheck"),IF(I34="INCHECK_UITGEVOERD",IF(S34="OK","","FOUT: incheck mist sleutelbevestiging/uitgevoerd"),""))) -> FOUT: schoonmaak kan pas na uitcheck
A35: C0034 | B35: 0331 | C35: =_xlfn.XLOOKUP(tbl_cycli[[#This Row],[huis_id]],OG_HUIZEN_LIJST!B:B,OG_HUIZEN_LIJST!C:C,"",0) -> Flankstraat 11 | D35: JA | E35: EXTERN | G35: 46022 | I35: SCHOONMAAK_NODIG | J35: 2025-12-19 15:37 | K35: nan | L35: =B35&"|"&D35 -> 0331|JA | M35: =IF(COUNTIFS(tbl_acties[cyclus_id],A35,tbl_acties[actie_type],"VOORINSPECTIE",tbl_acties[gepland_op],"<>")>0,"OK","MIS") -> MIS | N35: =IF(COUNTIFS(tbl_acties[cyclus_id],A35,tbl_acties[actie_type],"VOORINSPECTIE",tbl_acties[uitgevoerd_op],"<>")>0,"OK","MIS") -> MIS | O35: =IF(COUNTIFS(tbl_acties[cyclus_id],A35,tbl_acties[actie_type],"UITCHECK",tbl_acties[gepland_op],"<>")>0,"OK","MIS") -> OK | P35: =IF(COUNTIFS(tbl_acties[cyclus_id],A35,tbl_acties[actie_type],"UITCHECK",tbl_acties[uitgevoerd_op],"<>",tbl_acties[verwachte_schoonmaak_uren],"<>")>0,"OK","MIS") -> MIS | Q35: =IF(COUNTIFS(tbl_acties[cyclus_id],A35,tbl_acties[actie_type],"SCHOONMAAK",tbl_acties[uitgevoerd_op],"<>",tbl_acties[werkelijke_schoonmaak_uren],"<>")>0,"OK","MIS") -> MIS | R35: =IF(COUNTIFS(tbl_acties[cyclus_id],A35,tbl_acties[actie_type],"INCHECK",tbl_acties[gepland_op],"<>")>0,"OK","MIS") -> MIS | S35: =IF(COUNTIFS(tbl_acties[cyclus_id],A35,tbl_acties[actie_type],"INCHECK",tbl_acties[uitgevoerd_op],"<>",tbl_acties[sleutels_bevestigd],"JA")>0,"OK","MIS") -> MIS | U35: =IF(I35="UITCHECK_UITGEVOERD",IF(P35="OK","","FOUT: uitcheck mist uitgevoerd_op of verwachte uren"),IF(I35="SCHOONMAAK_NODIG",IF(P35="OK","","FOUT: schoonmaak kan pas na uitcheck"),IF(I35="INCHECK_UITGEVOERD",IF(S35="OK","","FOUT: incheck mist sleutelbevestiging/uitgevoerd"),""))) -> FOUT: schoonmaak kan pas na uitcheck
