Workbook

Sheet Dashboard
A1: COMPLETENESS DASHBOARD
A3: Adres | B3: Basis? | C3: GWE? | D3: Schoonmaak? | E3: STATUS
A4: =_xlfn.UNIQUE(_xlfn._xlws.FILTER(Input!A2:A4990, Input!A2:A4990<>"")) -> Compierekade 15 | B4: =IF(A4="","",IF(COUNTIFS(Input!$A:$A, A4, Input!$B:$B, "Basis")>0, "OK", "MISSING")) -> OK | C4: =IF(A4="","",IF(COUNTIFS(Input!$A:$A, A4, Input!$B:$B, "GWE")>0, "OK", "MISSING")) -> MISSING | D4: =IF(A4="","",IF(COUNTIFS(Input!$A:$A, A4, Input!$B:$B, "Schoonmaak")>0, "OK", "MISSING")) -> OK | E4: =IF(A4="","",IF(AND(B4="OK",C4="OK",D4="OK"), "✅ READY", "⚠️ INCOMPLETE")) -> ⚠️ INCOMPLETE
A5: =_xlfn.UNIQUE(_xlfn._xlws.FILTER(Input!A3:A4991, Input!A3:A4991<>"")) -> Compierekade 15 | B5: =IF(A5="","",IF(COUNTIFS(Input!$A:$A, A5, Input!$B:$B, "Basis")>0, "OK", "MISSING")) -> OK | C5: =IF(A5="","",IF(COUNTIFS(Input!$A:$A, A5, Input!$B:$B, "GWE")>0, "OK", "MISSING")) -> MISSING | D5: =IF(A5="","",IF(COUNTIFS(Input!$A:$A, A5, Input!$B:$B, "Schoonmaak")>0, "OK", "MISSING")) -> OK | E5: =IF(A5="","",IF(AND(B5="OK",C5="OK",D5="OK"), "✅ READY", "⚠️ INCOMPLETE")) -> ⚠️ INCOMPLETE
A6: =_xlfn.UNIQUE(_xlfn._xlws.FILTER(Input!A4:A4992, Input!A4:A4992<>"")) -> Compierekade 15 | B6: =IF(A6="","",IF(COUNTIFS(Input!$A:$A, A6, Input!$B:$B, "Basis")>0, "OK", "MISSING")) -> OK | C6: =IF(A6="","",IF(COUNTIFS(Input!$A:$A, A6, Input!$B:$B, "GWE")>0, "OK", "MISSING")) -> MISSING | D6: =IF(A6="","",IF(COUNTIFS(Input!$A:$A, A6, Input!$B:$B, "Schoonmaak")>0, "OK", "MISSING")) -> OK | E6: =IF(A6="","",IF(AND(B6="OK",C6="OK",D6="OK"), "✅ READY", "⚠️ INCOMPLETE")) -> ⚠️ INCOMPLETE
A7: =_xlfn.UNIQUE(_xlfn._xlws.FILTER(Input!A5:A4993, Input!A5:A4993<>"")) -> Compierekade 15 | B7: =IF(A7="","",IF(COUNTIFS(Input!$A:$A, A7, Input!$B:$B, "Basis")>0, "OK", "MISSING")) -> OK | C7: =IF(A7="","",IF(COUNTIFS(Input!$A:$A, A7, Input!$B:$B, "GWE")>0, "OK", "MISSING")) -> MISSING | D7: =IF(A7="","",IF(COUNTIFS(Input!$A:$A, A7, Input!$B:$B, "Schoonmaak")>0, "OK", "MISSING")) -> OK | E7: =IF(A7="","",IF(AND(B7="OK",C7="OK",D7="OK"), "✅ READY", "⚠️ INCOMPLETE")) -> ⚠️ INCOMPLETE
A8: =_xlfn.UNIQUE(_xlfn._xlws.FILTER(Input!A6:A4994, Input!A6:A4994<>"")) -> Compierekade 15 | B8: =IF(A8="","",IF(COUNTIFS(Input!$A:$A, A8, Input!$B:$B, "Basis")>0, "OK", "MISSING")) -> OK | C8: =IF(A8="","",IF(COUNTIFS(Input!$A:$A, A8, Input!$B:$B, "GWE")>0, "OK", "MISSING")) -> MISSING | D8: =IF(A8="","",IF(COUNTIFS(Input!$A:$A, A8, Input!$B:$B, "Schoonmaak")>0, "OK", "MISSING")) -> OK | E8: =IF(A8="","",IF(AND(B8="OK",C8="OK",D8="OK"), "✅ READY", "⚠️ INCOMPLETE")) -> ⚠️ INCOMPLETE
A9: =_xlfn.UNIQUE(_xlfn._xlws.FILTER(Input!A7:A4995, Input!A7:A4995<>"")) -> Compierekade 15 | B9: =IF(A9="","",IF(COUNTIFS(Input!$A:$A, A9, Input!$B:$B, "Basis")>0, "OK", "MISSING")) -> OK | C9: =IF(A9="","",IF(COUNTIFS(Input!$A:$A, A9, Input!$B:$B, "GWE")>0, "OK", "MISSING")) -> MISSING | D9: =IF(A9="","",IF(COUNTIFS(Input!$A:$A, A9, Input!$B:$B, "Schoonmaak")>0, "OK", "MISSING")) -> OK | E9: =IF(A9="","",IF(AND(B9="OK",C9="OK",D9="OK"), "✅ READY", "⚠️ INCOMPLETE")) -> ⚠️ INCOMPLETE
A10: =_xlfn.UNIQUE(_xlfn._xlws.FILTER(Input!A8:A4996, Input!A8:A4996<>"")) -> Compierekade 15 | B10: =IF(A10="","",IF(COUNTIFS(Input!$A:$A, A10, Input!$B:$B, "Basis")>0, "OK", "MISSING")) -> OK | C10: =IF(A10="","",IF(COUNTIFS(Input!$A:$A, A10, Input!$B:$B, "GWE")>0, "OK", "MISSING")) -> MISSING | D10: =IF(A10="","",IF(COUNTIFS(Input!$A:$A, A10, Input!$B:$B, "Schoonmaak")>0, "OK", "MISSING")) -> OK | E10: =IF(A10="","",IF(AND(B10="OK",C10="OK",D10="OK"), "✅ READY", "⚠️ INCOMPLETE")) -> ⚠️ INCOMPLETE
A11: =_xlfn.UNIQUE(_xlfn._xlws.FILTER(Input!A9:A4997, Input!A9:A4997<>"")) -> Compierekade 15 | B11: =IF(A11="","",IF(COUNTIFS(Input!$A:$A, A11, Input!$B:$B, "Basis")>0, "OK", "MISSING")) -> OK | C11: =IF(A11="","",IF(COUNTIFS(Input!$A:$A, A11, Input!$B:$B, "GWE")>0, "OK", "MISSING")) -> MISSING | D11: =IF(A11="","",IF(COUNTIFS(Input!$A:$A, A11, Input!$B:$B, "Schoonmaak")>0, "OK", "MISSING")) -> OK | E11: =IF(A11="","",IF(AND(B11="OK",C11="OK",D11="OK"), "✅ READY", "⚠️ INCOMPLETE")) -> ⚠️ INCOMPLETE
A12: =_xlfn.UNIQUE(_xlfn._xlws.FILTER(Input!A10:A4998, Input!A10:A4998<>"")) -> Akkerweg 41 [058] | B12: =IF(A12="","",IF(COUNTIFS(Input!$A:$A, A12, Input!$B:$B, "Basis")>0, "OK", "MISSING")) -> OK | C12: =IF(A12="","",IF(COUNTIFS(Input!$A:$A, A12, Input!$B:$B, "GWE")>0, "OK", "MISSING")) -> OK | D12: =IF(A12="","",IF(COUNTIFS(Input!$A:$A, A12, Input!$B:$B, "Schoonmaak")>0, "OK", "MISSING")) -> MISSING | E12: =IF(A12="","",IF(AND(B12="OK",C12="OK",D12="OK"), "✅ READY", "⚠️ INCOMPLETE")) -> ⚠️ INCOMPLETE
A13: =_xlfn.UNIQUE(_xlfn._xlws.FILTER(Input!A11:A4999, Input!A11:A4999<>"")) -> Akkerweg 41 [058] | B13: =IF(A13="","",IF(COUNTIFS(Input!$A:$A, A13, Input!$B:$B, "Basis")>0, "OK", "MISSING")) -> OK | C13: =IF(A13="","",IF(COUNTIFS(Input!$A:$A, A13, Input!$B:$B, "GWE")>0, "OK", "MISSING")) -> OK | D13: =IF(A13="","",IF(COUNTIFS(Input!$A:$A, A13, Input!$B:$B, "Schoonmaak")>0, "OK", "MISSING")) -> MISSING | E13: =IF(A13="","",IF(AND(B13="OK",C13="OK",D13="OK"), "✅ READY", "⚠️ INCOMPLETE")) -> ⚠️ INCOMPLETE
A14: =_xlfn.UNIQUE(_xlfn._xlws.FILTER(Input!A12:A5000, Input!A12:A5000<>"")) -> Akkerweg 41 [058] | B14: =IF(A14="","",IF(COUNTIFS(Input!$A:$A, A14, Input!$B:$B, "Basis")>0, "OK", "MISSING")) -> OK | C14: =IF(A14="","",IF(COUNTIFS(Input!$A:$A, A14, Input!$B:$B, "GWE")>0, "OK", "MISSING")) -> OK | D14: =IF(A14="","",IF(COUNTIFS(Input!$A:$A, A14, Input!$B:$B, "Schoonmaak")>0, "OK", "MISSING")) -> MISSING | E14: =IF(A14="","",IF(AND(B14="OK",C14="OK",D14="OK"), "✅ READY", "⚠️ INCOMPLETE")) -> ⚠️ INCOMPLETE
A15: =_xlfn.UNIQUE(_xlfn._xlws.FILTER(Input!A13:A5001, Input!A13:A5001<>"")) -> Akkerweg 41 [058] | B15: =IF(A15="","",IF(COUNTIFS(Input!$A:$A, A15, Input!$B:$B, "Basis")>0, "OK", "MISSING")) -> OK | C15: =IF(A15="","",IF(COUNTIFS(Input!$A:$A, A15, Input!$B:$B, "GWE")>0, "OK", "MISSING")) -> OK | D15: =IF(A15="","",IF(COUNTIFS(Input!$A:$A, A15, Input!$B:$B, "Schoonmaak")>0, "OK", "MISSING")) -> MISSING | E15: =IF(A15="","",IF(AND(B15="OK",C15="OK",D15="OK"), "✅ READY", "⚠️ INCOMPLETE")) -> ⚠️ INCOMPLETE
... A53: =_xlfn.UNIQUE(_xlfn._xlws.FILTER(Input!A51:A5039, Input!A51:A5039<>"")) -> #VALUE! | B53: =IF(A53="","",IF(COUNTIFS(Input!$A:$A, A53, Input!$B:$B, "Basis")>0, "OK", "MISSING")) -> #VALUE! | C53: =IF(A53="","",IF(COUNTIFS(Input!$A:$A, A53, Input!$B:$B, "GWE")>0, "OK", "MISSING")) -> #VALUE! | D53: =IF(A53="","",IF(COUNTIFS(Input!$A:$A, A53, Input!$B:$B, "Schoonmaak")>0, "OK", "MISSING")) -> #VALUE! | E53: =IF(A53="","",IF(AND(B53="OK",C53="OK",D53="OK"), "✅ READY", "⚠️ INCOMPLETE")) -> #VALUE!

Sheet Input
A1: Adres | B1: Type | C1: Klantnaam | D1: Object ID | E1: Klant Nr (Auto) | F1: RR Inspecteur | G1: Folder Link | H1: Check-in | I1: Check-out | J1: Borg (€) | K1: GWE Beheer | L1: GWE Maandbedrag (€) | M1: BTW % | N1: Voorschot GWE (Incl) | O1: Totaal Voorschot | P1: Meterbeheerder | Q1: Leverancier | R1: Leverancier Nr (Auto) | S1: Contractnr | T1: Extra Voorschot (€) | U1: Extra Voor. Omschr. | V1: Elek Begin | W1: Elek Eind | X1: Gas Begin | Y1: Gas Eind | Z1: Water Begin | AA1: Water Eind | AB1: Schoon Maak Pakket | AC1: Schoon Uren | AD1: Uurtarief (€) | AE1: Totaal Excl (€) | AF1: BTW % | AG1: BTW Bedrag (€) | AH1: Totaal Incl (€) | AI1: Kosten Type | AJ1: Eenheid | AK1: Beschrijving | AL1: Aantal | AM1: Prijs/Stuk (€) | AN1: Totaal Excl (€) | AO1: BTW % | AP1: BTW Bedrag (€) | AQ1: Totaal Incl (€)
A2: Compierekade 15 | B2: Basis | C2: Orange Investments Group | D2: =IF(A2="","",VLOOKUP(A2,Lists!$A:$B,2,FALSE)) -> 0345 | E2: =IF(C2="","",VLOOKUP(C2,Lists!$C:$D,2,FALSE)) -> 93 | H2: 45658 | I2: 46022 | J2: 6450 | K2: Eigen Beheer | L2: =IF(A2="","",IFERROR(VLOOKUP(A2,Lists!$A:$H,7,FALSE),0)) -> 0 | M2: 0.21 | N2: =L2 * (1 + M2) -> 0 | O2: =IF(K2="Eigen Beheer",0,IF(AND(ISNUMBER(N2),I2<>"",H2<>""),YEARFRAC(H2,I2,4)*12*N2,0)) -> 0 | R2: =IF(Q2="","",VLOOKUP(Q2,Lists!$E:$F,2,FALSE)) | AD2: 50 | AE2: =IF(AB2="","",IF(ISNUMBER(SEARCH("Basis",AB2)),(250/1.21)+MAX(0,AC2-5)*AD2,IF(ISNUMBER(SEARCH("Intensief",AB2)),(375/1.21)+MAX(0,AC2-7)*AD2,AC2*AD2))) | AF2: 0.21 | AG2: =IF(AE2<>"",AE2*AF2,"") | AH2: =IF(AE2<>"",AE2+AG2,"") | AL2: =IF($B2="GWE_Item",IF($AI2="Elektra",SUMIFS($W:$W,$A:$A,$A2,$B:$B,"GWE")-SUMIFS($V:$V,$A:$A,$A2,$B:$B,"GWE"),IF($AI2="Gas",SUMIFS($Y:$Y,$A:$A,$A2,$B:$B,"GWE")-SUMIFS($X:$X,$A:$A,$A2,$B:$B,"GWE"),IF($AI2="Water",SUMIFS($AA:$AA,$A:$A,$A2,$B:$B,"GWE")-SUMIFS($Z:$Z,$A:$A,$A2,$B:$B,"GWE"),""))),"") | AN2: =IF(AND(AL2<>"",AM2<>""),AL2*AM2,"") | AP2: =IF(AND(AN2<>"",AO2<>""),AN2*AO2,"") | AQ2: =IF(AND(AN2<>"",AP2<>""),AN2+AP2,"")
A3: Compierekade 15 | B3: Schade | C3: Orange Investments Group | D3: =IF(A3="","",VLOOKUP(A3,Lists!$A:$B,2,FALSE)) -> 0345 | E3: =IF(C3="","",VLOOKUP(C3,Lists!$C:$D,2,FALSE)) -> 93 | J3: =IF(A3="","",IFERROR(VLOOKUP(A3,Lists!$A:$H,8,FALSE),0)) -> 0 | L3: =IF(A3="","",IFERROR(VLOOKUP(A3,Lists!$A:$H,7,FALSE),0)) -> 0 | M3: 0.21 | N3: =L3 * (1 + M3) -> 0 | O3: =IF(K3="Eigen Beheer",0,IF(AND(ISNUMBER(N3),I3<>"",H3<>""),YEARFRAC(H3,I3,4)*12*N3,0)) -> 0 | R3: =IF(Q3="","",VLOOKUP(Q3,Lists!$E:$F,2,FALSE)) | AD3: 50 | AE3: =IF(AB3="","",IF(ISNUMBER(SEARCH("Basis",AB3)),(250/1.21)+MAX(0,AC3-5)*AD3,IF(ISNUMBER(SEARCH("Intensief",AB3)),(375/1.21)+MAX(0,AC3-7)*AD3,AC3*AD3))) | AF3: 0.21 | AG3: =IF(AE3<>"",AE3*AF3,"") | AH3: =IF(AE3<>"",AE3+AG3,"") | AI3: Overig | AK3: Kapotte stoel | AL3: 1 | AN3: 58.8 | AO3: 0.21 | AP3: =IF(AND(AN3<>"",AO3<>""),AN3*AO3,"") -> 12.348 | AQ3: =IF(AND(AN3<>"",AP3<>""),AN3+AP3,"") -> 71.148
A4: Compierekade 15 | B4: Schade | C4: Orange Investments Group | D4: =IF(A4="","",VLOOKUP(A4,Lists!$A:$B,2,FALSE)) -> 0345 | E4: =IF(C4="","",VLOOKUP(C4,Lists!$C:$D,2,FALSE)) -> 93 | J4: =IF(A4="","",IFERROR(VLOOKUP(A4,Lists!$A:$H,8,FALSE),0)) -> 0 | L4: =IF(A4="","",IFERROR(VLOOKUP(A4,Lists!$A:$H,7,FALSE),0)) -> 0 | M4: 0.21 | N4: =L4 * (1 + M4) -> 0 | O4: =IF(K4="Eigen Beheer",0,IF(AND(ISNUMBER(N4),I4<>"",H4<>""),YEARFRAC(H4,I4,4)*12*N4,0)) -> 0 | R4: =IF(Q4="","",VLOOKUP(Q4,Lists!$E:$F,2,FALSE)) | AD4: 50 | AE4: =IF(AB4="","",IF(ISNUMBER(SEARCH("Basis",AB4)),(250/1.21)+MAX(0,AC4-5)*AD4,IF(ISNUMBER(SEARCH("Intensief",AB4)),(375/1.21)+MAX(0,AC4-7)*AD4,AC4*AD4))) | AF4: 0.21 | AG4: =IF(AE4<>"",AE4*AF4,"") | AH4: =IF(AE4<>"",AE4+AG4,"") | AI4: Overig | AK4: bestekken, pannen, koekenpannen | AL4: 1 | AN4: 51.87 | AO4: 0.21 | AP4: =IF(AND(AN4<>"",AO4<>""),AN4*AO4,"") -> 10.8927 | AQ4: =IF(AND(AN4<>"",AP4<>""),AN4+AP4,"") -> 62.7627
A5: Compierekade 15 | B5: Schade | C5: Orange Investments Group | D5: =IF(A5="","",VLOOKUP(A5,Lists!$A:$B,2,FALSE)) -> 0345 | E5: =IF(C5="","",VLOOKUP(C5,Lists!$C:$D,2,FALSE)) -> 93 | J5: =IF(A5="","",IFERROR(VLOOKUP(A5,Lists!$A:$H,8,FALSE),0)) -> 0 | L5: =IF(A5="","",IFERROR(VLOOKUP(A5,Lists!$A:$H,7,FALSE),0)) -> 0 | M5: 0.21 | N5: =L5 * (1 + M5) -> 0 | O5: =IF(K5="Eigen Beheer",0,IF(AND(ISNUMBER(N5),I5<>"",H5<>""),YEARFRAC(H5,I5,4)*12*N5,0)) -> 0 | R5: =IF(Q5="","",VLOOKUP(Q5,Lists!$E:$F,2,FALSE)) | AD5: 50 | AE5: =IF(AB5="","",IF(ISNUMBER(SEARCH("Basis",AB5)),(250/1.21)+MAX(0,AC5-5)*AD5,IF(ISNUMBER(SEARCH("Intensief",AB5)),(375/1.21)+MAX(0,AC5-7)*AD5,AC5*AD5))) | AF5: 0.21 | AG5: =IF(AE5<>"",AE5*AF5,"") | AH5: =IF(AE5<>"",AE5+AG5,"") | AI5: Overig | AK5: Matrassen | AL5: 1 | AN5: 283.14 | AO5: 0.21 | AP5: =IF(AND(AN5<>"",AO5<>""),AN5*AO5,"") -> 59.4594 | AQ5: =IF(AND(AN5<>"",AP5<>""),AN5+AP5,"") -> 342.5994
A6: Compierekade 15 | B6: Schade | C6: Orange Investments Group | D6: =IF(A6="","",VLOOKUP(A6,Lists!$A:$B,2,FALSE)) -> 0345 | E6: =IF(C6="","",VLOOKUP(C6,Lists!$C:$D,2,FALSE)) -> 93 | J6: =IF(A6="","",IFERROR(VLOOKUP(A6,Lists!$A:$H,8,FALSE),0)) -> 0 | L6: =IF(A6="","",IFERROR(VLOOKUP(A6,Lists!$A:$H,7,FALSE),0)) -> 0 | M6: 0.21 | N6: =L6 * (1 + M6) -> 0 | O6: =IF(K6="Eigen Beheer",0,IF(AND(ISNUMBER(N6),I6<>"",H6<>""),YEARFRAC(H6,I6,4)*12*N6,0)) -> 0 | R6: =IF(Q6="","",VLOOKUP(Q6,Lists!$E:$F,2,FALSE)) | AD6: 50 | AE6: =IF(AB6="","",IF(ISNUMBER(SEARCH("Basis",AB6)),(250/1.21)+MAX(0,AC6-5)*AD6,IF(ISNUMBER(SEARCH("Intensief",AB6)),(375/1.21)+MAX(0,AC6-7)*AD6,AC6*AD6))) | AF6: 0.21 | AG6: =IF(AE6<>"",AE6*AF6,"") | AH6: =IF(AE6<>"",AE6+AG6,"") | AI6: Overig | AK6: Matrashoezen | AL6: 6 | AN6: 339.3 | AO6: 0.21 | AP6: =IF(AND(AN6<>"",AO6<>""),AN6*AO6,"") -> 71.253 | AQ6: =IF(AND(AN6<>"",AP6<>""),AN6+AP6,"") -> 410.553
A7: Compierekade 15 | B7: Schade | C7: Orange Investments Group | D7: =IF(A7="","",VLOOKUP(A7,Lists!$A:$B,2,FALSE)) -> 0345 | E7: =IF(C7="","",VLOOKUP(C7,Lists!$C:$D,2,FALSE)) -> 93 | J7: =IF(A7="","",IFERROR(VLOOKUP(A7,Lists!$A:$H,8,FALSE),0)) -> 0 | L7: =IF(A7="","",IFERROR(VLOOKUP(A7,Lists!$A:$H,7,FALSE),0)) -> 0 | M7: 0.21 | N7: =L7 * (1 + M7) -> 0 | O7: =IF(K7="Eigen Beheer",0,IF(AND(ISNUMBER(N7),I7<>"",H7<>""),YEARFRAC(H7,I7,4)*12*N7,0)) -> 0 | R7: =IF(Q7="","",VLOOKUP(Q7,Lists!$E:$F,2,FALSE)) | AD7: 50 | AE7: =IF(AB7="","",IF(ISNUMBER(SEARCH("Basis",AB7)),(250/1.21)+MAX(0,AC7-5)*AD7,IF(ISNUMBER(SEARCH("Intensief",AB7)),(375/1.21)+MAX(0,AC7-7)*AD7,AC7*AD7))) | AF7: 0.21 | AG7: =IF(AE7<>"",AE7*AF7,"") | AH7: =IF(AE7<>"",AE7+AG7,"") | AI7: Overig | AK7: Sleutel voor ingebouwd kast op de gang | AL7: 1 | AN7: 8 | AO7: 0.21 | AP7: =IF(AND(AN7<>"",AO7<>""),AN7*AO7,"") -> 1.68 | AQ7: =IF(AND(AN7<>"",AP7<>""),AN7+AP7,"") -> 9.68
A8: Compierekade 15 | B8: Schade | C8: Orange Investments Group | D8: =IF(A8="","",VLOOKUP(A8,Lists!$A:$B,2,FALSE)) -> 0345 | E8: =IF(C8="","",VLOOKUP(C8,Lists!$C:$D,2,FALSE)) -> 93 | J8: =IF(A8="","",IFERROR(VLOOKUP(A8,Lists!$A:$H,8,FALSE),0)) -> 0 | L8: =IF(A8="","",IFERROR(VLOOKUP(A8,Lists!$A:$H,7,FALSE),0)) -> 0 | M8: 0.21 | N8: =L8 * (1 + M8) -> 0 | O8: =IF(K8="Eigen Beheer",0,IF(AND(ISNUMBER(N8),I8<>"",H8<>""),YEARFRAC(H8,I8,4)*12*N8,0)) -> 0 | R8: =IF(Q8="","",VLOOKUP(Q8,Lists!$E:$F,2,FALSE)) | AD8: 50 | AE8: =IF(AB8="","",IF(ISNUMBER(SEARCH("Basis",AB8)),(250/1.21)+MAX(0,AC8-5)*AD8,IF(ISNUMBER(SEARCH("Intensief",AB8)),(375/1.21)+MAX(0,AC8-7)*AD8,AC8*AD8))) | AF8: 0.21 | AG8: =IF(AE8<>"",AE8*AF8,"") | AH8: =IF(AE8<>"",AE8+AG8,"") | AI8: Overig | AK8: Gat in de deur | AL8: 1 | AN8: 50 | AO8: 0.21 | AP8: =IF(AND(AN8<>"",AO8<>""),AN8*AO8,"") -> 10.5 | AQ8: =IF(AND(AN8<>"",AP8<>""),AN8+AP8,"") -> 60.5
A9: Compierekade 15 | B9: Schoonmaak | C9: Orange Investments Group | D9: =IF(A9="","",VLOOKUP(A9,Lists!$A:$B,2,FALSE)) -> 0345 | E9: =IF(C9="","",VLOOKUP(C9,Lists!$C:$D,2,FALSE)) -> 93 | J9: =IF(A9="","",IFERROR(VLOOKUP(A9,Lists!$A:$H,8,FALSE),0)) -> 0 | L9: =IF(A9="","",IFERROR(VLOOKUP(A9,Lists!$A:$H,7,FALSE),0)) -> 0 | M9: 0.21 | N9: =L9 * (1 + M9) -> 0 | O9: =IF(K9="Eigen Beheer",0,IF(AND(ISNUMBER(N9),I9<>"",H9<>""),YEARFRAC(H9,I9,4)*12*N9,0)) -> 0 | R9: =IF(Q9="","",VLOOKUP(Q9,Lists!$E:$F,2,FALSE)) | AB9: Intensief Schoonmaak | AD9: 50 | AE9: 620 | AF9: 0.21 | AG9: =IF(AE9<>"",AE9*AF9,"") -> 130.2 | AH9: =IF(AE9<>"",AE9+AG9,"") -> 750.2 | AL9: =IF($B9="GWE_Item",IF($AI9="Elektra",SUMIFS($W:$W,$A:$A,$A9,$B:$B,"GWE")-SUMIFS($V:$V,$A:$A,$A9,$B:$B,"GWE"),IF($AI9="Gas",SUMIFS($Y:$Y,$A:$A,$A9,$B:$B,"GWE")-SUMIFS($X:$X,$A:$A,$A9,$B:$B,"GWE"),IF($AI9="Water",SUMIFS($AA:$AA,$A:$A,$A9,$B:$B,"GWE")-SUMIFS($Z:$Z,$A:$A,$A9,$B:$B,"GWE"),""))),"") | AN9: =IF(AND(AL9<>"",AM9<>""),AL9*AM9,"") | AP9: =IF(AND(AN9<>"",AO9<>""),AN9*AO9,"") | AQ9: =IF(AND(AN9<>"",AP9<>""),AN9+AP9,"")
A10: Akkerweg 41 [058] | B10: GWE | C10: Buurman Vastgoed E B.V. | D10: =IF(A10="","",VLOOKUP(A10,Lists!$A:$B,2,FALSE)) -> 0384 | E10: =IF(C10="","",VLOOKUP(C10,Lists!$C:$D,2,FALSE)) -> 100191 | J10: =IF(A10="","",IFERROR(VLOOKUP(A10,Lists!$A:$H,8,FALSE),0)) -> 1000 | L10: =IF(A10="","",IFERROR(VLOOKUP(A10,Lists!$A:$H,7,FALSE),0)) -> 0 | M10: 0.21 | N10: =L10 * (1 + M10) -> 0 | O10: =IF(K10="Eigen Beheer",0,IF(AND(ISNUMBER(N10),I10<>"",H10<>""),YEARFRAC(H10,I10,4)*12*N10,0)) -> 0 | R10: =IF(Q10="","",VLOOKUP(Q10,Lists!$E:$F,2,FALSE)) | V10: 53 | W10: 124 | X10: 373 | Y10: 376 | Z10: 56 | AA10: 60 | AD10: 50 | AE10: =IF(AB10="","",IF(ISNUMBER(SEARCH("Basis",AB10)),(250/1.21)+MAX(0,AC10-5)*AD10,IF(ISNUMBER(SEARCH("Intensief",AB10)),(375/1.21)+MAX(0,AC10-7)*AD10,AC10*AD10))) | AF10: 0.21 | AG10: =IF(AE10<>"",AE10*AF10,"") | AH10: =IF(AE10<>"",AE10+AG10,"") | AL10: =IF($B10="GWE_Item",IF($AI10="Elektra",SUMIFS($W:$W,$A:$A,$A10,$B:$B,"GWE")-SUMIFS($V:$V,$A:$A,$A10,$B:$B,"GWE"),IF($AI10="Gas",SUMIFS($Y:$Y,$A:$A,$A10,$B:$B,"GWE")-SUMIFS($X:$X,$A:$A,$A10,$B:$B,"GWE"),IF($AI10="Water",SUMIFS($AA:$AA,$A:$A,$A10,$B:$B,"GWE")-SUMIFS($Z:$Z,$A:$A,$A10,$B:$B,"GWE"),""))),"") | AN10: =IF(AND(AL10<>"",AM10<>""),AL10*AM10,"") | AP10: =IF(AND(AN10<>"",AO10<>""),AN10*AO10,"") | AQ10: =IF(AND(AN10<>"",AP10<>""),AN10+AP10,"")
A11: Akkerweg 41 [058] | B11: GWE_Item | C11: Buurman Vastgoed E B.V. | D11: =IF(A11="","",VLOOKUP(A11,Lists!$A:$B,2,FALSE)) -> 0384 | E11: =IF(C11="","",VLOOKUP(C11,Lists!$C:$D,2,FALSE)) -> 100191 | J11: =IF(A11="","",IFERROR(VLOOKUP(A11,Lists!$A:$H,8,FALSE),0)) -> 1000 | L11: =IF(A11="","",IFERROR(VLOOKUP(A11,Lists!$A:$H,7,FALSE),0)) -> 0 | M11: 0.21 | N11: =L11 * (1 + M11) -> 0 | O11: =IF(K11="Eigen Beheer",0,IF(AND(ISNUMBER(N11),I11<>"",H11<>""),YEARFRAC(H11,I11,4)*12*N11,0)) -> 0 | R11: =IF(Q11="","",VLOOKUP(Q11,Lists!$E:$F,2,FALSE)) | AD11: 50 | AE11: =IF(AB11="","",IF(ISNUMBER(SEARCH("Basis",AB11)),(250/1.21)+MAX(0,AC11-5)*AD11,IF(ISNUMBER(SEARCH("Intensief",AB11)),(375/1.21)+MAX(0,AC11-7)*AD11,AC11*AD11))) | AF11: 0.21 | AG11: =IF(AE11<>"",AE11*AF11,"") | AH11: =IF(AE11<>"",AE11+AG11,"") | AI11: Elektra | AL11: =IF($B11="GWE_Item",IF($AI11="Elektra",SUMIFS($W:$W,$A:$A,$A11,$B:$B,"GWE")-SUMIFS($V:$V,$A:$A,$A11,$B:$B,"GWE"),IF($AI11="Gas",SUMIFS($Y:$Y,$A:$A,$A11,$B:$B,"GWE")-SUMIFS($X:$X,$A:$A,$A11,$B:$B,"GWE"),IF($AI11="Water",SUMIFS($AA:$AA,$A:$A,$A11,$B:$B,"GWE")-SUMIFS($Z:$Z,$A:$A,$A11,$B:$B,"GWE"),""))),"") -> 71 | AN11: 50.83 | AO11: 0.21 | AP11: =IF(AND(AN11<>"",AO11<>""),AN11*AO11,"") -> 10.6743 | AQ11: =IF(AND(AN11<>"",AP11<>""),AN11+AP11,"") -> 61.5043
A12: Akkerweg 41 [058] | B12: Basis | C12: Buurman Vastgoed E B.V. | D12: =IF(A12="","",VLOOKUP(A12,Lists!$A:$B,2,FALSE)) -> 0384 | E12: =IF(C12="","",VLOOKUP(C12,Lists!$C:$D,2,FALSE)) -> 100191 | H12: 45913 | I12: 46004 | J12: =IF(A12="","",IFERROR(VLOOKUP(A12,Lists!$A:$H,8,FALSE),0)) -> 1000 | K12: Via RyanRent | L12: 200 | M12: 0.21 | N12: =L12 * (1 + M12) -> 242 | O12: =IF(K12="Eigen Beheer",0,IF(AND(ISNUMBER(N12),I12<>"",H12<>""),YEARFRAC(H12,I12,4)*12*N12,0)) -> 726 | P12: Enexis | Q12: Vattenfall | R12: =IF(Q12="","",VLOOKUP(Q12,Lists!$E:$F,2,FALSE)) -> 2 | AD12: 50 | AE12: =IF(AB12="","",IF(ISNUMBER(SEARCH("Basis",AB12)),(250/1.21)+MAX(0,AC12-5)*AD12,IF(ISNUMBER(SEARCH("Intensief",AB12)),(375/1.21)+MAX(0,AC12-7)*AD12,AC12*AD12))) | AF12: 0.21 | AG12: =IF(AE12<>"",AE12*AF12,"") | AH12: =IF(AE12<>"",AE12+AG12,"") | AL12: =IF($B12="GWE_Item",IF($AI12="Elektra",SUMIFS($W:$W,$A:$A,$A12,$B:$B,"GWE")-SUMIFS($V:$V,$A:$A,$A12,$B:$B,"GWE"),IF($AI12="Gas",SUMIFS($Y:$Y,$A:$A,$A12,$B:$B,"GWE")-SUMIFS($X:$X,$A:$A,$A12,$B:$B,"GWE"),IF($AI12="Water",SUMIFS($AA:$AA,$A:$A,$A12,$B:$B,"GWE")-SUMIFS($Z:$Z,$A:$A,$A12,$B:$B,"GWE"),""))),"") | AN12: =IF(AND(AL12<>"",AM12<>""),AL12*AM12,"") | AP12: =IF(AND(AN12<>"",AO12<>""),AN12*AO12,"") | AQ12: =IF(AND(AN12<>"",AP12<>""),AN12+AP12,"")
A13: Akkerweg 41 [058] | B13: GWE_Item | C13: Buurman Vastgoed E B.V. | D13: =IF(A13="","",VLOOKUP(A13,Lists!$A:$B,2,FALSE)) -> 0384 | E13: =IF(C13="","",VLOOKUP(C13,Lists!$C:$D,2,FALSE)) -> 100191 | J13: =IF(A13="","",IFERROR(VLOOKUP(A13,Lists!$A:$H,8,FALSE),0)) -> 1000 | L13: =IF(A13="","",IFERROR(VLOOKUP(A13,Lists!$A:$H,7,FALSE),0)) -> 0 | M13: 0.21 | N13: =L13 * (1 + M13) -> 0 | O13: =IF(K13="Eigen Beheer",0,IF(AND(ISNUMBER(N13),I13<>"",H13<>""),YEARFRAC(H13,I13,4)*12*N13,0)) -> 0 | R13: =IF(Q13="","",VLOOKUP(Q13,Lists!$E:$F,2,FALSE)) | AD13: 50 | AE13: =IF(AB13="","",IF(ISNUMBER(SEARCH("Basis",AB13)),(250/1.21)+MAX(0,AC13-5)*AD13,IF(ISNUMBER(SEARCH("Intensief",AB13)),(375/1.21)+MAX(0,AC13-7)*AD13,AC13*AD13))) | AF13: 0.21 | AG13: =IF(AE13<>"",AE13*AF13,"") | AH13: =IF(AE13<>"",AE13+AG13,"") | AI13: Gas | AL13: =IF($B13="GWE_Item",IF($AI13="Elektra",SUMIFS($W:$W,$A:$A,$A13,$B:$B,"GWE")-SUMIFS($V:$V,$A:$A,$A13,$B:$B,"GWE"),IF($AI13="Gas",SUMIFS($Y:$Y,$A:$A,$A13,$B:$B,"GWE")-SUMIFS($X:$X,$A:$A,$A13,$B:$B,"GWE"),IF($AI13="Water",SUMIFS($AA:$AA,$A:$A,$A13,$B:$B,"GWE")-SUMIFS($Z:$Z,$A:$A,$A13,$B:$B,"GWE"),""))),"") -> 3 | AN13: =IF(AND(AL13<>"",AM13<>""),AL13*AM13,"") | AP13: =IF(AND(AN13<>"",AO13<>""),AN13*AO13,"") | AQ13: =IF(AND(AN13<>"",AP13<>""),AN13+AP13,"")
A14: Akkerweg 41 [058] | B14: GWE_Item | C14: Buurman Vastgoed E B.V. | D14: =IF(A14="","",VLOOKUP(A14,Lists!$A:$B,2,FALSE)) -> 0384 | E14: =IF(C14="","",VLOOKUP(C14,Lists!$C:$D,2,FALSE)) -> 100191 | J14: =IF(A14="","",IFERROR(VLOOKUP(A14,Lists!$A:$H,8,FALSE),0)) -> 1000 | L14: =IF(A14="","",IFERROR(VLOOKUP(A14,Lists!$A:$H,7,FALSE),0)) -> 0 | M14: 0.21 | N14: =L14 * (1 + M14) -> 0 | O14: =IF(K14="Eigen Beheer",0,IF(AND(ISNUMBER(N14),I14<>"",H14<>""),YEARFRAC(H14,I14,4)*12*N14,0)) -> 0 | R14: =IF(Q14="","",VLOOKUP(Q14,Lists!$E:$F,2,FALSE)) | AD14: 50 | AE14: =IF(AB14="","",IF(ISNUMBER(SEARCH("Basis",AB14)),(250/1.21)+MAX(0,AC14-5)*AD14,IF(ISNUMBER(SEARCH("Intensief",AB14)),(375/1.21)+MAX(0,AC14-7)*AD14,AC14*AD14))) | AF14: 0.21 | AG14: =IF(AE14<>"",AE14*AF14,"") | AH14: =IF(AE14<>"",AE14+AG14,"") | AI14: Water | AL14: =IF($B14="GWE_Item",IF($AI14="Elektra",SUMIFS($W:$W,$A:$A,$A14,$B:$B,"GWE")-SUMIFS($V:$V,$A:$A,$A14,$B:$B,"GWE"),IF($AI14="Gas",SUMIFS($Y:$Y,$A:$A,$A14,$B:$B,"GWE")-SUMIFS($X:$X,$A:$A,$A14,$B:$B,"GWE"),IF($AI14="Water",SUMIFS($AA:$AA,$A:$A,$A14,$B:$B,"GWE")-SUMIFS($Z:$Z,$A:$A,$A14,$B:$B,"GWE"),""))),"") -> 4 | AN14: =IF(AND(AL14<>"",AM14<>""),AL14*AM14,"") | AP14: =IF(AND(AN14<>"",AO14<>""),AN14*AO14,"") | AQ14: =IF(AND(AN14<>"",AP14<>""),AN14+AP14,"")
A15: Van Maanenstraat 14A | B15: Basis | C15: Focuzop-eu | D15: =IF(A15="","",VLOOKUP(A15,Lists!$A:$B,2,FALSE)) -> 0089 | E15: =IF(C15="","",VLOOKUP(C15,Lists!$C:$D,2,FALSE)) -> 50448 | H15: 45915 | I15: 46011 | J15: 1650 | K15: Via RyanRent | L15: =IF(A15="","",IFERROR(VLOOKUP(A15,Lists!$A:$H,7,FALSE),0)) -> 120 | M15: 0.21 | N15: =L15 * (1 + M15) -> 145.2 | O15: =IF(K15="Eigen Beheer",0,IF(AND(ISNUMBER(N15),I15<>"",H15<>""),YEARFRAC(H15,I15,4)*12*N15,0)) -> 459.8 | P15: Enexis | Q15: Vattenfall | R15: =IF(Q15="","",VLOOKUP(Q15,Lists!$E:$F,2,FALSE)) -> 2 | AD15: 50 | AE15: =IF(AB15="","",IF(ISNUMBER(SEARCH("Basis",AB15)),(250/1.21)+MAX(0,AC15-5)*AD15,IF(ISNUMBER(SEARCH("Intensief",AB15)),(375/1.21)+MAX(0,AC15-7)*AD15,AC15*AD15))) | AF15: 0.21 | AG15: =IF(AE15<>"",AE15*AF15,"") | AH15: =IF(AE15<>"",AE15+AG15,"") | AL15: =IF($B15="GWE_Item",IF($AI15="Elektra",SUMIFS($W:$W,$A:$A,$A15,$B:$B,"GWE")-SUMIFS($V:$V,$A:$A,$A15,$B:$B,"GWE"),IF($AI15="Gas",SUMIFS($Y:$Y,$A:$A,$A15,$B:$B,"GWE")-SUMIFS($X:$X,$A:$A,$A15,$B:$B,"GWE"),IF($AI15="Water",SUMIFS($AA:$AA,$A:$A,$A15,$B:$B,"GWE")-SUMIFS($Z:$Z,$A:$A,$A15,$B:$B,"GWE"),""))),"") | AN15: =IF(AND(AL15<>"",AM15<>""),AL15*AM15,"") | AP15: =IF(AND(AN15<>"",AO15<>""),AN15*AO15,"") | AQ15: =IF(AND(AN15<>"",AP15<>""),AN15+AP15,"")
A16: Van Maanenstraat 14A | B16: GWE | C16: Focuzop-eu | D16: =IF(A16="","",VLOOKUP(A16,Lists!$A:$B,2,FALSE)) -> 0089 | E16: =IF(C16="","",VLOOKUP(C16,Lists!$C:$D,2,FALSE)) -> 50448 | J16: =IF(A16="","",IFERROR(VLOOKUP(A16,Lists!$A:$H,8,FALSE),0)) -> 1650 | L16: =IF(A16="","",IFERROR(VLOOKUP(A16,Lists!$A:$H,7,FALSE),0)) -> 120 | M16: 0.21 | N16: =L16 * (1 + M16) -> 145.2 | O16: =IF(K16="Eigen Beheer",0,IF(AND(ISNUMBER(N16),I16<>"",H16<>""),YEARFRAC(H16,I16,4)*12*N16,0)) -> 0 | R16: =IF(Q16="","",VLOOKUP(Q16,Lists!$E:$F,2,FALSE)) | Z16: 487 | AA16: 499 | AD16: 50 | AE16: =IF(AB16="","",IF(ISNUMBER(SEARCH("Basis",AB16)),(250/1.21)+MAX(0,AC16-5)*AD16,IF(ISNUMBER(SEARCH("Intensief",AB16)),(375/1.21)+MAX(0,AC16-7)*AD16,AC16*AD16))) | AF16: 0.21 | AG16: =IF(AE16<>"",AE16*AF16,"") | AH16: =IF(AE16<>"",AE16+AG16,"") | AL16: =IF($B16="GWE_Item",IF($AI16="Elektra",SUMIFS($W:$W,$A:$A,$A16,$B:$B,"GWE")-SUMIFS($V:$V,$A:$A,$A16,$B:$B,"GWE"),IF($AI16="Gas",SUMIFS($Y:$Y,$A:$A,$A16,$B:$B,"GWE")-SUMIFS($X:$X,$A:$A,$A16,$B:$B,"GWE"),IF($AI16="Water",SUMIFS($AA:$AA,$A:$A,$A16,$B:$B,"GWE")-SUMIFS($Z:$Z,$A:$A,$A16,$B:$B,"GWE"),""))),"") | AN16: =IF(AND(AL16<>"",AM16<>""),AL16*AM16,"") | AP16: =IF(AND(AN16<>"",AO16<>""),AN16*AO16,"") | AQ16: =IF(AND(AN16<>"",AP16<>""),AN16+AP16,"")
A17: Van Maanenstraat 14A | B17: GWE_Item | C17: Focuzop-eu | D17: =IF(A17="","",VLOOKUP(A17,Lists!$A:$B,2,FALSE)) -> 0089 | E17: =IF(C17="","",VLOOKUP(C17,Lists!$C:$D,2,FALSE)) -> 50448 | J17: =IF(A17="","",IFERROR(VLOOKUP(A17,Lists!$A:$H,8,FALSE),0)) -> 1650 | L17: =IF(A17="","",IFERROR(VLOOKUP(A17,Lists!$A:$H,7,FALSE),0)) -> 120 | M17: 0.21 | N17: =L17 * (1 + M17) -> 145.2 | O17: =IF(K17="Eigen Beheer",0,IF(AND(ISNUMBER(N17),I17<>"",H17<>""),YEARFRAC(H17,I17,4)*12*N17,0)) -> 0 | R17: =IF(Q17="","",VLOOKUP(Q17,Lists!$E:$F,2,FALSE)) | AD17: 50 | AE17: =IF(AB17="","",IF(ISNUMBER(SEARCH("Basis",AB17)),(250/1.21)+MAX(0,AC17-5)*AD17,IF(ISNUMBER(SEARCH("Intensief",AB17)),(375/1.21)+MAX(0,AC17-7)*AD17,AC17*AD17))) | AF17: 0.21 | AG17: =IF(AE17<>"",AE17*AF17,"") | AH17: =IF(AE17<>"",AE17+AG17,"") | AI17: Water | AJ17: m3 | AK17: levering | AL17: =IF($B17="GWE_Item",IF($AI17="Elektra",SUMIFS($W:$W,$A:$A,$A17,$B:$B,"GWE")-SUMIFS($V:$V,$A:$A,$A17,$B:$B,"GWE"),IF($AI17="Gas",SUMIFS($Y:$Y,$A:$A,$A17,$B:$B,"GWE")-SUMIFS($X:$X,$A:$A,$A17,$B:$B,"GWE"),IF($AI17="Water",SUMIFS($AA:$AA,$A:$A,$A17,$B:$B,"GWE")-SUMIFS($Z:$Z,$A:$A,$A17,$B:$B,"GWE"),""))),"") -> 12 | AM17: 1.29 | AN17: =IF(AND(AL17<>"",AM17<>""),AL17*AM17,"") -> 15.48 | AO17: 0.09 | AP17: =IF(AND(AN17<>"",AO17<>""),AN17*AO17,"") -> 1.3932 | AQ17: =IF(AND(AN17<>"",AP17<>""),AN17+AP17,"") -> 16.8732
A18: Van Maanenstraat 14A | B18: GWE_Item | C18: Focuzop-eu | D18: =IF(A18="","",VLOOKUP(A18,Lists!$A:$B,2,FALSE)) -> 0089 | E18: =IF(C18="","",VLOOKUP(C18,Lists!$C:$D,2,FALSE)) -> 50448 | J18: =IF(A18="","",IFERROR(VLOOKUP(A18,Lists!$A:$H,8,FALSE),0)) -> 1650 | L18: =IF(A18="","",IFERROR(VLOOKUP(A18,Lists!$A:$H,7,FALSE),0)) -> 120 | M18: 0.21 | N18: =L18 * (1 + M18) -> 145.2 | O18: =IF(K18="Eigen Beheer",0,IF(AND(ISNUMBER(N18),I18<>"",H18<>""),YEARFRAC(H18,I18,4)*12*N18,0)) -> 0 | R18: =IF(Q18="","",VLOOKUP(Q18,Lists!$E:$F,2,FALSE)) | AD18: 50 | AE18: =IF(AB18="","",IF(ISNUMBER(SEARCH("Basis",AB18)),(250/1.21)+MAX(0,AC18-5)*AD18,IF(ISNUMBER(SEARCH("Intensief",AB18)),(375/1.21)+MAX(0,AC18-7)*AD18,AC18*AD18))) | AF18: 0.21 | AG18: =IF(AE18<>"",AE18*AF18,"") | AH18: =IF(AE18<>"",AE18+AG18,"") | AI18: Water | AJ18: dag | AK18: vastrecht | AL18: 97 | AM18: 0.25474 | AN18: =IF(AND(AL18<>"",AM18<>""),AL18*AM18,"") -> 24.70978 | AO18: 0.09 | AP18: =IF(AND(AN18<>"",AO18<>""),AN18*AO18,"") -> 2.2238802 | AQ18: =IF(AND(AN18<>"",AP18<>""),AN18+AP18,"") -> 26.93366
A19: Van Maanenstraat 14A | B19: GWE_Item | C19: Focuzop-eu | D19: =IF(A19="","",VLOOKUP(A19,Lists!$A:$B,2,FALSE)) -> 0089 | E19: =IF(C19="","",VLOOKUP(C19,Lists!$C:$D,2,FALSE)) -> 50448 | J19: =IF(A19="","",IFERROR(VLOOKUP(A19,Lists!$A:$H,8,FALSE),0)) -> 1650 | L19: =IF(A19="","",IFERROR(VLOOKUP(A19,Lists!$A:$H,7,FALSE),0)) -> 120 | M19: 0.21 | N19: =L19 * (1 + M19) -> 145.2 | O19: =IF(K19="Eigen Beheer",0,IF(AND(ISNUMBER(N19),I19<>"",H19<>""),YEARFRAC(H19,I19,4)*12*N19,0)) -> 0 | R19: =IF(Q19="","",VLOOKUP(Q19,Lists!$E:$F,2,FALSE)) | AD19: 50 | AE19: =IF(AB19="","",IF(ISNUMBER(SEARCH("Basis",AB19)),(250/1.21)+MAX(0,AC19-5)*AD19,IF(ISNUMBER(SEARCH("Intensief",AB19)),(375/1.21)+MAX(0,AC19-7)*AD19,AC19*AD19))) | AF19: 0.21 | AG19: =IF(AE19<>"",AE19*AF19,"") | AH19: =IF(AE19<>"",AE19+AG19,"") | AI19: Water | AJ19: m3 | AK19: Belasting op leidingwater | AL19: =IF($B19="GWE_Item",IF($AI19="Elektra",SUMIFS($W:$W,$A:$A,$A19,$B:$B,"GWE")-SUMIFS($V:$V,$A:$A,$A19,$B:$B,"GWE"),IF($AI19="Gas",SUMIFS($Y:$Y,$A:$A,$A19,$B:$B,"GWE")-SUMIFS($X:$X,$A:$A,$A19,$B:$B,"GWE"),IF($AI19="Water",SUMIFS($AA:$AA,$A:$A,$A19,$B:$B,"GWE")-SUMIFS($Z:$Z,$A:$A,$A19,$B:$B,"GWE"),""))),"") -> 12 | AM19: 0.458 | AN19: =IF(AND(AL19<>"",AM19<>""),AL19*AM19,"") -> 5.496 | AO19: 0.09 | AP19: =IF(AND(AN19<>"",AO19<>""),AN19*AO19,"") -> 0.49464 | AQ19: =IF(AND(AN19<>"",AP19<>""),AN19+AP19,"") -> 5.99064
A20: Van Maanenstraat 14A | B20: GWE_Item | C20: Focuzop-eu | D20: =IF(A20="","",VLOOKUP(A20,Lists!$A:$B,2,FALSE)) -> 0089 | E20: =IF(C20="","",VLOOKUP(C20,Lists!$C:$D,2,FALSE)) -> 50448 | J20: =IF(A20="","",IFERROR(VLOOKUP(A20,Lists!$A:$H,8,FALSE),0)) -> 1650 | L20: =IF(A20="","",IFERROR(VLOOKUP(A20,Lists!$A:$H,7,FALSE),0)) -> 120 | M20: 0.21 | N20: =L20 * (1 + M20) -> 145.2 | O20: =IF(K20="Eigen Beheer",0,IF(AND(ISNUMBER(N20),I20<>"",H20<>""),YEARFRAC(H20,I20,4)*12*N20,0)) -> 0 | R20: =IF(Q20="","",VLOOKUP(Q20,Lists!$E:$F,2,FALSE)) | AD20: 50 | AE20: =IF(AB20="","",IF(ISNUMBER(SEARCH("Basis",AB20)),(250/1.21)+MAX(0,AC20-5)*AD20,IF(ISNUMBER(SEARCH("Intensief",AB20)),(375/1.21)+MAX(0,AC20-7)*AD20,AC20*AD20))) | AF20: 0.21 | AG20: =IF(AE20<>"",AE20*AF20,"") | AH20: =IF(AE20<>"",AE20+AG20,"") | AI20: Water | AJ20: m3 | AK20: Precarrioheffing | AL20: =IF($B20="GWE_Item",IF($AI20="Elektra",SUMIFS($W:$W,$A:$A,$A20,$B:$B,"GWE")-SUMIFS($V:$V,$A:$A,$A20,$B:$B,"GWE"),IF($AI20="Gas",SUMIFS($Y:$Y,$A:$A,$A20,$B:$B,"GWE")-SUMIFS($X:$X,$A:$A,$A20,$B:$B,"GWE"),IF($AI20="Water",SUMIFS($AA:$AA,$A:$A,$A20,$B:$B,"GWE")-SUMIFS($Z:$Z,$A:$A,$A20,$B:$B,"GWE"),""))),"") -> 12 | AM20: 0.0923 | AN20: =IF(AND(AL20<>"",AM20<>""),AL20*AM20,"") -> 1.1076 | AO20: 0.09 | AP20: =IF(AND(AN20<>"",AO20<>""),AN20*AO20,"") -> 0.099684 | AQ20: =IF(AND(AN20<>"",AP20<>""),AN20+AP20,"") -> 1.207284
A21: Van Maanenstraat 14A | B21: Schade | C21: Focuzop-eu | D21: =IF(A21="","",VLOOKUP(A21,Lists!$A:$B,2,FALSE)) -> 0089 | E21: =IF(C21="","",VLOOKUP(C21,Lists!$C:$D,2,FALSE)) -> 50448 | J21: =IF(A21="","",IFERROR(VLOOKUP(A21,Lists!$A:$H,8,FALSE),0)) -> 1650 | L21: =IF(A21="","",IFERROR(VLOOKUP(A21,Lists!$A:$H,7,FALSE),0)) -> 120 | M21: 0.21 | N21: =L21 * (1 + M21) -> 145.2 | O21: =IF(K21="Eigen Beheer",0,IF(AND(ISNUMBER(N21),I21<>"",H21<>""),YEARFRAC(H21,I21,4)*12*N21,0)) -> 0 | R21: =IF(Q21="","",VLOOKUP(Q21,Lists!$E:$F,2,FALSE)) | AD21: 50 | AE21: =IF(AB21="","",IF(ISNUMBER(SEARCH("Basis",AB21)),(250/1.21)+MAX(0,AC21-5)*AD21,IF(ISNUMBER(SEARCH("Intensief",AB21)),(375/1.21)+MAX(0,AC21-7)*AD21,AC21*AD21))) | AF21: 0.21 | AG21: =IF(AE21<>"",AE21*AF21,"") | AH21: =IF(AE21<>"",AE21+AG21,"") | AL21: =IF($B21="GWE_Item",IF($AI21="Elektra",SUMIFS($W:$W,$A:$A,$A21,$B:$B,"GWE")-SUMIFS($V:$V,$A:$A,$A21,$B:$B,"GWE"),IF($AI21="Gas",SUMIFS($Y:$Y,$A:$A,$A21,$B:$B,"GWE")-SUMIFS($X:$X,$A:$A,$A21,$B:$B,"GWE"),IF($AI21="Water",SUMIFS($AA:$AA,$A:$A,$A21,$B:$B,"GWE")-SUMIFS($Z:$Z,$A:$A,$A21,$B:$B,"GWE"),""))),"") | AN21: =IF(AND(AL21<>"",AM21<>""),AL21*AM21,"") | AP21: =IF(AND(AN21<>"",AO21<>""),AN21*AO21,"") | AQ21: =IF(AND(AN21<>"",AP21<>""),AN21+AP21,"")
A22: Van Maanenstraat 14A | B22: Schade | C22: Focuzop-eu | D22: =IF(A22="","",VLOOKUP(A22,Lists!$A:$B,2,FALSE)) -> 0089 | E22: =IF(C22="","",VLOOKUP(C22,Lists!$C:$D,2,FALSE)) -> 50448 | J22: =IF(A22="","",IFERROR(VLOOKUP(A22,Lists!$A:$H,8,FALSE),0)) -> 1650 | L22: =IF(A22="","",IFERROR(VLOOKUP(A22,Lists!$A:$H,7,FALSE),0)) -> 120 | M22: 0.21 | N22: =L22 * (1 + M22) -> 145.2 | O22: =IF(K22="Eigen Beheer",0,IF(AND(ISNUMBER(N22),I22<>"",H22<>""),YEARFRAC(H22,I22,4)*12*N22,0)) -> 0 | R22: =IF(Q22="","",VLOOKUP(Q22,Lists!$E:$F,2,FALSE)) | AD22: 50 | AE22: =IF(AB22="","",IF(ISNUMBER(SEARCH("Basis",AB22)),(250/1.21)+MAX(0,AC22-5)*AD22,IF(ISNUMBER(SEARCH("Intensief",AB22)),(375/1.21)+MAX(0,AC22-7)*AD22,AC22*AD22))) | AF22: 0.21 | AG22: =IF(AE22<>"",AE22*AF22,"") | AH22: =IF(AE22<>"",AE22+AG22,"") | AL22: =IF($B22="GWE_Item",IF($AI22="Elektra",SUMIFS($W:$W,$A:$A,$A22,$B:$B,"GWE")-SUMIFS($V:$V,$A:$A,$A22,$B:$B,"GWE"),IF($AI22="Gas",SUMIFS($Y:$Y,$A:$A,$A22,$B:$B,"GWE")-SUMIFS($X:$X,$A:$A,$A22,$B:$B,"GWE"),IF($AI22="Water",SUMIFS($AA:$AA,$A:$A,$A22,$B:$B,"GWE")-SUMIFS($Z:$Z,$A:$A,$A22,$B:$B,"GWE"),""))),"") | AN22: =IF(AND(AL22<>"",AM22<>""),AL22*AM22,"") | AP22: =IF(AND(AN22<>"",AO22<>""),AN22*AO22,"") | AQ22: =IF(AND(AN22<>"",AP22<>""),AN22+AP22,"")
A23: Van Maanenstraat 14A | B23: Schade | C23: Focuzop-eu | D23: =IF(A23="","",VLOOKUP(A23,Lists!$A:$B,2,FALSE)) -> 0089 | E23: =IF(C23="","",VLOOKUP(C23,Lists!$C:$D,2,FALSE)) -> 50448 | J23: =IF(A23="","",IFERROR(VLOOKUP(A23,Lists!$A:$H,8,FALSE),0)) -> 1650 | L23: =IF(A23="","",IFERROR(VLOOKUP(A23,Lists!$A:$H,7,FALSE),0)) -> 120 | M23: 0.21 | N23: =L23 * (1 + M23) -> 145.2 | O23: =IF(K23="Eigen Beheer",0,IF(AND(ISNUMBER(N23),I23<>"",H23<>""),YEARFRAC(H23,I23,4)*12*N23,0)) -> 0 | R23: =IF(Q23="","",VLOOKUP(Q23,Lists!$E:$F,2,FALSE)) | AD23: 50 | AE23: =IF(AB23="","",IF(ISNUMBER(SEARCH("Basis",AB23)),(250/1.21)+MAX(0,AC23-5)*AD23,IF(ISNUMBER(SEARCH("Intensief",AB23)),(375/1.21)+MAX(0,AC23-7)*AD23,AC23*AD23))) | AF23: 0.21 | AG23: =IF(AE23<>"",AE23*AF23,"") | AH23: =IF(AE23<>"",AE23+AG23,"") | AL23: =IF($B23="GWE_Item",IF($AI23="Elektra",SUMIFS($W:$W,$A:$A,$A23,$B:$B,"GWE")-SUMIFS($V:$V,$A:$A,$A23,$B:$B,"GWE"),IF($AI23="Gas",SUMIFS($Y:$Y,$A:$A,$A23,$B:$B,"GWE")-SUMIFS($X:$X,$A:$A,$A23,$B:$B,"GWE"),IF($AI23="Water",SUMIFS($AA:$AA,$A:$A,$A23,$B:$B,"GWE")-SUMIFS($Z:$Z,$A:$A,$A23,$B:$B,"GWE"),""))),"") | AN23: =IF(AND(AL23<>"",AM23<>""),AL23*AM23,"") | AP23: =IF(AND(AN23<>"",AO23<>""),AN23*AO23,"") | AQ23: =IF(AND(AN23<>"",AP23<>""),AN23+AP23,"")
A24: Van Maanenstraat 14A | B24: Schade | C24: Focuzop-eu | D24: =IF(A24="","",VLOOKUP(A24,Lists!$A:$B,2,FALSE)) -> 0089 | E24: =IF(C24="","",VLOOKUP(C24,Lists!$C:$D,2,FALSE)) -> 50448 | J24: =IF(A24="","",IFERROR(VLOOKUP(A24,Lists!$A:$H,8,FALSE),0)) -> 1650 | L24: =IF(A24="","",IFERROR(VLOOKUP(A24,Lists!$A:$H,7,FALSE),0)) -> 120 | M24: 0.21 | N24: =L24 * (1 + M24) -> 145.2 | O24: =IF(K24="Eigen Beheer",0,IF(AND(ISNUMBER(N24),I24<>"",H24<>""),YEARFRAC(H24,I24,4)*12*N24,0)) -> 0 | R24: =IF(Q24="","",VLOOKUP(Q24,Lists!$E:$F,2,FALSE)) | AD24: 50 | AE24: =IF(AB24="","",IF(ISNUMBER(SEARCH("Basis",AB24)),(250/1.21)+MAX(0,AC24-5)*AD24,IF(ISNUMBER(SEARCH("Intensief",AB24)),(375/1.21)+MAX(0,AC24-7)*AD24,AC24*AD24))) | AF24: 0.21 | AG24: =IF(AE24<>"",AE24*AF24,"") | AH24: =IF(AE24<>"",AE24+AG24,"") | AL24: =IF($B24="GWE_Item",IF($AI24="Elektra",SUMIFS($W:$W,$A:$A,$A24,$B:$B,"GWE")-SUMIFS($V:$V,$A:$A,$A24,$B:$B,"GWE"),IF($AI24="Gas",SUMIFS($Y:$Y,$A:$A,$A24,$B:$B,"GWE")-SUMIFS($X:$X,$A:$A,$A24,$B:$B,"GWE"),IF($AI24="Water",SUMIFS($AA:$AA,$A:$A,$A24,$B:$B,"GWE")-SUMIFS($Z:$Z,$A:$A,$A24,$B:$B,"GWE"),""))),"") | AN24: =IF(AND(AL24<>"",AM24<>""),AL24*AM24,"") | AP24: =IF(AND(AN24<>"",AO24<>""),AN24*AO24,"") | AQ24: =IF(AND(AN24<>"",AP24<>""),AN24+AP24,"")
A25: Kerkwerversingel 127 | B25: Basis | C25: Light Personeelsdiensten BV | D25: =IF(A25="","",VLOOKUP(A25,Lists!$A:$B,2,FALSE)) -> 0225 | E25: =IF(C25="","",VLOOKUP(C25,Lists!$C:$D,2,FALSE)) -> 100155 | H25: 45642 | I25: 46007 | J25: =IF(A25="","",IFERROR(VLOOKUP(A25,Lists!$A:$H,8,FALSE),0)) -> 4164 | K25: Via RyanRent | L25: =IF(A25="","",IFERROR(VLOOKUP(A25,Lists!$A:$H,7,FALSE),0)) -> 200 | M25: 0.21 | N25: =L25 * (1 + M25) -> 242 | O25: =IF(K25="Eigen Beheer",0,IF(AND(ISNUMBER(N25),I25<>"",H25<>""),YEARFRAC(H25,I25,4)*12*N25,0)) -> 2904 | P25: Enexis | Q25: vattenfall | R25: =IF(Q25="","",VLOOKUP(Q25,Lists!$E:$F,2,FALSE)) -> 2 | AD25: 50 | AE25: =IF(AB25="","",IF(ISNUMBER(SEARCH("Basis",AB25)),(250/1.21)+MAX(0,AC25-5)*AD25,IF(ISNUMBER(SEARCH("Intensief",AB25)),(375/1.21)+MAX(0,AC25-7)*AD25,AC25*AD25))) | AF25: 0.21 | AG25: =IF(AE25<>"",AE25*AF25,"") | AH25: =IF(AE25<>"",AE25+AG25,"") | AL25: =IF($B25="GWE_Item",IF($AI25="Elektra",SUMIFS($W:$W,$A:$A,$A25,$B:$B,"GWE")-SUMIFS($V:$V,$A:$A,$A25,$B:$B,"GWE"),IF($AI25="Gas",SUMIFS($Y:$Y,$A:$A,$A25,$B:$B,"GWE")-SUMIFS($X:$X,$A:$A,$A25,$B:$B,"GWE"),IF($AI25="Water",SUMIFS($AA:$AA,$A:$A,$A25,$B:$B,"GWE")-SUMIFS($Z:$Z,$A:$A,$A25,$B:$B,"GWE"),""))),"") | AN25: =IF(AND(AL25<>"",AM25<>""),AL25*AM25,"") | AP25: =IF(AND(AN25<>"",AO25<>""),AN25*AO25,"") | AQ25: =IF(AND(AN25<>"",AP25<>""),AN25+AP25,"")
A26: Kerkwerversingel 127 | B26: GWE | C26: Light Personeelsdiensten BV | D26: =IF(A26="","",VLOOKUP(A26,Lists!$A:$B,2,FALSE)) -> 0225 | E26: =IF(C26="","",VLOOKUP(C26,Lists!$C:$D,2,FALSE)) -> 100155 | J26: =IF(A26="","",IFERROR(VLOOKUP(A26,Lists!$A:$H,8,FALSE),0)) -> 4164 | L26: =IF(A26="","",IFERROR(VLOOKUP(A26,Lists!$A:$H,7,FALSE),0)) -> 200 | M26: 0.21 | N26: =L26 * (1 + M26) -> 242 | O26: =IF(K26="Eigen Beheer",0,IF(AND(ISNUMBER(N26),I26<>"",H26<>""),YEARFRAC(H26,I26,4)*12*N26,0)) -> 0 | R26: =IF(Q26="","",VLOOKUP(Q26,Lists!$E:$F,2,FALSE)) | Z26: 1483 | AA26: 1541 | AD26: 50 | AE26: =IF(AB26="","",IF(ISNUMBER(SEARCH("Basis",AB26)),(250/1.21)+MAX(0,AC26-5)*AD26,IF(ISNUMBER(SEARCH("Intensief",AB26)),(375/1.21)+MAX(0,AC26-7)*AD26,AC26*AD26))) | AF26: 0.21 | AG26: =IF(AE26<>"",AE26*AF26,"") | AH26: =IF(AE26<>"",AE26+AG26,"") | AL26: =IF($B26="GWE_Item",IF($AI26="Elektra",SUMIFS($W:$W,$A:$A,$A26,$B:$B,"GWE")-SUMIFS($V:$V,$A:$A,$A26,$B:$B,"GWE"),IF($AI26="Gas",SUMIFS($Y:$Y,$A:$A,$A26,$B:$B,"GWE")-SUMIFS($X:$X,$A:$A,$A26,$B:$B,"GWE"),IF($AI26="Water",SUMIFS($AA:$AA,$A:$A,$A26,$B:$B,"GWE")-SUMIFS($Z:$Z,$A:$A,$A26,$B:$B,"GWE"),""))),"") | AN26: =IF(AND(AL26<>"",AM26<>""),AL26*AM26,"") | AP26: =IF(AND(AN26<>"",AO26<>""),AN26*AO26,"") | AQ26: =IF(AND(AN26<>"",AP26<>""),AN26+AP26,"")
A27: Kerkwerversingel 127 | B27: GWE_Item | C27: Light Personeelsdiensten BV | D27: =IF(A27="","",VLOOKUP(A27,Lists!$A:$B,2,FALSE)) -> 0225 | E27: =IF(C27="","",VLOOKUP(C27,Lists!$C:$D,2,FALSE)) -> 100155 | J27: =IF(A27="","",IFERROR(VLOOKUP(A27,Lists!$A:$H,8,FALSE),0)) -> 4164 | L27: =IF(A27="","",IFERROR(VLOOKUP(A27,Lists!$A:$H,7,FALSE),0)) -> 200 | M27: 0.21 | N27: =L27 * (1 + M27) -> 242 | O27: =IF(K27="Eigen Beheer",0,IF(AND(ISNUMBER(N27),I27<>"",H27<>""),YEARFRAC(H27,I27,4)*12*N27,0)) -> 0 | R27: =IF(Q27="","",VLOOKUP(Q27,Lists!$E:$F,2,FALSE)) | AD27: 50 | AE27: =IF(AB27="","",IF(ISNUMBER(SEARCH("Basis",AB27)),(250/1.21)+MAX(0,AC27-5)*AD27,IF(ISNUMBER(SEARCH("Intensief",AB27)),(375/1.21)+MAX(0,AC27-7)*AD27,AC27*AD27))) | AF27: 0.21 | AG27: =IF(AE27<>"",AE27*AF27,"") | AH27: =IF(AE27<>"",AE27+AG27,"") | AI27: Water | AJ27: m3 | AK27: levering | AL27: =IF($B27="GWE_Item",IF($AI27="Elektra",SUMIFS($W:$W,$A:$A,$A27,$B:$B,"GWE")-SUMIFS($V:$V,$A:$A,$A27,$B:$B,"GWE"),IF($AI27="Gas",SUMIFS($Y:$Y,$A:$A,$A27,$B:$B,"GWE")-SUMIFS($X:$X,$A:$A,$A27,$B:$B,"GWE"),IF($AI27="Water",SUMIFS($AA:$AA,$A:$A,$A27,$B:$B,"GWE")-SUMIFS($Z:$Z,$A:$A,$A27,$B:$B,"GWE"),""))),"") -> 58 | AM27: 1.29 | AN27: =IF(AND(AL27<>"",AM27<>""),AL27*AM27,"") -> 74.82 | AO27: 0.09 | AP27: =IF(AND(AN27<>"",AO27<>""),AN27*AO27,"") -> 6.7338 | AQ27: =IF(AND(AN27<>"",AP27<>""),AN27+AP27,"") -> 81.5538
A28: Kerkwerversingel 127 | B28: GWE_Item | C28: Light Personeelsdiensten BV | D28: =IF(A28="","",VLOOKUP(A28,Lists!$A:$B,2,FALSE)) -> 0225 | E28: =IF(C28="","",VLOOKUP(C28,Lists!$C:$D,2,FALSE)) -> 100155 | J28: =IF(A28="","",IFERROR(VLOOKUP(A28,Lists!$A:$H,8,FALSE),0)) -> 4164 | L28: =IF(A28="","",IFERROR(VLOOKUP(A28,Lists!$A:$H,7,FALSE),0)) -> 200 | M28: 0.21 | N28: =L28 * (1 + M28) -> 242 | O28: =IF(K28="Eigen Beheer",0,IF(AND(ISNUMBER(N28),I28<>"",H28<>""),YEARFRAC(H28,I28,4)*12*N28,0)) -> 0 | R28: =IF(Q28="","",VLOOKUP(Q28,Lists!$E:$F,2,FALSE)) | AD28: 50 | AE28: =IF(AB28="","",IF(ISNUMBER(SEARCH("Basis",AB28)),(250/1.21)+MAX(0,AC28-5)*AD28,IF(ISNUMBER(SEARCH("Intensief",AB28)),(375/1.21)+MAX(0,AC28-7)*AD28,AC28*AD28))) | AF28: 0.21 | AG28: =IF(AE28<>"",AE28*AF28,"") | AH28: =IF(AE28<>"",AE28+AG28,"") | AI28: Water | AJ28: dag | AK28: vastrecht | AL28: 366 | AM28: 0.25474 | AN28: =IF(AND(AL28<>"",AM28<>""),AL28*AM28,"") -> 93.23484 | AO28: 0.09 | AP28: =IF(AND(AN28<>"",AO28<>""),AN28*AO28,"") -> 8.3911356 | AQ28: =IF(AND(AN28<>"",AP28<>""),AN28+AP28,"") -> 101.62598
A29: Kerkwerversingel 127 | B29: GWE_Item | C29: Light Personeelsdiensten BV | D29: =IF(A29="","",VLOOKUP(A29,Lists!$A:$B,2,FALSE)) -> 0225 | E29: =IF(C29="","",VLOOKUP(C29,Lists!$C:$D,2,FALSE)) -> 100155 | J29: =IF(A29="","",IFERROR(VLOOKUP(A29,Lists!$A:$H,8,FALSE),0)) -> 4164 | L29: =IF(A29="","",IFERROR(VLOOKUP(A29,Lists!$A:$H,7,FALSE),0)) -> 200 | M29: 0.21 | N29: =L29 * (1 + M29) -> 242 | O29: =IF(K29="Eigen Beheer",0,IF(AND(ISNUMBER(N29),I29<>"",H29<>""),YEARFRAC(H29,I29,4)*12*N29,0)) -> 0 | R29: =IF(Q29="","",VLOOKUP(Q29,Lists!$E:$F,2,FALSE)) | AD29: 50 | AE29: =IF(AB29="","",IF(ISNUMBER(SEARCH("Basis",AB29)),(250/1.21)+MAX(0,AC29-5)*AD29,IF(ISNUMBER(SEARCH("Intensief",AB29)),(375/1.21)+MAX(0,AC29-7)*AD29,AC29*AD29))) | AF29: 0.21 | AG29: =IF(AE29<>"",AE29*AF29,"") | AH29: =IF(AE29<>"",AE29+AG29,"") | AI29: Water | AJ29: m3 | AK29: Belasting op leidingwater | AL29: =IF($B29="GWE_Item",IF($AI29="Elektra",SUMIFS($W:$W,$A:$A,$A29,$B:$B,"GWE")-SUMIFS($V:$V,$A:$A,$A29,$B:$B,"GWE"),IF($AI29="Gas",SUMIFS($Y:$Y,$A:$A,$A29,$B:$B,"GWE")-SUMIFS($X:$X,$A:$A,$A29,$B:$B,"GWE"),IF($AI29="Water",SUMIFS($AA:$AA,$A:$A,$A29,$B:$B,"GWE")-SUMIFS($Z:$Z,$A:$A,$A29,$B:$B,"GWE"),""))),"") -> 58 | AM29: 0.458 | AN29: =IF(AND(AL29<>"",AM29<>""),AL29*AM29,"") -> 26.564 | AO29: 0.09 | AP29: =IF(AND(AN29<>"",AO29<>""),AN29*AO29,"") -> 2.39076 | AQ29: =IF(AND(AN29<>"",AP29<>""),AN29+AP29,"") -> 28.95476
A30: Kerkwerversingel 127 | B30: GWE_Item | C30: Light Personeelsdiensten BV | D30: =IF(A30="","",VLOOKUP(A30,Lists!$A:$B,2,FALSE)) -> 0225 | E30: =IF(C30="","",VLOOKUP(C30,Lists!$C:$D,2,FALSE)) -> 100155 | J30: =IF(A30="","",IFERROR(VLOOKUP(A30,Lists!$A:$H,8,FALSE),0)) -> 4164 | L30: =IF(A30="","",IFERROR(VLOOKUP(A30,Lists!$A:$H,7,FALSE),0)) -> 200 | M30: 0.21 | N30: =L30 * (1 + M30) -> 242 | O30: =IF(K30="Eigen Beheer",0,IF(AND(ISNUMBER(N30),I30<>"",H30<>""),YEARFRAC(H30,I30,4)*12*N30,0)) -> 0 | R30: =IF(Q30="","",VLOOKUP(Q30,Lists!$E:$F,2,FALSE)) | AD30: 50 | AE30: =IF(AB30="","",IF(ISNUMBER(SEARCH("Basis",AB30)),(250/1.21)+MAX(0,AC30-5)*AD30,IF(ISNUMBER(SEARCH("Intensief",AB30)),(375/1.21)+MAX(0,AC30-7)*AD30,AC30*AD30))) | AF30: 0.21 | AG30: =IF(AE30<>"",AE30*AF30,"") | AH30: =IF(AE30<>"",AE30+AG30,"") | AI30: Water | AJ30: m3 | AK30: Precarrioheffing | AL30: =IF($B30="GWE_Item",IF($AI30="Elektra",SUMIFS($W:$W,$A:$A,$A30,$B:$B,"GWE")-SUMIFS($V:$V,$A:$A,$A30,$B:$B,"GWE"),IF($AI30="Gas",SUMIFS($Y:$Y,$A:$A,$A30,$B:$B,"GWE")-SUMIFS($X:$X,$A:$A,$A30,$B:$B,"GWE"),IF($AI30="Water",SUMIFS($AA:$AA,$A:$A,$A30,$B:$B,"GWE")-SUMIFS($Z:$Z,$A:$A,$A30,$B:$B,"GWE"),""))),"") -> 58 | AM30: 0.0923 | AN30: =IF(AND(AL30<>"",AM30<>""),AL30*AM30,"") -> 5.3534 | AO30: 0.09 | AP30: =IF(AND(AN30<>"",AO30<>""),AN30*AO30,"") -> 0.481806 | AQ30: =IF(AND(AN30<>"",AP30<>""),AN30+AP30,"") -> 5.835206
A31: Akkerweg 41 [018] | B31: Basis | C31: Uitzendwerk B.V. | D31: =IF(A31="","",VLOOKUP(A31,Lists!$A:$B,2,FALSE)) -> 0295 | E31: =IF(C31="","",VLOOKUP(C31,Lists!$C:$D,2,FALSE)) -> 100183 | H31: 45838 | I31: 45961 | J31: 3200 | K31: Via RyanRent | L31: 400 | M31: 0.21 | N31: =L31 * (1 + M31) -> 484 | O31: =IF(K31="Eigen Beheer",0,IF(AND(ISNUMBER(N31),I31<>"",H31<>""),YEARFRAC(H31,I31,4)*12*N31,0)) -> 1936 | P31: Enexis | Q31: Vattenfall | R31: =IF(Q31="","",VLOOKUP(Q31,Lists!$E:$F,2,FALSE)) -> 2 | AD31: 50 | AE31: =IF(AB31="","",IF(ISNUMBER(SEARCH("Basis",AB31)),(250/1.21)+MAX(0,AC31-5)*AD31,IF(ISNUMBER(SEARCH("Intensief",AB31)),(375/1.21)+MAX(0,AC31-7)*AD31,AC31*AD31))) | AF31: 0.21 | AG31: =IF(AE31<>"",AE31*AF31,"") | AH31: =IF(AE31<>"",AE31+AG31,"") | AL31: =IF($B31="GWE_Item",IF($AI31="Elektra",SUMIFS($W:$W,$A:$A,$A31,$B:$B,"GWE")-SUMIFS($V:$V,$A:$A,$A31,$B:$B,"GWE"),IF($AI31="Gas",SUMIFS($Y:$Y,$A:$A,$A31,$B:$B,"GWE")-SUMIFS($X:$X,$A:$A,$A31,$B:$B,"GWE"),IF($AI31="Water",SUMIFS($AA:$AA,$A:$A,$A31,$B:$B,"GWE")-SUMIFS($Z:$Z,$A:$A,$A31,$B:$B,"GWE"),""))),"") | AN31: =IF(AND(AL31<>"",AM31<>""),AL31*AM31,"") | AP31: =IF(AND(AN31<>"",AO31<>""),AN31*AO31,"") | AQ31: =IF(AND(AN31<>"",AP31<>""),AN31+AP31,"")
A32: Akkerweg 41 [018] | B32: GWE | C32: Uitzendwerk B.V. | D32: =IF(A32="","",VLOOKUP(A32,Lists!$A:$B,2,FALSE)) -> 0295 | E32: =IF(C32="","",VLOOKUP(C32,Lists!$C:$D,2,FALSE)) -> 100183 | J32: 3200 | L32: 400 | M32: 0.21 | N32: =L32 * (1 + M32) -> 484 | O32: =IF(K32="Eigen Beheer",0,IF(AND(ISNUMBER(N32),I32<>"",H32<>""),YEARFRAC(H32,I32,4)*12*N32,0)) -> 0 | R32: =IF(Q32="","",VLOOKUP(Q32,Lists!$E:$F,2,FALSE)) | V32: 12552 | W32: 14399 | Z32: 326 | AA32: 380 | AD32: 50 | AE32: =IF(AB32="","",IF(ISNUMBER(SEARCH("Basis",AB32)),(250/1.21)+MAX(0,AC32-5)*AD32,IF(ISNUMBER(SEARCH("Intensief",AB32)),(375/1.21)+MAX(0,AC32-7)*AD32,AC32*AD32))) | AF32: 0.21 | AG32: =IF(AE32<>"",AE32*AF32,"") | AH32: =IF(AE32<>"",AE32+AG32,"") | AL32: =IF($B32="GWE_Item",IF($AI32="Elektra",SUMIFS($W:$W,$A:$A,$A32,$B:$B,"GWE")-SUMIFS($V:$V,$A:$A,$A32,$B:$B,"GWE"),IF($AI32="Gas",SUMIFS($Y:$Y,$A:$A,$A32,$B:$B,"GWE")-SUMIFS($X:$X,$A:$A,$A32,$B:$B,"GWE"),IF($AI32="Water",SUMIFS($AA:$AA,$A:$A,$A32,$B:$B,"GWE")-SUMIFS($Z:$Z,$A:$A,$A32,$B:$B,"GWE"),""))),"") | AN32: =IF(AND(AL32<>"",AM32<>""),AL32*AM32,"") | AP32: =IF(AND(AN32<>"",AO32<>""),AN32*AO32,"") | AQ32: =IF(AND(AN32<>"",AP32<>""),AN32+AP32,"")
A33: Akkerweg 41 [018] | B33: Schoonmaak | C33: Uitzendwerk B.V. | D33: =IF(A33="","",VLOOKUP(A33,Lists!$A:$B,2,FALSE)) -> 0295 | E33: =IF(C33="","",VLOOKUP(C33,Lists!$C:$D,2,FALSE)) -> 100183 | J33: 3200 | L33: 400 | M33: 0.21 | N33: =L33 * (1 + M33) -> 484 | O33: =IF(K33="Eigen Beheer",0,IF(AND(ISNUMBER(N33),I33<>"",H33<>""),YEARFRAC(H33,I33,4)*12*N33,0)) -> 0 | R33: =IF(Q33="","",VLOOKUP(Q33,Lists!$E:$F,2,FALSE)) | AB33: Achteraf Betaald | AC33: 6 | AD33: 50 | AE33: =IF(AB33="","",IF(ISNUMBER(SEARCH("Basis",AB33)),(250/1.21)+MAX(0,AC33-5)*AD33,IF(ISNUMBER(SEARCH("Intensief",AB33)),(375/1.21)+MAX(0,AC33-7)*AD33,AC33*AD33))) -> 300 | AF33: 0.21 | AG33: =IF(AE33<>"",AE33*AF33,"") -> 63 | AH33: =IF(AE33<>"",AE33+AG33,"") -> 363 | AL33: =IF($B33="GWE_Item",IF($AI33="Elektra",SUMIFS($W:$W,$A:$A,$A33,$B:$B,"GWE")-SUMIFS($V:$V,$A:$A,$A33,$B:$B,"GWE"),IF($AI33="Gas",SUMIFS($Y:$Y,$A:$A,$A33,$B:$B,"GWE")-SUMIFS($X:$X,$A:$A,$A33,$B:$B,"GWE"),IF($AI33="Water",SUMIFS($AA:$AA,$A:$A,$A33,$B:$B,"GWE")-SUMIFS($Z:$Z,$A:$A,$A33,$B:$B,"GWE"),""))),"") | AN33: =IF(AND(AL33<>"",AM33<>""),AL33*AM33,"") | AP33: =IF(AND(AN33<>"",AO33<>""),AN33*AO33,"") | AQ33: =IF(AND(AN33<>"",AP33<>""),AN33+AP33,"")
A34: Akkerweg 41 [018] | B34: Schade | C34: Uitzendwerk B.V. | D34: =IF(A34="","",VLOOKUP(A34,Lists!$A:$B,2,FALSE)) -> 0295 | E34: =IF(C34="","",VLOOKUP(C34,Lists!$C:$D,2,FALSE)) -> 100183 | J34: 3200 | L34: 400 | M34: 0.21 | N34: =L34 * (1 + M34) -> 484 | O34: =IF(K34="Eigen Beheer",0,IF(AND(ISNUMBER(N34),I34<>"",H34<>""),YEARFRAC(H34,I34,4)*12*N34,0)) -> 0 | R34: =IF(Q34="","",VLOOKUP(Q34,Lists!$E:$F,2,FALSE)) | AD34: 50 | AE34: =IF(AB34="","",IF(ISNUMBER(SEARCH("Basis",AB34)),(250/1.21)+MAX(0,AC34-5)*AD34,IF(ISNUMBER(SEARCH("Intensief",AB34)),(375/1.21)+MAX(0,AC34-7)*AD34,AC34*AD34))) | AF34: 0.21 | AG34: =IF(AE34<>"",AE34*AF34,"") | AH34: =IF(AE34<>"",AE34+AG34,"") | AI34: Overig | AK34: Inventaris | AL34: 1 | AM34: =AN34/AL34 -> 455.18 | AN34: 455.18 | AO34: 0.21 | AP34: =IF(AND(AN34<>"",AO34<>""),AN34*AO34,"") -> 95.5878 | AQ34: =IF(AND(AN34<>"",AP34<>""),AN34+AP34,"") -> 550.7678
A35: Akkerweg 41 [018] | B35: Schade | C35: Uitzendwerk B.V. | D35: =IF(A35="","",VLOOKUP(A35,Lists!$A:$B,2,FALSE)) -> 0295 | E35: =IF(C35="","",VLOOKUP(C35,Lists!$C:$D,2,FALSE)) -> 100183 | J35: 3200 | L35: 400 | M35: 0.21 | N35: =L35 * (1 + M35) -> 484 | O35: =IF(K35="Eigen Beheer",0,IF(AND(ISNUMBER(N35),I35<>"",H35<>""),YEARFRAC(H35,I35,4)*12*N35,0)) -> 0 | R35: =IF(Q35="","",VLOOKUP(Q35,Lists!$E:$F,2,FALSE)) | AD35: 50 | AE35: =IF(AB35="","",IF(ISNUMBER(SEARCH("Basis",AB35)),(250/1.21)+MAX(0,AC35-5)*AD35,IF(ISNUMBER(SEARCH("Intensief",AB35)),(375/1.21)+MAX(0,AC35-7)*AD35,AC35*AD35))) | AF35: 0.21 | AG35: =IF(AE35<>"",AE35*AF35,"") | AH35: =IF(AE35<>"",AE35+AG35,"") | AI35: Overig | AK35: Ramen Decoratie | AL35: 2 | AM35: =AN35/AL35 -> 383.5 | AN35: 767 | AO35: 0.21 | AP35: =IF(AND(AN35<>"",AO35<>""),AN35*AO35,"") -> 161.07 | AQ35: =IF(AND(AN35<>"",AP35<>""),AN35+AP35,"") -> 928.07
A36: Akkerweg 41 [018] | B36: GWE_Item | C36: Uitzendwerk B.V. | D36: =IF(A36="","",VLOOKUP(A36,Lists!$A:$B,2,FALSE)) -> 0295 | E36: =IF(C36="","",VLOOKUP(C36,Lists!$C:$D,2,FALSE)) -> 100183 | J36: 3200 | L36: 400 | M36: 0.21 | N36: =L36 * (1 + M36) -> 484 | O36: =IF(K36="Eigen Beheer",0,IF(AND(ISNUMBER(N36),I36<>"",H36<>""),YEARFRAC(H36,I36,4)*12*N36,0)) -> 0 | R36: =IF(Q36="","",VLOOKUP(Q36,Lists!$E:$F,2,FALSE)) | AD36: 50 | AE36: =IF(AB36="","",IF(ISNUMBER(SEARCH("Basis",AB36)),(250/1.21)+MAX(0,AC36-5)*AD36,IF(ISNUMBER(SEARCH("Intensief",AB36)),(375/1.21)+MAX(0,AC36-7)*AD36,AC36*AD36))) | AF36: 0.21 | AG36: =IF(AE36<>"",AE36*AF36,"") | AH36: =IF(AE36<>"",AE36+AG36,"") | AI36: Overig | AK36: Elektra +Water | AL36: =IF($B36="GWE_Item",IF($AI36="Elektra",SUMIFS($W:$W,$A:$A,$A36,$B:$B,"GWE")-SUMIFS($V:$V,$A:$A,$A36,$B:$B,"GWE"),IF($AI36="Gas",SUMIFS($Y:$Y,$A:$A,$A36,$B:$B,"GWE")-SUMIFS($X:$X,$A:$A,$A36,$B:$B,"GWE"),IF($AI36="Water",SUMIFS($AA:$AA,$A:$A,$A36,$B:$B,"GWE")-SUMIFS($Z:$Z,$A:$A,$A36,$B:$B,"GWE"),""))),"") | AN36: 899.65 | AO36: 0.21 | AP36: =IF(AND(AN36<>"",AO36<>""),AN36*AO36,"") -> 188.9265 | AQ36: =IF(AND(AN36<>"",AP36<>""),AN36+AP36,"") -> 1088.5765
D37: =IF(A37="","",VLOOKUP(A37,Lists!$A:$B,2,FALSE)) | E37: =IF(C37="","",VLOOKUP(C37,Lists!$C:$D,2,FALSE)) | J37: =IF(A37="","",IFERROR(VLOOKUP(A37,Lists!$A:$H,8,FALSE),0)) | L37: =IF(A37="","",IFERROR(VLOOKUP(A37,Lists!$A:$H,7,FALSE),0)) | M37: 0.21 | N37: =L37 * (1 + M37) -> #VALUE! | O37: =IF(K37="Eigen Beheer",0,IF(AND(ISNUMBER(N37),I37<>"",H37<>""),YEARFRAC(H37,I37,4)*12*N37,0)) -> 0 | R37: =IF(Q37="","",VLOOKUP(Q37,Lists!$E:$F,2,FALSE)) | AD37: 50 | AE37: =IF(AB37="","",IF(ISNUMBER(SEARCH("Basis",AB37)),(250/1.21)+MAX(0,AC37-5)*AD37,IF(ISNUMBER(SEARCH("Intensief",AB37)),(375/1.21)+MAX(0,AC37-7)*AD37,AC37*AD37))) | AF37: 0.21 | AG37: =IF(AE37<>"",AE37*AF37,"") | AH37: =IF(AE37<>"",AE37+AG37,"") | AL37: =IF($B37="GWE_Item",IF($AI37="Elektra",SUMIFS($W:$W,$A:$A,$A37,$B:$B,"GWE")-SUMIFS($V:$V,$A:$A,$A37,$B:$B,"GWE"),IF($AI37="Gas",SUMIFS($Y:$Y,$A:$A,$A37,$B:$B,"GWE")-SUMIFS($X:$X,$A:$A,$A37,$B:$B,"GWE"),IF($AI37="Water",SUMIFS($AA:$AA,$A:$A,$A37,$B:$B,"GWE")-SUMIFS($Z:$Z,$A:$A,$A37,$B:$B,"GWE"),""))),"") | AN37: =IF(AND(AL37<>"",AM37<>""),AL37*AM37,"") | AP37: =IF(AND(AN37<>"",AO37<>""),AN37*AO37,"") | AQ37: =IF(AND(AN37<>"",AP37<>""),AN37+AP37,"")
D38: =IF(A38="","",VLOOKUP(A38,Lists!$A:$B,2,FALSE)) | E38: =IF(C38="","",VLOOKUP(C38,Lists!$C:$D,2,FALSE)) | J38: =IF(A38="","",IFERROR(VLOOKUP(A38,Lists!$A:$H,8,FALSE),0)) | L38: =IF(A38="","",IFERROR(VLOOKUP(A38,Lists!$A:$H,7,FALSE),0)) | M38: 0.21 | N38: =L38 * (1 + M38) -> #VALUE! | O38: =IF(K38="Eigen Beheer",0,IF(AND(ISNUMBER(N38),I38<>"",H38<>""),YEARFRAC(H38,I38,4)*12*N38,0)) -> 0 | R38: =IF(Q38="","",VLOOKUP(Q38,Lists!$E:$F,2,FALSE)) | AD38: 50 | AE38: =IF(AB38="","",IF(ISNUMBER(SEARCH("Basis",AB38)),(250/1.21)+MAX(0,AC38-5)*AD38,IF(ISNUMBER(SEARCH("Intensief",AB38)),(375/1.21)+MAX(0,AC38-7)*AD38,AC38*AD38))) | AF38: 0.21 | AG38: =IF(AE38<>"",AE38*AF38,"") | AH38: =IF(AE38<>"",AE38+AG38,"") | AL38: =IF($B38="GWE_Item",IF($AI38="Elektra",SUMIFS($W:$W,$A:$A,$A38,$B:$B,"GWE")-SUMIFS($V:$V,$A:$A,$A38,$B:$B,"GWE"),IF($AI38="Gas",SUMIFS($Y:$Y,$A:$A,$A38,$B:$B,"GWE")-SUMIFS($X:$X,$A:$A,$A38,$B:$B,"GWE"),IF($AI38="Water",SUMIFS($AA:$AA,$A:$A,$A38,$B:$B,"GWE")-SUMIFS($Z:$Z,$A:$A,$A38,$B:$B,"GWE"),""))),"") | AN38: =IF(AND(AL38<>"",AM38<>""),AL38*AM38,"") | AP38: =IF(AND(AN38<>"",AO38<>""),AN38*AO38,"") | AQ38: =IF(AND(AN38<>"",AP38<>""),AN38+AP38,"")
D39: =IF(A39="","",VLOOKUP(A39,Lists!$A:$B,2,FALSE)) | E39: =IF(C39="","",VLOOKUP(C39,Lists!$C:$D,2,FALSE)) | J39: =IF(A39="","",IFERROR(VLOOKUP(A39,Lists!$A:$H,8,FALSE),0)) | L39: =IF(A39="","",IFERROR(VLOOKUP(A39,Lists!$A:$H,7,FALSE),0)) | M39: 0.21 | N39: =L39 * (1 + M39) -> #VALUE! | O39: =IF(K39="Eigen Beheer",0,IF(AND(ISNUMBER(N39),I39<>"",H39<>""),YEARFRAC(H39,I39,4)*12*N39,0)) -> 0 | R39: =IF(Q39="","",VLOOKUP(Q39,Lists!$E:$F,2,FALSE)) | AD39: 50 | AE39: =IF(AB39="","",IF(ISNUMBER(SEARCH("Basis",AB39)),(250/1.21)+MAX(0,AC39-5)*AD39,IF(ISNUMBER(SEARCH("Intensief",AB39)),(375/1.21)+MAX(0,AC39-7)*AD39,AC39*AD39))) | AF39: 0.21 | AG39: =IF(AE39<>"",AE39*AF39,"") | AH39: =IF(AE39<>"",AE39+AG39,"") | AL39: =IF($B39="GWE_Item",IF($AI39="Elektra",SUMIFS($W:$W,$A:$A,$A39,$B:$B,"GWE")-SUMIFS($V:$V,$A:$A,$A39,$B:$B,"GWE"),IF($AI39="Gas",SUMIFS($Y:$Y,$A:$A,$A39,$B:$B,"GWE")-SUMIFS($X:$X,$A:$A,$A39,$B:$B,"GWE"),IF($AI39="Water",SUMIFS($AA:$AA,$A:$A,$A39,$B:$B,"GWE")-SUMIFS($Z:$Z,$A:$A,$A39,$B:$B,"GWE"),""))),"") | AN39: =IF(AND(AL39<>"",AM39<>""),AL39*AM39,"") | AP39: =IF(AND(AN39<>"",AO39<>""),AN39*AO39,"") | AQ39: =IF(AND(AN39<>"",AP39<>""),AN39+AP39,"")
D40: =IF(A40="","",VLOOKUP(A40,Lists!$A:$B,2,FALSE)) | E40: =IF(C40="","",VLOOKUP(C40,Lists!$C:$D,2,FALSE)) | J40: =IF(A40="","",IFERROR(VLOOKUP(A40,Lists!$A:$H,8,FALSE),0)) | L40: =IF(A40="","",IFERROR(VLOOKUP(A40,Lists!$A:$H,7,FALSE),0)) | M40: 0.21 | N40: =L40 * (1 + M40) -> #VALUE! | O40: =IF(K40="Eigen Beheer",0,IF(AND(ISNUMBER(N40),I40<>"",H40<>""),YEARFRAC(H40,I40,4)*12*N40,0)) -> 0 | R40: =IF(Q40="","",VLOOKUP(Q40,Lists!$E:$F,2,FALSE)) | AD40: 50 | AE40: =IF(AB40="","",IF(ISNUMBER(SEARCH("Basis",AB40)),(250/1.21)+MAX(0,AC40-5)*AD40,IF(ISNUMBER(SEARCH("Intensief",AB40)),(375/1.21)+MAX(0,AC40-7)*AD40,AC40*AD40))) | AF40: 0.21 | AG40: =IF(AE40<>"",AE40*AF40,"") | AH40: =IF(AE40<>"",AE40+AG40,"") | AL40: =IF($B40="GWE_Item",IF($AI40="Elektra",SUMIFS($W:$W,$A:$A,$A40,$B:$B,"GWE")-SUMIFS($V:$V,$A:$A,$A40,$B:$B,"GWE"),IF($AI40="Gas",SUMIFS($Y:$Y,$A:$A,$A40,$B:$B,"GWE")-SUMIFS($X:$X,$A:$A,$A40,$B:$B,"GWE"),IF($AI40="Water",SUMIFS($AA:$AA,$A:$A,$A40,$B:$B,"GWE")-SUMIFS($Z:$Z,$A:$A,$A40,$B:$B,"GWE"),""))),"") | AN40: =IF(AND(AL40<>"",AM40<>""),AL40*AM40,"") | AP40: =IF(AND(AN40<>"",AO40<>""),AN40*AO40,"") | AQ40: =IF(AND(AN40<>"",AP40<>""),AN40+AP40,"")
...

Sheet Lists
A1: Address | B1: Object ID | C1: Clients (Name) | D1: Clients (ID) | E1: Leveranciers (Name) | F1: Leveranciers (ID) | G1: GWE Voorschot (Default) | H1: Borg (Default) | I1: Meterbeheerder | K1: GWE Beheer | M1: Schoonmaak Pakket | O1: Kosten Type
A2: 1e Middellandstraat 104A | B2: 0388 | C2: 't Werkt B.V. | D2: 50223 | E2: C. van Winsen | F2: 98 | G2: 200 | H2: 0 | I2: Stedin | K2: Via RyanRent | M2: Basis Schoonmaak | O2: Elektra
A3: 2e Maasbosstraat 2 a | B3: 0148 | C3: 24/7 drive | D3: 50224 | E3: 4 Homes | F3: 82 | G3: 0 | H3: 0 | I3: Liander | K3: Eigen Beheer | M3: Intensief Schoonmaak | O3: Gas
A4: 2e Maasbosstraat 2 b | B4: 0149 | C4: 4 Homes B.V. | D4: 94 | E4: A. Brouwers & S. Brouwers- van Weert | F4: 95 | G4: 0 | H4: 3300 | I4: Enexis | M4: Geen Schoonmaak | O4: Water
A5: 2e Maasbosstraat 2 c | B5: 0150 | C5: 4 Homes B.V. | D5: 100151 | E5: A. Ghali | F5: 81 | G5: 0 | H5: 2550 | I5: Westland Infra | M5: Achteraf Betaald | O5: Overig
A6: 2e van Leydengaelstraat 6 | B6: 0022 | C6: A. Blaszcak | D6: 50146 | E6: A.H.S. Willemsen | F6: 28 | G6: 0 | H6: 2271.76 | M6: Op Maat
A7: Abelenlaan 143 | B7: 0014 | C7: A. Brouwers en S. Brouwers- van Weert | D7: 50405 | E7: A.P.W. Koedooder | F7: 24 | G7: 0 | H7: 1940
A8: Acacia 2 | B8: 0003 | C8: A. Dzaka | D8: 74 | E8: Aannemer Bouwman | F8: 6 | G8: 0 | H8: 2022.35
A9: Acacialaan 9 | B9: 0223 | C9: A. Ghali | D9: 50142 | E9: B. Bakker | F9: 46 | G9: 0 | H9: 2300
A10: Achterdijk 47A | B10: 0190 | C10: A. Verschueren | D10: 72 | E10: B. Bosch | F10: 85 | G10: 500 | H10: 2255
A11: Adriaan Baasstraat 34 | B11: 0007 | C11: A.H.S. Willemsen | D11: 100098 | E11: B. Verstegen & K. Maas | F11: 94 | G11: 250 | H11: 2594.12
A12: Akkerweg 41 [010] | B12: 0341 | C12: A.I.G. Lukkien | D12: 50189 | E12: B. van Abeelen | F12: 52 | G12: 0 | H12: 0
A13: Akkerweg 41 [011] | B13: 0372 | C13: A.P.W. Koedooder | D13: 86 | E13: Bart Vlastuin | F13: 45 | G13: 350 | H13: 0
A14: Akkerweg 41 [014] | B14: 0293 | C14: A.W.N. Alkemade | D14: 44 | E14: Beking | F14: 18 | G14: 400 | H14: 0
A15: Akkerweg 41 [015] | B15: 0294 | C15: A.Y. Nicolai | D15: 64 | E15: Business Housing | F15: 83 | G15: 300 | H15: 0
A16: Akkerweg 41 [016] | B16: 0342 | C16: ABC Bedrijfsservice B.V | D16: 50353 | E16: C. van Driel e/o B.M. Verdouw | F16: 115 | G16: 0 | H16: 0
A17: Akkerweg 41 [017] | B17: 0373 | C17: AKRION ADMINISTRATION | D17: 50332 | E17: C.R. Valk & H.J. Valk | F17: 80 | G17: 300 | H17: 0
A18: Akkerweg 41 [018] | B18: 0295 | C18: AKT Autoschade | D18: 50315 | E18: CB-Homes | F18: 91 | G18: 0 | H18: 0
... A125: Heemskerkstraat 19 | B125: 0072 | C125: Flowerhill B.V. | D125: 40 | E125: Ziggo | F125: 3 | G125: 250 | H125: 2250
A126: Hendrik Deddenstraat 26 | B126: 0073 | C126: Focuzop-eu | D126: 50448 | G126: 0 | H126: 0
A127: Hendriklaan 49 | B127: 0325 | C127: Fryslân Homes | D127: 84 | G127: 450 | H127: 5500
A128: Herautpad 22 | B128: 0176 | C128: Furniture Lease | D128: 50026 | G128: 0 | H128: 1750
A129: Herenpad 20 A | B129: 0133 | C129: G.D. Dijkstra | D129: 50168 | G129: 0 | H129: 3409.28
A130: Herenpad 20 B | B130: 0134 | C130: G.K. Stoel | D130: 100125 | G130: 0 | H130: 2363.07
A131: Hoefslag 8 | B131: 0107 | C131: GAP Costruzioni S.r.l. | D131: 100262 | G131: 250 | H131: 2446.35
A132: Hof van zeeland 2 | B132: 0334 | C132: GMC KOVI Global Metal Construction | D132: 50433 | G132: 0 | H132: 0
A133: Hoge Noordweg 27B | B133: 0177 | C133: GOTI Verhuur B.V. | D133: 7 | G133: 0 | H133: 1829.53
A134: Hoge Noordweg 28 | B134: 0178 | C134: GSI B.V. | D134: 50426 | G134: 0 | H134: 0
A135: Hogenbanweg 331 | B135: 0031 | C135: Gap Costruzioni Dutch Branch | D135: 50394 | G135: 0 | H135: 1974.12
A136: Hontenissestraat 124 | B136: 0181 | C136: Gastvrijaanzee.nl | D136: 50439 | G136: 250 | H136: 2240.44
A137: Hoofdstraat 110 | B137: 0075 | C137: Gemeente Waadhoeke | D137: 50252 | G137: 0 | H137: 2342.25
... A376: Wijngaard 66 | B376: 0212 | C376: van Heeswijk | D376: 57 | G376: 250 | H376: 2750
A377: Wilgensingel 63 | B377: 0139 | G377: 300 | H377: 0
A378: Wilgenstraat 37 | B378: 0140 | G378: 300 | H378: 3955.8
A379: Wilhelmina Druckerstraat 68 | B379: 0142 | G379: 350 | H379: 2394.3
A380: Wilhelminastraat 8 | B380: 0141 | G380: 300 | H380: 2700
A381: Willem Lodewijkstraat 8 | B381: 0143 | G381: 200 | H381: 2000
A382: Willem de Rijkelaan 134 | B382: 0161 | G382: 0 | H382: 2909.6
A383: Woutersweg 20 | B383: 0186 | G383: 0 | H383: 2394.3
A384: Wouwbaan 230 | B384: 0145 | G384: 0 | H384: 2928.69
...
