Workbook

Sheet Dashboard
A1: COMPLETENESS DASHBOARD
A3: Adres | B3: Basis? | C3: GWE? | D3: Schoonmaak? | E3: STATUS
A4: =_xlfn.UNIQUE(_xlfn.FILTER(Input!A2:A5000, Input!A2:A5000<>"")) | B4: =IF(A4="","",IF(COUNTIFS(Input!$A:$A, A4, Input!$B:$B, "Basis")>0, "OK", "MISSING")) | C4: =IF(A4="","",IF(COUNTIFS(Input!$A:$A, A4, Input!$B:$B, "GWE")>0, "OK", "MISSING")) | D4: =IF(A4="","",IF(COUNTIFS(Input!$A:$A, A4, Input!$B:$B, "Schoonmaak")>0, "OK", "MISSING")) | E4: =IF(A4="","",IF(AND(B4="OK",C4="OK",D4="OK"), "✅ READY", "⚠️ INCOMPLETE"))
B5: =IF(A5="","",IF(COUNTIFS(Input!$A:$A, A5, Input!$B:$B, "Basis")>0, "OK", "MISSING")) | C5: =IF(A5="","",IF(COUNTIFS(Input!$A:$A, A5, Input!$B:$B, "GWE")>0, "OK", "MISSING")) | D5: =IF(A5="","",IF(COUNTIFS(Input!$A:$A, A5, Input!$B:$B, "Schoonmaak")>0, "OK", "MISSING")) | E5: =IF(A5="","",IF(AND(B5="OK",C5="OK",D5="OK"), "✅ READY", "⚠️ INCOMPLETE"))
B6: =IF(A6="","",IF(COUNTIFS(Input!$A:$A, A6, Input!$B:$B, "Basis")>0, "OK", "MISSING")) | C6: =IF(A6="","",IF(COUNTIFS(Input!$A:$A, A6, Input!$B:$B, "GWE")>0, "OK", "MISSING")) | D6: =IF(A6="","",IF(COUNTIFS(Input!$A:$A, A6, Input!$B:$B, "Schoonmaak")>0, "OK", "MISSING")) | E6: =IF(A6="","",IF(AND(B6="OK",C6="OK",D6="OK"), "✅ READY", "⚠️ INCOMPLETE"))
B7: =IF(A7="","",IF(COUNTIFS(Input!$A:$A, A7, Input!$B:$B, "Basis")>0, "OK", "MISSING")) | C7: =IF(A7="","",IF(COUNTIFS(Input!$A:$A, A7, Input!$B:$B, "GWE")>0, "OK", "MISSING")) | D7: =IF(A7="","",IF(COUNTIFS(Input!$A:$A, A7, Input!$B:$B, "Schoonmaak")>0, "OK", "MISSING")) | E7: =IF(A7="","",IF(AND(B7="OK",C7="OK",D7="OK"), "✅ READY", "⚠️ INCOMPLETE"))
B8: =IF(A8="","",IF(COUNTIFS(Input!$A:$A, A8, Input!$B:$B, "Basis")>0, "OK", "MISSING")) | C8: =IF(A8="","",IF(COUNTIFS(Input!$A:$A, A8, Input!$B:$B, "GWE")>0, "OK", "MISSING")) | D8: =IF(A8="","",IF(COUNTIFS(Input!$A:$A, A8, Input!$B:$B, "Schoonmaak")>0, "OK", "MISSING")) | E8: =IF(A8="","",IF(AND(B8="OK",C8="OK",D8="OK"), "✅ READY", "⚠️ INCOMPLETE"))
B9: =IF(A9="","",IF(COUNTIFS(Input!$A:$A, A9, Input!$B:$B, "Basis")>0, "OK", "MISSING")) | C9: =IF(A9="","",IF(COUNTIFS(Input!$A:$A, A9, Input!$B:$B, "GWE")>0, "OK", "MISSING")) | D9: =IF(A9="","",IF(COUNTIFS(Input!$A:$A, A9, Input!$B:$B, "Schoonmaak")>0, "OK", "MISSING")) | E9: =IF(A9="","",IF(AND(B9="OK",C9="OK",D9="OK"), "✅ READY", "⚠️ INCOMPLETE"))
B10: =IF(A10="","",IF(COUNTIFS(Input!$A:$A, A10, Input!$B:$B, "Basis")>0, "OK", "MISSING")) | C10: =IF(A10="","",IF(COUNTIFS(Input!$A:$A, A10, Input!$B:$B, "GWE")>0, "OK", "MISSING")) | D10: =IF(A10="","",IF(COUNTIFS(Input!$A:$A, A10, Input!$B:$B, "Schoonmaak")>0, "OK", "MISSING")) | E10: =IF(A10="","",IF(AND(B10="OK",C10="OK",D10="OK"), "✅ READY", "⚠️ INCOMPLETE"))
B11: =IF(A11="","",IF(COUNTIFS(Input!$A:$A, A11, Input!$B:$B, "Basis")>0, "OK", "MISSING")) | C11: =IF(A11="","",IF(COUNTIFS(Input!$A:$A, A11, Input!$B:$B, "GWE")>0, "OK", "MISSING")) | D11: =IF(A11="","",IF(COUNTIFS(Input!$A:$A, A11, Input!$B:$B, "Schoonmaak")>0, "OK", "MISSING")) | E11: =IF(A11="","",IF(AND(B11="OK",C11="OK",D11="OK"), "✅ READY", "⚠️ INCOMPLETE"))
B12: =IF(A12="","",IF(COUNTIFS(Input!$A:$A, A12, Input!$B:$B, "Basis")>0, "OK", "MISSING")) | C12: =IF(A12="","",IF(COUNTIFS(Input!$A:$A, A12, Input!$B:$B, "GWE")>0, "OK", "MISSING")) | D12: =IF(A12="","",IF(COUNTIFS(Input!$A:$A, A12, Input!$B:$B, "Schoonmaak")>0, "OK", "MISSING")) | E12: =IF(A12="","",IF(AND(B12="OK",C12="OK",D12="OK"), "✅ READY", "⚠️ INCOMPLETE"))
B13: =IF(A13="","",IF(COUNTIFS(Input!$A:$A, A13, Input!$B:$B, "Basis")>0, "OK", "MISSING")) | C13: =IF(A13="","",IF(COUNTIFS(Input!$A:$A, A13, Input!$B:$B, "GWE")>0, "OK", "MISSING")) | D13: =IF(A13="","",IF(COUNTIFS(Input!$A:$A, A13, Input!$B:$B, "Schoonmaak")>0, "OK", "MISSING")) | E13: =IF(A13="","",IF(AND(B13="OK",C13="OK",D13="OK"), "✅ READY", "⚠️ INCOMPLETE"))
B14: =IF(A14="","",IF(COUNTIFS(Input!$A:$A, A14, Input!$B:$B, "Basis")>0, "OK", "MISSING")) | C14: =IF(A14="","",IF(COUNTIFS(Input!$A:$A, A14, Input!$B:$B, "GWE")>0, "OK", "MISSING")) | D14: =IF(A14="","",IF(COUNTIFS(Input!$A:$A, A14, Input!$B:$B, "Schoonmaak")>0, "OK", "MISSING")) | E14: =IF(A14="","",IF(AND(B14="OK",C14="OK",D14="OK"), "✅ READY", "⚠️ INCOMPLETE"))
B15: =IF(A15="","",IF(COUNTIFS(Input!$A:$A, A15, Input!$B:$B, "Basis")>0, "OK", "MISSING")) | C15: =IF(A15="","",IF(COUNTIFS(Input!$A:$A, A15, Input!$B:$B, "GWE")>0, "OK", "MISSING")) | D15: =IF(A15="","",IF(COUNTIFS(Input!$A:$A, A15, Input!$B:$B, "Schoonmaak")>0, "OK", "MISSING")) | E15: =IF(A15="","",IF(AND(B15="OK",C15="OK",D15="OK"), "✅ READY", "⚠️ INCOMPLETE"))
B16: =IF(A16="","",IF(COUNTIFS(Input!$A:$A, A16, Input!$B:$B, "Basis")>0, "OK", "MISSING")) | C16: =IF(A16="","",IF(COUNTIFS(Input!$A:$A, A16, Input!$B:$B, "GWE")>0, "OK", "MISSING")) | D16: =IF(A16="","",IF(COUNTIFS(Input!$A:$A, A16, Input!$B:$B, "Schoonmaak")>0, "OK", "MISSING")) | E16: =IF(A16="","",IF(AND(B16="OK",C16="OK",D16="OK"), "✅ READY", "⚠️ INCOMPLETE"))
... B53: =IF(A53="","",IF(COUNTIFS(Input!$A:$A, A53, Input!$B:$B, "Basis")>0, "OK", "MISSING")) | C53: =IF(A53="","",IF(COUNTIFS(Input!$A:$A, A53, Input!$B:$B, "GWE")>0, "OK", "MISSING")) | D53: =IF(A53="","",IF(COUNTIFS(Input!$A:$A, A53, Input!$B:$B, "Schoonmaak")>0, "OK", "MISSING")) | E53: =IF(A53="","",IF(AND(B53="OK",C53="OK",D53="OK"), "✅ READY", "⚠️ INCOMPLETE"))

Sheet Input
A1: Adres | B1: Type | C1: Klantnaam | D1: Object ID | E1: Klant Nr (Auto) | F1: RR Inspecteur | G1: Folder Link | H1: Check-in | I1: Check-out | J1: Borg (€) | K1: GWE Beheer | L1: GWE Maandbedrag (€) | M1: BTW % | N1: Voorschot GWE (Incl) | O1: Totaal Voorschot | P1: Meterbeheerder | Q1: Leverancier | R1: Leverancier Nr (Auto) | S1: Contractnr | T1: Extra Voorschot (€) | U1: Extra Voor. Omschr. | V1: Elek Begin | W1: Elek Eind | X1: Gas Begin | Y1: Gas Eind | Z1: Water Begin | AA1: Water Eind | AB1: Schoon Maak Pakket | AC1: Schoon Uren | AD1: Uurtarief (€) | AE1: Totaal Excl (€) | AF1: BTW % | AG1: BTW Bedrag (€) | AH1: Totaal Incl (€) | AI1: Kosten Type | AJ1: Eenheid | AK1: Beschrijving | AL1: Aantal | AM1: Prijs/Stuk (€) | AN1: Totaal Excl (€) | AO1: BTW % | AP1: BTW Bedrag (€) | AQ1: Totaal Incl (€)
D2: =IF(A2="","",VLOOKUP(A2,Lists!$A:$B,2,FALSE)) | E2: =IF(C2="","",VLOOKUP(C2,Lists!$C:$D,2,FALSE)) | J2: =IF(A2="","",IFERROR(VLOOKUP(A2,Lists!$A:$H,8,FALSE),0)) | L2: =IF(A2="","",IFERROR(VLOOKUP(A2,Lists!$A:$H,7,FALSE),0)) | M2: 0.21 | N2: =L2 * (1 + M2) | O2: =IF(K2="Eigen Beheer",0,IF(AND(ISNUMBER(N2),I2<>"",H2<>""),ROUND((I2-H2)/Lists!$Q$2,2)*N2,0)) | R2: =IF(Q2="","",VLOOKUP(Q2,Lists!$E:$F,2,FALSE)) | AD2: 50 | AE2: =IF(AB2="","",IF(ISNUMBER(SEARCH("Basis",AB2)),(250/1.21)+MAX(0,AC2-5)*AD2,IF(ISNUMBER(SEARCH("Intensief",AB2)),(375/1.21)+MAX(0,AC2-7)*AD2,AC2*AD2))) | AF2: 0.21 | AG2: =IF(AE2<>"",AE2*AF2,"") | AH2: =IF(AE2<>"",AE2+AG2,"") | AL2: =IF($B2="GWE_Item",IF($AI2="Elektra",SUMIFS($W:$W,$A:$A,$A2,$B:$B,"GWE")-SUMIFS($V:$V,$A:$A,$A2,$B:$B,"GWE"),IF($AI2="Gas",SUMIFS($Y:$Y,$A:$A,$A2,$B:$B,"GWE")-SUMIFS($X:$X,$A:$A,$A2,$B:$B,"GWE"),IF($AI2="Water",SUMIFS($AA:$AA,$A:$A,$A2,$B:$B,"GWE")-SUMIFS($Z:$Z,$A:$A,$A2,$B:$B,"GWE"),""))),"") | AN2: =IF(AND(AL2<>"",AM2<>""),AL2*AM2,"") | AP2: =IF(AND(AN2<>"",AO2<>""),AN2*AO2,"") | AQ2: =IF(AND(AN2<>"",AP2<>""),AN2+AP2,"")
D3: =IF(A3="","",VLOOKUP(A3,Lists!$A:$B,2,FALSE)) | E3: =IF(C3="","",VLOOKUP(C3,Lists!$C:$D,2,FALSE)) | J3: =IF(A3="","",IFERROR(VLOOKUP(A3,Lists!$A:$H,8,FALSE),0)) | L3: =IF(A3="","",IFERROR(VLOOKUP(A3,Lists!$A:$H,7,FALSE),0)) | M3: 0.21 | N3: =L3 * (1 + M3) | O3: =IF(K3="Eigen Beheer",0,IF(AND(ISNUMBER(N3),I3<>"",H3<>""),ROUND((I3-H3)/Lists!$Q$2,2)*N3,0)) | R3: =IF(Q3="","",VLOOKUP(Q3,Lists!$E:$F,2,FALSE)) | AD3: 50 | AE3: =IF(AB3="","",IF(ISNUMBER(SEARCH("Basis",AB3)),(250/1.21)+MAX(0,AC3-5)*AD3,IF(ISNUMBER(SEARCH("Intensief",AB3)),(375/1.21)+MAX(0,AC3-7)*AD3,AC3*AD3))) | AF3: 0.21 | AG3: =IF(AE3<>"",AE3*AF3,"") | AH3: =IF(AE3<>"",AE3+AG3,"") | AL3: =IF($B3="GWE_Item",IF($AI3="Elektra",SUMIFS($W:$W,$A:$A,$A3,$B:$B,"GWE")-SUMIFS($V:$V,$A:$A,$A3,$B:$B,"GWE"),IF($AI3="Gas",SUMIFS($Y:$Y,$A:$A,$A3,$B:$B,"GWE")-SUMIFS($X:$X,$A:$A,$A3,$B:$B,"GWE"),IF($AI3="Water",SUMIFS($AA:$AA,$A:$A,$A3,$B:$B,"GWE")-SUMIFS($Z:$Z,$A:$A,$A3,$B:$B,"GWE"),""))),"") | AN3: =IF(AND(AL3<>"",AM3<>""),AL3*AM3,"") | AP3: =IF(AND(AN3<>"",AO3<>""),AN3*AO3,"") | AQ3: =IF(AND(AN3<>"",AP3<>""),AN3+AP3,"")
D4: =IF(A4="","",VLOOKUP(A4,Lists!$A:$B,2,FALSE)) | E4: =IF(C4="","",VLOOKUP(C4,Lists!$C:$D,2,FALSE)) | J4: =IF(A4="","",IFERROR(VLOOKUP(A4,Lists!$A:$H,8,FALSE),0)) | L4: =IF(A4="","",IFERROR(VLOOKUP(A4,Lists!$A:$H,7,FALSE),0)) | M4: 0.21 | N4: =L4 * (1 + M4) | O4: =IF(K4="Eigen Beheer",0,IF(AND(ISNUMBER(N4),I4<>"",H4<>""),ROUND((I4-H4)/Lists!$Q$2,2)*N4,0)) | R4: =IF(Q4="","",VLOOKUP(Q4,Lists!$E:$F,2,FALSE)) | AD4: 50 | AE4: =IF(AB4="","",IF(ISNUMBER(SEARCH("Basis",AB4)),(250/1.21)+MAX(0,AC4-5)*AD4,IF(ISNUMBER(SEARCH("Intensief",AB4)),(375/1.21)+MAX(0,AC4-7)*AD4,AC4*AD4))) | AF4: 0.21 | AG4: =IF(AE4<>"",AE4*AF4,"") | AH4: =IF(AE4<>"",AE4+AG4,"") | AL4: =IF($B4="GWE_Item",IF($AI4="Elektra",SUMIFS($W:$W,$A:$A,$A4,$B:$B,"GWE")-SUMIFS($V:$V,$A:$A,$A4,$B:$B,"GWE"),IF($AI4="Gas",SUMIFS($Y:$Y,$A:$A,$A4,$B:$B,"GWE")-SUMIFS($X:$X,$A:$A,$A4,$B:$B,"GWE"),IF($AI4="Water",SUMIFS($AA:$AA,$A:$A,$A4,$B:$B,"GWE")-SUMIFS($Z:$Z,$A:$A,$A4,$B:$B,"GWE"),""))),"") | AN4: =IF(AND(AL4<>"",AM4<>""),AL4*AM4,"") | AP4: =IF(AND(AN4<>"",AO4<>""),AN4*AO4,"") | AQ4: =IF(AND(AN4<>"",AP4<>""),AN4+AP4,"")
D5: =IF(A5="","",VLOOKUP(A5,Lists!$A:$B,2,FALSE)) | E5: =IF(C5="","",VLOOKUP(C5,Lists!$C:$D,2,FALSE)) | J5: =IF(A5="","",IFERROR(VLOOKUP(A5,Lists!$A:$H,8,FALSE),0)) | L5: =IF(A5="","",IFERROR(VLOOKUP(A5,Lists!$A:$H,7,FALSE),0)) | M5: 0.21 | N5: =L5 * (1 + M5) | O5: =IF(K5="Eigen Beheer",0,IF(AND(ISNUMBER(N5),I5<>"",H5<>""),ROUND((I5-H5)/Lists!$Q$2,2)*N5,0)) | R5: =IF(Q5="","",VLOOKUP(Q5,Lists!$E:$F,2,FALSE)) | AD5: 50 | AE5: =IF(AB5="","",IF(ISNUMBER(SEARCH("Basis",AB5)),(250/1.21)+MAX(0,AC5-5)*AD5,IF(ISNUMBER(SEARCH("Intensief",AB5)),(375/1.21)+MAX(0,AC5-7)*AD5,AC5*AD5))) | AF5: 0.21 | AG5: =IF(AE5<>"",AE5*AF5,"") | AH5: =IF(AE5<>"",AE5+AG5,"") | AL5: =IF($B5="GWE_Item",IF($AI5="Elektra",SUMIFS($W:$W,$A:$A,$A5,$B:$B,"GWE")-SUMIFS($V:$V,$A:$A,$A5,$B:$B,"GWE"),IF($AI5="Gas",SUMIFS($Y:$Y,$A:$A,$A5,$B:$B,"GWE")-SUMIFS($X:$X,$A:$A,$A5,$B:$B,"GWE"),IF($AI5="Water",SUMIFS($AA:$AA,$A:$A,$A5,$B:$B,"GWE")-SUMIFS($Z:$Z,$A:$A,$A5,$B:$B,"GWE"),""))),"") | AN5: =IF(AND(AL5<>"",AM5<>""),AL5*AM5,"") | AP5: =IF(AND(AN5<>"",AO5<>""),AN5*AO5,"") | AQ5: =IF(AND(AN5<>"",AP5<>""),AN5+AP5,"")
D6: =IF(A6="","",VLOOKUP(A6,Lists!$A:$B,2,FALSE)) | E6: =IF(C6="","",VLOOKUP(C6,Lists!$C:$D,2,FALSE)) | J6: =IF(A6="","",IFERROR(VLOOKUP(A6,Lists!$A:$H,8,FALSE),0)) | L6: =IF(A6="","",IFERROR(VLOOKUP(A6,Lists!$A:$H,7,FALSE),0)) | M6: 0.21 | N6: =L6 * (1 + M6) | O6: =IF(K6="Eigen Beheer",0,IF(AND(ISNUMBER(N6),I6<>"",H6<>""),ROUND((I6-H6)/Lists!$Q$2,2)*N6,0)) | R6: =IF(Q6="","",VLOOKUP(Q6,Lists!$E:$F,2,FALSE)) | AD6: 50 | AE6: =IF(AB6="","",IF(ISNUMBER(SEARCH("Basis",AB6)),(250/1.21)+MAX(0,AC6-5)*AD6,IF(ISNUMBER(SEARCH("Intensief",AB6)),(375/1.21)+MAX(0,AC6-7)*AD6,AC6*AD6))) | AF6: 0.21 | AG6: =IF(AE6<>"",AE6*AF6,"") | AH6: =IF(AE6<>"",AE6+AG6,"") | AL6: =IF($B6="GWE_Item",IF($AI6="Elektra",SUMIFS($W:$W,$A:$A,$A6,$B:$B,"GWE")-SUMIFS($V:$V,$A:$A,$A6,$B:$B,"GWE"),IF($AI6="Gas",SUMIFS($Y:$Y,$A:$A,$A6,$B:$B,"GWE")-SUMIFS($X:$X,$A:$A,$A6,$B:$B,"GWE"),IF($AI6="Water",SUMIFS($AA:$AA,$A:$A,$A6,$B:$B,"GWE")-SUMIFS($Z:$Z,$A:$A,$A6,$B:$B,"GWE"),""))),"") | AN6: =IF(AND(AL6<>"",AM6<>""),AL6*AM6,"") | AP6: =IF(AND(AN6<>"",AO6<>""),AN6*AO6,"") | AQ6: =IF(AND(AN6<>"",AP6<>""),AN6+AP6,"")
D7: =IF(A7="","",VLOOKUP(A7,Lists!$A:$B,2,FALSE)) | E7: =IF(C7="","",VLOOKUP(C7,Lists!$C:$D,2,FALSE)) | J7: =IF(A7="","",IFERROR(VLOOKUP(A7,Lists!$A:$H,8,FALSE),0)) | L7: =IF(A7="","",IFERROR(VLOOKUP(A7,Lists!$A:$H,7,FALSE),0)) | M7: 0.21 | N7: =L7 * (1 + M7) | O7: =IF(K7="Eigen Beheer",0,IF(AND(ISNUMBER(N7),I7<>"",H7<>""),ROUND((I7-H7)/Lists!$Q$2,2)*N7,0)) | R7: =IF(Q7="","",VLOOKUP(Q7,Lists!$E:$F,2,FALSE)) | AD7: 50 | AE7: =IF(AB7="","",IF(ISNUMBER(SEARCH("Basis",AB7)),(250/1.21)+MAX(0,AC7-5)*AD7,IF(ISNUMBER(SEARCH("Intensief",AB7)),(375/1.21)+MAX(0,AC7-7)*AD7,AC7*AD7))) | AF7: 0.21 | AG7: =IF(AE7<>"",AE7*AF7,"") | AH7: =IF(AE7<>"",AE7+AG7,"") | AL7: =IF($B7="GWE_Item",IF($AI7="Elektra",SUMIFS($W:$W,$A:$A,$A7,$B:$B,"GWE")-SUMIFS($V:$V,$A:$A,$A7,$B:$B,"GWE"),IF($AI7="Gas",SUMIFS($Y:$Y,$A:$A,$A7,$B:$B,"GWE")-SUMIFS($X:$X,$A:$A,$A7,$B:$B,"GWE"),IF($AI7="Water",SUMIFS($AA:$AA,$A:$A,$A7,$B:$B,"GWE")-SUMIFS($Z:$Z,$A:$A,$A7,$B:$B,"GWE"),""))),"") | AN7: =IF(AND(AL7<>"",AM7<>""),AL7*AM7,"") | AP7: =IF(AND(AN7<>"",AO7<>""),AN7*AO7,"") | AQ7: =IF(AND(AN7<>"",AP7<>""),AN7+AP7,"")
D8: =IF(A8="","",VLOOKUP(A8,Lists!$A:$B,2,FALSE)) | E8: =IF(C8="","",VLOOKUP(C8,Lists!$C:$D,2,FALSE)) | J8: =IF(A8="","",IFERROR(VLOOKUP(A8,Lists!$A:$H,8,FALSE),0)) | L8: =IF(A8="","",IFERROR(VLOOKUP(A8,Lists!$A:$H,7,FALSE),0)) | M8: 0.21 | N8: =L8 * (1 + M8) | O8: =IF(K8="Eigen Beheer",0,IF(AND(ISNUMBER(N8),I8<>"",H8<>""),ROUND((I8-H8)/Lists!$Q$2,2)*N8,0)) | R8: =IF(Q8="","",VLOOKUP(Q8,Lists!$E:$F,2,FALSE)) | AD8: 50 | AE8: =IF(AB8="","",IF(ISNUMBER(SEARCH("Basis",AB8)),(250/1.21)+MAX(0,AC8-5)*AD8,IF(ISNUMBER(SEARCH("Intensief",AB8)),(375/1.21)+MAX(0,AC8-7)*AD8,AC8*AD8))) | AF8: 0.21 | AG8: =IF(AE8<>"",AE8*AF8,"") | AH8: =IF(AE8<>"",AE8+AG8,"") | AL8: =IF($B8="GWE_Item",IF($AI8="Elektra",SUMIFS($W:$W,$A:$A,$A8,$B:$B,"GWE")-SUMIFS($V:$V,$A:$A,$A8,$B:$B,"GWE"),IF($AI8="Gas",SUMIFS($Y:$Y,$A:$A,$A8,$B:$B,"GWE")-SUMIFS($X:$X,$A:$A,$A8,$B:$B,"GWE"),IF($AI8="Water",SUMIFS($AA:$AA,$A:$A,$A8,$B:$B,"GWE")-SUMIFS($Z:$Z,$A:$A,$A8,$B:$B,"GWE"),""))),"") | AN8: =IF(AND(AL8<>"",AM8<>""),AL8*AM8,"") | AP8: =IF(AND(AN8<>"",AO8<>""),AN8*AO8,"") | AQ8: =IF(AND(AN8<>"",AP8<>""),AN8+AP8,"")
D9: =IF(A9="","",VLOOKUP(A9,Lists!$A:$B,2,FALSE)) | E9: =IF(C9="","",VLOOKUP(C9,Lists!$C:$D,2,FALSE)) | J9: =IF(A9="","",IFERROR(VLOOKUP(A9,Lists!$A:$H,8,FALSE),0)) | L9: =IF(A9="","",IFERROR(VLOOKUP(A9,Lists!$A:$H,7,FALSE),0)) | M9: 0.21 | N9: =L9 * (1 + M9) | O9: =IF(K9="Eigen Beheer",0,IF(AND(ISNUMBER(N9),I9<>"",H9<>""),ROUND((I9-H9)/Lists!$Q$2,2)*N9,0)) | R9: =IF(Q9="","",VLOOKUP(Q9,Lists!$E:$F,2,FALSE)) | AD9: 50 | AE9: =IF(AB9="","",IF(ISNUMBER(SEARCH("Basis",AB9)),(250/1.21)+MAX(0,AC9-5)*AD9,IF(ISNUMBER(SEARCH("Intensief",AB9)),(375/1.21)+MAX(0,AC9-7)*AD9,AC9*AD9))) | AF9: 0.21 | AG9: =IF(AE9<>"",AE9*AF9,"") | AH9: =IF(AE9<>"",AE9+AG9,"") | AL9: =IF($B9="GWE_Item",IF($AI9="Elektra",SUMIFS($W:$W,$A:$A,$A9,$B:$B,"GWE")-SUMIFS($V:$V,$A:$A,$A9,$B:$B,"GWE"),IF($AI9="Gas",SUMIFS($Y:$Y,$A:$A,$A9,$B:$B,"GWE")-SUMIFS($X:$X,$A:$A,$A9,$B:$B,"GWE"),IF($AI9="Water",SUMIFS($AA:$AA,$A:$A,$A9,$B:$B,"GWE")-SUMIFS($Z:$Z,$A:$A,$A9,$B:$B,"GWE"),""))),"") | AN9: =IF(AND(AL9<>"",AM9<>""),AL9*AM9,"") | AP9: =IF(AND(AN9<>"",AO9<>""),AN9*AO9,"") | AQ9: =IF(AND(AN9<>"",AP9<>""),AN9+AP9,"")
D10: =IF(A10="","",VLOOKUP(A10,Lists!$A:$B,2,FALSE)) | E10: =IF(C10="","",VLOOKUP(C10,Lists!$C:$D,2,FALSE)) | J10: =IF(A10="","",IFERROR(VLOOKUP(A10,Lists!$A:$H,8,FALSE),0)) | L10: =IF(A10="","",IFERROR(VLOOKUP(A10,Lists!$A:$H,7,FALSE),0)) | M10: 0.21 | N10: =L10 * (1 + M10) | O10: =IF(K10="Eigen Beheer",0,IF(AND(ISNUMBER(N10),I10<>"",H10<>""),ROUND((I10-H10)/Lists!$Q$2,2)*N10,0)) | R10: =IF(Q10="","",VLOOKUP(Q10,Lists!$E:$F,2,FALSE)) | AD10: 50 | AE10: =IF(AB10="","",IF(ISNUMBER(SEARCH("Basis",AB10)),(250/1.21)+MAX(0,AC10-5)*AD10,IF(ISNUMBER(SEARCH("Intensief",AB10)),(375/1.21)+MAX(0,AC10-7)*AD10,AC10*AD10))) | AF10: 0.21 | AG10: =IF(AE10<>"",AE10*AF10,"") | AH10: =IF(AE10<>"",AE10+AG10,"") | AL10: =IF($B10="GWE_Item",IF($AI10="Elektra",SUMIFS($W:$W,$A:$A,$A10,$B:$B,"GWE")-SUMIFS($V:$V,$A:$A,$A10,$B:$B,"GWE"),IF($AI10="Gas",SUMIFS($Y:$Y,$A:$A,$A10,$B:$B,"GWE")-SUMIFS($X:$X,$A:$A,$A10,$B:$B,"GWE"),IF($AI10="Water",SUMIFS($AA:$AA,$A:$A,$A10,$B:$B,"GWE")-SUMIFS($Z:$Z,$A:$A,$A10,$B:$B,"GWE"),""))),"") | AN10: =IF(AND(AL10<>"",AM10<>""),AL10*AM10,"") | AP10: =IF(AND(AN10<>"",AO10<>""),AN10*AO10,"") | AQ10: =IF(AND(AN10<>"",AP10<>""),AN10+AP10,"")
D11: =IF(A11="","",VLOOKUP(A11,Lists!$A:$B,2,FALSE)) | E11: =IF(C11="","",VLOOKUP(C11,Lists!$C:$D,2,FALSE)) | J11: =IF(A11="","",IFERROR(VLOOKUP(A11,Lists!$A:$H,8,FALSE),0)) | L11: =IF(A11="","",IFERROR(VLOOKUP(A11,Lists!$A:$H,7,FALSE),0)) | M11: 0.21 | N11: =L11 * (1 + M11) | O11: =IF(K11="Eigen Beheer",0,IF(AND(ISNUMBER(N11),I11<>"",H11<>""),ROUND((I11-H11)/Lists!$Q$2,2)*N11,0)) | R11: =IF(Q11="","",VLOOKUP(Q11,Lists!$E:$F,2,FALSE)) | AD11: 50 | AE11: =IF(AB11="","",IF(ISNUMBER(SEARCH("Basis",AB11)),(250/1.21)+MAX(0,AC11-5)*AD11,IF(ISNUMBER(SEARCH("Intensief",AB11)),(375/1.21)+MAX(0,AC11-7)*AD11,AC11*AD11))) | AF11: 0.21 | AG11: =IF(AE11<>"",AE11*AF11,"") | AH11: =IF(AE11<>"",AE11+AG11,"") | AL11: =IF($B11="GWE_Item",IF($AI11="Elektra",SUMIFS($W:$W,$A:$A,$A11,$B:$B,"GWE")-SUMIFS($V:$V,$A:$A,$A11,$B:$B,"GWE"),IF($AI11="Gas",SUMIFS($Y:$Y,$A:$A,$A11,$B:$B,"GWE")-SUMIFS($X:$X,$A:$A,$A11,$B:$B,"GWE"),IF($AI11="Water",SUMIFS($AA:$AA,$A:$A,$A11,$B:$B,"GWE")-SUMIFS($Z:$Z,$A:$A,$A11,$B:$B,"GWE"),""))),"") | AN11: =IF(AND(AL11<>"",AM11<>""),AL11*AM11,"") | AP11: =IF(AND(AN11<>"",AO11<>""),AN11*AO11,"") | AQ11: =IF(AND(AN11<>"",AP11<>""),AN11+AP11,"")
D12: =IF(A12="","",VLOOKUP(A12,Lists!$A:$B,2,FALSE)) | E12: =IF(C12="","",VLOOKUP(C12,Lists!$C:$D,2,FALSE)) | J12: =IF(A12="","",IFERROR(VLOOKUP(A12,Lists!$A:$H,8,FALSE),0)) | L12: =IF(A12="","",IFERROR(VLOOKUP(A12,Lists!$A:$H,7,FALSE),0)) | M12: 0.21 | N12: =L12 * (1 + M12) | O12: =IF(K12="Eigen Beheer",0,IF(AND(ISNUMBER(N12),I12<>"",H12<>""),ROUND((I12-H12)/Lists!$Q$2,2)*N12,0)) | R12: =IF(Q12="","",VLOOKUP(Q12,Lists!$E:$F,2,FALSE)) | AD12: 50 | AE12: =IF(AB12="","",IF(ISNUMBER(SEARCH("Basis",AB12)),(250/1.21)+MAX(0,AC12-5)*AD12,IF(ISNUMBER(SEARCH("Intensief",AB12)),(375/1.21)+MAX(0,AC12-7)*AD12,AC12*AD12))) | AF12: 0.21 | AG12: =IF(AE12<>"",AE12*AF12,"") | AH12: =IF(AE12<>"",AE12+AG12,"") | AL12: =IF($B12="GWE_Item",IF($AI12="Elektra",SUMIFS($W:$W,$A:$A,$A12,$B:$B,"GWE")-SUMIFS($V:$V,$A:$A,$A12,$B:$B,"GWE"),IF($AI12="Gas",SUMIFS($Y:$Y,$A:$A,$A12,$B:$B,"GWE")-SUMIFS($X:$X,$A:$A,$A12,$B:$B,"GWE"),IF($AI12="Water",SUMIFS($AA:$AA,$A:$A,$A12,$B:$B,"GWE")-SUMIFS($Z:$Z,$A:$A,$A12,$B:$B,"GWE"),""))),"") | AN12: =IF(AND(AL12<>"",AM12<>""),AL12*AM12,"") | AP12: =IF(AND(AN12<>"",AO12<>""),AN12*AO12,"") | AQ12: =IF(AND(AN12<>"",AP12<>""),AN12+AP12,"")
D13: =IF(A13="","",VLOOKUP(A13,Lists!$A:$B,2,FALSE)) | E13: =IF(C13="","",VLOOKUP(C13,Lists!$C:$D,2,FALSE)) | J13: =IF(A13="","",IFERROR(VLOOKUP(A13,Lists!$A:$H,8,FALSE),0)) | L13: =IF(A13="","",IFERROR(VLOOKUP(A13,Lists!$A:$H,7,FALSE),0)) | M13: 0.21 | N13: =L13 * (1 + M13) | O13: =IF(K13="Eigen Beheer",0,IF(AND(ISNUMBER(N13),I13<>"",H13<>""),ROUND((I13-H13)/Lists!$Q$2,2)*N13,0)) | R13: =IF(Q13="","",VLOOKUP(Q13,Lists!$E:$F,2,FALSE)) | AD13: 50 | AE13: =IF(AB13="","",IF(ISNUMBER(SEARCH("Basis",AB13)),(250/1.21)+MAX(0,AC13-5)*AD13,IF(ISNUMBER(SEARCH("Intensief",AB13)),(375/1.21)+MAX(0,AC13-7)*AD13,AC13*AD13))) | AF13: 0.21 | AG13: =IF(AE13<>"",AE13*AF13,"") | AH13: =IF(AE13<>"",AE13+AG13,"") | AL13: =IF($B13="GWE_Item",IF($AI13="Elektra",SUMIFS($W:$W,$A:$A,$A13,$B:$B,"GWE")-SUMIFS($V:$V,$A:$A,$A13,$B:$B,"GWE"),IF($AI13="Gas",SUMIFS($Y:$Y,$A:$A,$A13,$B:$B,"GWE")-SUMIFS($X:$X,$A:$A,$A13,$B:$B,"GWE"),IF($AI13="Water",SUMIFS($AA:$AA,$A:$A,$A13,$B:$B,"GWE")-SUMIFS($Z:$Z,$A:$A,$A13,$B:$B,"GWE"),""))),"") | AN13: =IF(AND(AL13<>"",AM13<>""),AL13*AM13,"") | AP13: =IF(AND(AN13<>"",AO13<>""),AN13*AO13,"") | AQ13: =IF(AND(AN13<>"",AP13<>""),AN13+AP13,"")
... D201: =IF(A201="","",VLOOKUP(A201,Lists!$A:$B,2,FALSE)) | E201: =IF(C201="","",VLOOKUP(C201,Lists!$C:$D,2,FALSE)) | J201: =IF(A201="","",IFERROR(VLOOKUP(A201,Lists!$A:$H,8,FALSE),0)) | L201: =IF(A201="","",IFERROR(VLOOKUP(A201,Lists!$A:$H,7,FALSE),0)) | M201: 0.21 | N201: =L201 * (1 + M201) | O201: =IF(K201="Eigen Beheer",0,IF(AND(ISNUMBER(N201),I201<>"",H201<>""),ROUND((I201-H201)/Lists!$Q$2,2)*N201,0)) | R201: =IF(Q201="","",VLOOKUP(Q201,Lists!$E:$F,2,FALSE)) | AD201: 50 | AE201: =IF(AB201="","",IF(ISNUMBER(SEARCH("Basis",AB201)),(250/1.21)+MAX(0,AC201-5)*AD201,IF(ISNUMBER(SEARCH("Intensief",AB201)),(375/1.21)+MAX(0,AC201-7)*AD201,AC201*AD201))) | AF201: 0.21 | AG201: =IF(AE201<>"",AE201*AF201,"") | AH201: =IF(AE201<>"",AE201+AG201,"") | AL201: =IF($B201="GWE_Item",IF($AI201="Elektra",SUMIFS($W:$W,$A:$A,$A201,$B:$B,"GWE")-SUMIFS($V:$V,$A:$A,$A201,$B:$B,"GWE"),IF($AI201="Gas",SUMIFS($Y:$Y,$A:$A,$A201,$B:$B,"GWE")-SUMIFS($X:$X,$A:$A,$A201,$B:$B,"GWE"),IF($AI201="Water",SUMIFS($AA:$AA,$A:$A,$A201,$B:$B,"GWE")-SUMIFS($Z:$Z,$A:$A,$A201,$B:$B,"GWE"),""))),"") | AN201: =IF(AND(AL201<>"",AM201<>""),AL201*AM201,"") | AP201: =IF(AND(AN201<>"",AO201<>""),AN201*AO201,"") | AQ201: =IF(AND(AN201<>"",AP201<>""),AN201+AP201,"")

Sheet Lists
A1: Address | B1: Object ID | C1: Clients (Name) | D1: Clients (ID) | E1: Leveranciers (Name) | F1: Leveranciers (ID) | G1: GWE Voorschot (Default) | H1: Borg (Default) | I1: Meterbeheerder | K1: GWE Beheer | M1: Schoonmaak Pakket | O1: Kosten Type | Q1: Dagen per Maand
A2: 1e Middellandstraat 104A | B2: 0388 | C2: 't Werkt B.V. | D2: 173 | E2: 123Wonen Vastgoedbeheer B.V. | F2: 203 | G2: 200 | H2: 0 | I2: Stedin | K2: Via RyanRent | M2: Basis Schoonmaak | O2: Elektra | Q2: =365.25/12
A3: 1e Verdeligsweg 6 - 537 | B3: 0431 | C3: 24/7 drive | D3: 174 | E3: 123wonen Bergen op Zoom | F3: 165 | G3: 0 | H3: 0 | I3: Liander | K3: Eigen Beheer | M3: Intensief Schoonmaak | O3: Gas
A4: 1e Verdeligsweg 6 - 821 | B4: 0432 | C4: 4 Homes B.V. | D4: 85 | E4: 4 Homes | F4: 332 | G4: 0 | H4: 0 | I4: Enexis | M4: Geen Schoonmaak | O4: Water
A5: 1e Verdeligsweg 6 - 822 | B5: 0433 | C5: A. Blaszcak | D5: 118 | E5: A. Blaszcak | F5: 170 | G5: 0 | H5: 0 | I5: Westland Infra | M5: Achteraf Betaald | O5: Overig
A6: 2e Maasbosstraat 2 a | B6: 0148 | C6: A. Brouwers en S. Brouwers- van Weert | D6: 267 | E6: A. Brouwers en S. Brouwers- van Weert | F6: 347 | G6: 69.48 | H6: 0 | M6: Op Maat
A7: 2e Maasbosstraat 2 b | B7: 0149 | C7: A. Dzaka | D7: 69 | E7: A. Ghali | F7: 167 | G7: 52.12 | H7: 3300
A8: 2e Maasbosstraat 2 c | B8: 0150 | C8: A. Ghali | D8: 115 | E8: A.H.S. Willemsen | F8: 396 | G8: 44.04 | H8: 2550
A9: 2e van Leydengaelstraat 6 | B9: 0022 | C9: A. Verschueren | D9: 67 | E9: A.I.G. Lukkien | F9: 199 | G9: 0 | H9: 2271.76
A10: Abelenlaan 143 | B10: 0014 | C10: A.H.S. Willemsen | D10: 302 | E10: A.P.W. Koedooder | F10: 48 | G10: 0 | H10: 1940
A11: Acacia 2 | B11: 0003 | C11: A.I.G. Lukkien | D11: 150 | E11: ANWB | F11: 377 | G11: 0 | H11: 2022.35
A12: Acacialaan 9 | B12: 0223 | C12: A.P.W. Koedooder | D12: 77 | E12: Advocatenkantoor de Boorder | F12: 52 | G12: 112.25 | H12: 2300
A13: Achterdijk 47a | B13: 0190 | C13: A.W.N. Alkemade | D13: 40 | E13: Alis Vastgoed B.V. | F13: 18 | G13: 500 | H13: 2255
A14: Admiraliteitskade 80-02 | B14: 0478 | C14: A.Y. Nicolai | D14: 59 | E14: All Safety | F14: 304 | G14: 0 | H14: 0
A15: Adriaan Baasstraat 34 | B15: 0007 | C15: ABC Bedrijfsservice B.V | D15: 250 | E15: Alpha Housing B.V. | F15: 257 | G15: 250 | H15: 2594.12
A16: Akkerweg 41 [016] | B16: 0342 | C16: AKRION ADMINISTRATION | D16: 242 | E16: Alpha Star Finance | F16: 149 | G16: 0 | H16: 0
A17: Akkerweg 41 [018] | B17: 0295 | C17: AKT Autoschade | D17: 237 | E17: Aluxa Vastgoed B.V. | F17: 209 | G17: 400 | H17: 3200
A18: Akkerweg 41 [019] | B18: 0343 | C18: Adecco Group | D18: 249 | E18: Alvast Antikraak | F18: 490 | G18: 0 | H18: 0
... A371: Piersonstraat 8 | B371: 0114 | C371: van Heeswijk | D371: 52 | E371: S. Meijer | F371: 27 | G371: 200 | H371: 3500
A372: Plaats 10 | B372: 0120 | E372: S. de Gooijer | F372: 44 | G372: 250 | H372: 2850
A373: Platostraat 38 | B373: 0414 | E373: SB Electronics B.V. | F373: 473 | G373: 4.67 | H373: 0
A374: Platostraat 80 | B374: 0231 | E374: SKDC | F374: 118 | G374: 266.32 | H374: 2516.83
A375: Pleinweg 101a | B375: 0044 | E375: SKG-IKOB Certificatie B.V. | F375: 156 | G375: 200 | H375: 2040
A376: Pleinweg 101b | B376: 0045 | E376: SS Rotterdam | F376: 438 | G376: 200 | H376: 2175.29
A377: Ploegstraat 2a | B377: 0079 | E377: SVHW | F377: 123 | G377: 107.58 | H377: 0
A378: Poeldijkseweg 27 | B378: 0285 | E378: Sabewa Zeeland | F378: 361 | G378: 0 | H378: 0
A379: Poeldijkseweg 29 | B379: 0378 | E379: Samson Airconditioning | F379: 302 | G379: 0 | H379: 0
A380: Poolsestraat 29a | B380: 0386 | E380: Sancus Bouw en infro | F380: 386 | G380: 300 | H380: 2950
A381: Poppestraat 59 | B381: 0115 | E381: SchadeNet | F381: 355 | G381: 0 | H381: 3275
A382: Prins Bernhardstraat 40 | B382: 0116 | E382: Sebrechts | F382: 293 | G382: 0 | H382: 3250
A383: Prins Willemweg 2 | B383: 0287 | E383: Service en Zo | F383: 297 | G383: 0 | H383: 0
... A491: van der Werffstraat 240 | B491: 0245 | E491: Zien! B.V. | F491: 234 | G491: 186.36 | H491: 0
E492: Ziggo Services B.V. | F492: 260
E493: de Verhuurder vastgoedbemiddeling | F493: 340
E494: dockHolland Huisvesting B.V. | F494: 193
E495: flexcraft | F495: 301
E496: gbtwente | F496: 282
E497: hallo, | F497: 79
E498: hemdvoorhem.nl B.V. | F498: 81
E499: hotel Rozenburg | F499: 291
...
