Workbook
Name Gas_verbruik: Input!$B$9
Name KWh_verbruik: Input!$B$6
Name Water_verbruik: Input!$B$12

Sheet Dashboard
A1: COMPLETENESS DASHBOARD
A3: Adres | B3: Basis? | C3: GWE? | D3: Schoonmaak? | E3: STATUS
A4: =_xlfn.UNIQUE(_xlfn._xlws.FILTER(Input!A2:A5000, Input!A2:A5000<>"")) -> Rooseveltlaan 185 | B4: =IF(A4="","",IF(COUNTIFS(Input!$A:$A, A4, Input!$B:$B, "Basis")>0, "OK", "MISSING")) -> OK | C4: =IF(A4="","",IF(COUNTIFS(Input!$A:$A, A4, Input!$B:$B, "GWE")>0, "OK", "MISSING")) -> OK | D4: =IF(A4="","",IF(COUNTIFS(Input!$A:$A, A4, Input!$B:$B, "Schoonmaak")>0, "OK", "MISSING")) -> OK | E4: =IF(A4="","",IF(AND(B4="OK",C4="OK",D4="OK"), "✅ READY", "⚠️ INCOMPLETE")) -> ✅ READY
B5: =IF(A5="","",IF(COUNTIFS(Input!$A:$A, A5, Input!$B:$B, "Basis")>0, "OK", "MISSING")) | C5: =IF(A5="","",IF(COUNTIFS(Input!$A:$A, A5, Input!$B:$B, "GWE")>0, "OK", "MISSING")) | D5: =IF(A5="","",IF(COUNTIFS(Input!$A:$A, A5, Input!$B:$B, "Schoonmaak")>0, "OK", "MISSING")) | E5: =IF(A5="","",IF(AND(B5="OK",C5="OK",D5="OK"), "✅ READY", "⚠️ INCOMPLETE"))
B6: =IF(A6="","",IF(COUNTIFS(Input!$A:$A, A6, Input!$B:$B, "Basis")>0, "OK", "MISSING")) | C6: =IF(A6="","",IF(COUNTIFS(Input!$A:$A, A6, Input!$B:$B, "GWE")>0, "OK", "MISSING")) | D6: =IF(A6="","",IF(COUNTIFS(Input!$A:$A, A6, Input!$B:$B, "Schoonmaak")>0, "OK", "MISSING")) | E6: =IF(A6="","",IF(AND(B6="OK",C6="OK",D6="OK"), "✅ READY", "⚠️ INCOMPLETE"))
B7: =IF(A7="","",IF(COUNTIFS(Input!$A:$A, A7, Input!$B:$B, "Basis")>0, "OK", "MISSING")) | C7: =IF(A7="","",IF(COUNTIFS(Input!$A:$A, A7, Input!$B:$B, "GWE")>0, "OK", "MISSING")) | D7: =IF(A7="","",IF(COUNTIFS(Input!$A:$A, A7, Input!$B:$B, "Schoonmaak")>0, "OK", "MISSING")) | E7: =IF(A7="","",IF(AND(B7="OK",C7="OK",D7="OK"), "✅ READY", "⚠️ INCOMPLETE"))
B8: =IF(A8="","",IF(COUNTIFS(Input!$A:$A, A8, Input!$B:$B, "Basis")>0, "OK", "MISSING")) | C8: =IF(A8="","",IF(COUNTIFS(Input!$A:$A, A8, Input!$B:$B, "GWE")>0, "OK", "MISSING")) | D8: =IF(A8="","",IF(COUNTIFS(Input!$A:$A, A8, Input!$B:$B, "Schoonmaak")>0, "OK", "MISSING")) | E8: =IF(A8="","",IF(AND(B8="OK",C8="OK",D8="OK"), "✅ READY", "⚠️ INCOMPLETE"))
B9: =IF(A9="","",IF(COUNTIFS(Input!$A:$A, A9, Input!$B:$B, "Basis")>0, "OK", "MISSING")) | C9: =IF(A9="","",IF(COUNTIFS(Input!$A:$A, A9, Input!$B:$B, "GWE")>0, "OK", "MISSING")) | D9: =IF(A9="","",IF(COUNTIFS(Input!$A:$A, A9, Input!$B:$B, "Schoonmaak")>0, "OK", "MISSING")) | E9: =IF(A9="","",IF(AND(B9="OK",C9="OK",D9="OK"), "✅ READY", "⚠️ INCOMPLETE"))
B10: =IF(A10="","",IF(COUNTIFS(Input!$A:$A, A10, Input!$B:$B, "Basis")>0, "OK", "MISSING")) | C10: =IF(A10="","",IF(COUNTIFS(Input!$A:$A, A10, Input!$B:$B, "GWE")>0, "OK", "MISSING")) | D10: =IF(A10="","",IF(COUNTIFS(Input!$A:$A, A10, Input!$B:$B, "Schoonmaak")>0, "OK", "MISSING")) | E10: =IF(A10="","",IF(AND(B10="OK",C10="OK",D10="OK"), "✅ READY", "⚠️ INCOMPLETE"))
B11: =IF(A11="","",IF(COUNTIFS(Input!$A:$A, A11, Input!$B:$B, "Basis")>0, "OK", "MISSING")) | C11: =IF(A11="","",IF(COUNTIFS(Input!$A:$A, A11, Input!$B:$B, "GWE")>0, "OK", "MISSING")) | D11: =IF(A11="","",IF(COUNTIFS(Input!$A:$A, A11, Input!$B:$B, "Schoonmaak")>0, "OK", "MISSING")) | E11: =IF(A11="","",IF(AND(B11="OK",C11="OK",D11="OK"), "✅ READY", "⚠️ INCOMPLETE"))
B12: =IF(A12="","",IF(COUNTIFS(Input!$A:$A, A12, Input!$B:$B, "Basis")>0, "OK", "MISSING")) | C12: =IF(A12="","",IF(COUNTIFS(Input!$A:$A, A12, Input!$B:$B, "GWE")>0, "OK", "MISSING")) | D12: =IF(A12="","",IF(COUNTIFS(Input!$A:$A, A12, Input!$B:$B, "Schoonmaak")>0, "OK", "MISSING")) | E12: =IF(A12="","",IF(AND(B12="OK",C12="OK",D12="OK"), "✅ READY", "⚠️ INCOMPLETE"))
B13: =IF(A13="","",IF(COUNTIFS(Input!$A:$A, A13, Input!$B:$B, "Basis")>0, "OK", "MISSING")) | C13: =IF(A13="","",IF(COUNTIFS(Input!$A:$A, A13, Input!$B:$B, "GWE")>0, "OK", "MISSING")) | D13: =IF(A13="","",IF(COUNTIFS(Input!$A:$A, A13, Input!$B:$B, "Schoonmaak")>0, "OK", "MISSING")) | E13: =IF(A13="","",IF(AND(B13="OK",C13="OK",D13="OK"), "✅ READY", "⚠️ INCOMPLETE"))
B14: =IF(A14="","",IF(COUNTIFS(Input!$A:$A, A14, Input!$B:$B, "Basis")>0, "OK", "MISSING")) | C14: =IF(A14="","",IF(COUNTIFS(Input!$A:$A, A14, Input!$B:$B, "GWE")>0, "OK", "MISSING")) | D14: =IF(A14="","",IF(COUNTIFS(Input!$A:$A, A14, Input!$B:$B, "Schoonmaak")>0, "OK", "MISSING")) | E14: =IF(A14="","",IF(AND(B14="OK",C14="OK",D14="OK"), "✅ READY", "⚠️ INCOMPLETE"))
B15: =IF(A15="","",IF(COUNTIFS(Input!$A:$A, A15, Input!$B:$B, "Basis")>0, "OK", "MISSING")) | C15: =IF(A15="","",IF(COUNTIFS(Input!$A:$A, A15, Input!$B:$B, "GWE")>0, "OK", "MISSING")) | D15: =IF(A15="","",IF(COUNTIFS(Input!$A:$A, A15, Input!$B:$B, "Schoonmaak")>0, "OK", "MISSING")) | E15: =IF(A15="","",IF(AND(B15="OK",C15="OK",D15="OK"), "✅ READY", "⚠️ INCOMPLETE"))
B16: =IF(A16="","",IF(COUNTIFS(Input!$A:$A, A16, Input!$B:$B, "Basis")>0, "OK", "MISSING")) | C16: =IF(A16="","",IF(COUNTIFS(Input!$A:$A, A16, Input!$B:$B, "GWE")>0, "OK", "MISSING")) | D16: =IF(A16="","",IF(COUNTIFS(Input!$A:$A, A16, Input!$B:$B, "Schoonmaak")>0, "OK", "MISSING")) | E16: =IF(A16="","",IF(AND(B16="OK",C16="OK",D16="OK"), "✅ READY", "⚠️ INCOMPLETE"))
... B53: =IF(A53="","",IF(COUNTIFS(Input!$A:$A, A53, Input!$B:$B, "Basis")>0, "OK", "MISSING")) | C53: =IF(A53="","",IF(COUNTIFS(Input!$A:$A, A53, Input!$B:$B, "GWE")>0, "OK", "MISSING")) | D53: =IF(A53="","",IF(COUNTIFS(Input!$A:$A, A53, Input!$B:$B, "Schoonmaak")>0, "OK", "MISSING")) | E53: =IF(A53="","",IF(AND(B53="OK",C53="OK",D53="OK"), "✅ READY", "⚠️ INCOMPLETE"))

Sheet Input
A1: Adres | B1: Type | C1: Klantnaam | D1: Object ID | E1: Check-in | F1: Check-out | G1: Borg (€) | H1: GWE Beheer | I1: Meterbeheerder | J1: Leverancier | K1: Contractnr | L1: Extra Voorschot (€) | M1: Extra Voor. Omschr. | N1: Elek Begin | O1: Elek Eind | P1: Gas Begin | Q1: Gas Eind | R1: Water Begin | S1: Water Eind | T1: Schoon Maak Pakket | U1: Schoon Uren | V1: Uurtarief (€) | W1: Totaal Excl (€) | X1: BTW % | Y1: BTW Bedrag (€) | Z1: Totaal Incl (€) | AA1: Kosten Type | AB1: Eenheid | AC1: Beschrijving | AD1: Aantal | AE1: Prijs/Stuk (€) | AF1: Totaal Excl (€) | AG1: BTW % | AH1: BTW Bedrag (€) | AI1: Totaal Incl (€)
A2: Rooseveltlaan 185 | B2: GWE | C2: DS People B.V. | D2: =IF(A2="","",VLOOKUP(A2,Lists!$A:$B,2,FALSE)) -> 0179 | N2: 13598 | O2: 16906 | P2: 11954 | Q2: 15360 | R2: 1128 | S2: 1313 | W2: =IF(AND(U2<>"",V2<>""),U2*V2,"") | Y2: =IF(AND(W2<>"",X2<>""),W2*X2,"") | Z2: =IF(AND(W2<>"",Y2<>""),W2+Y2,"") | AD2: =IF($B2="GWE_Item",IF($AA2="Elektra",SUMIFS($O:$O,$A:$A,$A2,$B:$B,"GWE")-SUMIFS($N:$N,$A:$A,$A2,$B:$B,"GWE"),IF($AA2="Gas",SUMIFS($Q:$Q,$A:$A,$A2,$B:$B,"GWE")-SUMIFS($P:$P,$A:$A,$A2,$B:$B,"GWE"),IF($AA2="Water",SUMIFS($S:$S,$A:$A,$A2,$B:$B,"GWE")-SUMIFS($R:$R,$A:$A,$A2,$B:$B,"GWE"),""))),"") | AF2: =IF(AND(AD2<>"",AE2<>""),AD2*AE2,"") | AH2: =IF(AND(AF2<>"",AG2<>""),AF2*AG2,"") | AI2: =IF(AND(AF2<>"",AH2<>""),AF2+AH2,"")
A3: Rooseveltlaan 185 | B3: GWE_Item | C3: DS People B.V. | D3: =IF(A3="","",VLOOKUP(A3,Lists!$A:$B,2,FALSE)) -> 0179 | W3: =IF(AND(U3<>"",V3<>""),U3*V3,"") | Y3: =IF(AND(W3<>"",X3<>""),W3*X3,"") | Z3: =IF(AND(W3<>"",Y3<>""),W3+Y3,"") | AA3: Water | AB3: =IF(AA3="Elektra","kWh",IF(AA3="Gas","m³",IF(AA3="Water","m³",""))) -> m³ | AC3: Levering | AD3: =IF($B3="GWE_Item",IF($AA3="Elektra",SUMIFS($O:$O,$A:$A,$A3,$B:$B,"GWE")-SUMIFS($N:$N,$A:$A,$A3,$B:$B,"GWE"),IF($AA3="Gas",SUMIFS($Q:$Q,$A:$A,$A3,$B:$B,"GWE")-SUMIFS($P:$P,$A:$A,$A3,$B:$B,"GWE"),IF($AA3="Water",SUMIFS($S:$S,$A:$A,$A3,$B:$B,"GWE")-SUMIFS($R:$R,$A:$A,$A3,$B:$B,"GWE"),""))),"") -> 185 | AE3: 1.29 | AF3: =IF(AND(AD3<>"",AE3<>""),AD3*AE3,"") -> 238.65 | AG3: 0.09 | AH3: =IF(AND(AF3<>"",AG3<>""),AF3*AG3,"") -> 21.4785 | AI3: =IF(AND(AF3<>"",AH3<>""),AF3+AH3,"") -> 260.1285
A4: Rooseveltlaan 185 | B4: GWE_Item | C4: DS People B.V. | D4: =IF(A4="","",VLOOKUP(A4,Lists!$A:$B,2,FALSE)) -> 0179 | W4: =IF(AND(U4<>"",V4<>""),U4*V4,"") | Y4: =IF(AND(W4<>"",X4<>""),W4*X4,"") | Z4: =IF(AND(W4<>"",Y4<>""),W4+Y4,"") | AA4: Water | AB4: =IF(AA4="Elektra","kWh",IF(AA4="Gas","m³",IF(AA4="Water","m³",""))) -> m³ | AC4: Vastrecht | AD4: 579 | AE4: 0.25474 | AF4: =IF(AND(AD4<>"",AE4<>""),AD4*AE4,"") -> 147.49446 | AG4: 0.09 | AH4: =IF(AND(AF4<>"",AG4<>""),AF4*AG4,"") -> 13.274501 | AI4: =IF(AND(AF4<>"",AH4<>""),AF4+AH4,"") -> 160.76896
A5: Rooseveltlaan 185 | B5: GWE_Item | C5: DS People B.V. | D5: =IF(A5="","",VLOOKUP(A5,Lists!$A:$B,2,FALSE)) -> 0179 | W5: =IF(AND(U5<>"",V5<>""),U5*V5,"") | Y5: =IF(AND(W5<>"",X5<>""),W5*X5,"") | Z5: =IF(AND(W5<>"",Y5<>""),W5+Y5,"") | AA5: Water | AB5: =IF(AA5="Elektra","kWh",IF(AA5="Gas","m³",IF(AA5="Water","m³",""))) -> m³ | AC5: Belasting op leiding water | AD5: =IF($B5="GWE_Item",IF($AA5="Elektra",SUMIFS($O:$O,$A:$A,$A5,$B:$B,"GWE")-SUMIFS($N:$N,$A:$A,$A5,$B:$B,"GWE"),IF($AA5="Gas",SUMIFS($Q:$Q,$A:$A,$A5,$B:$B,"GWE")-SUMIFS($P:$P,$A:$A,$A5,$B:$B,"GWE"),IF($AA5="Water",SUMIFS($S:$S,$A:$A,$A5,$B:$B,"GWE")-SUMIFS($R:$R,$A:$A,$A5,$B:$B,"GWE"),""))),"") -> 185 | AE5: 0.458 | AF5: =IF(AND(AD5<>"",AE5<>""),AD5*AE5,"") -> 84.73 | AG5: 0.09 | AH5: =IF(AND(AF5<>"",AG5<>""),AF5*AG5,"") -> 7.6257 | AI5: =IF(AND(AF5<>"",AH5<>""),AF5+AH5,"") -> 92.3557
A6: Rooseveltlaan 185 | B6: GWE_Item | C6: DS People B.V. | D6: =IF(A6="","",VLOOKUP(A6,Lists!$A:$B,2,FALSE)) -> 0179 | W6: =IF(AND(U6<>"",V6<>""),U6*V6,"") | Y6: =IF(AND(W6<>"",X6<>""),W6*X6,"") | Z6: =IF(AND(W6<>"",Y6<>""),W6+Y6,"") | AA6: Water | AB6: =IF(AA6="Elektra","kWh",IF(AA6="Gas","m³",IF(AA6="Water","m³",""))) -> m³ | AC6: Precarioheffing | AD6: =IF($B6="GWE_Item",IF($AA6="Elektra",SUMIFS($O:$O,$A:$A,$A6,$B:$B,"GWE")-SUMIFS($N:$N,$A:$A,$A6,$B:$B,"GWE"),IF($AA6="Gas",SUMIFS($Q:$Q,$A:$A,$A6,$B:$B,"GWE")-SUMIFS($P:$P,$A:$A,$A6,$B:$B,"GWE"),IF($AA6="Water",SUMIFS($S:$S,$A:$A,$A6,$B:$B,"GWE")-SUMIFS($R:$R,$A:$A,$A6,$B:$B,"GWE"),""))),"") -> 185 | AE6: 0.0923 | AF6: =IF(AND(AD6<>"",AE6<>""),AD6*AE6,"") -> 17.0755 | AG6: 0.09 | AH6: =IF(AND(AF6<>"",AG6<>""),AF6*AG6,"") -> 1.536795 | AI6: =IF(AND(AF6<>"",AH6<>""),AF6+AH6,"") -> 18.612295
A7: Rooseveltlaan 185 | B7: GWE_Item | C7: DS People B.V. | D7: =IF(A7="","",VLOOKUP(A7,Lists!$A:$B,2,FALSE)) -> 0179 | W7: =IF(AND(U7<>"",V7<>""),U7*V7,"") | Y7: =IF(AND(W7<>"",X7<>""),W7*X7,"") | Z7: =IF(AND(W7<>"",Y7<>""),W7+Y7,"") | AA7: Elektra | AB7: =IF(AA7="Elektra","kWh",IF(AA7="Gas","m³",IF(AA7="Water","m³",""))) -> kWh | AC7: Enkel tarief | AD7: =IF($B7="GWE_Item",IF($AA7="Elektra",SUMIFS($O:$O,$A:$A,$A7,$B:$B,"GWE")-SUMIFS($N:$N,$A:$A,$A7,$B:$B,"GWE"),IF($AA7="Gas",SUMIFS($Q:$Q,$A:$A,$A7,$B:$B,"GWE")-SUMIFS($P:$P,$A:$A,$A7,$B:$B,"GWE"),IF($AA7="Water",SUMIFS($S:$S,$A:$A,$A7,$B:$B,"GWE")-SUMIFS($R:$R,$A:$A,$A7,$B:$B,"GWE"),""))),"") -> 3308 | AE7: 0.274476 | AF7: =IF(AND(AD7<>"",AE7<>""),AD7*AE7,"") -> 907.96661 | AG7: 0.21 | AH7: =IF(AND(AF7<>"",AG7<>""),AF7*AG7,"") -> 190.67299 | AI7: =IF(AND(AF7<>"",AH7<>""),AF7+AH7,"") -> 1098.6396
A8: Rooseveltlaan 185 | B8: GWE_Item | C8: DS People B.V. | D8: =IF(A8="","",VLOOKUP(A8,Lists!$A:$B,2,FALSE)) -> 0179 | W8: =IF(AND(U8<>"",V8<>""),U8*V8,"") | Y8: =IF(AND(W8<>"",X8<>""),W8*X8,"") | Z8: =IF(AND(W8<>"",Y8<>""),W8+Y8,"") | AA8: Elektra | AB8: dag | AC8: Vaste Leveringskosten (Elektra) | AD8: 579 | AE8: 0.397808 | AF8: =IF(AND(AD8<>"",AE8<>""),AD8*AE8,"") -> 230.33083 | AG8: 0.21 | AH8: =IF(AND(AF8<>"",AG8<>""),AF8*AG8,"") -> 48.369475 | AI8: =IF(AND(AF8<>"",AH8<>""),AF8+AH8,"") -> 278.70031
A9: Rooseveltlaan 185 | B9: GWE_Item | C9: DS People B.V. | D9: =IF(A9="","",VLOOKUP(A9,Lists!$A:$B,2,FALSE)) -> 0179 | W9: =IF(AND(U9<>"",V9<>""),U9*V9,"") | Y9: =IF(AND(W9<>"",X9<>""),W9*X9,"") | Z9: =IF(AND(W9<>"",Y9<>""),W9+Y9,"") | AA9: Elektra | AB9: dag | AC9: Vermindering Energie belasting | AD9: 579 | AE9: -1.740245 | AF9: =IF(AND(AD9<>"",AE9<>""),AD9*AE9,"") -> -1007.6019 | AG9: 0.21 | AH9: =IF(AND(AF9<>"",AG9<>""),AF9*AG9,"") -> -211.59639 | AI9: =IF(AND(AF9<>"",AH9<>""),AF9+AH9,"") -> -1219.1982
A10: Rooseveltlaan 185 | B10: GWE_Item | C10: DS People B.V. | D10: =IF(A10="","",VLOOKUP(A10,Lists!$A:$B,2,FALSE)) -> 0179 | W10: =IF(AND(U10<>"",V10<>""),U10*V10,"") | Y10: =IF(AND(W10<>"",X10<>""),W10*X10,"") | Z10: =IF(AND(W10<>"",Y10<>""),W10+Y10,"") | AA10: Elektra | AB10: dag | AC10: Net beheerkosten 3 x 25 p/d (elektra) | AD10: 579 | AE10: 1.303896 | AF10: =IF(AND(AD10<>"",AE10<>""),AD10*AE10,"") -> 754.95578 | AG10: 0.21 | AH10: =IF(AND(AF10<>"",AG10<>""),AF10*AG10,"") -> 158.54071 | AI10: =IF(AND(AF10<>"",AH10<>""),AF10+AH10,"") -> 913.4965
A11: Rooseveltlaan 185 | B11: GWE_Item | C11: DS People B.V. | D11: =IF(A11="","",VLOOKUP(A11,Lists!$A:$B,2,FALSE)) -> 0179 | W11: =IF(AND(U11<>"",V11<>""),U11*V11,"") | Y11: =IF(AND(W11<>"",X11<>""),W11*X11,"") | Z11: =IF(AND(W11<>"",Y11<>""),W11+Y11,"") | AA11: Gas | AB11: =IF(AA11="Elektra","kWh",IF(AA11="Gas","m³",IF(AA11="Water","m³",""))) -> m³ | AC11: Gas Verbruik | AD11: =IF($B11="GWE_Item",IF($AA11="Elektra",SUMIFS($O:$O,$A:$A,$A11,$B:$B,"GWE")-SUMIFS($N:$N,$A:$A,$A11,$B:$B,"GWE"),IF($AA11="Gas",SUMIFS($Q:$Q,$A:$A,$A11,$B:$B,"GWE")-SUMIFS($P:$P,$A:$A,$A11,$B:$B,"GWE"),IF($AA11="Water",SUMIFS($S:$S,$A:$A,$A11,$B:$B,"GWE")-SUMIFS($R:$R,$A:$A,$A11,$B:$B,"GWE"),""))),"") -> 3406 | AE11: 1.287755 | AF11: =IF(AND(AD11<>"",AE11<>""),AD11*AE11,"") -> 4386.0935 | AG11: 0.21 | AH11: =IF(AND(AF11<>"",AG11<>""),AF11*AG11,"") -> 921.07964 | AI11: =IF(AND(AF11<>"",AH11<>""),AF11+AH11,"") -> 5307.1732
A12: Rooseveltlaan 185 | B12: GWE_Item | C12: DS People B.V. | D12: =IF(A12="","",VLOOKUP(A12,Lists!$A:$B,2,FALSE)) -> 0179 | W12: =IF(AND(U12<>"",V12<>""),U12*V12,"") | Y12: =IF(AND(W12<>"",X12<>""),W12*X12,"") | Z12: =IF(AND(W12<>"",Y12<>""),W12+Y12,"") | AA12: Gas | AB12: dag | AC12: Vaste Leveringskosten (Gas) | AD12: 579 | AE12: 0.298356 | AF12: =IF(AND(AD12<>"",AE12<>""),AD12*AE12,"") -> 172.74812 | AG12: 0.21 | AH12: =IF(AND(AF12<>"",AG12<>""),AF12*AG12,"") -> 36.277106 | AI12: =IF(AND(AF12<>"",AH12<>""),AF12+AH12,"") -> 209.02523
A13: Rooseveltlaan 185 | B13: GWE_Item | C13: DS People B.V. | D13: =IF(A13="","",VLOOKUP(A13,Lists!$A:$B,2,FALSE)) -> 0179 | W13: =IF(AND(U13<>"",V13<>""),U13*V13,"") | Y13: =IF(AND(W13<>"",X13<>""),W13*X13,"") | Z13: =IF(AND(W13<>"",Y13<>""),W13+Y13,"") | AA13: Gas | AB13: dag | AC13: Net beheerkosten 3 x 25 p/d (gas) | AD13: 579 | AE13: 0.674212 | AF13: =IF(AND(AD13<>"",AE13<>""),AD13*AE13,"") -> 390.36875 | AG13: 0.21 | AH13: =IF(AND(AF13<>"",AG13<>""),AF13*AG13,"") -> 81.977437 | AI13: =IF(AND(AF13<>"",AH13<>""),AF13+AH13,"") -> 472.34619
A14: Rooseveltlaan 185 | B14: Schoonmaak | C14: DS People B.V. | D14: =IF(A14="","",VLOOKUP(A14,Lists!$A:$B,2,FALSE)) -> 0179 | T14: Intensief Schoonmaak | U14: 7 | V14: 50 | W14: =IF(AND(U14<>"",V14<>""),U14*V14,"") -> 350 | X14: 0.21 | Y14: =IF(AND(W14<>"",X14<>""),W14*X14,"") -> 73.5 | Z14: =IF(AND(W14<>"",Y14<>""),W14+Y14,"") -> 423.5 | AD14: =IF($B14="GWE_Item",IF($AA14="Elektra",SUMIFS($O:$O,$A:$A,$A14,$B:$B,"GWE")-SUMIFS($N:$N,$A:$A,$A14,$B:$B,"GWE"),IF($AA14="Gas",SUMIFS($Q:$Q,$A:$A,$A14,$B:$B,"GWE")-SUMIFS($P:$P,$A:$A,$A14,$B:$B,"GWE"),IF($AA14="Water",SUMIFS($S:$S,$A:$A,$A14,$B:$B,"GWE")-SUMIFS($R:$R,$A:$A,$A14,$B:$B,"GWE"),""))),"") | AF14: =IF(AND(AD14<>"",AE14<>""),AD14*AE14,"") | AH14: =IF(AND(AF14<>"",AG14<>""),AF14*AG14,"") | AI14: =IF(AND(AF14<>"",AH14<>""),AF14+AH14,"")
A15: Rooseveltlaan 185 | B15: Basis | C15: DS People B.V. | D15: =IF(A15="","",VLOOKUP(A15,Lists!$A:$B,2,FALSE)) -> 0179 | E15: 45382 | F15: 45961 | G15: 3100 | H15: Via RyanRent | I15: Vattenfall | J15: Vattenfall | W15: =IF(AND(U15<>"",V15<>""),U15*V15,"") | Y15: =IF(AND(W15<>"",X15<>""),W15*X15,"") | Z15: =IF(AND(W15<>"",Y15<>""),W15+Y15,"") | AD15: =IF($B15="GWE_Item",IF($AA15="Elektra",SUMIFS($O:$O,$A:$A,$A15,$B:$B,"GWE")-SUMIFS($N:$N,$A:$A,$A15,$B:$B,"GWE"),IF($AA15="Gas",SUMIFS($Q:$Q,$A:$A,$A15,$B:$B,"GWE")-SUMIFS($P:$P,$A:$A,$A15,$B:$B,"GWE"),IF($AA15="Water",SUMIFS($S:$S,$A:$A,$A15,$B:$B,"GWE")-SUMIFS($R:$R,$A:$A,$A15,$B:$B,"GWE"),""))),"") | AF15: =IF(AND(AD15<>"",AE15<>""),AD15*AE15,"") | AH15: =IF(AND(AF15<>"",AG15<>""),AF15*AG15,"") | AI15: =IF(AND(AF15<>"",AH15<>""),AF15+AH15,"")
A16: 2e Maasbosstraat 2 c | B16: Basis | C16: A. Dzaka | D16: =IF(A16="","",VLOOKUP(A16,Lists!$A:$B,2,FALSE)) -> 0150 | W16: =IF(AND(U16<>"",V16<>""),U16*V16,"") | Y16: =IF(AND(W16<>"",X16<>""),W16*X16,"") | Z16: =IF(AND(W16<>"",Y16<>""),W16+Y16,"") | AD16: =IF($B16="GWE_Item",IF($AA16="Elektra",SUMIFS($O:$O,$A:$A,$A16,$B:$B,"GWE")-SUMIFS($N:$N,$A:$A,$A16,$B:$B,"GWE"),IF($AA16="Gas",SUMIFS($Q:$Q,$A:$A,$A16,$B:$B,"GWE")-SUMIFS($P:$P,$A:$A,$A16,$B:$B,"GWE"),IF($AA16="Water",SUMIFS($S:$S,$A:$A,$A16,$B:$B,"GWE")-SUMIFS($R:$R,$A:$A,$A16,$B:$B,"GWE"),""))),"") | AF16: =IF(AND(AD16<>"",AE16<>""),AD16*AE16,"") | AH16: =IF(AND(AF16<>"",AG16<>""),AF16*AG16,"") | AI16: =IF(AND(AF16<>"",AH16<>""),AF16+AH16,"")
A17: 2e Maasbosstraat 2 c | D17: =IF(A17="","",VLOOKUP(A17,Lists!$A:$B,2,FALSE)) -> 0150 | W17: =IF(AND(U17<>"",V17<>""),U17*V17,"") | Y17: =IF(AND(W17<>"",X17<>""),W17*X17,"") | Z17: =IF(AND(W17<>"",Y17<>""),W17+Y17,"") | AD17: =IF($B17="GWE_Item",IF($AA17="Elektra",SUMIFS($O:$O,$A:$A,$A17,$B:$B,"GWE")-SUMIFS($N:$N,$A:$A,$A17,$B:$B,"GWE"),IF($AA17="Gas",SUMIFS($Q:$Q,$A:$A,$A17,$B:$B,"GWE")-SUMIFS($P:$P,$A:$A,$A17,$B:$B,"GWE"),IF($AA17="Water",SUMIFS($S:$S,$A:$A,$A17,$B:$B,"GWE")-SUMIFS($R:$R,$A:$A,$A17,$B:$B,"GWE"),""))),"") | AF17: =IF(AND(AD17<>"",AE17<>""),AD17*AE17,"") | AH17: =IF(AND(AF17<>"",AG17<>""),AF17*AG17,"") | AI17: =IF(AND(AF17<>"",AH17<>""),AF17+AH17,"")
A18: 2e Maasbosstraat 2 c | D18: =IF(A18="","",VLOOKUP(A18,Lists!$A:$B,2,FALSE)) -> 0150 | W18: =IF(AND(U18<>"",V18<>""),U18*V18,"") | Y18: =IF(AND(W18<>"",X18<>""),W18*X18,"") | Z18: =IF(AND(W18<>"",Y18<>""),W18+Y18,"") | AD18: =IF($B18="GWE_Item",IF($AA18="Elektra",SUMIFS($O:$O,$A:$A,$A18,$B:$B,"GWE")-SUMIFS($N:$N,$A:$A,$A18,$B:$B,"GWE"),IF($AA18="Gas",SUMIFS($Q:$Q,$A:$A,$A18,$B:$B,"GWE")-SUMIFS($P:$P,$A:$A,$A18,$B:$B,"GWE"),IF($AA18="Water",SUMIFS($S:$S,$A:$A,$A18,$B:$B,"GWE")-SUMIFS($R:$R,$A:$A,$A18,$B:$B,"GWE"),""))),"") | AF18: =IF(AND(AD18<>"",AE18<>""),AD18*AE18,"") | AH18: =IF(AND(AF18<>"",AG18<>""),AF18*AG18,"") | AI18: =IF(AND(AF18<>"",AH18<>""),AF18+AH18,"")
A19: 2e Maasbosstraat 2 c | D19: =IF(A19="","",VLOOKUP(A19,Lists!$A:$B,2,FALSE)) -> 0150 | W19: =IF(AND(U19<>"",V19<>""),U19*V19,"") | Y19: =IF(AND(W19<>"",X19<>""),W19*X19,"") | Z19: =IF(AND(W19<>"",Y19<>""),W19+Y19,"") | AD19: =IF($B19="GWE_Item",IF($AA19="Elektra",SUMIFS($O:$O,$A:$A,$A19,$B:$B,"GWE")-SUMIFS($N:$N,$A:$A,$A19,$B:$B,"GWE"),IF($AA19="Gas",SUMIFS($Q:$Q,$A:$A,$A19,$B:$B,"GWE")-SUMIFS($P:$P,$A:$A,$A19,$B:$B,"GWE"),IF($AA19="Water",SUMIFS($S:$S,$A:$A,$A19,$B:$B,"GWE")-SUMIFS($R:$R,$A:$A,$A19,$B:$B,"GWE"),""))),"") | AF19: =IF(AND(AD19<>"",AE19<>""),AD19*AE19,"") | AH19: =IF(AND(AF19<>"",AG19<>""),AF19*AG19,"") | AI19: =IF(AND(AF19<>"",AH19<>""),AF19+AH19,"")
A20: 2e Maasbosstraat 2 c | D20: =IF(A20="","",VLOOKUP(A20,Lists!$A:$B,2,FALSE)) -> 0150 | W20: =IF(AND(U20<>"",V20<>""),U20*V20,"") | Y20: =IF(AND(W20<>"",X20<>""),W20*X20,"") | Z20: =IF(AND(W20<>"",Y20<>""),W20+Y20,"") | AD20: =IF($B20="GWE_Item",IF($AA20="Elektra",SUMIFS($O:$O,$A:$A,$A20,$B:$B,"GWE")-SUMIFS($N:$N,$A:$A,$A20,$B:$B,"GWE"),IF($AA20="Gas",SUMIFS($Q:$Q,$A:$A,$A20,$B:$B,"GWE")-SUMIFS($P:$P,$A:$A,$A20,$B:$B,"GWE"),IF($AA20="Water",SUMIFS($S:$S,$A:$A,$A20,$B:$B,"GWE")-SUMIFS($R:$R,$A:$A,$A20,$B:$B,"GWE"),""))),"") | AF20: =IF(AND(AD20<>"",AE20<>""),AD20*AE20,"") | AH20: =IF(AND(AF20<>"",AG20<>""),AF20*AG20,"") | AI20: =IF(AND(AF20<>"",AH20<>""),AF20+AH20,"")
A21: 2e Maasbosstraat 2 c | D21: =IF(A21="","",VLOOKUP(A21,Lists!$A:$B,2,FALSE)) -> 0150 | W21: =IF(AND(U21<>"",V21<>""),U21*V21,"") | Y21: =IF(AND(W21<>"",X21<>""),W21*X21,"") | Z21: =IF(AND(W21<>"",Y21<>""),W21+Y21,"") | AD21: =IF($B21="GWE_Item",IF($AA21="Elektra",SUMIFS($O:$O,$A:$A,$A21,$B:$B,"GWE")-SUMIFS($N:$N,$A:$A,$A21,$B:$B,"GWE"),IF($AA21="Gas",SUMIFS($Q:$Q,$A:$A,$A21,$B:$B,"GWE")-SUMIFS($P:$P,$A:$A,$A21,$B:$B,"GWE"),IF($AA21="Water",SUMIFS($S:$S,$A:$A,$A21,$B:$B,"GWE")-SUMIFS($R:$R,$A:$A,$A21,$B:$B,"GWE"),""))),"") | AF21: =IF(AND(AD21<>"",AE21<>""),AD21*AE21,"") | AH21: =IF(AND(AF21<>"",AG21<>""),AF21*AG21,"") | AI21: =IF(AND(AF21<>"",AH21<>""),AF21+AH21,"")
A22: 2e Maasbosstraat 2 c | D22: =IF(A22="","",VLOOKUP(A22,Lists!$A:$B,2,FALSE)) -> 0150 | W22: =IF(AND(U22<>"",V22<>""),U22*V22,"") | Y22: =IF(AND(W22<>"",X22<>""),W22*X22,"") | Z22: =IF(AND(W22<>"",Y22<>""),W22+Y22,"") | AD22: =IF($B22="GWE_Item",IF($AA22="Elektra",SUMIFS($O:$O,$A:$A,$A22,$B:$B,"GWE")-SUMIFS($N:$N,$A:$A,$A22,$B:$B,"GWE"),IF($AA22="Gas",SUMIFS($Q:$Q,$A:$A,$A22,$B:$B,"GWE")-SUMIFS($P:$P,$A:$A,$A22,$B:$B,"GWE"),IF($AA22="Water",SUMIFS($S:$S,$A:$A,$A22,$B:$B,"GWE")-SUMIFS($R:$R,$A:$A,$A22,$B:$B,"GWE"),""))),"") | AF22: =IF(AND(AD22<>"",AE22<>""),AD22*AE22,"") | AH22: =IF(AND(AF22<>"",AG22<>""),AF22*AG22,"") | AI22: =IF(AND(AF22<>"",AH22<>""),AF22+AH22,"")
A23: 2e Maasbosstraat 2 c | D23: =IF(A23="","",VLOOKUP(A23,Lists!$A:$B,2,FALSE)) -> 0150 | W23: =IF(AND(U23<>"",V23<>""),U23*V23,"") | Y23: =IF(AND(W23<>"",X23<>""),W23*X23,"") | Z23: =IF(AND(W23<>"",Y23<>""),W23+Y23,"") | AD23: =IF($B23="GWE_Item",IF($AA23="Elektra",SUMIFS($O:$O,$A:$A,$A23,$B:$B,"GWE")-SUMIFS($N:$N,$A:$A,$A23,$B:$B,"GWE"),IF($AA23="Gas",SUMIFS($Q:$Q,$A:$A,$A23,$B:$B,"GWE")-SUMIFS($P:$P,$A:$A,$A23,$B:$B,"GWE"),IF($AA23="Water",SUMIFS($S:$S,$A:$A,$A23,$B:$B,"GWE")-SUMIFS($R:$R,$A:$A,$A23,$B:$B,"GWE"),""))),"") | AF23: =IF(AND(AD23<>"",AE23<>""),AD23*AE23,"") | AH23: =IF(AND(AF23<>"",AG23<>""),AF23*AG23,"") | AI23: =IF(AND(AF23<>"",AH23<>""),AF23+AH23,"")
A24: 2e Maasbosstraat 2 c | D24: =IF(A24="","",VLOOKUP(A24,Lists!$A:$B,2,FALSE)) -> 0150 | W24: =IF(AND(U24<>"",V24<>""),U24*V24,"") | Y24: =IF(AND(W24<>"",X24<>""),W24*X24,"") | Z24: =IF(AND(W24<>"",Y24<>""),W24+Y24,"") | AD24: =IF($B24="GWE_Item",IF($AA24="Elektra",SUMIFS($O:$O,$A:$A,$A24,$B:$B,"GWE")-SUMIFS($N:$N,$A:$A,$A24,$B:$B,"GWE"),IF($AA24="Gas",SUMIFS($Q:$Q,$A:$A,$A24,$B:$B,"GWE")-SUMIFS($P:$P,$A:$A,$A24,$B:$B,"GWE"),IF($AA24="Water",SUMIFS($S:$S,$A:$A,$A24,$B:$B,"GWE")-SUMIFS($R:$R,$A:$A,$A24,$B:$B,"GWE"),""))),"") | AF24: =IF(AND(AD24<>"",AE24<>""),AD24*AE24,"") | AH24: =IF(AND(AF24<>"",AG24<>""),AF24*AG24,"") | AI24: =IF(AND(AF24<>"",AH24<>""),AF24+AH24,"")
A25: 2e Maasbosstraat 2 c | D25: =IF(A25="","",VLOOKUP(A25,Lists!$A:$B,2,FALSE)) -> 0150 | W25: =IF(AND(U25<>"",V25<>""),U25*V25,"") | Y25: =IF(AND(W25<>"",X25<>""),W25*X25,"") | Z25: =IF(AND(W25<>"",Y25<>""),W25+Y25,"") | AD25: =IF($B25="GWE_Item",IF($AA25="Elektra",SUMIFS($O:$O,$A:$A,$A25,$B:$B,"GWE")-SUMIFS($N:$N,$A:$A,$A25,$B:$B,"GWE"),IF($AA25="Gas",SUMIFS($Q:$Q,$A:$A,$A25,$B:$B,"GWE")-SUMIFS($P:$P,$A:$A,$A25,$B:$B,"GWE"),IF($AA25="Water",SUMIFS($S:$S,$A:$A,$A25,$B:$B,"GWE")-SUMIFS($R:$R,$A:$A,$A25,$B:$B,"GWE"),""))),"") | AF25: =IF(AND(AD25<>"",AE25<>""),AD25*AE25,"") | AH25: =IF(AND(AF25<>"",AG25<>""),AF25*AG25,"") | AI25: =IF(AND(AF25<>"",AH25<>""),AF25+AH25,"")
A26: 2e Maasbosstraat 2 c | D26: =IF(A26="","",VLOOKUP(A26,Lists!$A:$B,2,FALSE)) -> 0150 | W26: =IF(AND(U26<>"",V26<>""),U26*V26,"") | Y26: =IF(AND(W26<>"",X26<>""),W26*X26,"") | Z26: =IF(AND(W26<>"",Y26<>""),W26+Y26,"") | AD26: =IF($B26="GWE_Item",IF($AA26="Elektra",SUMIFS($O:$O,$A:$A,$A26,$B:$B,"GWE")-SUMIFS($N:$N,$A:$A,$A26,$B:$B,"GWE"),IF($AA26="Gas",SUMIFS($Q:$Q,$A:$A,$A26,$B:$B,"GWE")-SUMIFS($P:$P,$A:$A,$A26,$B:$B,"GWE"),IF($AA26="Water",SUMIFS($S:$S,$A:$A,$A26,$B:$B,"GWE")-SUMIFS($R:$R,$A:$A,$A26,$B:$B,"GWE"),""))),"") | AF26: =IF(AND(AD26<>"",AE26<>""),AD26*AE26,"") | AH26: =IF(AND(AF26<>"",AG26<>""),AF26*AG26,"") | AI26: =IF(AND(AF26<>"",AH26<>""),AF26+AH26,"")
A27: 2e Maasbosstraat 2 c | D27: =IF(A27="","",VLOOKUP(A27,Lists!$A:$B,2,FALSE)) -> 0150 | W27: =IF(AND(U27<>"",V27<>""),U27*V27,"") | Y27: =IF(AND(W27<>"",X27<>""),W27*X27,"") | Z27: =IF(AND(W27<>"",Y27<>""),W27+Y27,"") | AD27: =IF($B27="GWE_Item",IF($AA27="Elektra",SUMIFS($O:$O,$A:$A,$A27,$B:$B,"GWE")-SUMIFS($N:$N,$A:$A,$A27,$B:$B,"GWE"),IF($AA27="Gas",SUMIFS($Q:$Q,$A:$A,$A27,$B:$B,"GWE")-SUMIFS($P:$P,$A:$A,$A27,$B:$B,"GWE"),IF($AA27="Water",SUMIFS($S:$S,$A:$A,$A27,$B:$B,"GWE")-SUMIFS($R:$R,$A:$A,$A27,$B:$B,"GWE"),""))),"") | AF27: =IF(AND(AD27<>"",AE27<>""),AD27*AE27,"") | AH27: =IF(AND(AF27<>"",AG27<>""),AF27*AG27,"") | AI27: =IF(AND(AF27<>"",AH27<>""),AF27+AH27,"")
A28: 2e Maasbosstraat 2 c | D28: =IF(A28="","",VLOOKUP(A28,Lists!$A:$B,2,FALSE)) -> 0150 | W28: =IF(AND(U28<>"",V28<>""),U28*V28,"") | Y28: =IF(AND(W28<>"",X28<>""),W28*X28,"") | Z28: =IF(AND(W28<>"",Y28<>""),W28+Y28,"") | AD28: =IF($B28="GWE_Item",IF($AA28="Elektra",SUMIFS($O:$O,$A:$A,$A28,$B:$B,"GWE")-SUMIFS($N:$N,$A:$A,$A28,$B:$B,"GWE"),IF($AA28="Gas",SUMIFS($Q:$Q,$A:$A,$A28,$B:$B,"GWE")-SUMIFS($P:$P,$A:$A,$A28,$B:$B,"GWE"),IF($AA28="Water",SUMIFS($S:$S,$A:$A,$A28,$B:$B,"GWE")-SUMIFS($R:$R,$A:$A,$A28,$B:$B,"GWE"),""))),"") | AF28: =IF(AND(AD28<>"",AE28<>""),AD28*AE28,"") | AH28: =IF(AND(AF28<>"",AG28<>""),AF28*AG28,"") | AI28: =IF(AND(AF28<>"",AH28<>""),AF28+AH28,"")
... A32: 2e Maasbosstraat 2 c | D32: =IF(A32="","",VLOOKUP(A32,Lists!$A:$B,2,FALSE)) -> 0150 | W32: =IF(AND(U32<>"",V32<>""),U32*V32,"") | Y32: =IF(AND(W32<>"",X32<>""),W32*X32,"") | Z32: =IF(AND(W32<>"",Y32<>""),W32+Y32,"") | AD32: =IF($B32="GWE_Item",IF($AA32="Elektra",SUMIFS($O:$O,$A:$A,$A32,$B:$B,"GWE")-SUMIFS($N:$N,$A:$A,$A32,$B:$B,"GWE"),IF($AA32="Gas",SUMIFS($Q:$Q,$A:$A,$A32,$B:$B,"GWE")-SUMIFS($P:$P,$A:$A,$A32,$B:$B,"GWE"),IF($AA32="Water",SUMIFS($S:$S,$A:$A,$A32,$B:$B,"GWE")-SUMIFS($R:$R,$A:$A,$A32,$B:$B,"GWE"),""))),"") | AF32: =IF(AND(AD32<>"",AE32<>""),AD32*AE32,"") | AH32: =IF(AND(AF32<>"",AG32<>""),AF32*AG32,"") | AI32: =IF(AND(AF32<>"",AH32<>""),AF32+AH32,"")
D33: =IF(A33="","",VLOOKUP(A33,Lists!$A:$B,2,FALSE)) | W33: =IF(AND(U33<>"",V33<>""),U33*V33,"") | Y33: =IF(AND(W33<>"",X33<>""),W33*X33,"") | Z33: =IF(AND(W33<>"",Y33<>""),W33+Y33,"") | AD33: =IF($B33="GWE_Item",IF($AA33="Elektra",SUMIFS($O:$O,$A:$A,$A33,$B:$B,"GWE")-SUMIFS($N:$N,$A:$A,$A33,$B:$B,"GWE"),IF($AA33="Gas",SUMIFS($Q:$Q,$A:$A,$A33,$B:$B,"GWE")-SUMIFS($P:$P,$A:$A,$A33,$B:$B,"GWE"),IF($AA33="Water",SUMIFS($S:$S,$A:$A,$A33,$B:$B,"GWE")-SUMIFS($R:$R,$A:$A,$A33,$B:$B,"GWE"),""))),"") | AF33: =IF(AND(AD33<>"",AE33<>""),AD33*AE33,"") | AH33: =IF(AND(AF33<>"",AG33<>""),AF33*AG33,"") | AI33: =IF(AND(AF33<>"",AH33<>""),AF33+AH33,"")
D34: =IF(A34="","",VLOOKUP(A34,Lists!$A:$B,2,FALSE)) | W34: =IF(AND(U34<>"",V34<>""),U34*V34,"") | Y34: =IF(AND(W34<>"",X34<>""),W34*X34,"") | Z34: =IF(AND(W34<>"",Y34<>""),W34+Y34,"") | AD34: =IF($B34="GWE_Item",IF($AA34="Elektra",SUMIFS($O:$O,$A:$A,$A34,$B:$B,"GWE")-SUMIFS($N:$N,$A:$A,$A34,$B:$B,"GWE"),IF($AA34="Gas",SUMIFS($Q:$Q,$A:$A,$A34,$B:$B,"GWE")-SUMIFS($P:$P,$A:$A,$A34,$B:$B,"GWE"),IF($AA34="Water",SUMIFS($S:$S,$A:$A,$A34,$B:$B,"GWE")-SUMIFS($R:$R,$A:$A,$A34,$B:$B,"GWE"),""))),"") | AF34: =IF(AND(AD34<>"",AE34<>""),AD34*AE34,"") | AH34: =IF(AND(AF34<>"",AG34<>""),AF34*AG34,"") | AI34: =IF(AND(AF34<>"",AH34<>""),AF34+AH34,"")
D35: =IF(A35="","",VLOOKUP(A35,Lists!$A:$B,2,FALSE)) | W35: =IF(AND(U35<>"",V35<>""),U35*V35,"") | Y35: =IF(AND(W35<>"",X35<>""),W35*X35,"") | Z35: =IF(AND(W35<>"",Y35<>""),W35+Y35,"") | AD35: =IF($B35="GWE_Item",IF($AA35="Elektra",SUMIFS($O:$O,$A:$A,$A35,$B:$B,"GWE")-SUMIFS($N:$N,$A:$A,$A35,$B:$B,"GWE"),IF($AA35="Gas",SUMIFS($Q:$Q,$A:$A,$A35,$B:$B,"GWE")-SUMIFS($P:$P,$A:$A,$A35,$B:$B,"GWE"),IF($AA35="Water",SUMIFS($S:$S,$A:$A,$A35,$B:$B,"GWE")-SUMIFS($R:$R,$A:$A,$A35,$B:$B,"GWE"),""))),"") | AF35: =IF(AND(AD35<>"",AE35<>""),AD35*AE35,"") | AH35: =IF(AND(AF35<>"",AG35<>""),AF35*AG35,"") | AI35: =IF(AND(AF35<>"",AH35<>""),AF35+AH35,"")
D36: =IF(A36="","",VLOOKUP(A36,Lists!$A:$B,2,FALSE)) | W36: =IF(AND(U36<>"",V36<>""),U36*V36,"") | Y36: =IF(AND(W36<>"",X36<>""),W36*X36,"") | Z36: =IF(AND(W36<>"",Y36<>""),W36+Y36,"") | AD36: =IF($B36="GWE_Item",IF($AA36="Elektra",SUMIFS($O:$O,$A:$A,$A36,$B:$B,"GWE")-SUMIFS($N:$N,$A:$A,$A36,$B:$B,"GWE"),IF($AA36="Gas",SUMIFS($Q:$Q,$A:$A,$A36,$B:$B,"GWE")-SUMIFS($P:$P,$A:$A,$A36,$B:$B,"GWE"),IF($AA36="Water",SUMIFS($S:$S,$A:$A,$A36,$B:$B,"GWE")-SUMIFS($R:$R,$A:$A,$A36,$B:$B,"GWE"),""))),"") | AF36: =IF(AND(AD36<>"",AE36<>""),AD36*AE36,"") | AH36: =IF(AND(AF36<>"",AG36<>""),AF36*AG36,"") | AI36: =IF(AND(AF36<>"",AH36<>""),AF36+AH36,"")
D37: =IF(A37="","",VLOOKUP(A37,Lists!$A:$B,2,FALSE)) | W37: =IF(AND(U37<>"",V37<>""),U37*V37,"") | Y37: =IF(AND(W37<>"",X37<>""),W37*X37,"") | Z37: =IF(AND(W37<>"",Y37<>""),W37+Y37,"") | AD37: =IF($B37="GWE_Item",IF($AA37="Elektra",SUMIFS($O:$O,$A:$A,$A37,$B:$B,"GWE")-SUMIFS($N:$N,$A:$A,$A37,$B:$B,"GWE"),IF($AA37="Gas",SUMIFS($Q:$Q,$A:$A,$A37,$B:$B,"GWE")-SUMIFS($P:$P,$A:$A,$A37,$B:$B,"GWE"),IF($AA37="Water",SUMIFS($S:$S,$A:$A,$A37,$B:$B,"GWE")-SUMIFS($R:$R,$A:$A,$A37,$B:$B,"GWE"),""))),"") | AF37: =IF(AND(AD37<>"",AE37<>""),AD37*AE37,"") | AH37: =IF(AND(AF37<>"",AG37<>""),AF37*AG37,"") | AI37: =IF(AND(AF37<>"",AH37<>""),AF37+AH37,"")
D38: =IF(A38="","",VLOOKUP(A38,Lists!$A:$B,2,FALSE)) | W38: =IF(AND(U38<>"",V38<>""),U38*V38,"") | Y38: =IF(AND(W38<>"",X38<>""),W38*X38,"") | Z38: =IF(AND(W38<>"",Y38<>""),W38+Y38,"") | AD38: =IF($B38="GWE_Item",IF($AA38="Elektra",SUMIFS($O:$O,$A:$A,$A38,$B:$B,"GWE")-SUMIFS($N:$N,$A:$A,$A38,$B:$B,"GWE"),IF($AA38="Gas",SUMIFS($Q:$Q,$A:$A,$A38,$B:$B,"GWE")-SUMIFS($P:$P,$A:$A,$A38,$B:$B,"GWE"),IF($AA38="Water",SUMIFS($S:$S,$A:$A,$A38,$B:$B,"GWE")-SUMIFS($R:$R,$A:$A,$A38,$B:$B,"GWE"),""))),"") | AF38: =IF(AND(AD38<>"",AE38<>""),AD38*AE38,"") | AH38: =IF(AND(AF38<>"",AG38<>""),AF38*AG38,"") | AI38: =IF(AND(AF38<>"",AH38<>""),AF38+AH38,"")
D39: =IF(A39="","",VLOOKUP(A39,Lists!$A:$B,2,FALSE)) | W39: =IF(AND(U39<>"",V39<>""),U39*V39,"") | Y39: =IF(AND(W39<>"",X39<>""),W39*X39,"") | Z39: =IF(AND(W39<>"",Y39<>""),W39+Y39,"") | AD39: =IF($B39="GWE_Item",IF($AA39="Elektra",SUMIFS($O:$O,$A:$A,$A39,$B:$B,"GWE")-SUMIFS($N:$N,$A:$A,$A39,$B:$B,"GWE"),IF($AA39="Gas",SUMIFS($Q:$Q,$A:$A,$A39,$B:$B,"GWE")-SUMIFS($P:$P,$A:$A,$A39,$B:$B,"GWE"),IF($AA39="Water",SUMIFS($S:$S,$A:$A,$A39,$B:$B,"GWE")-SUMIFS($R:$R,$A:$A,$A39,$B:$B,"GWE"),""))),"") | AF39: =IF(AND(AD39<>"",AE39<>""),AD39*AE39,"") | AH39: =IF(AND(AF39<>"",AG39<>""),AF39*AG39,"") | AI39: =IF(AND(AF39<>"",AH39<>""),AF39+AH39,"")
D40: =IF(A40="","",VLOOKUP(A40,Lists!$A:$B,2,FALSE)) | W40: =IF(AND(U40<>"",V40<>""),U40*V40,"") | Y40: =IF(AND(W40<>"",X40<>""),W40*X40,"") | Z40: =IF(AND(W40<>"",Y40<>""),W40+Y40,"") | AD40: =IF($B40="GWE_Item",IF($AA40="Elektra",SUMIFS($O:$O,$A:$A,$A40,$B:$B,"GWE")-SUMIFS($N:$N,$A:$A,$A40,$B:$B,"GWE"),IF($AA40="Gas",SUMIFS($Q:$Q,$A:$A,$A40,$B:$B,"GWE")-SUMIFS($P:$P,$A:$A,$A40,$B:$B,"GWE"),IF($AA40="Water",SUMIFS($S:$S,$A:$A,$A40,$B:$B,"GWE")-SUMIFS($R:$R,$A:$A,$A40,$B:$B,"GWE"),""))),"") | AF40: =IF(AND(AD40<>"",AE40<>""),AD40*AE40,"") | AH40: =IF(AND(AF40<>"",AG40<>""),AF40*AG40,"") | AI40: =IF(AND(AF40<>"",AH40<>""),AF40+AH40,"")
D41: =IF(A41="","",VLOOKUP(A41,Lists!$A:$B,2,FALSE)) | W41: =IF(AND(U41<>"",V41<>""),U41*V41,"") | Y41: =IF(AND(W41<>"",X41<>""),W41*X41,"") | Z41: =IF(AND(W41<>"",Y41<>""),W41+Y41,"") | AD41: =IF($B41="GWE_Item",IF($AA41="Elektra",SUMIFS($O:$O,$A:$A,$A41,$B:$B,"GWE")-SUMIFS($N:$N,$A:$A,$A41,$B:$B,"GWE"),IF($AA41="Gas",SUMIFS($Q:$Q,$A:$A,$A41,$B:$B,"GWE")-SUMIFS($P:$P,$A:$A,$A41,$B:$B,"GWE"),IF($AA41="Water",SUMIFS($S:$S,$A:$A,$A41,$B:$B,"GWE")-SUMIFS($R:$R,$A:$A,$A41,$B:$B,"GWE"),""))),"") | AF41: =IF(AND(AD41<>"",AE41<>""),AD41*AE41,"") | AH41: =IF(AND(AF41<>"",AG41<>""),AF41*AG41,"") | AI41: =IF(AND(AF41<>"",AH41<>""),AF41+AH41,"")
D42: =IF(A42="","",VLOOKUP(A42,Lists!$A:$B,2,FALSE)) | W42: =IF(AND(U42<>"",V42<>""),U42*V42,"") | Y42: =IF(AND(W42<>"",X42<>""),W42*X42,"") | Z42: =IF(AND(W42<>"",Y42<>""),W42+Y42,"") | AD42: =IF($B42="GWE_Item",IF($AA42="Elektra",SUMIFS($O:$O,$A:$A,$A42,$B:$B,"GWE")-SUMIFS($N:$N,$A:$A,$A42,$B:$B,"GWE"),IF($AA42="Gas",SUMIFS($Q:$Q,$A:$A,$A42,$B:$B,"GWE")-SUMIFS($P:$P,$A:$A,$A42,$B:$B,"GWE"),IF($AA42="Water",SUMIFS($S:$S,$A:$A,$A42,$B:$B,"GWE")-SUMIFS($R:$R,$A:$A,$A42,$B:$B,"GWE"),""))),"") | AF42: =IF(AND(AD42<>"",AE42<>""),AD42*AE42,"") | AH42: =IF(AND(AF42<>"",AG42<>""),AF42*AG42,"") | AI42: =IF(AND(AF42<>"",AH42<>""),AF42+AH42,"")
D43: =IF(A43="","",VLOOKUP(A43,Lists!$A:$B,2,FALSE)) | W43: =IF(AND(U43<>"",V43<>""),U43*V43,"") | Y43: =IF(AND(W43<>"",X43<>""),W43*X43,"") | Z43: =IF(AND(W43<>"",Y43<>""),W43+Y43,"") | AD43: =IF($B43="GWE_Item",IF($AA43="Elektra",SUMIFS($O:$O,$A:$A,$A43,$B:$B,"GWE")-SUMIFS($N:$N,$A:$A,$A43,$B:$B,"GWE"),IF($AA43="Gas",SUMIFS($Q:$Q,$A:$A,$A43,$B:$B,"GWE")-SUMIFS($P:$P,$A:$A,$A43,$B:$B,"GWE"),IF($AA43="Water",SUMIFS($S:$S,$A:$A,$A43,$B:$B,"GWE")-SUMIFS($R:$R,$A:$A,$A43,$B:$B,"GWE"),""))),"") | AF43: =IF(AND(AD43<>"",AE43<>""),AD43*AE43,"") | AH43: =IF(AND(AF43<>"",AG43<>""),AF43*AG43,"") | AI43: =IF(AND(AF43<>"",AH43<>""),AF43+AH43,"")
...

Sheet Lists
A1: Address | B1: Object ID | C1: Clients
A2: 1e Middellandstraat 104A | B2: 0388 | C2: 't Werkt B.V.
A3: 2e Maasbosstraat 2 a | B3: 0148 | C3: 24/7 drive
A4: 2e Maasbosstraat 2 b | B4: 0149 | C4: 4 Homes B.V.
A5: 2e Maasbosstraat 2 c | B5: 0150 | C5: 4 Homes B.V.
A6: 2e van Leydengaelstraat 6 | B6: 0022 | C6: A. Blaszcak
A7: Abelenlaan 143 | B7: 0014 | C7: A. Brouwers en S. Brouwers- van Weert
A8: Acacia 2 | B8: 0003 | C8: A. Dzaka
A9: Acacialaan 9 | B9: 0223 | C9: A. Ghali
A10: Achterdijk 47A | B10: 0190 | C10: A. Verschueren
A11: Adriaan Baasstraat 34 | B11: 0007 | C11: A.H.S. Willemsen
A12: Akkerweg 41 [010] | B12: 0341 | C12: A.I.G. Lukkien
... A376: Wilgensingel 63 | B376: 0139 | C376: van Heeswijk
A377: Wilgenstraat 37 | B377: 0140
A378: Wilhelmina Druckerstraat 68 | B378: 0142
A379: Wilhelminastraat 8 | B379: 0141
A380: Willem Lodewijkstraat 8 | B380: 0143
A381: Willem de Rijkelaan 134 | B381: 0161
A382: Woutersweg 20 | B382: 0186
A383: Wouwbaan 230 | B383: 0145
A384: Zuidhoek 209D | B384: 0232
A385: Zwethkade Zuid 30A | B385: 0376
A386: Zwingel 8B | B386: 0371
A387: de Genestetstraat 32 | B387: 0169
A388: van Scorelstraat 73 | B388: 0016
... A392: van der Werffstraat 240 | B392: 0245
