Workbook

Sheet relaties_export_2026-01-12_1609
A1: id | B1: naam | C1: type | D1: contactpersoon | E1: email | F1: telefoonnummer | G1: adres | H1: postcode | I1: plaats | J1: land | K1: kvk_nummer | L1: btw_nummer | M1: iban | N1: is_klant | O1: is_leverancier | P1: is_eigenaar | Q1: marge_max | R1: created_at
A2: 1 | B2: M.C. Claassen | C2: bureau | E2: mcc.2006@hotmail.com | G2: Camino Viejo de Valencia 8 1e izq | J2: Nederland | M2: NL05 RABO 0383 7113 04 | N2: 1 | O2: 0 | P2: 0 | R2: 46034.625
A3: 2 | B3: Bright Home Rentals B.V. | C3: bureau | E3: administratie@brighthomerentals.nl | G3: Ebweg 73 | I3: BARENDRECHT | J3: Nederland | K3: 66838452.0 | M3: NL62 RABO 0312 8075 46 | N3: 1 | O3: 1 | P3: 0 | R3: 46034.625
A4: 3 | B4: T.A. van der Burg | C4: bureau | E4: vanderburgron@gmail.com | G4: Heeswijk 113 | I4: Montfoort | J4: Nederland | K4: 53093623.0 | M4: NL67 INGB 0795 2367 27 | N4: 1 | O4: 1 | P4: 0 | R4: 46034.625
A5: 4 | B5: Randstad Wonen | C5: bureau | E5: info@randstadwonen.nl | N5: 1 | O5: 0 | P5: 0 | R5: 46034.625
A6: 5 | B6: Ruva Vastgoed B.V. | C6: zakelijk | E6: beheer@ruvavastgoed.nl | G6: Burgemeester van Campenhoutstraat 2 | I6: MADE | J6: Nederland | K6: 52768384.0 | M6: NL93 RABO 0116 6871 50 | N6: 1 | O6: 1 | P6: 0 | R6: 46034.625
A7: 6 | B7: GOTI Verhuur B.V. | C7: zakelijk | E7: info@gotiverhuur.nl | G7: Noorderhaven 63 | I7: Harlingen | J7: Nederland | K7: 1098148.0 | M7: NL94 INGB 0665 1314 02 | N7: 1 | O7: 1 | P7: 0 | R7: 46034.625
A8: 7 | B8: Maatschap J.W. Meershoek & W.M. Meershoek | C8: zakelijk | E8: j.meershoek1@chello.nl | G8: Grootzand 11 | I8: HOEK VAN HOLLAND | J8: Nederland | M8: NL37 ABNA 0406 1514 07 | N8: 1 | O8: 1 | P8: 0 | R8: 46034.625
A9: 8 | B9: Joost de Jong Holding B.V. | C9: particulier | E9: jcdejong@aol.nl | G9: Wetterkrite 49 | I9: Goutum | J9: Nederland | K9: 63936070.0 | M9: NL70 INGB 0007 1264 17 | N9: 1 | O9: 1 | P9: 0 | R9: 46034.625
A10: 9 | B10: H.C. van Os - Remeeus | C10: particulier | E10: marcel@cohousingnederland.nl | G10: Iependaal 19 | I10: ROZENBURG | J10: Nederland | M10: NL60 RABO 0369 8896 57 | N10: 1 | O10: 1 | P10: 0 | R10: 46034.625
A11: 10 | B11: Klaas Bos | C11: particulier | E11: klaas.bos@example.com | N11: 1 | O11: 0 | P11: 0 | R11: 46034.625
A12: 11 | B12: Finest Housing B.V. | C12: particulier | E12: backoffice@finesthousing.nl | G12: John F. Kennedylaan 246 | I12: PANNINGEN | J12: Nederland | K12: 75080060.0 | M12: NL57 RABO 0342 8897 61 | N12: 1 | O12: 1 | P12: 0 | R12: 46034.625
A13: 12 | B13: M.J. van Os | C13: particulier | E13: marcelvanos0@gmail.com | G13: Burg Letteweg 31 | I13: OOSTVOORNE | J13: Nederland | M13: NL21 INGB 0664 8003 94 | N13: 1 | O13: 0 | P13: 0 | R13: 46034.625
A14: 13 | B14: United Homes B.V. | C14: particulier | E14: administratie@unitedhomes.eu | G14: Van Vollenhovenstraat 10 | I14: Rotterdam | J14: Nederland | M14: NL85 RABO 0131 3612 60 | N14: 1 | O14: 1 | P14: 0 | R14: 46034.625
A15: 14 | B15: Edy Comert BV | C15: particulier | E15: office@edycom.ro | G15: Bergerweg 61 | I15: Sittard | J15: Nederland | K15: 51124769.0 | N15: 1 | O15: 0 | P15: 0 | R15: 46034.625
A16: 15 | B16: Flexcraft SSC BV | C16: particulier | E16: huisvesting@flexcraft.eu | G16: Einsteinstraat 9 B | I16: Gorinchem | J16: Nederland | K16: 67541690.0 | N16: 1 | O16: 0 | P16: 0 | R16: 46034.625
A17: 16 | B17: Vaktec BV | C17: particulier | E17: j.deboer@vaktec.nl | G17: Kielerbocht 29A | I17: Groningen | J17: Nederland | N17: 1 | O17: 0 | P17: 0 | R17: 46034.625
A18: 17 | B18: Tradiro Services B.V. | C18: particulier | E18: facturen@tradiro.nl | G18: Honderdland 960 | I18: Maasdijk | J18: Nederland | K18: 59979135.0 | M18: NL05 RABO 0154 0739 89 | N18: 1 | O18: 1 | P18: 0 | R18: 46034.625
A19: 18 | B19: Sagius Uitzenders B.V. | C19: particulier | E19: facturen@sagiusuitzenders.nl | G19: Bleiswijkseweg 43 | I19: ZOETERMEER | J19: Nederland | M19: NL41 RABO 0145 8741 25 | N19: 1 | O19: 0 | P19: 0 | R19: 46034.625
A20: 19 | B20: Groene Hart Service Detachering B.V. | C20: bureau | E20: facturatie@groenehartservice.nl | G20: Fokkerstraat 5 | I20: REEUWIJK | J20: Nederland | M20: NL41 INGB 0650 5389 00 | N20: 1 | O20: 1 | P20: 0 | R20: 46034.625
A21: 20 | B21: S. Dolstra | C21: particulier | E21: dolstra@yahoo.com | G21: Molenweg 10 a | I21: KRUISLAND | J21: Nederland | M21: NL51 RABO 0194 3333 02 | N21: 1 | O21: 1 | P21: 0 | R21: 46034.625
A22: 21 | B22: The Housing Guild B.V. | C22: particulier | E22: r.nijboer@degildegroep.nl | G22: Blankenstein 136 | I22: MEPPEL | J22: Nederland | M22: NL81 ABNA 0823 0941 54 | N22: 1 | O22: 0 | P22: 0 | R22: 46034.625
A23: 22 | B23: J. Hermans | C23: particulier | E23: frankjolanda@online.nl | G23: Meedhuizerweg 5 | I23: MEEDHUIZEN | J23: Nederland | M23: NL92 RABO 0154 3249 14 | N23: 1 | O23: 0 | P23: 0 | R23: 46034.625
A24: 23 | B24: S. Bakker OPH Verhuur | C24: particulier | G24: Hoofdweg 7 | I24: Hitzum | J24: Nederland | M24: NL85 INGB 0102 8401 21 | N24: 1 | O24: 1 | P24: 0 | R24: 46034.625
A25: 24 | B25: V.O.F. Groepsaccommodaties Drenthe | C25: particulier | G25: Westeind 12 | I25: Norg | J25: Nederland | K25: 67963692.0 | N25: 1 | O25: 0 | P25: 0 | R25: 46034.625
A26: 25 | B26: O.J.P Soc Constru√ß√µes | C26: particulier | E26: romeu.ferreira@ojp.pt | G26: Rua Quinta da Tapada 20 R C | J26: Portugal | M26: PT50 0010 0000 5582 3720 0019 1 | N26: 1 | O26: 0 | P26: 0 | R26: 46034.625
A27: 26 | B27: Vivir Wonen | C27: particulier | E27: info@vivirwonen.nl | G27: Postbus 811 | I27: Gorinchem | J27: Nederland | K27: 58693807.0 | M27: NL52 RABO 0106 0699 77 | N27: 1 | O27: 1 | P27: 0 | R27: 46034.625
A28: 27 | B28: Global Accomodation Solutions (Incassobureau) | C28: particulier | E28: info@globalaccommodation.solutions | G28: Jan Pietersz. Coenstraat 7 | I28: 'S-GRAVENHAGE | J28: Nederland | K28: 78155797.0 | M28: NL76 INGB 0008 9801 73 | N28: 1 | O28: 0 | P28: 0 | R28: 46034.625
A29: 28 | B29: Alis Vastgoed B.V. | C29: particulier | E29: rifat@prokonak.nl | G29: Fruitweg 25 | I29: 'S-GRAVENHAGE | J29: Nederland | N29: 1 | O29: 1 | P29: 0 | R29: 46034.625
A30: 29 | B30: Resource One B.V. | C30: particulier | E30: info@qualityhomerentals.nl | G30: Nobelstraat 76 | I30: BRIELLE | J30: Nederland | K30: 74887068.0 | M30: NL95 KNAB 0259 2344 78 | N30: 1 | O30: 1 | P30: 0 | R30: 46034.625
A31: 30 | B31: Team Home Rentals B.V. | C31: particulier | E31: administratie@teamhomerentals.nl | G31: Dopplerweg1 | I31: Spijkenisse | J31: Nederland | K31: 71523561.0 | M31: NL61 RABO 0330 2631 02 | N31: 1 | O31: 1 | P31: 0 | R31: 46034.625
A32: 31 | B32: Direct Rendement B.V. | C32: particulier | E32: info@directrendement.nl | G32: Kortedijk 57 | I32: VLAARDINGEN | J32: Nederland | K32: 72724382.0 | M32: NL09 INGB 0008 5322 69 | N32: 1 | O32: 1 | P32: 0 | R32: 46034.625
A33: 32 | B33: Interim Jobs B.V. | C33: particulier | E33: e.ozel@interimjobs.nl | G33: Vlierwerf 3 d | I33: ROOSENDAAL | J33: Nederland | K33: 67044360.0 | M33: NL83 RABO 0313 5561 05 | N33: 1 | O33: 1 | P33: 0 | R33: 46034.625
A34: 33 | B34: L.M. Schilstra | C34: particulier | G34: Adres onbekend | J34: Nederland | M34: NL17 RABO 0158 8674 16 | N34: 1 | O34: 1 | P34: 0 | R34: 46034.625
A35: 34 | B35: Employ | C35: particulier | N35: 1 | O35: 0 | P35: 0 | R35: 46034.625
A36: 35 | B36: Best@Work B.V. | C36: particulier | E36: info@bestatwork.nl | G36: Industrieweg 74-76 | I36: WAALWIJK | J36: Nederland | K36: 74210025.0 | N36: 1 | O36: 0 | P36: 0 | R36: 46034.625
A37: 36 | B37: WS Detachering BV | C37: particulier | E37: administratie@workstead.nl | G37: Barneveldsestraat 44 | I37: Renswoude | J37: Nederland | N37: 1 | O37: 0 | P37: 0 | R37: 46034.625
A38: 37 | B38: Flowerhill B.V. | C38: bureau | E38: jb.heuvel@quicknet.nl | G38: Prinses Marijkestraat 36 | I38: Andijk | J38: Nederland | K38: 69891478.0 | N38: 1 | O38: 0 | P38: 0 | R38: 46034.625
A39: 38 | B39: J.D. Jongsma | C39: particulier | E39: jand.jongsma@icloud.com | G39: Tamboerstraat 16 | I39: LOON OP ZAND | J39: Nederland | M39: NL88 INGB 0794 4823 68 | N39: 1 | O39: 0 | P39: 0 | R39: 46034.625
A40: 39 | B40: Multiserwis SP z o.o. | C40: particulier | E40: karol.pastucha@bilfinger.com | G40: ul. Prudnicka 40 | I40: Krapkowise | J40: Polen | K40: 120630.0 | M40: DE81 7007 0010 0206 0184 00 | N40: 1 | O40: 0 | P40: 0 | R40: 46034.625
...

Sheet Sheet1
A1: Overzicht woningen RyanRent BV
C2: Facturatie | D2: Adres | E2: Postcode | F2: Plaats | G2: Aant. pers. | H2: Aant. SK | I2: Startdatum | J2: Einddatum Min. Per. | K2: Opgezegd | L2: Huurder | M2: relatie_id | N2: relatie | O2: Mutatie Daan | P2: Marge | Q2: Verhuur INCL. BTW | R2: Verhuur EXCL. BTW | S2: Verhuur PPPW | T2: Kale verhuurprijs | U2: Voorschot GWE | V2: Overige kosten | W2: Afval | Y2: Eigenaar | Z2: relatie_id | AA2: relatie | AB2: Telefoonnummer | AC2: Inhuur INCL BTW | AD2: Inhuur EXCL BTW | AE2: Kale inhuurprijs | AF2: Inhuur PPPW | AG2: Startdatum | AH2: Einddatum Min. Per. | AI2: HOVK | AJ2: minimale duur | AK2: start | AL2: eind | AM2: opzegtermijn | AN2: opmerking | AO2: Rechtsvorm | AR2: VHOVK | AS2: minimale duur | AT2: start | AU2: eind | AV2: Opzegtermijn | AW2: rechtsvorm
B3: =_xlfn.XLOOKUP(D3,'[1]Sleutelplan nieuw'!B:B,'[1]Sleutelplan nieuw'!A:A,"",2) -> 0388 | C3: Factuur | D3: 1e Middellandstraat 104A | E3: 3021BH | F3: Rotterdam | G3: 2 | H3: 2 | I3: 45961 | J3: 46112 | L3: Bakker | M3: =_xlfn.XLOOKUP(L3,'relaties_export_2026-01-12_1609'!B:B,'relaties_export_2026-01-12_1609'!A:A,"",3) -> 23 | N3: =_xlfn.XLOOKUP(M3,'relaties_export_2026-01-12_1609'!A:A,'relaties_export_2026-01-12_1609'!B:B,"",3) -> S. Bakker OPH Verhuur | P3: =R3-U3-V3-AD3 -> 500 | Q3: =T3*1.09+U3*1.21 -> 1986 | R3: =T3+U3 -> 1800 | S3: =(R3/G3)/4.33333 -> 207.69247 | T3: 1600 | U3: 200 | V3: 0 | Y3: Orange Invesments Group | Z3: =_xlfn.XLOOKUP(Y3,'relaties_export_2026-01-12_1609'!B:B,'relaties_export_2026-01-12_1609'!A:A,"",3) -> 751 | AA3: =_xlfn.XLOOKUP(Z3,'relaties_export_2026-01-12_1609'!A:A,'relaties_export_2026-01-12_1609'!B:B,"",3) -> Orange Invesments Group | AB3: 0174-504792 | AC3: 1100 | AD3: 1100 | AE3: 1100 | AF3: =(AD3/G3)/4.33333 -> 126.92317 | AG3: 45961 | AH3: 46112
A4: 1 | B4: =_xlfn.XLOOKUP(D4,'[1]Sleutelplan nieuw'!B:B,'[1]Sleutelplan nieuw'!A:A,"",2) -> 0022 | C4: Factuur | D4: 2e van Leydengaelstraat 6 | E4: 3134 LL | F4: Vlaardingen | G4: 8 | H4: 4 | I4: 44958 | J4: 45323 | L4: Tradiro | M4: =_xlfn.XLOOKUP(L4,'relaties_export_2026-01-12_1609'!B:B,'relaties_export_2026-01-12_1609'!A:A,"",3) -> 17 | N4: =_xlfn.XLOOKUP(M4,'relaties_export_2026-01-12_1609'!A:A,'relaties_export_2026-01-12_1609'!B:B,"",3) -> Tradiro Services B.V. | P4: =R4-U4-V4-AD4 -> 285.56 | Q4: =T4*1.09+U4*1.21 -> 3194.3104 | R4: =T4+U4 -> 2930.56 | S4: =(R4/G4)/4.33333 -> 84.53545 | T4: 2930.56 | U4: 0 | V4: 0 | Y4: Verknocht | Z4: =_xlfn.XLOOKUP(Y4,'relaties_export_2026-01-12_1609'!B:B,'relaties_export_2026-01-12_1609'!A:A,"",3) -> 574 | AA4: =_xlfn.XLOOKUP(Z4,'relaties_export_2026-01-12_1609'!A:A,'relaties_export_2026-01-12_1609'!B:B,"",3) -> Verknocht | AC4: 2645 | AD4: 2645 | AE4: 2645 | AF4: =(AD4/G4)/4.33333 -> 76.298136 | AG4: 44927 | AH4: 45292
B5: =_xlfn.XLOOKUP(D5,'[1]Sleutelplan nieuw'!B:B,'[1]Sleutelplan nieuw'!A:A,"",2) -> 0148 | C5: DS | D5: 2e Maasbosstraat 2 a | E5: 3134XJ | F5: Vlaardingen | L5: Tradiro | M5: =_xlfn.XLOOKUP(L5,'relaties_export_2026-01-12_1609'!B:B,'relaties_export_2026-01-12_1609'!A:A,"",3) -> 17 | N5: =_xlfn.XLOOKUP(M5,'relaties_export_2026-01-12_1609'!A:A,'relaties_export_2026-01-12_1609'!B:B,"",3) -> Tradiro Services B.V. | Y5: A.J. Maat | Z5: 306 | AA5: =_xlfn.XLOOKUP(Z5,'relaties_export_2026-01-12_1609'!A:A,'relaties_export_2026-01-12_1609'!B:B,"",3) -> Jacco Maat | AC5: 1570.24 | AD5: 1570.24 | AE5: 1570.24
B6: =_xlfn.XLOOKUP(D6,'[1]Sleutelplan nieuw'!B:B,'[1]Sleutelplan nieuw'!A:A,"",2) -> 0149 | C6: DS | D6: 2e Maasbosstraat 2 b | E6: 3134XJ | F6: Vlaardingen | L6: Tradiro | M6: =_xlfn.XLOOKUP(L6,'relaties_export_2026-01-12_1609'!B:B,'relaties_export_2026-01-12_1609'!A:A,"",3) -> 17 | N6: =_xlfn.XLOOKUP(M6,'relaties_export_2026-01-12_1609'!A:A,'relaties_export_2026-01-12_1609'!B:B,"",3) -> Tradiro Services B.V. | Y6: A.J. Maat | Z6: 306 | AA6: =_xlfn.XLOOKUP(Z6,'relaties_export_2026-01-12_1609'!A:A,'relaties_export_2026-01-12_1609'!B:B,"",3) -> Jacco Maat | AC6: 1570.24 | AD6: 1570.24 | AE6: 1570.24
B7: =_xlfn.XLOOKUP(D7,'[1]Sleutelplan nieuw'!B:B,'[1]Sleutelplan nieuw'!A:A,"",2) -> 0150 | C7: DS | D7: 2e Maasbosstraat 2 c | E7: 3134XJ | F7: Vlaardingen | L7: Tradiro | M7: =_xlfn.XLOOKUP(L7,'relaties_export_2026-01-12_1609'!B:B,'relaties_export_2026-01-12_1609'!A:A,"",3) -> 17 | N7: =_xlfn.XLOOKUP(M7,'relaties_export_2026-01-12_1609'!A:A,'relaties_export_2026-01-12_1609'!B:B,"",3) -> Tradiro Services B.V. | Y7: A.J. Maat | Z7: 306 | AA7: =_xlfn.XLOOKUP(Z7,'relaties_export_2026-01-12_1609'!A:A,'relaties_export_2026-01-12_1609'!B:B,"",3) -> Jacco Maat | AC7: 1475.31 | AD7: 1475.31 | AE7: 1475.31
A8: 3 | B8: =_xlfn.XLOOKUP(D8,'[1]Sleutelplan nieuw'!B:B,'[1]Sleutelplan nieuw'!A:A,"",2) -> 0003 | C8: Factuur | D8: Acacia 2 | E8: 3224EB | F8: Hellevoetsluis | G8: 5 | H8: 5 | I8: 44991 | J8: 45356 | L8: United Homes | M8: =_xlfn.XLOOKUP(L8,'relaties_export_2026-01-12_1609'!B:B,'relaties_export_2026-01-12_1609'!A:A,"",3) -> 13 | N8: =_xlfn.XLOOKUP(M8,'relaties_export_2026-01-12_1609'!A:A,'relaties_export_2026-01-12_1609'!B:B,"",3) -> United Homes B.V. | P8: =R8-U8-V8-AD8 -> 1195.81 | Q8: =T8*1.09+U8*1.21 -> 4164.6829 | R8: =T8+U8 -> 3820.81 | S8: =(R8/G8)/4.3333 -> 176.34643 | T8: 3820.81 | U8: 0 | V8: 0 | Y8: MvB Services BV (Meindert van Buuren) | Z8: =_xlfn.XLOOKUP(Y8,'relaties_export_2026-01-12_1609'!B:B,'relaties_export_2026-01-12_1609'!A:A,"",2) -> 789 | AA8: =_xlfn.XLOOKUP(Z8,'relaties_export_2026-01-12_1609'!A:A,'relaties_export_2026-01-12_1609'!B:B,"",3) -> MvB Services BV (Meindert van Buuren) | AB8: 06-23234296 | AC8: 2625 | AD8: 2625 | AE8: 2625 | AF8: =(AD8/G8)/4.33333 -> 121.15394 | AG8: 44986 | AH8: 45351
A9: 5 | B9: =_xlfn.XLOOKUP(D9,'[1]Sleutelplan nieuw'!B:B,'[1]Sleutelplan nieuw'!A:A,"",2) -> 0190 | C9: Factuur | D9: Achterdijk 47a | E9: 4243 TM | F9: Nieuwland | G9: 7 | H9: 4 | I9: 45241 | J9: 45606 | L9: Dock Holland | M9: 145 | N9: =_xlfn.XLOOKUP(M9,'relaties_export_2026-01-12_1609'!A:A,'relaties_export_2026-01-12_1609'!B:B,"",3) -> dockHolland Huisvesting B.V. | P9: =R9-U9-V9-AD9 -> 370.78 | Q9: =T9*1.09+U9*1.21 -> 4543.4534 | R9: =T9+U9 -> 4113.26 | S9: =(R9/G9)/4.3333 -> 135.60302 | T9: 3613.26 | U9: 500 | V9: 0 | Y9: Vivir wonen (Mendy) | Z9: =_xlfn.XLOOKUP(Y9,'relaties_export_2026-01-12_1609'!B:B,'relaties_export_2026-01-12_1609'!A:A,"",2) -> 824 | AA9: =_xlfn.XLOOKUP(Z9,'relaties_export_2026-01-12_1609'!A:A,'relaties_export_2026-01-12_1609'!B:B,"",3) -> Vivir wonen (Mendy) | AB9: 06-12333496 | AC9: 3347.48 | AD9: 3242.48 | AE9: 2742.48 | AF9: =(AD9/G9)/4.33333 -> 106.89503 | AG9: 45038 | AH9: 45403
A10: 6 | B10: =_xlfn.XLOOKUP(D10,'[1]Sleutelplan nieuw'!B:B,'[1]Sleutelplan nieuw'!A:A,"",2) -> 0007 | C10: DS | D10: Adriaan Baasstraat 34 | E10: 7902HN | F10: Hoogeveen | G10: 4 | H10: 4 | I10: 45765 | J10: 46129 | L10: InAxtion Vastgoed B.V. | M10: =_xlfn.XLOOKUP(L10,'relaties_export_2026-01-12_1609'!B:B,'relaties_export_2026-01-12_1609'!A:A,"",3) -> 154 | N10: =_xlfn.XLOOKUP(M10,'relaties_export_2026-01-12_1609'!A:A,'relaties_export_2026-01-12_1609'!B:B,"",3) -> InAxtion Vastgoed B.V. | P10: =R10-U10-V10-AD10 -> 550 | Q10: =T10*1.09+U10*1.21 -> 2700.5 | R10: =T10+U10 -> 2450 | S10: =(R10/G10)/4.3333 -> 141.34724 | T10: 2200 | U10: 250 | V10: 0 | Y10: Eva Laus | Z10: =_xlfn.XLOOKUP(Y10,'relaties_export_2026-01-12_1609'!B:B,'relaties_export_2026-01-12_1609'!A:A,"",3) -> 790 | AA10: =_xlfn.XLOOKUP(Z10,'relaties_export_2026-01-12_1609'!A:A,'relaties_export_2026-01-12_1609'!B:B,"",3) -> Eva Laus | AB10: 06-12707279 | AC10: 1650 | AD10: 1650 | AE10: 1650 | AF10: =(AD10/G10)/4.33333 -> 95.192381 | AG10: 44682 | AH10: 45412
A11: 7 | B11: 0341 | C11: Factuur | D11: Akkerweg 41 [huis 10] | E11: 1779GJ | F11: Den Oever | G11: 6 | H11: 3 | I11: 45709 | J11: 45992 | L11: NL Realty | M11: =_xlfn.XLOOKUP(L11,'relaties_export_2026-01-12_1609'!B:B,'relaties_export_2026-01-12_1609'!A:A,"",3) -> 236 | N11: =_xlfn.XLOOKUP(M11,'relaties_export_2026-01-12_1609'!A:A,'relaties_export_2026-01-12_1609'!B:B,"",3) -> NL Realty B.V. | P11: =R11-U11-V11-AD11 -> 0 | Y11: Cris | Z11: =_xlfn.XLOOKUP(Y11,'relaties_export_2026-01-12_1609'!B:B,'relaties_export_2026-01-12_1609'!A:A,"",3) -> 726 | AA11: =_xlfn.XLOOKUP(Z11,'relaties_export_2026-01-12_1609'!A:A,'relaties_export_2026-01-12_1609'!B:B,"",3) -> Cris | AB11: 06-4537722 | AG11: 45709 | AH11: 45992
A12: 8 | B12: 0372 | C12: Factuur | D12: Akkerweg 41 [huis 11] | E12: 1779GJ | F12: Den Oever | G12: 6 | H12: 3 | I12: 45765 | J12: 45931 | L12: MNA Proud Facilities B.V. | M12: =_xlfn.XLOOKUP(L12,'relaties_export_2026-01-12_1609'!B:B,'relaties_export_2026-01-12_1609'!A:A,"",3) -> 348 | N12: =_xlfn.XLOOKUP(M12,'relaties_export_2026-01-12_1609'!A:A,'relaties_export_2026-01-12_1609'!B:B,"",3) -> MNA Proud Facilities B.V. | O12: Verhuisd naar huis 10 | P12: =R12-U12-V12-AD12 -> 395.18 | Q12: =T12*1.09+U12*1.21 -> 3911.5 | R12: =T12+U12 -> 3550 | S12: =(R12/G12)/4.3333 -> 136.53951 | T12: 3200 | U12: 350 | Y12: Cris | Z12: =_xlfn.XLOOKUP(Y12,'relaties_export_2026-01-12_1609'!B:B,'relaties_export_2026-01-12_1609'!A:A,"",3) -> 726 | AA12: =_xlfn.XLOOKUP(Z12,'relaties_export_2026-01-12_1609'!A:A,'relaties_export_2026-01-12_1609'!B:B,"",3) -> Cris | AB12: 06-4537722 | AC12: 3055.3 | AD12: 2804.82 | AE12: 2094.5 | AF12: =(AD12/G12)/4.33333 -> 107.87778 | AG12: 45765 | AH12: 46494
A13: 9 | B13: {=_xlfn.XLOOKUP(LEFT(D13,3),LEFT('[1]Sleutelplan nieuw'!B:B,3),'[1]Sleutelplan nieuw'!A:A,"",2)} -> 0293 | C13: Factuur | D13: Akkerweg 41 [huis 14] | E13: 1779GJ | F13: Den Oever | G13: 6 | H13: 3 | I13: 45913 | J13: 46022 | L13: Buurman Vastgoed E B.V. | M13: =_xlfn.XLOOKUP(L13,'relaties_export_2026-01-12_1609'!B:B,'relaties_export_2026-01-12_1609'!A:A,"",3) -> 346 | N13: =_xlfn.XLOOKUP(M13,'relaties_export_2026-01-12_1609'!A:A,'relaties_export_2026-01-12_1609'!B:B,"",3) -> Buurman Vastgoed E B.V. | O13: Terug naar eigenaar 31-12 | P13: =R13-U13-V13-AD13 -> 505 | Q13: =T13*1.09+U13*1.21 -> 4282.65 | R13: =T13+U13 -> 3885 | S13: =(R13/G13)/4.3333 -> 149.42423 | T13: 3485 | U13: 400 | Y13: Cris | Z13: =_xlfn.XLOOKUP(Y13,'relaties_export_2026-01-12_1609'!B:B,'relaties_export_2026-01-12_1609'!A:A,"",3) -> 726 | AA13: =_xlfn.XLOOKUP(Z13,'relaties_export_2026-01-12_1609'!A:A,'relaties_export_2026-01-12_1609'!B:B,"",3) -> Cris | AB13: 06-4537722 | AC13: =3260.2+363 -> 3623.2 | AD13: 2980 | AE13: 2880 | AF13: =(AD13/G13)/4.33333 -> 114.61547 | AG13: 45913 | AH13: 46022
A14: 10 | B14: 0294 | C14: Factuur | D14: Akkerweg 41 [huis 15] | E14: 1779GJ | F14: Den Oever | G14: 6 | H14: 4 | I14: 45325 | J14: 45690 | L14: NL Realty | M14: =_xlfn.XLOOKUP(L14,'relaties_export_2026-01-12_1609'!B:B,'relaties_export_2026-01-12_1609'!A:A,"",3) -> 236 | N14: =_xlfn.XLOOKUP(M14,'relaties_export_2026-01-12_1609'!A:A,'relaties_export_2026-01-12_1609'!B:B,"",3) -> NL Realty B.V. | P14: =R14-U14-V14-AD14 -> 704.39 | Q14: =T14*1.09+U14*1.21 -> 4295.4693 | R14: =T14+U14 -> 3907.77 | S14: =(R14/G14)/4.3333 -> 150.3 | T14: 3607.77 | U14: 300 | V14: 0 | Y14: C. van Driel e/o B.M. Verdouw | Z14: =_xlfn.XLOOKUP(Y14,'relaties_export_2026-01-12_1609'!B:B,'relaties_export_2026-01-12_1609'!A:A,"",3) -> 766 | AA14: =_xlfn.XLOOKUP(Z14,'relaties_export_2026-01-12_1609'!A:A,'relaties_export_2026-01-12_1609'!B:B,"",3) -> C. van Driel e/o B.M. Verdouw | AB14: 06 53141599 | AC14: 3181.85 | AD14: 2903.38 | AE14: 2394.13 | AF14: =(AD14/G14)/4.33333 -> 111.66855 | AG14: 45200 | AH14: 46873
A15: 12 | B15: 0373 | C15: Factuur | D15: Akkerweg 41 [huis 17] | E15: 1779GJ | F15: Den Oever | G15: 6 | H15: 4 | I15: 45765 | J15: 45931 | L15: MNA Proud Facilities B.V. | M15: =_xlfn.XLOOKUP(L15,'relaties_export_2026-01-12_1609'!B:B,'relaties_export_2026-01-12_1609'!A:A,"",3) -> 348 | N15: =_xlfn.XLOOKUP(M15,'relaties_export_2026-01-12_1609'!A:A,'relaties_export_2026-01-12_1609'!B:B,"",3) -> MNA Proud Facilities B.V. | P15: =R15-V15-AD15 -> 595.2 | Q15: =T15*1.09+U15*1.21 -> 3851 | R15: =T15+U15 -> 3500 | S15: =(R15/G15)/4.3333 -> 134.61642 | T15: 3200 | U15: 300 | Y15: Cris | Z15: =_xlfn.XLOOKUP(Y15,'relaties_export_2026-01-12_1609'!B:B,'relaties_export_2026-01-12_1609'!A:A,"",3) -> 726 | AA15: =_xlfn.XLOOKUP(Z15,'relaties_export_2026-01-12_1609'!A:A,'relaties_export_2026-01-12_1609'!B:B,"",3) -> Cris | AB15: 06-4537722 | AC15: 3176.3 | AD15: 2904.8 | AE15: 2094.5 | AF15: =(AD15/G15)/4.33333 -> 111.72316 | AG15: 45765 | AH15: 46494
B16: 0383 | C16: Factuur | D16: Akkerweg 41 [huis 20] | E16: 1779GJ | F16: Den Oever | G16: 7 | H16: 4 | I16: 45915 | J16: 46022 | L16: Buurman Vastgoed E B.V. | M16: =_xlfn.XLOOKUP(L16,'relaties_export_2026-01-12_1609'!B:B,'relaties_export_2026-01-12_1609'!A:A,"",3) -> 346 | N16: =_xlfn.XLOOKUP(M16,'relaties_export_2026-01-12_1609'!A:A,'relaties_export_2026-01-12_1609'!B:B,"",3) -> Buurman Vastgoed E B.V. | O16: Terug naar eigenaar 31-12 | P16: =R16-V16-AD16 -> 620 | Q16: =T16*1.09+U16*1.21 -> 4975.35 | R16: 3600 | S16: =(R16/G16)/4.3333 -> 118.68223 | T16: 4065 | U16: 450 | Y16: Cris | Z16: =_xlfn.XLOOKUP(Y16,'relaties_export_2026-01-12_1609'!B:B,'relaties_export_2026-01-12_1609'!A:A,"",3) -> 726 | AA16: =_xlfn.XLOOKUP(Z16,'relaties_export_2026-01-12_1609'!A:A,'relaties_export_2026-01-12_1609'!B:B,"",3) -> Cris | AB16: 06-4537722 | AC16: =3260.2+363 -> 3623.2 | AD16: 2980 | AE16: 2880 | AF16: =(AD16/G16)/4.33333 -> 98.241834 | AG16: 45915 | AH16: 46022
B17: 0297 | C17: Factuur | D17: Akkerweg 41 [huis 26] | E17: 1779GJ | F17: Den Oever | G17: 3 | H17: 3 | I17: 45931 | J17: 46022 | L17: Royal DS Personeel-service | M17: =_xlfn.XLOOKUP(L17,'relaties_export_2026-01-12_1609'!B:B,'relaties_export_2026-01-12_1609'!A:A,"",3) -> 304 | N17: =_xlfn.XLOOKUP(M17,'relaties_export_2026-01-12_1609'!A:A,'relaties_export_2026-01-12_1609'!B:B,"",3) -> Royal DS Personeel-service | O17: Terug naar eigenaar 31-12 | P17: =R17-V17-AD17 -> 540 | Q17: =T17*1.09+U17*1.21+V17*1.21 -> 2543 | R17: =T17+U17+V17 -> 2300 | S17: =(R17/G17)/4.3333 -> 176.92444 | T17: 2000 | U17: 200 | V17: 100 | Y17: Cris | Z17: =_xlfn.XLOOKUP(Y17,'relaties_export_2026-01-12_1609'!B:B,'relaties_export_2026-01-12_1609'!A:A,"",3) -> 726 | AA17: =_xlfn.XLOOKUP(Z17,'relaties_export_2026-01-12_1609'!A:A,'relaties_export_2026-01-12_1609'!B:B,"",3) -> Cris | AB17: 06-4537722 | AC17: =3260.2 -> 3260.2 | AD17: 1660 | AE17: 1560 | AF17: =(AD17/G17)/4.33333 -> 127.69241
A18: 15 | B18: 0350 | C18: Factuur | D18: Akkerweg 41 [huis 35] | E18: 1779GJ | F18: Den Oever | G18: 4 | H18: 3 | I18: 45765 | J18: 45931 | L18: MNA Proud Facilities B.V. | M18: =_xlfn.XLOOKUP(L18,'relaties_export_2026-01-12_1609'!B:B,'relaties_export_2026-01-12_1609'!A:A,"",3) -> 348 | N18: =_xlfn.XLOOKUP(M18,'relaties_export_2026-01-12_1609'!A:A,'relaties_export_2026-01-12_1609'!B:B,"",3) -> MNA Proud Facilities B.V. | P18: =R18-V18-AD18 -> 423.12 | Q18: =T18*1.09+U18*1.21 -> 2646 | R18: =T18+U18 -> 2400 | S18: =(R18/G18)/4.3333 -> 138.4626 | T18: 2150 | U18: 250 | Y18: Cris | Z18: =_xlfn.XLOOKUP(Y18,'relaties_export_2026-01-12_1609'!B:B,'relaties_export_2026-01-12_1609'!A:A,"",3) -> 726 | AA18: =_xlfn.XLOOKUP(Z18,'relaties_export_2026-01-12_1609'!A:A,'relaties_export_2026-01-12_1609'!B:B,"",3) -> Cris | AB18: 06-4537722 | AC18: 2161.5 | AD18: 1976.88 | AE18: 1362.66 | AF18: =(AD18/G18)/4.33333 -> 114.05086 | AG18: 45765 | AH18: 46494
A19: 16 | B19: 0356 | C19: Factuur | D19: Akkerweg 41 [huis 36] | E19: 1779GJ | F19: Den Oever | G19: 3 | H19: 3 | I19: 45853 | J19: 46582 | L19: MNA Proud Facilities B.V. | M19: =_xlfn.XLOOKUP(L19,'relaties_export_2026-01-12_1609'!B:B,'relaties_export_2026-01-12_1609'!A:A,"",3) -> 348 | N19: =_xlfn.XLOOKUP(M19,'relaties_export_2026-01-12_1609'!A:A,'relaties_export_2026-01-12_1609'!B:B,"",3) -> MNA Proud Facilities B.V. | P19: =R19-V19-AD19 -> 282.09 | Q19: =T19*1.09+U19*1.21 -> 2646 | R19: 2100 | S19: =(R19/G19)/4.3333 -> 161.5397 | T19: 2150 | U19: 250 | Y19: Cris | Z19: =_xlfn.XLOOKUP(Y19,'relaties_export_2026-01-12_1609'!B:B,'relaties_export_2026-01-12_1609'!A:A,"",3) -> 726 | AA19: =_xlfn.XLOOKUP(Z19,'relaties_export_2026-01-12_1609'!A:A,'relaties_export_2026-01-12_1609'!B:B,"",3) -> Cris | AB19: 06-4537722 | AC19: 1992.5 | AD19: 1817.91 | AE19: 1251.74 | AF19: =(AD19/G19)/4.33333 -> 139.83934 | AG19: 45853 | AH19: 46491
A20: 17 | B20: 0299 | C20: Factuur | D20: Akkerweg 41 [huis 37] | E20: 1779GJ | F20: Den Oever | G20: 8 | H20: 4 | I20: 45304 | J20: 45669 | L20: NL Realty | M20: =_xlfn.XLOOKUP(L20,'relaties_export_2026-01-12_1609'!B:B,'relaties_export_2026-01-12_1609'!A:A,"",3) -> 236 | N20: =_xlfn.XLOOKUP(M20,'relaties_export_2026-01-12_1609'!A:A,'relaties_export_2026-01-12_1609'!B:B,"",3) -> NL Realty B.V. | P20: =R20-V20-AD20 -> 1340.31 | Q20: =T20*1.09+U20*1.21 -> 5606.2924 | R20: =T20+U20 -> 5110.36 | S20: =(R20/G20)/4.3333 -> 147.41536 | T20: 4810.36 | U20: 300 | V20: 0 | Y20: C. van Driel e/o B.M. Verdouw | Z20: =_xlfn.XLOOKUP(Y20,'relaties_export_2026-01-12_1609'!B:B,'relaties_export_2026-01-12_1609'!A:A,"",3) -> 766 | AA20: =_xlfn.XLOOKUP(Z20,'relaties_export_2026-01-12_1609'!A:A,'relaties_export_2026-01-12_1609'!B:B,"",3) -> C. van Driel e/o B.M. Verdouw | AB20: 06 53141599 | AC20: 4126.52 | AD20: 3770.05 | AE20: 3260.8 | AF20: =(AD20/G20)/4.33333 -> 108.75153 | AG20: 45200 | AH20: 46873
A21: 19 | B21: 0300 | C21: Factuur | D21: Akkerweg 41 [huis 40] | E21: 1779GJ | F21: Den Oever | G21: 8 | H21: 8 | I21: 45609 | J21: 45701 | L21: Eemsdelta | M21: =_xlfn.XLOOKUP(L21,'relaties_export_2026-01-12_1609'!B:B,'relaties_export_2026-01-12_1609'!A:A,"",3) -> 218 | N21: =_xlfn.XLOOKUP(M21,'relaties_export_2026-01-12_1609'!A:A,'relaties_export_2026-01-12_1609'!B:B,"",3) -> Eemsdelta Housing B.V. | O21: Gaat eruit 30-11 | P21: =R21-V21-AD21 -> -4490.05 | U21: 600 | Y21: C. van Driel e/o B.M. Verdouw | Z21: =_xlfn.XLOOKUP(Y21,'relaties_export_2026-01-12_1609'!B:B,'relaties_export_2026-01-12_1609'!A:A,"",3) -> 766 | AA21: =_xlfn.XLOOKUP(Z21,'relaties_export_2026-01-12_1609'!A:A,'relaties_export_2026-01-12_1609'!B:B,"",3) -> C. van Driel e/o B.M. Verdouw | AB21: 06 53141599 | AC21: 4935.32 | AD21: 4490.05 | AE21: 3780.8 | AF21: =(AD21/G21)/4.33333 -> 129.52077 | AG21: 45609 | AH21: 45701
A22: 20 | B22: 0301 | C22: Factuur | D22: Akkerweg 41 [huis 41] | E22: 1779GJ | F22: Den Oever | G22: 8 | H22: 8 | I22: 45660 | J22: 45841 | L22: Royal DS Personeel-service | M22: =_xlfn.XLOOKUP(L22,'relaties_export_2026-01-12_1609'!B:B,'relaties_export_2026-01-12_1609'!A:A,"",3) -> 304 | N22: =_xlfn.XLOOKUP(M22,'relaties_export_2026-01-12_1609'!A:A,'relaties_export_2026-01-12_1609'!B:B,"",3) -> Royal DS Personeel-service | P22: =R22-V22-AD22 -> 1009.95 | Q22: =T22*1.09+U22*1.21 -> 6067 | R22: =T22+U22 -> 5500 | S22: =(R22/G22)/4.3333 -> 158.65507 | T22: 4900 | U22: 600 | Y22: C. van Driel e/o B.M. Verdouw | Z22: =_xlfn.XLOOKUP(Y22,'relaties_export_2026-01-12_1609'!B:B,'relaties_export_2026-01-12_1609'!A:A,"",3) -> 766 | AA22: =_xlfn.XLOOKUP(Z22,'relaties_export_2026-01-12_1609'!A:A,'relaties_export_2026-01-12_1609'!B:B,"",3) -> C. van Driel e/o B.M. Verdouw | AB22: 06 53141599 | AC22: 4935.32 | AD22: 4490.05 | AE22: 3780.8 | AF22: =(AD22/G22)/4.33333 -> 129.52077
A23: 21 | B23: 0302 | C23: Factuur | D23: Akkerweg 41 [huis 42] | E23: 1779GJ | F23: Den Oever | G23: 8 | H23: 8 | I23: 45913 | J23: 46022 | L23: Buurman Vastgoed E B.V. | M23: =_xlfn.XLOOKUP(L23,'relaties_export_2026-01-12_1609'!B:B,'relaties_export_2026-01-12_1609'!A:A,"",3) -> 346 | N23: =_xlfn.XLOOKUP(M23,'relaties_export_2026-01-12_1609'!A:A,'relaties_export_2026-01-12_1609'!B:B,"",3) -> Buurman Vastgoed E B.V. | O23: Gaat eruit 31-12 | P23: =R23-V23-AD23 -> 609.95 | Q23: =T23*1.09+U23*1.21 -> 5613 | R23: =T23+U23 -> 5100 | S23: =(R23/G23)/4.3333 -> 147.11652 | T23: 4650 | U23: 450 | Y23: C. van Driel e/o B.M. Verdouw | Z23: =_xlfn.XLOOKUP(Y23,'relaties_export_2026-01-12_1609'!B:B,'relaties_export_2026-01-12_1609'!A:A,"",3) -> 766 | AA23: =_xlfn.XLOOKUP(Z23,'relaties_export_2026-01-12_1609'!A:A,'relaties_export_2026-01-12_1609'!B:B,"",3) -> C. van Driel e/o B.M. Verdouw | AB23: 06 53141599 | AC23: 4935.32 | AD23: 4490.05 | AE23: 3780.8 | AF23: =(AD23/G23)/4.33333 -> 129.52077
A24: 22 | B24: 0303 | C24: Factuur | D24: Akkerweg 41 [huis 55] | E24: 1779GJ | F24: Den Oever | G24: 6 | H24: 6 | I24: 45695 | J24: 45992 | L24: NL Realty | M24: =_xlfn.XLOOKUP(L24,'relaties_export_2026-01-12_1609'!B:B,'relaties_export_2026-01-12_1609'!A:A,"",3) -> 236 | N24: =_xlfn.XLOOKUP(M24,'relaties_export_2026-01-12_1609'!A:A,'relaties_export_2026-01-12_1609'!B:B,"",3) -> NL Realty B.V. | O24: Gaat eruit 01-12 | P24: =R24-V24-AD24 -> -3293.38 | Y24: C. van Driel e/o B.M. Verdouw | Z24: =_xlfn.XLOOKUP(Y24,'relaties_export_2026-01-12_1609'!B:B,'relaties_export_2026-01-12_1609'!A:A,"",3) -> 766 | AA24: =_xlfn.XLOOKUP(Z24,'relaties_export_2026-01-12_1609'!A:A,'relaties_export_2026-01-12_1609'!B:B,"",3) -> C. van Driel e/o B.M. Verdouw | AB24: 06 53141599 | AC24: 3606.95 | AD24: 3293.38 | AE24: 2784.13 | AF24: =(AD24/G24)/4.33333 -> 126.66856 | AG24: 45672 | AH24: 47498
A25: 23 | B25: 0304 | C25: Factuur | D25: Akkerweg 41 [huis 56] | E25: 1779GJ | F25: Den Oever | G25: 8 | H25: 8 | I25: 45702 | J25: 45992 | L25: NL Realty | M25: =_xlfn.XLOOKUP(L25,'relaties_export_2026-01-12_1609'!B:B,'relaties_export_2026-01-12_1609'!A:A,"",3) -> 236 | N25: =_xlfn.XLOOKUP(M25,'relaties_export_2026-01-12_1609'!A:A,'relaties_export_2026-01-12_1609'!B:B,"",3) -> NL Realty B.V. | O25: Gaat eruit 01-12 | P25: =R25-V25-AD25 -> -4490.05 | Y25: C. van Driel e/o B.M. Verdouw | Z25: =_xlfn.XLOOKUP(Y25,'relaties_export_2026-01-12_1609'!B:B,'relaties_export_2026-01-12_1609'!A:A,"",3) -> 766 | AA25: =_xlfn.XLOOKUP(Z25,'relaties_export_2026-01-12_1609'!A:A,'relaties_export_2026-01-12_1609'!B:B,"",3) -> C. van Driel e/o B.M. Verdouw | AB25: 06 53141599 | AC25: 4935.32 | AD25: 4490.05 | AE25: 3780.8 | AF25: =(AD25/G25)/4.33333 -> 129.52077 | AG25: 45672 | AH25: 47498
A26: 24 | B26: 0305 | C26: Factuur | D26: Akkerweg 41 [huis 57] | E26: 1779GJ | F26: Den Oever | G26: 4 | H26: 3 | I26: 45772 | J26: 45931 | L26: MNA Proud Facilities B.V. | M26: =_xlfn.XLOOKUP(L26,'relaties_export_2026-01-12_1609'!B:B,'relaties_export_2026-01-12_1609'!A:A,"",3) -> 348 | N26: =_xlfn.XLOOKUP(M26,'relaties_export_2026-01-12_1609'!A:A,'relaties_export_2026-01-12_1609'!B:B,"",3) -> MNA Proud Facilities B.V. | P26: =R26-V26-AD26 -> 173.63 | Q26: =T26*1.09+U26*1.21+V26*1.21 -> 2646 | R26: =T26+U26+V26 -> 2400 | S26: =(R26/G26)/4.3333 -> 138.4626 | T26: 2150 | U26: 250 | Y26: Cris | Z26: =_xlfn.XLOOKUP(Y26,'relaties_export_2026-01-12_1609'!B:B,'relaties_export_2026-01-12_1609'!A:A,"",3) -> 726 | AA26: =_xlfn.XLOOKUP(Z26,'relaties_export_2026-01-12_1609'!A:A,'relaties_export_2026-01-12_1609'!B:B,"",3) -> Cris | AB26: 06-4537722 | AC26: 2434 | AD26: 2226.37 | AE26: 1618.35 | AF26: =(AD26/G26)/4.33333 -> 128.44452 | AG26: 45772 | AH26: 46501
B27: 0384 | C27: Factuur | D27: Akkerweg 41 [huis 58] | E27: 1779GJ | F27: Den Oever | G27: 3 | H27: 3 | I27: 45913 | J27: 46022 | L27: Buurman Vastgoed E B.V. | M27: =_xlfn.XLOOKUP(L27,'relaties_export_2026-01-12_1609'!B:B,'relaties_export_2026-01-12_1609'!A:A,"",3) -> 346 | N27: =_xlfn.XLOOKUP(M27,'relaties_export_2026-01-12_1609'!A:A,'relaties_export_2026-01-12_1609'!B:B,"",3) -> Buurman Vastgoed E B.V. | O27: Terug naar eigenaar 30-11 | P27: =R27-V27-AD27 -> 0 | Y27: Cris | Z27: =_xlfn.XLOOKUP(Y27,'relaties_export_2026-01-12_1609'!B:B,'relaties_export_2026-01-12_1609'!A:A,"",3) -> 726 | AA27: =_xlfn.XLOOKUP(Z27,'relaties_export_2026-01-12_1609'!A:A,'relaties_export_2026-01-12_1609'!B:B,"",3) -> Cris | AB27: 06-4537722 | AG27: 45913 | AH27: 46022
B28: 0327 | C28: Factuur | D28: Akkerweg 41 [huis 74] | E28: 1779GJ | F28: Den Oever | G28: 5 | H28: 3 | I28: 45893 | J28: 46011 | L28: FISSH B.V. | M28: =_xlfn.XLOOKUP(L28,'relaties_export_2026-01-12_1609'!B:B,'relaties_export_2026-01-12_1609'!A:A,"",3) -> 347 | N28: =_xlfn.XLOOKUP(M28,'relaties_export_2026-01-12_1609'!A:A,'relaties_export_2026-01-12_1609'!B:B,"",3) -> FISSH B.V. | P28: =R28-V28-AD28 -> 877 | Q28: =T28*1.09+U28*1.21+V28*1.21 -> 3896.78 | R28: =T28+U28+V28 -> 3542 | S28: =(R28/G28)/4.3333 -> 163.47818 | T28: 3242 | U28: 300 | Y28: Cris | Z28: =_xlfn.XLOOKUP(Y28,'relaties_export_2026-01-12_1609'!B:B,'relaties_export_2026-01-12_1609'!A:A,"",3) -> 726 | AA28: =_xlfn.XLOOKUP(Z28,'relaties_export_2026-01-12_1609'!A:A,'relaties_export_2026-01-12_1609'!B:B,"",3) -> Cris | AB28: 06-4537722 | AC28: 2952.85 | AD28: 2665 | AE28: 2265 | AF28: =(AD28/G28)/4.33333 -> 123.00009 | AG28: 45893 | AH28: 46011
B29: 0307 | C29: Factuur | D29: Akkerweg 41 [huis 75] | E29: 1779GJ | F29: Den Oever | G29: 3 | H29: 4 | I29: 45962 | L29: FISSH B.V. | M29: =_xlfn.XLOOKUP(L29,'relaties_export_2026-01-12_1609'!B:B,'relaties_export_2026-01-12_1609'!A:A,"",3) -> 347 | N29: =_xlfn.XLOOKUP(M29,'relaties_export_2026-01-12_1609'!A:A,'relaties_export_2026-01-12_1609'!B:B,"",3) -> FISSH B.V. | P29: =R29-V29-AD29 -> 478.12 | Q29: =T29*1.09+U29*1.21 -> 3197 | R29: =T29+U29 -> 2900 | S29: =(R29/G29)/4.3333 -> 223.07864 | T29: 2600 | U29: 300 | Y29: Cris | Z29: =_xlfn.XLOOKUP(Y29,'relaties_export_2026-01-12_1609'!B:B,'relaties_export_2026-01-12_1609'!A:A,"",3) -> 726 | AA29: =_xlfn.XLOOKUP(Z29,'relaties_export_2026-01-12_1609'!A:A,'relaties_export_2026-01-12_1609'!B:B,"",3) -> Cris | AB29: 06-4537722 | AC29: 2658.55 | AD29: 2421.88 | AE29: 1707.66 | AF29: =(AD29/G29)/4.33333 -> 186.2986 | AG29: 45962
A30: 26 | B30: =_xlfn.XLOOKUP(D30,'[1]Sleutelplan nieuw'!B:B,'[1]Sleutelplan nieuw'!A:A,"",2) -> 0002 | C30: DS | D30: Allard Piersonlaan 142 | E30: 2522 MT | F30: Den Haag | G30: 4 | H30: 3 | I30: 44946 | J30: 45311 | L30: Looije | M30: =_xlfn.XLOOKUP(L30,'relaties_export_2026-01-12_1609'!B:B,'relaties_export_2026-01-12_1609'!A:A,"",3) -> 260 | N30: =_xlfn.XLOOKUP(M30,'relaties_export_2026-01-12_1609'!A:A,'relaties_export_2026-01-12_1609'!B:B,"",3) -> Looije Facilities B.V. | P30: =R30-U30-V30-AD30 -> 412.68 | Q30: =T30*1.09+U30*1.21 -> 1994.1877 | R30: =T30+U30 -> 1829.53 | S30: =(R30/G30)/4.33333 -> 105.54989 | T30: 1829.53 | U30: 0 | V30: 0 | Y30: R. Paltan | Z30: =_xlfn.XLOOKUP(Y30,'relaties_export_2026-01-12_1609'!B:B,'relaties_export_2026-01-12_1609'!A:A,"",3) | AA30: =_xlfn.XLOOKUP(Z30,'relaties_export_2026-01-12_1609'!A:A,'relaties_export_2026-01-12_1609'!B:B,"",3) -> naam | AC30: 1416.85 | AD30: 1416.85 | AE30: 1391.85 | AF30: =(AD30/G30)/4.33333 -> 81.741409 | AG30: 44946
A31: 28 | B31: =_xlfn.XLOOKUP(D31,'[1]Sleutelplan nieuw'!B:B,'[1]Sleutelplan nieuw'!A:A,"",2) -> 0043 | C31: DS | D31: Amperelaan 23 | E31: 8451BW | F31: Oudeschoot | G31: 4 | H31: 4 | I31: 45208 | J31: 45573 | L31: Vivir Wonen | M31: =_xlfn.XLOOKUP(L31,'relaties_export_2026-01-12_1609'!B:B,'relaties_export_2026-01-12_1609'!A:A,"",3) -> 26 | N31: =_xlfn.XLOOKUP(M31,'relaties_export_2026-01-12_1609'!A:A,'relaties_export_2026-01-12_1609'!B:B,"",3) -> Vivir Wonen | P31: =R31-U31-V31-AD31 -> 753.42 | Q31: =T31*1.09+U31*1.21 -> 2693.4663 | R31: =T31+U31 -> 2471.07 | S31: =(R31/G31)/4.3333 -> 142.56283 | T31: 2471.07 | U31: 0 | V31: 0 | Y31: H. Samson | Z31: =_xlfn.XLOOKUP(Y31,'relaties_export_2026-01-12_1609'!B:B,'relaties_export_2026-01-12_1609'!A:A,"",3) -> 792 | AA31: =_xlfn.XLOOKUP(Z31,'relaties_export_2026-01-12_1609'!A:A,'relaties_export_2026-01-12_1609'!B:B,"",3) -> H. Samson | AB31: 06-22487252 | AC31: 1717.65 | AD31: 1717.65 | AE31: 1717.65 | AF31: =(AD31/G31)/4.33333 -> 99.095269 | AG31: 44381 | AH31: 45474
A32: 29 | B32: 0135 | C32: Factuur | D32: Amperestraat 36A | E32: 3112MD | F32: Schiedam | G32: 3 | H32: 2 | I32: 45405 | J32: 45769 | L32: Tradiro | M32: =_xlfn.XLOOKUP(L32,'relaties_export_2026-01-12_1609'!B:B,'relaties_export_2026-01-12_1609'!A:A,"",3) -> 17 | N32: =_xlfn.XLOOKUP(M32,'relaties_export_2026-01-12_1609'!A:A,'relaties_export_2026-01-12_1609'!B:B,"",3) -> Tradiro Services B.V. | P32: =R32-U32-V32-AD32 -> 130.13 | Q32: =T32*1.09+U32*1.21 -> 1843.8767 | R32: =T32+U32 -> 1691.63 | S32: =(R32/G32)/4.3333 -> 130.12639 | T32: 1691.63 | U32: 0 | V32: 0 | Y32: Parkwonen | Z32: =_xlfn.XLOOKUP(Y32,'relaties_export_2026-01-12_1609'!B:B,'relaties_export_2026-01-12_1609'!A:A,"",3) -> 258 | AA32: =_xlfn.XLOOKUP(Z32,'relaties_export_2026-01-12_1609'!A:A,'relaties_export_2026-01-12_1609'!B:B,"",3) -> Parkwonen | AC32: 1561.5 | AD32: 1561.5 | AE32: 1561.5 | AF32: =(AD32/G32)/4.33333 -> 120.11548
A33: 30 | B33: {=_xlfn.XLOOKUP(LEFT(D33,3),LEFT('[1]Sleutelplan nieuw'!B:B,3),'[1]Sleutelplan nieuw'!A:A,"",2)} -> 0353 | C33: Factuur | D33: Archimedesstraat 6B | E33: 3112DB | F33: Schiedam | G33: 4 | H33: 2 | I33: 45748 | J33: OBT | L33: Tradiro | M33: =_xlfn.XLOOKUP(L33,'relaties_export_2026-01-12_1609'!B:B,'relaties_export_2026-01-12_1609'!A:A,"",3) -> 17 | N33: =_xlfn.XLOOKUP(M33,'relaties_export_2026-01-12_1609'!A:A,'relaties_export_2026-01-12_1609'!B:B,"",3) -> Tradiro Services B.V. | P33: =R33-U33-V33-AD33 -> 373.96 | Q33: =T33*1.09+U33*1.21 -> 1770.1164 | R33: =T33+U33 -> 1623.96 | S33: =(R33/G33)/4.3333 -> 93.690721 | T33: 1623.96 | U33: 0 | Y33: Houses2Rent | Z33: =_xlfn.XLOOKUP(Y33,'relaties_export_2026-01-12_1609'!B:B,'relaties_export_2026-01-12_1609'!A:A,"",3) -> 271 | AA33: =_xlfn.XLOOKUP(Z33,'relaties_export_2026-01-12_1609'!A:A,'relaties_export_2026-01-12_1609'!B:B,"",3) -> Houses2Rent | AB33: 06-20877085 | AC33: 1250 | AD33: 1250 | AE33: 1250 | AF33: =(AD33/G33)/4.33333 -> 72.11544 | AG33: 45748
A34: 32 | B34: =_xlfn.XLOOKUP(D34,'[1]Sleutelplan nieuw'!B:B,'[1]Sleutelplan nieuw'!A:A,"",2) -> 0055 | C34: DS | D34: Baanhoek 139 | E34: 3361 GC | F34: Sliedrecht | G34: 4 | H34: 4 | L34: HousingWell | M34: =_xlfn.XLOOKUP(L34,'relaties_export_2026-01-12_1609'!B:B,'relaties_export_2026-01-12_1609'!A:A,"",3) -> 310 | N34: =_xlfn.XLOOKUP(M34,'relaties_export_2026-01-12_1609'!A:A,'relaties_export_2026-01-12_1609'!B:B,"",3) -> HousingWell B.V. | P34: =R34-U34-V34-AD34 -> 697.47 | Q34: =T34*1.09+U34*1.21 -> 3332.1223 | R34: =T34+U34 -> 3029.47 | S34: =(R34/G34)/4.33333 -> 174.77725 | T34: 2779.47 | U34: 250 | Y34: R. Verspui | Z34: =_xlfn.XLOOKUP(Y34,'relaties_export_2026-01-12_1609'!B:B,'relaties_export_2026-01-12_1609'!A:A,"",3) -> 852 | AA34: =_xlfn.XLOOKUP(Z34,'relaties_export_2026-01-12_1609'!A:A,'relaties_export_2026-01-12_1609'!B:B,"",3) -> R. Verspui | AB34: 06-22268830 | AC34: 2082 | AD34: 2082 | AE34: 2082 | AF34: =(AD34/G34)/4.33333 -> 120.11548 | AG34: 45473 | AH34: 45837
A35: 33 | B35: =_xlfn.XLOOKUP(D35,'[1]Sleutelplan nieuw'!B:B,'[1]Sleutelplan nieuw'!A:A,"",2) -> 0012 | C35: DS | D35: Baarlelaan 27 | E35: 7906GB | F35: Hoogeveen | G35: 4 | H35: 4 | I35: 44932 | J35: 45296 | L35: Vivir Wonen | M35: =_xlfn.XLOOKUP(L35,'relaties_export_2026-01-12_1609'!B:B,'relaties_export_2026-01-12_1609'!A:A,"",3) -> 26 | N35: =_xlfn.XLOOKUP(M35,'relaties_export_2026-01-12_1609'!A:A,'relaties_export_2026-01-12_1609'!B:B,"",3) -> Vivir Wonen | P35: =R35-U35-V35-AD35 -> 409.23 | Q35: =T35*1.09+U35*1.21 -> 2244.5607 | R35: =T35+U35 -> 2059.23 | S35: =(R35/G35)/4.33333 -> 118.80182 | T35: 2059.23 | U35: 0 | V35: 0 | Y35: Eva Laus | Z35: =_xlfn.XLOOKUP(Y35,'relaties_export_2026-01-12_1609'!B:B,'relaties_export_2026-01-12_1609'!A:A,"",3) -> 790 | AA35: =_xlfn.XLOOKUP(Z35,'relaties_export_2026-01-12_1609'!A:A,'relaties_export_2026-01-12_1609'!B:B,"",3) -> Eva Laus | AB35: 06-12707279 | AC35: 1650 | AD35: 1650 | AE35: 1650 | AF35: =(AD35/G35)/4.33333 -> 95.192381 | AG35: 44986 | AH35: 45351
A36: 34 | B36: =_xlfn.XLOOKUP(D36,'[1]Sleutelplan nieuw'!B:B,'[1]Sleutelplan nieuw'!A:A,"",2) -> 0013 | C36: DS | D36: Baarsveen 197 | E36: 3205 BB | F36: Spijkenisse | G36: 5 | H36: 5 | I36: 45231 | J36: 45412 | L36: BBTS (Vastgoed Spijkenisse) | M36: =_xlfn.XLOOKUP(L36,'relaties_export_2026-01-12_1609'!B:B,'relaties_export_2026-01-12_1609'!A:A,"",1) -> 190 | N36: =_xlfn.XLOOKUP(M36,'relaties_export_2026-01-12_1609'!A:A,'relaties_export_2026-01-12_1609'!B:B,"",3) -> BBTS (Vastgoed Spijkenisse) | P36: =R36-U36-V36-AD36 -> 2233.04 | Q36: =T36*1.09+U36*1.21 -> 5580.669 | R36: =T36+U36 -> 5084.1 | S36: =(R36/G36)/4.33333 -> 234.65095 | T36: 4759.1 | U36: 325 | V36: 0 | Y36: Beking | Z36: =_xlfn.XLOOKUP(Y36,'relaties_export_2026-01-12_1609'!B:B,'relaties_export_2026-01-12_1609'!A:A,"",3) -> 185 | AA36: =_xlfn.XLOOKUP(Z36,'relaties_export_2026-01-12_1609'!A:A,'relaties_export_2026-01-12_1609'!B:B,"",3) -> Dhr. R. J. Beking | AB36: 06-53714776 | AC36: 2526.06 | AD36: 2526.06 | AE36: 2526.06 | AF36: =(AD36/G36)/4.33333 -> 116.58747 | AG36: 44835 | AH36: 45200
A37: 35 | B37: =_xlfn.XLOOKUP(D37,'[1]Sleutelplan nieuw'!B:B,'[1]Sleutelplan nieuw'!A:A,"",2) -> 0040 | C37: DS | D37: Beatrixstraat 3 | E37: 3181GA | F37: Rozenburg | G37: 3 | H37: 3 | I37: 45940 | J37: 46304 | L37: Impes Service | M37: =_xlfn.XLOOKUP(L37,'relaties_export_2026-01-12_1609'!B:B,'relaties_export_2026-01-12_1609'!A:A,"",3) -> 220 | N37: =_xlfn.XLOOKUP(M37,'relaties_export_2026-01-12_1609'!A:A,'relaties_export_2026-01-12_1609'!B:B,"",3) -> Impes Service S.p.A. | O37: Nieuw per 10-10-25 | P37: =R37-U37-V37-AD37 -> 743 | Q37: =T37*1.09+U37*1.21 -> 3627 | R37: =T37+U37 -> 3300 | S37: =(R37/G37)/4.33333 -> 253.84635 | T37: 3050 | U37: 250 | V37: 0 | Y37: Crul | Z37: =_xlfn.XLOOKUP(Y37,'relaties_export_2026-01-12_1609'!B:B,'relaties_export_2026-01-12_1609'!A:A,"",3) -> 180 | AA37: =_xlfn.XLOOKUP(Z37,'relaties_export_2026-01-12_1609'!A:A,'relaties_export_2026-01-12_1609'!B:B,"",3) -> Mw. M. Hyllested Poulsen en Dhr. S. Crull | AB37: 0045-28180001 | AC37: 2307 | AD37: 2307 | AE37: 2307 | AF37: =(AD37/G37)/4.33333 -> 177.46167 | AG37: 44835 | AH37: 5--5-2024
A38: 36 | B38: =_xlfn.XLOOKUP(D38,'[1]Sleutelplan nieuw'!B:B,'[1]Sleutelplan nieuw'!A:A,"",2) -> 0152 | C38: Factuur | D38: Beeklaan 294 | E38: 2562AV | F38: Den Haag | G38: 8 | H38: 4 | I38: 45898 | J38: 46262 | L38: Duijndam Personeelsdiensten B.V. | M38: =_xlfn.XLOOKUP(L38,'relaties_export_2026-01-12_1609'!B:B,'relaties_export_2026-01-12_1609'!A:A,"",3) -> 360 | N38: =_xlfn.XLOOKUP(M38,'relaties_export_2026-01-12_1609'!A:A,'relaties_export_2026-01-12_1609'!B:B,"",3) -> Duijndam Personeelsdiensten B.V. | P38: =R38-U38-V38-AD38 -> 394 | Q38: =T38*1.09+U38*1.21 -> 5558.5 | R38: =T38+U38 -> 5050 | S38: =(R38/G38)/4.33333 -> 145.67319 | T38: 4600 | U38: 450 | V38: 0 | Y38: Homescout21 B.V. | Z38: =_xlfn.XLOOKUP(Y38,'relaties_export_2026-01-12_1609'!B:B,'relaties_export_2026-01-12_1609'!A:A,"",3) -> 211 | AA38: =_xlfn.XLOOKUP(Z38,'relaties_export_2026-01-12_1609'!A:A,'relaties_export_2026-01-12_1609'!B:B,"",3) -> Homescout21 B.V. | AC38: 4206 | AD38: 4206 | AE38: 4206 | AF38: =(AD38/G38)/4.33333 -> 121.32702
A39: 38 | B39: =_xlfn.XLOOKUP(D39,'[1]Sleutelplan nieuw'!B:B,'[1]Sleutelplan nieuw'!A:A,"",2) -> 0322 | C39: Factuur | D39: Bettingeslag 10 | E39: 7824HD | F39: Emmen | G39: 4 | H39: 4 | I39: 45803 | J39: 45925 | L39: CB Construction | M39: =_xlfn.XLOOKUP(L39,'relaties_export_2026-01-12_1609'!B:B,'relaties_export_2026-01-12_1609'!A:A,"",3) -> 352 | N39: =_xlfn.XLOOKUP(M39,'relaties_export_2026-01-12_1609'!A:A,'relaties_export_2026-01-12_1609'!B:B,"",3) -> CB Construction UAB | O39: Gaat eruit 28-12 | P39: =R39-U39-V39-AD39 -> -1650 | U39: 250 | Y39: J.P. Stoel | Z39: =_xlfn.XLOOKUP(Y39,'relaties_export_2026-01-12_1609'!B:B,'relaties_export_2026-01-12_1609'!A:A,"",3) -> 795 | AA39: =_xlfn.XLOOKUP(Z39,'relaties_export_2026-01-12_1609'!A:A,'relaties_export_2026-01-12_1609'!B:B,"",3) -> J.P. Stoel | AB39: 06-40896047 | AC39: 1400 | AD39: 1400 | AE39: 1400 | AF39: =(AD39/G39)/4.33333 -> 80.769293 | AG39: 45689 | AH39: 46054
A40: 39 | B40: =_xlfn.XLOOKUP(D40,'[1]Sleutelplan nieuw'!B:B,'[1]Sleutelplan nieuw'!A:A,"",2) -> 0346 | C40: Factuur | D40: Beukenlaan 53 | E40: 3181XA | F40: Rozenburg | G40: 6 | H40: 3 | I40: 45717 | L40: PMM Workforce Management Ltd | M40: =_xlfn.XLOOKUP(L40,'relaties_export_2026-01-12_1609'!B:B,'relaties_export_2026-01-12_1609'!A:A,"",2) -> 277 | N40: =_xlfn.XLOOKUP(M40,'relaties_export_2026-01-12_1609'!A:A,'relaties_export_2026-01-12_1609'!B:B,"",3) -> PMM Workforce Management Ltd | O40: Terug naar eigenaar per 31-12 | P40: =R40-U40-V40-AD40 -> 0 | Y40: TwinsBV | Z40: =_xlfn.XLOOKUP(Y40,'relaties_export_2026-01-12_1609'!B:B,'relaties_export_2026-01-12_1609'!A:A,"",3) -> 796 | AA40: =_xlfn.XLOOKUP(Z40,'relaties_export_2026-01-12_1609'!A:A,'relaties_export_2026-01-12_1609'!B:B,"",3) -> TwinsBV
...

Sheet relaties_marked
A1: Object_id | B1: relatie_id | C1: huurder | D1: relatie_id | E1: eigenaar
A2: 0388 | B2: 23 | C2: S. Bakker OPH Verhuur | D2: 751 | E2: Orange Invesments Group
A3: 0022 | B3: 17 | C3: Tradiro Services B.V. | D3: 574 | E3: Verknocht
A4: 0148 | B4: 17 | C4: Tradiro Services B.V. | D4: 306 | E4: Jacco Maat
A5: 0149 | B5: 17 | C5: Tradiro Services B.V. | D5: 306 | E5: Jacco Maat
A6: 0150 | B6: 17 | C6: Tradiro Services B.V. | D6: 306 | E6: Jacco Maat
A7: 0003 | B7: 13 | C7: United Homes B.V. | D7: 789 | E7: MvB Services BV (Meindert van Buuren)
A8: 0190 | B8: 145 | C8: dockHolland Huisvesting B.V. | D8: 824 | E8: Vivir wonen (Mendy)
A9: 0007 | B9: 154 | C9: InAxtion Vastgoed B.V. | D9: 790 | E9: Eva Laus
A10: 0341 | B10: 236 | C10: NL Realty B.V. | D10: 726 | E10: Cris
A11: 0372 | B11: 348 | C11: MNA Proud Facilities B.V. | D11: 726 | E11: Cris
A12: 0293 | B12: 346 | C12: Buurman Vastgoed E B.V. | D12: 726 | E12: Cris
A13: 0294 | B13: 236 | C13: NL Realty B.V. | D13: 766 | E13: C. van Driel e/o B.M. Verdouw
... A28: 0307 | B28: 347 | C28: FISSH B.V. | D28: 726 | E28: Cris
A29: 0002 | B29: 260 | C29: Looije Facilities B.V. | E29: naam
A30: 0043 | B30: 26 | C30: Vivir Wonen | D30: 792 | E30: H. Samson
A31: 0135 | B31: 17 | C31: Tradiro Services B.V. | D31: 258 | E31: Parkwonen
A32: 0353 | B32: 17 | C32: Tradiro Services B.V. | D32: 271 | E32: Houses2Rent
A33: 0055 | B33: 310 | C33: HousingWell B.V. | D33: 852 | E33: R. Verspui
A34: 0012 | B34: 26 | C34: Vivir Wonen | D34: 790 | E34: Eva Laus
A35: 0013 | B35: 190 | C35: BBTS (Vastgoed Spijkenisse) | D35: 185 | E35: Dhr. R. J. Beking
A36: 0040 | B36: 220 | C36: Impes Service S.p.A. | D36: 180 | E36: Mw. M. Hyllested Poulsen en Dhr. S. Crull
A37: 0152 | B37: 360 | C37: Duijndam Personeelsdiensten B.V. | D37: 211 | E37: Homescout21 B.V.
A38: 0322 | B38: 352 | C38: CB Construction UAB | D38: 795 | E38: J.P. Stoel
A39: 0346 | B39: 277 | C39: PMM Workforce Management Ltd | D39: 796 | E39: TwinsBV
A40: 0047 | B40: 149 | C40: Werckpost Service B.V. | D40: 147 | E40: T. Hoolhorst
A41: 0048 | B41: 124 | C41: AmDor Projecten B.V. | D41: 77 | E41: A.P.W. Koedooder
... A44: 0049 | B44: 286 | C44: Team Unica B.V. | D44: 175 | E44: Dhr. J.L. Meerding
A45: 0280 | B45: id | C45: naam | D45: 952 | E45: M. Nottet
A46: 0281 | B46: id | C46: naam | D46: 952 | E46: M. Nottet
A47: 0004 | B47: 17 | C47: Tradiro Services B.V. | D47: 258 | E47: Parkwonen
A48: 0027 | B48: 17 | C48: Tradiro Services B.V. | D48: 797 | E48: W. van Straalen
A49: 0097 | B49: 17 | C49: Tradiro Services B.V. | D49: 302 | E49: A.H.S. Willemsen
A50: 0160 | B50: 17 | C50: Tradiro Services B.V. | D50: 295 | E50: In Stijl Totaalbouw BV
A51: 0131 | B51: 17 | C51: Tradiro Services B.V. | D51: 258 | E51: Parkwonen
A52: 0026 | B52: 17 | C52: Tradiro Services B.V. | D52: 258 | E52: Parkwonen
A53: 0370 | B53: 17 | C53: Tradiro Services B.V. | D53: 85 | E53: 4 Homes B.V.
A54: 0051 | B54: 13 | C54: United Homes B.V. | D54: #VALUE! | E54: #VALUE!
A55: 0052 | B55: 13 | C55: United Homes B.V. | D55: #VALUE! | E55: #VALUE!
A56: 0375 | B56: 17 | C56: Tradiro Services B.V. | D56: 799 | E56: Z. Yilmaz
...
