Workbook
Name Aantal_dagen: Algemeen!$B$22
Name Borg_gebruikt: Algemeen!$B$53
Name Borg_terug: Algemeen!$B$54
Name BTW_percentage_schoonmaak: Algemeen!$B$38
Name Contractnummer: Algemeen!$B$43
Name Email: Algemeen!$B$9
Name Energie_leverancier: Algemeen!$B$42
Name Extra_schoonmaak_bedrag: Schoonmaak!$B$9
Name Extra_schoonmaak_bedrag_calc: Algemeen!$B$40
Name Extra_uren: Schoonmaak!$B$7
Name Extra_voorschot_bedrag: Algemeen!$B$31
Name Extra_voorschot_gebruikt: Algemeen!$B$57
Name Extra_voorschot_omschrijving: Algemeen!$B$32
Name Extra_voorschot_restschade: Algemeen!$B$59
Name Extra_voorschot_terug: Algemeen!$B$58
Name Gas_begin: GWE_Detail!$B$7
Name Gas_eind: GWE_Detail!$B$8
Name Gas_verbruik: GWE_Detail!$B$9
Name GWE_Beheer: Algemeen!$B$26
Name GWE_BTW: GWE_Detail!$B$39
Name GWE_Maandbedrag: Algemeen!$B$27
Name GWE_meer_minder: Algemeen!$B$56
Name GWE_totaal_excl: GWE_Detail!$B$38
Name GWE_totaal_incl: GWE_Detail!$B$40
Name Inbegrepen_uren: Algemeen!$B$36
Name Incheck_datum: Algemeen!$B$20
Name Klant_Adres: Algemeen!$B$6
Name Klant_Plaats: Algemeen!$B$8
Name Klant_Postcode: Algemeen!$B$7
Name Klantnaam: Algemeen!$B$4
Name Klantnummer: Algemeen!$B$5
Name KWh_begin: GWE_Detail!$B$4
Name KWh_eind: GWE_Detail!$B$5
Name KWh_verbruik: GWE_Detail!$B$6
Name Meterbeheerder: Algemeen!$B$41
Name Object_adres: Algemeen!$B$12
Name Object_ID: Algemeen!$B$17
Name Overige_voorschotten: Algemeen!$B$30
Name Plaats: Algemeen!$B$16
Name Postcode: Algemeen!$B$15
Name Restschade: Algemeen!$B$55
Name RR_Factuurnummer: Algemeen!$B$50
Name RR_Folder_link: Algemeen!$B$47
Name RR_Inspecteur: Algemeen!$B$49
Name RR_Klantnummer: Algemeen!$B$46
Name RR_Projectleider: Algemeen!$B$48
Name Schade_BTW: Schade!$B$59
Name Schade_totaal_excl: Schade!$B$58
Name Schade_totaal_incl: Schade!$B$60
Name Schoonmaak_pakket: Algemeen!$B$35
Name Schoonmaak_totaal_kosten: Algemeen!$B$39
Name Totaal_eindafrekening: Algemeen!$B$60
Name Totaal_uren_gew: Schoonmaak!$B$6
Name Uitcheck_datum: Algemeen!$B$21
Name Unit_nr: Algemeen!$B$14
Name Uurtarief_schoonmaak: Algemeen!$B$37
Name Voorschot_borg: Algemeen!$B$25
Name Voorschot_GWE: Algemeen!$B$28
Name Voorschot_schoonmaak: Algemeen!$B$29
Name Water_begin: GWE_Detail!$B$10

Sheet Algemeen
A1: RYANRENT EINDAFREKENING - BASISGEGEVENS
A3: KLANTGEGEVENS
A4: Naam Klant * | B4: DS People B.V.
A5: Klantnummer (automatisch) | B5: =IFERROR(VLOOKUP(B4,Lists!$F:$K,2,FALSE),"") -> 50201
A6: Adres (automatisch) | B6: =IFERROR(VLOOKUP(B4,Lists!$F:$K,3,FALSE),"") -> Deltageul 13
A7: Postcode (automatisch) | B7: =IFERROR(VLOOKUP(B4,Lists!$F:$K,4,FALSE),"") -> 0
A8: Plaats (automatisch) | B8: =IFERROR(VLOOKUP(B4,Lists!$F:$K,5,FALSE),"") -> STELLENDAM
A9: Email (automatisch) | B9: =IFERROR(VLOOKUP(B4,Lists!$F:$K,6,FALSE),"") -> Facturen@dspeople.nl
A11: OBJECTGEGEVENS
A12: Adres Object * | B12: Rooseveltlaan 185
A13: Object ID (automatisch) | B13: =IFERROR(VLOOKUP(B12,Lists!$A:$B,2,FALSE),"") -> 0179
A14: Unit Nummer
A15: Postcode | B15: =IFERROR(VLOOKUP(B12,Lists!$A:$D,3,FALSE),"") -> 2481KA
A16: Plaats | B16: =IFERROR(VLOOKUP(B12,Lists!$A:$D,4,FALSE),"") -> Woubrugge
A17: Object ID (automatisch) | B17: =IF(B12="","",VLOOKUP(B12,Lists!$A$2:$B$389,2,FALSE)) -> 0179
A19: VERBLIJFSPERIODE
A20: Incheck Datum * | B20: 45382
A21: Uitcheck Datum * | B21: 45961
A22: Aantal Dagen (automatisch) | B22: =IF(AND(B20<>"",B21<>""),B21-B20,"") -> 579
A24: VOORSCHOTTEN
A25: Voorschot Borg * | B25: 3100
A26: GWE Beheer * | B26: Via RyanRent
A27: GWE Maandbedrag | B27: 300
A28: Voorschot GWE (automatisch) | B28: =IF(B26="Eigen Beheer",0,IF(ISNUMBER(B27), (B27 * 12 / 365) * Aantal_dagen, 0)) -> 5710.6849
A29: Voorschot Schoonmaak *
A30: Overige Voorschotten | B30: 0
A31: Extra Voorschot Bedrag | B31: 0
A32: Extra Voorschot Omschrijving
A34: CONTRACTGEGEVENS
A35: Schoonmaak Pakket * | B35: Achteraf Betaald
A36: Inbegrepen Uren (automatisch) | B36: =IF(B35="Basis Schoonmaak",5,IF(B35="Intensief Schoonmaak",7,0)) -> 0
A37: Uurtarief Schoonmaak (excl. BTW) * | B37: 50
A38: BTW Percentage Schoonmaak * | B38: 0.21
A39: Schoonmaak Totaal Kosten (automatisch) | B39: =IF([0]!Totaal_uren_gew="","",MAX(Inbegrepen_uren,[0]!Totaal_uren_gew)*B37*(1+B38)) -> 423.5
A40: Extra Schoonmaak Bedrag (automatisch) | B40: =MAX(0,Schoonmaak_totaal_kosten-Voorschot_schoonmaak) -> 423.5
A41: Meterbeheerder | B41: Vattenfall
A42: Energie Leverancier | B42: Vattenfall
A43: Contractnummer
A45: INTERNE RYANRENT GEGEVENS
A46: RR Klantnummer | B46: =Klantnummer -> 50201
...

Sheet Lists
A1: Address | B1: Object ID | C1: Postcode | D1: Plaats | F1: Naam | G1: Klantnummer | H1: Adres | I1: Postcode | J1: Plaats | K1: Email
A2: 1e | B2: 0388 | D2: Middellandstraat 104A | F2: 't Werkt B.V. | G2: 50223 | H2: Burgemeester Meslaan 98 | J2: TIEL | K2: finance@twerkt.nl
A3: 2e Maasbosstraat 2 a | B3: 0148 | D3: VLAARDINGEN | F3: 24/7 drive | G3: 50224 | H3: Ekkersrijt 7025 | J3: SON EN BREUGEL | K3: factuur@247drive.nl
A4: 2e Maasbosstraat 2 b | B4: 0149 | C4: 2807BB | D4: Gouda | F4: 4 Homes B.V. | G4: 94
A5: 2e Maasbosstraat 2 c | B5: 0150 | C5: 7553LC | D5: Hengelo | F5: 4 Homes B.V. | G5: 100151 | H5: Prins Reinierstraat 18a | J5: Steenbergen | K5: factuur@4homes.nl
A6: 2e van Leydengaelstraat 6 | B6: 0022 | C6: 1779GJ | D6: Den Oever | F6: A. Blaszcak | G6: 50146 | H6: Prof. Kernkampstraat 24 | J6: Tilburg | K6: info@aneta.nl
A7: Abelenlaan 143 | B7: 0014 | C7: 1779GJ | D7: Den Oever | F7: A. Brouwers en S. Brouwers- van Weert | G7: 50405 | H7: Dokter Barentsenstraat 42 | J7: Bergeyk
A8: Acacia 2 | B8: 0003 | C8: 3224EB | D8: Hellevoetsluis | F8: A. Dzaka | G8: 74 | H8: Merwedepad 29 | J8: Rozenburg ZH | K8: adisa-kemo@hotmail.com
A9: Acacialaan 9 | B9: 0223 | C9: 3085CZ | D9: Rotterdam | F9: A. Ghali | G9: 50142 | H9: Rooseveltlaan 956 | J9: Utrecht
A10: Achterdijk 47 | B10: 0190 | C10: 3071EE | D10: Rotterdam | F10: A. Verschueren | G10: 72 | H10: Mangelbeekstraat 1 | K10: verhuur@reham.nl
A11: Adriaan Baasstraat 34 | B11: 0007 | C11: 1779GJ | D11: Den Oever | F11: A.H.S. Willemsen | G11: 100098 | K11: huurwoningarnhem@gmail.com
A12: Akkerweg 41 | B12: 0384 | D12: [huis 58] | F12: A.I.G. Lukkien | G12: 50189 | H12: Achterstekamp 28 | J12: Stadskanaal
A13: Akkerweg 41 [010] | B13: 0341 | D13: Den oever | F13: A.P.W. Koedooder | G13: 86 | H13: Isaac Beeckmanhof 1 | J13: ROTTERDAM | K13: apwkoedooder@gmail.com
A14: Akkerweg 41 [011] | B14: 0372 | D14: Den oever | F14: A.W.N. Alkemade | G14: 44 | H14: Laan van Pluymestein 36 | J14: WASSENAAR | K14: melkveebedrijfalkemade@kpnmail.nl
A15: Akkerweg 41 [014] | B15: 0293 | D15: Den Oever | F15: A.Y. Nicolai | G15: 64 | H15: De Setangel 14 | J15: GROU | K15: famnicolai@hotmail.com
A16: Akkerweg 41 [015] | B16: 0294 | D16: Den Oever | F16: ABC Bedrijfsservice B.V | G16: 50353 | H16: Sint Canisiussingel 36 | J16: Nijmegen | K16: randy@abc-jobs.eu
A17: Akkerweg 41 [016] | B17: 0342 | D17: Den oever | F17: AKRION ADMINISTRATION | G17: 50332 | H17: Corn. Speelmanstraat 77 | J17: 's-Gravenhage | K17: info@interm-project.com
A18: Akkerweg 41 [017] | B18: 0373 | D18: Den oever | F18: AKT Autoschade | G18: 50315 | H18: Goirkekanaaldijk 211-18 | J18: Tilburg | K18: facturen@aktautoschade.com
A19: Akkerweg 41 [018] | B19: 0295 | D19: Den oever | F19: Adecco Group | G19: 50352 | J19: Zaltbommel | K19: crediteurenadministratie@adecco.nl
A20: Akkerweg 41 [019] | B20: 0343 | D20: Den oever | F20: Aelbers Flexibele Personeels Diensten B.V. | G20: 50348 | H20: Grutbroek 15 | J20: Doetinchem | K20: facturen@aelberspersoneel.nl
A21: Akkerweg 41 [020] | B21: 0383 | C21: 1779GJ | D21: Den oever | F21: Alis Vastgoed B.V. | G21: 31 | H21: Fruitweg 25 | J21: 'S-GRAVENHAGE | K21: rifat@prokonak.nl
A22: Akkerweg 41 [022] | B22: 0296 | D22: Den oever | F22: Alpha Workforce Aps | G22: 50287 | H22: Priory Hall | J22: Dublin | K22: operations@alphaworkforce.net
A23: Akkerweg 41 [026] | B23: 0297 | D23: Den oever | F23: AmDor Projecten B.V. | G23: 50157 | H23: Maarsseveensevaart 92 | J23: MAARSSEN | K23: invoice@amdorprojecten.nl
A24: Akkerweg 41 [031] | B24: 0298 | D24: Den oever | F24: Autobedrijf Voorne | G24: 50299 | H24: Langeweg 3 | J24: OOSTVOORNE | K24: info@autobedrijfvoorne.nl
A25: Akkerweg 41 [035] | B25: 0350 | D25: Den oever | F25: Autobedrijf W. Bronder | G25: 50008 | H25: Boomweg 17 | J25: Rockanje | K25: k.bronder@outlook.com
A26: Akkerweg 41 [036] | B26: 0356 | D26: Den oever | F26: Autodaxx B.V. | G26: 50175 | H26: Argon 21 | J26: OUD GASTEL | K26: inkoopfactuur@autodaxx.nl
A27: Akkerweg 41 [037] | B27: 0299 | D27: Den Oever | F27: B. Bosch | G27: 50169 | H27: Stuartweg 29 | J27: Vianen | K27: brucebosch@live.nl
A28: Akkerweg 41 [038] | B28: 0357 | D28: Den oever | F28: B. van Abeelen | G28: 100265 | H28: Blauwloop 2 | J28: Loon op Zand | K28: vanabeelenstucadoorsbedrijf@gmail.com
A29: Akkerweg 41 [040] | B29: 0300 | D29: Den oever | F29: BDR Uitzendbureau B.V. | G29: 50254 | H29: Sint-Andriesstraat 222 | J29: ROTTERDAM | K29: muratbayka@gmail.com
A30: Akkerweg 41 [041] | B30: 0301 | D30: Den oever | F30: BJ Bakker | G30: 50330 | H30: Spiens 3 | J30: Dokkum | K30: bjbakker85@hotmail.com
A31: Akkerweg 41 [042] | B31: 0302 | D31: Den oever | F31: Bator V.O.F. | G31: 50101 | H31: Jacob Marisstraat 37 | J31: Zwijndrecht
A32: Akkerweg 41 [055] | B32: 0303 | D32: Den oever | F32: Best@Work B.V. | G32: 38 | H32: Industrieweg 74-76 | J32: WAALWIJK | K32: info@bestatwork.nl
A33: Akkerweg 41 [056] | B33: 0304 | D33: Den oever | F33: Betterway BV | G33: 50401 | H33: Nijverheidsweg-Noord 81 | J33: Amersfoort | K33: rbecker@fbaivastgoed.com
A34: Akkerweg 41 [057] | B34: 0305 | D34: Den oever | F34: Bosch B Dhr (Scheepjesbrug 814 Meerkerk) | G34: 50302 | H34: Nolweg 9 | J34: Schelluinen | K34: brucebosch@live.nl
A35: Akkerweg 41 [059] | B35: 0306 | D35: Den oever | F35: Bouius | G35: 50419 | H35: Jan van Scorelstraat 50 | J35: Leeuwarden | K35: r.bouius@hotmail.com
A36: Akkerweg 41 [068] | B36: 0326 | D36: Den oever | F36: Bouw Service International B.V. | G36: 50257 | H36: Kanaal Noord 446 | J36: BEEMTE BROEKLAND | K36: bouwserviceinternational@gmail.com
A37: Akkerweg 41 [074] | B37: 0379 | D37: Den Oever | F37: Bright Home Rentals B.V. | G37: 2 | H37: Ebweg 73 | J37: BARENDRECHT | K37: administratie@brighthomerentals.nl
A38: Akkerweg 41 [075] | B38: 0307 | D38: Den oever | F38: Business Housing | G38: 58 | H38: Oosteinde 26 | J38: Oud Alblas | K38: eliane@zamens.nl
A39: Allard Piersonlaan 142 | B39: 0002 | C39: 2522 MT | D39: Den Haag | F39: Buurman Vastgoed E B.V. | G39: 100191 | H39: Westerweg 291 | J39: Alkmaar | K39: admin@inexho.com
A40: Ambergweg 14 | B40: 0201 | C40: 3081JH | D40: Rotterdam | F40: Bw-engineering | G40: 100178 | H40: van Brakelstraat 66 | J40: Rotterdam | K40: r.adelaar@bw-engineering.nl
...

Sheet GWE_Detail
A1: GAS / WATER / ELEKTRA DETAIL
A3: METERSTANDEN
A4: Elektra (kWh) Begin * | B4: 13598
A5: Elektra (kWh) Eind * | B5: =10076+6830 -> 16906
A6: Elektra (kWh) Verbruik (automatisch) | B6: =IF(AND(B4<>"",B5<>""),B5-B4,"") -> 3308
A7: Gas (m³) Begin * | B7: 11954
A8: Gas (m³) Eind * | B8: 15360
A9: Gas (m³) Verbruik (automatisch) | B9: =IF(AND(B7<>"",B8<>""),B8-B7,"") -> 3406
A10: Water (m³) Begin | B10: 1128
A11: Water (m³) Eind | B11: 1313
A12: Water (m³) Verbruik (automatisch) | B12: =IF(AND(B10<>"",B11<>""),B11-B10,"") -> 185
A14: KOSTENREGELS - Verbruik omzetten naar Euro's
A15: 💡 Vul hier de kosten in op basis van verbruik × tarief van energieleverancier. Voorbeelden staan hieronder (grijs). Verwijder voorbeelden en vul eigen regels in.
A16: Type | B16: Omschrijving | C16: Eenheid | D16: Verbruik | E16: Tarief excl. BTW (€) | F16: Kosten excl. BTW (€) | G16: BTW % | H16: BTW (€)
A17: Water | B17: Levering | C17: =IF(A17="Elektra","kWh",IF(A17="Gas","m³",IF(A17="Water","m³",""))) -> m³ | D17: =IF(A17="Elektra",KWh_verbruik,IF(A17="Gas",Gas_verbruik,IF(A17="Water",Water_verbruik,""))) -> 185 | E17: 1.29 | F17: =IF(OR(D17="",E17=""),0,D17*E17) -> 238.65 | G17: 0.09 | H17: =F17*G17 -> 21.4785
A18: Water | B18: Vastrecht | C18: dag | D18: 579 | E18: 0.25474 | F18: =IF(OR(D18="",E18=""),0,D18*E18) -> 147.49446 | G18: 0.09 | H18: =F18*G18 -> 13.274501
A19: Water | B19: Belasting op leiding water | C19: =IF(A19="Elektra","kWh",IF(A19="Gas","m³",IF(A19="Water","m³",""))) -> m³ | D19: =IF(A19="Elektra",KWh_verbruik,IF(A19="Gas",Gas_verbruik,IF(A19="Water",Water_verbruik,""))) -> 185 | E19: 0.458 | F19: =IF(OR(D19="",E19=""),0,D19*E19) -> 84.73 | G19: 0.09 | H19: =F19*G19 -> 7.6257
A20: Water | B20: Precarioheffing | C20: =IF(A20="Elektra","kWh",IF(A20="Gas","m³",IF(A20="Water","m³",""))) -> m³ | D20: =IF(A20="Elektra",KWh_verbruik,IF(A20="Gas",Gas_verbruik,IF(A20="Water",Water_verbruik,""))) -> 185 | E20: 0.0923 | F20: =IF(OR(D20="",E20=""),0,D20*E20) -> 17.0755 | G20: 0.09 | H20: =F20*G20 -> 1.536795
A21: Elektra | B21: Enkel tarief | C21: =IF(A21="Elektra","kWh",IF(A21="Gas","m³",IF(A21="Water","m³",""))) -> kWh | D21: =IF(A21="Elektra",KWh_verbruik,IF(A21="Gas",Gas_verbruik,IF(A21="Water",Water_verbruik,""))) -> 3308 | E21: 0.274476 | F21: =IF(OR(D21="",E21=""),0,D21*E21) -> 907.96661 | G21: 0.21 | H21: =F21*G21 -> 190.67299
A22: Elektra | B22: Vaste Leveringskosten (Elektra) | C22: dag | D22: 579 | E22: 0.397808 | F22: =IF(OR(D22="",E22=""),0,D22*E22) -> 230.33083 | G22: 0.21 | H22: =F22*G22 -> 48.369475
A23: Elektra | B23: Vermindering Energie belasting | C23: dag | D23: 579 | E23: -1.740245 | F23: =IF(OR(D23="",E23=""),0,D23*E23) -> -1007.6019 | G23: 0.21 | H23: =F23*G23 -> -211.59639
A24: Elektra | B24: Net beheerkosten 3 x 25 p/d (elektra) | C24: dag | D24: 579 | E24: 1.303896 | F24: =IF(OR(D24="",E24=""),0,D24*E24) -> 754.95578 | G24: 0.21 | H24: =F24*G24 -> 158.54071
A25: Gas | B25: Gas Verbruik | C25: =IF(A25="Elektra","kWh",IF(A25="Gas","m³",IF(A25="Water","m³",""))) -> m³ | D25: =IF(A25="Elektra",KWh_verbruik,IF(A25="Gas",Gas_verbruik,IF(A25="Water",Water_verbruik,""))) -> 3406 | E25: 1.287755 | F25: =IF(OR(D25="",E25=""),0,D25*E25) -> 4386.0935 | G25: 0.21 | H25: =F25*G25 -> 921.07964
A26: Gas | B26: Vaste Leveringskosten (Gas) | C26: dag | D26: 579 | E26: 0.298356 | F26: =IF(OR(D26="",E26=""),0,D26*E26) -> 172.74812 | G26: 0.21 | H26: =F26*G26 -> 36.277106
A27: Gas | B27: Net beheerkosten 3 x 25 p/d (gas) | C27: dag | D27: 579 | E27: 0.674212 | F27: =IF(OR(D27="",E27=""),0,D27*E27) -> 390.36875 | G27: 0.21 | H27: =F27*G27 -> 81.977437
C28: =IF(A28="Elektra","kWh",IF(A28="Gas","m³",IF(A28="Water","m³",""))) | D28: =IF(A28="Elektra",KWh_verbruik,IF(A28="Gas",Gas_verbruik,IF(A28="Water",Water_verbruik,""))) | F28: =IF(OR(D28="",E28=""),0,D28*E28) -> 0 | G28: 0.21 | H28: =F28*G28 -> 0
C29: =IF(A29="Elektra","kWh",IF(A29="Gas","m³",IF(A29="Water","m³",""))) | D29: =IF(A29="Elektra",KWh_verbruik,IF(A29="Gas",Gas_verbruik,IF(A29="Water",Water_verbruik,""))) | F29: =IF(OR(D29="",E29=""),0,D29*E29) -> 0 | G29: 0.21 | H29: =F29*G29 -> 0
C30: =IF(A30="Elektra","kWh",IF(A30="Gas","m³",IF(A30="Water","m³",""))) | D30: =IF(A30="Elektra",KWh_verbruik,IF(A30="Gas",Gas_verbruik,IF(A30="Water",Water_verbruik,""))) | F30: =IF(OR(D30="",E30=""),0,D30*E30) -> 0 | G30: 0.21 | H30: =F30*G30 -> 0
C31: =IF(A31="Elektra","kWh",IF(A31="Gas","m³",IF(A31="Water","m³",""))) | D31: =IF(A31="Elektra",KWh_verbruik,IF(A31="Gas",Gas_verbruik,IF(A31="Water",Water_verbruik,""))) | F31: =IF(OR(D31="",E31=""),0,D31*E31) -> 0 | G31: 0.21 | H31: =F31*G31 -> 0
C32: =IF(A32="Elektra","kWh",IF(A32="Gas","m³",IF(A32="Water","m³",""))) | D32: =IF(A32="Elektra",KWh_verbruik,IF(A32="Gas",Gas_verbruik,IF(A32="Water",Water_verbruik,""))) | F32: =IF(OR(D32="",E32=""),0,D32*E32) -> 0 | G32: 0.21 | H32: =F32*G32 -> 0
C33: =IF(A33="Elektra","kWh",IF(A33="Gas","m³",IF(A33="Water","m³",""))) | D33: =IF(A33="Elektra",KWh_verbruik,IF(A33="Gas",Gas_verbruik,IF(A33="Water",Water_verbruik,""))) | F33: =IF(OR(D33="",E33=""),0,D33*E33) -> 0 | G33: 0.21 | H33: =F33*G33 -> 0
C34: =IF(A34="Elektra","kWh",IF(A34="Gas","m³",IF(A34="Water","m³",""))) | D34: =IF(A34="Elektra",KWh_verbruik,IF(A34="Gas",Gas_verbruik,IF(A34="Water",Water_verbruik,""))) | F34: =IF(OR(D34="",E34=""),0,D34*E34) -> 0 | G34: 0.21 | H34: =F34*G34 -> 0
C35: =IF(A35="Elektra","kWh",IF(A35="Gas","m³",IF(A35="Water","m³",""))) | D35: =IF(A35="Elektra",KWh_verbruik,IF(A35="Gas",Gas_verbruik,IF(A35="Water",Water_verbruik,""))) | F35: =IF(OR(D35="",E35=""),0,D35*E35) -> 0 | G35: 0.21 | H35: =F35*G35 -> 0
C36: =IF(A36="Elektra","kWh",IF(A36="Gas","m³",IF(A36="Water","m³",""))) | D36: =IF(A36="Elektra",KWh_verbruik,IF(A36="Gas",Gas_verbruik,IF(A36="Water",Water_verbruik,""))) | F36: =IF(OR(D36="",E36=""),0,D36*E36) -> 0 | G36: 0.21 | H36: =F36*G36 -> 0
A37: TOTALEN (automatisch berekend)
A38: Totaal excl. BTW (automatisch) | B38: =SUM(F17:F36) -> 6322.8117
A39: BTW (Totaal, automatisch) | B39: =SUM(H17:H37) -> 1269.2365
A40: Totaal incl. BTW (automatisch) | B40: =GWE_totaal_excl+GWE_BTW -> 7592.0482

Sheet Schoonmaak
A1: SCHOONMAAK OVERZICHT
A3: SCHOONMAAK GEGEVENS
A4: Schoonmaak Pakket * | B4: =[0]!Schoonmaak_pakket -> Achteraf Betaald
A5: Inbegrepen Uren (automatisch) | B5: =IF(B4="Basis Schoonmaak",5,IF(B4="Intensief Schoonmaak",7,""))
A6: Totaal Uren Gewerkt * | B6: 7
A7: Extra Uren (automatisch) | B7: =IF(AND(B5<>"",B6<>""),MAX(0,B6-B5),"")
A8: Uurtarief * | B8: =[0]!Uurtarief_schoonmaak -> 50
A9: Extra Schoonmaak Bedrag (automatisch) | B9: =IF(AND(B7<>"",B8<>""),B7*B8,"")

Sheet Schade
A1: SCHADEPOSTEN OVERZICHT
A3: Vul hieronder alle schadeposten in. Bedrag wordt automatisch berekend (Aantal × Tarief).
A5: Beschrijving | B5: Aantal | C5: Tarief excl. BTW | D5: Bedrag excl. BTW | E5: BTW % | F5: BTW (€)
D6: =IF(AND(B6<>"",C6<>""),B6*C6,"") | E6: 0.21 | F6: =IF(AND(D6<>"",E6<>""),D6*E6,"")
D7: =IF(AND(B7<>"",C7<>""),B7*C7,"") | E7: 0.21 | F7: =IF(AND(D7<>"",E7<>""),D7*E7,"")
D8: =IF(AND(B8<>"",C8<>""),B8*C8,"") | E8: 0.21 | F8: =IF(AND(D8<>"",E8<>""),D8*E8,"")
D9: =IF(AND(B9<>"",C9<>""),B9*C9,"") | E9: 0.21 | F9: =IF(AND(D9<>"",E9<>""),D9*E9,"")
D10: =IF(AND(B10<>"",C10<>""),B10*C10,"") | E10: 0.21 | F10: =IF(AND(D10<>"",E10<>""),D10*E10,"")
D11: =IF(AND(B11<>"",C11<>""),B11*C11,"") | E11: 0.21 | F11: =IF(AND(D11<>"",E11<>""),D11*E11,"")
D12: =IF(AND(B12<>"",C12<>""),B12*C12,"") | E12: 0.21 | F12: =IF(AND(D12<>"",E12<>""),D12*E12,"")
D13: =IF(AND(B13<>"",C13<>""),B13*C13,"") | E13: 0.21 | F13: =IF(AND(D13<>"",E13<>""),D13*E13,"")
D14: =IF(AND(B14<>"",C14<>""),B14*C14,"") | E14: 0.21 | F14: =IF(AND(D14<>"",E14<>""),D14*E14,"")
D15: =IF(AND(B15<>"",C15<>""),B15*C15,"") | E15: 0.21 | F15: =IF(AND(D15<>"",E15<>""),D15*E15,"")
D16: =IF(AND(B16<>"",C16<>""),B16*C16,"") | E16: 0.21 | F16: =IF(AND(D16<>"",E16<>""),D16*E16,"")
D17: =IF(AND(B17<>"",C17<>""),B17*C17,"") | E17: 0.21 | F17: =IF(AND(D17<>"",E17<>""),D17*E17,"")
... D55: =IF(AND(B55<>"",C55<>""),B55*C55,"") | E55: 0.21 | F55: =IF(AND(D55<>"",E55<>""),D55*E55,"")
A57: TOTALEN (automatisch berekend)
A58: Totaal Schade excl. BTW (automatisch) | B58: =SUM(D6:D56) -> 0
A59: BTW (Totaal, automatisch) | B59: =SUM(F6:F57) -> 0
A60: Totaal Schade incl. BTW (automatisch) | B60: =IF(B58="","",B58+B59) -> 0
