Workbook

Sheet Dashboard
A1: SALES DASHBOARD
A2: Gegenereerd: 21-01-2026 13:52
B4: Totaal Woningen | D4: Actief | F4: Beschikbaar | J4: Status | K4: Aantal | M4: Object | N4: Marge
B5: 514 | D5: 499 | F5: 173 | J5: Beschikbaar | K5: 173 | M5: 0291 - Koperwerf 28... | N5: 41710
B6: Verhuurd | D6: Binnenkort Vrij | F6: Inactief | J6: Verhuurd | K6: 311 | M6: 0474 - Honselaarsdijk 27... | N6: 15163.2
B7: 311 | D7: 15 | F7: 15 | J7: Binnenkort Vrij | K7: 15 | M7: 0325 - Hendriklaan 49... | N7: 6030
B8: Totale Marge/Maand | D8: Gem. Marge/Woning | F8: Jaarlijkse Omzet | J8: Inactief | K8: 15 | M8: 0409 - Noordstraat 26... | N8: 5883.03
B9: € 282.109,53 | D9: € 548,85 | F9: € 3.385.314,36 | M9: 0205 - Kreekrug 1... | N9: 4800
M10: 0383 - Akkerweg 41 [huis 20... | N10: 4515
M11: 0293 - Akkerweg 41 [huis 14... | N11: 3885
J12: Stad | K12: Woningen | M12: 0009 - Galgeweg 48-A... | N12: 3643.5
J13: Rotterdam | K13: 73 | M13: 0404 - Europalaan 50... | N13: 3615.03
J14: Schiedam | K14: 50 | M14: 0139 - Wilgensingel 63 ... | N14: 3457.68
J15: Vlaardingen | K15: 39
J16: VLAARDINGEN | K16: 21
J17: Hensbroek | K17: 17
J18: Maassluis | K18: 13
J19: Rozenburg | K19: 12
J20: Hoogvliet | K20: 11
J21: Den Oever | K21: 11
J22: Delft | K22: 11

Sheet Zoek Woning
A1: WONING OPZOEKEN
A3: Selecteer Object ID: | B3: 3
A5: WONING INFORMATIE | D5: EIGENAAR
A6: Object ID: | B6: =IFERROR(VLOOKUP($B$3,Data!$A:$CS,1,FALSE),"") | D6: Naam: | E6: =IFERROR(VLOOKUP($B$3,Data!$A:$CS,24,FALSE),"")
A7: Adres: | B7: =IFERROR(VLOOKUP($B$3,Data!$A:$CS,3,FALSE),"") | D7: Email: | E7: =IFERROR(VLOOKUP($B$3,Data!$A:$CS,27,FALSE),"")
A8: Postcode: | B8: =IFERROR(VLOOKUP($B$3,Data!$A:$CS,4,FALSE),"") | D8: Telefoon: | E8: =IFERROR(VLOOKUP($B$3,Data!$A:$CS,28,FALSE),"")
A9: Plaats: | B9: =IFERROR(VLOOKUP($B$3,Data!$A:$CS,5,FALSE),"") | D9: Adres: | E9: =IFERROR(VLOOKUP($B$3,Data!$A:$CS,29,FALSE),"")
A10: Type: | B10: =IFERROR(VLOOKUP($B$3,Data!$A:$CS,6,FALSE),"") | D10: IBAN: | E10: =IFERROR(VLOOKUP($B$3,Data!$A:$CS,35,FALSE),"")
A11: Oppervlakte: | B11: =IFERROR(VLOOKUP($B$3,Data!$A:$CS,7,FALSE),"")
A12: Slaapkamers: | B12: =IFERROR(VLOOKUP($B$3,Data!$A:$CS,8,FALSE),"") | D12: HUURDER
A13: Capaciteit: | B13: =IFERROR(VLOOKUP($B$3,Data!$A:$CS,9,FALSE),"") | D13: Naam: | E13: =IFERROR(VLOOKUP($B$3,Data!$A:$CS,56,FALSE),"")
A14: Status: | B14: =IFERROR(VLOOKUP($B$3,Data!$A:$CS,96,FALSE),"") | D14: Email: | E14: =IFERROR(VLOOKUP($B$3,Data!$A:$CS,59,FALSE),"")
A15: Dagen tot beschikbaar: | B15: =IFERROR(VLOOKUP($B$3,Data!$A:$CS,97,FALSE),"") | D15: Telefoon: | E15: =IFERROR(VLOOKUP($B$3,Data!$A:$CS,60,FALSE),"")
D16: Type: | E16: =IFERROR(VLOOKUP($B$3,Data!$A:$CS,57,FALSE),"")
A17: INHUUR CONTRACT | D17: VERHUUR CONTRACT
A18: Start: | B18: =IFERROR(VLOOKUP($B$3,Data!$A:$CS,37,FALSE),"") | D18: Start: | E18: =IFERROR(VLOOKUP($B$3,Data!$A:$CS,70,FALSE),"")
A19: Eind: | B19: =IFERROR(VLOOKUP($B$3,Data!$A:$CS,38,FALSE),"") | D19: Eind: | E19: =IFERROR(VLOOKUP($B$3,Data!$A:$CS,71,FALSE),"")
A20: Bedrag excl: | B20: =IFERROR(VLOOKUP($B$3,Data!$A:$CS,47,FALSE),"") | D20: Bedrag excl: | E20: =IFERROR(VLOOKUP($B$3,Data!$A:$CS,76,FALSE),"")
A21: Borg: | B21: =IFERROR(VLOOKUP($B$3,Data!$A:$CS,50,FALSE),"") | D21: Borg: | E21: =IFERROR(VLOOKUP($B$3,Data!$A:$CS,82,FALSE),"")
A23: MARGE ANALYSE
A24: Marge/maand: | B24: =IFERROR(VLOOKUP($B$3,Data!$A:$CS,93,FALSE),"")
A25: Marge/jaar: | B25: =IFERROR(VLOOKUP($B$3,Data!$A:$CS,94,FALSE),"")
A26: Marge %: | B26: =IFERROR(VLOOKUP($B$3,Data!$A:$CS,95,FALSE),"")
A28: DOCUMENTEN & LINKS
A29: Woning Folder: | B29: =IFERROR(VLOOKUP($B$3,Data!$A:$CS,16,FALSE),"")
A30: Inhuur Docs: | B30: =IFERROR(VLOOKUP($B$3,Data!$A:$CS,17,FALSE),"")
A31: Verhuur Docs: | B31: =IFERROR(VLOOKUP($B$3,Data!$A:$CS,18,FALSE),"")
A32: Overeenkomsten: | B32: =IFERROR(VLOOKUP($B$3,Data!$A:$CS,19,FALSE),"")
A33: Contract Link: | B33: =IFERROR(VLOOKUP($B$3,Data!$A:$CS,44,FALSE),"")

Sheet Print Kaart
A1: WONING INFORMATIEKAART
A3: Object: | B3: ='Zoek Woning'!B6 | D3: Status: | E3: ='Zoek Woning'!B14
A4: Adres: | B4: ='Zoek Woning'!B7
A7: WONING SPECIFICATIES
A8: Postcode: | B8: ='Zoek Woning'!B8 | C8: Plaats: | D8: ='Zoek Woning'!B9
A9: Type: | B9: ='Zoek Woning'!B10 | C9: Opp. (m²): | D9: ='Zoek Woning'!B11
A10: Slaapkamers: | B10: ='Zoek Woning'!B12 | C10: Capaciteit: | D10: ='Zoek Woning'!B13
A12: EIGENAAR
A13: Naam: | B13: ='Zoek Woning'!E6
A14: Email: | B14: ='Zoek Woning'!E7
A15: Telefoon: | B15: ='Zoek Woning'!E8
A17: HUIDIGE HUURDER
A18: Naam: | B18: ='Zoek Woning'!E13
A19: Email: | B19: s
A20: Telefoon: | B20: ='Zoek Woning'!E15
A22: FINANCIEEL OVERZICHT
A23: Inhuur/maand: | B23: ='Zoek Woning'!B20 | C23: Verhuur/maand: | D23: ='Zoek Woning'!E20
A24: Marge/maand: | B24: ='Zoek Woning'!B24 | C24: Marge/jaar: | D24: ='Zoek Woning'!B25
A25: Marge %: | B25: ='Zoek Woning'!B26
A27: CONTRACT DETAILS
A28: Inhuur start: | B28: ='Zoek Woning'!B18 | C28: Inhuur eind: | D28: ='Zoek Woning'!B19
A29: Verhuur start: | B29: ='Zoek Woning'!E18 | C29: Verhuur eind: | D29: ='Zoek Woning'!E19
A31: DOCUMENTEN
A32: Woning Folder: | B32: ='Zoek Woning'!B29
A33: Inhuur Docs: | B33: ='Zoek Woning'!B30
A34: Verhuur Docs: | B34: ='Zoek Woning'!B31
A36: Gegenereerd: 21-01-2026

Sheet Contacten
A1: CONTACTEN OVERZICHT
A3: EIGENAREN
A4: ID | B4: Naam | C4: Email | D4: Telefoon | E4: Adres | F4: Postcode | G4: Plaats | H4: Woningen
A5: 763 | B5: T. Eenhuistra/J. Pluimakers | H5: 3
A6: 326 | B6: S. Kleiren | C6: sabine.kleiren@gmail.com | H6: 2
A7: 984 | B7: Park Wonen BV | C7: info@parkwonen.nl | D7: 010 — 844 25 52 | E7: Kruisplein 488a | F7: 3012 CC | G7: Rotterdam | H7: 3
A8: 850 | B8: M. Kathiravelu | H8: 1
A9: 644 | B9: J.G. van Pieterson | E9: C.G. Roosweg 28 | G9: Schoonhoven | H9: 1
A10: 258 | B10: Parkwonen | C10: info@parkwonen.nl | E10: Kruisplein 488A | G10: Rotterdam | H10: 6
A11: 147 | B11: T. Hoolhorst | C11: t.hoolhorst@gmail.com | E11: Leliestraat 21 | G11: Utrecht | H11: 1
A12: 175 | B12: Dhr. J.L. Meerding | C12: jlmeerding@gmai.com | E12: Mauvezand 6 | G12: Laren NH | H12: 3
A13: 206 | B13: Dhr. T. Roestenberg en Mw. Roestenberg - Hustinx | C13: timoroestenberg@hotmail.com | D13: 06 199 144 13 | E13: De Haarmansenk 7 | G13: Schalkhaar | H13: 1
A14: 111 | B14: Hugo Vastgoed B.V. | C14: administratie@hemobeheer.nl | D14: 2076 515 45 06 | E14: Academiesingel 37 A | G14: BREDA | H14: 1
A15: 802 | B15: Maatschap vd Vlist -Teuben | H15: 1
A16: 806 | B16: Value+ Vastgoedmanagement | H16: 1
A17: 241 | B17: BJ Bakker | C17: bjbakker85@hotmail.com | E17: Spiens 3 | G17: Dokkum | H17: 1
A18: 701 | B18: Fransen Vastgoed / Holland Huisvesting B.V. | C18: info@fransenvastgoed.nl | E18: Lekdreef 2 | G18: Krimpen aan de Lek | H18: 3
A19: 630 | B19: J. van der Linde | H19: 1
A20: 839 | B20: J, van de Linde | H20: 1
A21: 271 | B21: Houses2Rent | C21: info@houses2rent.nl | D21: 06-20877085 | E21: Stellingmolen 42 | G21: Maassluis | H21: 10
A22: 314 | B22: G.K. Stoel | C22: rolfstoel@hotmail.com | D22: 06-14901449 | E22: Patrijsstraat 39 | G22: Papendrecht | H22: 1
A23: 795 | B23: J.P. Stoel | C23: Jpstoel@gma | D23: 06 408 960 47 | H23: 4
A24: 295 | B24: In Stijl Totaalbouw BV | C24: info@instijltotaalbouw.nl | D24: 06-44404678 | E24: Burgemeester Freijterslaan 1 | G24: Roosendaal | H24: 4
A25: 302 | B25: A.H.S. Willemsen | C25: huurwoningarnhem@gmail.com | H25: 1
A26: 823 | B26: City Estate (Reinier Derksen) | H26: 2
A27: 60 | B27: M. Poel | C27: monique_pruijsen@hotmail.com | D27: 20650128055 | E27: Esdoornlaan 64 | G27: ROZENBURG | H27: 1
A28: 824 | B28: Vivir wonen (Mendy) | H28: 1
A29: 792 | B29: H. Samson | H29: 1
A30: 783 | B30: Johan ven der Burg | H30: 3
A31: 7 | B31: Maatschap J.W. Meershoek & W.M. Meershoek | C31: j.meershoek1@chello.nl | E31: Grootzand 11 | G31: HOEK VAN HOLLAND | H31: 1
A32: 115 | B32: A. Ghali | E32: Rooseveltlaan 956 | G32: Utrecht | H32: 1
A33: 291 | B33: Johan van der Burg | C33: johanvanderburg87@gmail.com | H33: 2
A34: 836 | B34: Sjoerd Dolstra | H34: 1
A35: 602 | B35: Westhavendomein BV | C35: vastgoed@westhavendomein.nl | D35: 010-2477477 | H35: 3
A36: 803 | B36: M&M Hendriks | H36: 1
A37: 164 | B37: Dhr. R. Bekken | C37: renzo.bekken@gmail.com | D37: 206 24524308 | E37: Roemer Visscherlaan 57 | G37: Zeist | H37: 1
A38: 135 | B38: B. Bosch | C38: brucebosch@live.nl | E38: Stuartweg 29 | G38: Vianen | H38: 1
A39: 848 | B39: R. Bouius | C39: bouius@hotmail.com | D39: 06-13658480 | H39: 1
A40: 211 | B40: Homescout21 B.V. | C40: rene@homescout21.com | E40: Keizerstraat 28 1 | G40: 'S-GRAVENHAGE | H40: 10
A41: 542 | B41: Hopmans Flexstay | H41: 1
...

Sheet Tijdlijn
A1: CONTRACT TIJDLIJN
A3: Object | B3: Adres | C3: Huurder | D3: Start | E3: Eind | F3: Status | G3: Dagen Resterend
A4: 0332 | B4: Kerkweg 9a [huis 340] | C4: Orange Investments Group | D4: 2025-01-24 | E4: 2026-01-24 | F4: Actief | G4: 2
A5: 0329 | B5: Noordmolenstraat 36B | C5: BBTS (Vastgoed Spijkenisse) | D5: 2025-02-01 | E5: 2026-02-01 | F5: Actief | G5: 10
A6: 0328 | B6: Noordmolenstraat 36A | C6: BBTS (Vastgoed Spijkenisse) | D6: 2025-02-01 | E6: 2026-02-01 | F6: Actief | G6: 10
A7: 0333 | B7: Kethelweg 66D | C7: Tradiro Services B.V. | D7: 2025-02-01 | E7: 2026-02-01 | F7: Actief | G7: 10
A8: 0330 | B8: Noordmolenstraat 36C | C8: BBTS (Vastgoed Spijkenisse) | D8: 2025-02-01 | E8: 2026-02-01 | F8: Actief | G8: 10
A9: 0323 | B9: Marnixstraat 32 | C9: Flexvesting B.V. | D9: 2025-02-01 | E9: 2026-02-01 | F9: Actief | G9: 10
A10: 0340 | B10: Professor Poelslaan 58C | C10: Tradiro Services B.V. | D10: 2025-02-15 | E10: 2026-02-15 | F10: Actief | G10: 24
A11: 0340 | B11: Professor Poelslaan 58C | C11: Tradiro Services B.V. | D11: 2025-02-15 | E11: 2026-02-15 | F11: Actief | G11: 24
A12: 0337 | B12: Kruisweg 16 | C12: Tradiro Services B.V. | D12: 2025-02-25 | E12: 2026-02-25 | F12: Actief | G12: 34
A13: 0324 | B13: Van Swinderenstraat 21 | C13: Flexvesting B.V. | D13: 2025-03-01 | E13: 2026-02-28 | F13: Actief | G13: 37
A14: 0136 | B14: Elisadonk 220 | C14: EG Facility & Services BV | D14: 2024-03-01 | E14: 2026-02-28 | F14: Actief | G14: 37
A15: 0117 | B15: Prunuslaan 36 | C15: Workforce Housing International B.V | D15: 2021-05-03 | E15: 2026-02-28 | F15: Actief | G15: 37
... A109: 0258 | B109: Middenbaan Noord 22B | C109: BBTS (Vastgoed Spijkenisse) | D109: 2023-05-01 | E109: 2028-04-30 | F109: Actief | G109: 829
A110: 0158 | B110: Visartstraat 31 | C110: BBTS (Vastgoed Spijkenisse) | D110: 23-12-01 | E110: 24-11-30 | F110: Actief
A111: 0167 | B111: Vogelschorstraat 24 | C111: BBTS (Vastgoed Spijkenisse) | D111: 24-01-01 | E111: 29-12-31 | F111: Actief
A112: 0001 | B112: Nunspeetlaan 14 | C112: Tradiro Services B.V. | D112: 2026-01-14 | F112: Onbepaalde tijd | G112: 0
A113: 0002 | B113: Allard Piersonlaan 142 | C113: Tradiro Services B.V. | D113: 2026-01-14 | F113: Onbepaalde tijd | G113: 0
A114: 0009 | B114: Galgeweg 48-A | C114: Tradiro Services B.V. | D114: 2026-01-14 | F114: Onbepaalde tijd | G114: 0
A115: 0010 | B115: Kethelweg 1B | C115: Tradiro Services B.V. | D115: 2023-02-01 | F115: Onbepaalde tijd | G115: 0
A116: 0011 | B116: Kethelweg 1C | C116: Tradiro Services B.V. | D116: 2023-02-01 | F116: Onbepaalde tijd | G116: 0
A117: 0015 | B117: Maasdijk 69 | C117: Tradiro Services B.V. | D117: 2026-01-14 | F117: Onbepaalde tijd | G117: 0
A118: 0020 | B118: Mr. Troelstrastraat 37 | C118: Tradiro Services B.V. | D118: 2023-02-01 | F118: Onbepaalde tijd | G118: 0
A119: 0021 | B119: Vaartweg 106C | C119: Tradiro Services B.V. | D119: 2023-02-01 | F119: Onbepaalde tijd | G119: 0
A120: 0025 | B120: Groenelaan 30B | C120: Tradiro Services B.V. | D120: 2023-02-01 | F120: Onbepaalde tijd | G120: 0
A121: 0027 | B121: Buizerdstraat 210 | C121: Tradiro Services B.V. | D121: 2023-03-01 | F121: Onbepaalde tijd | G121: 0
A122: 0028 | B122: Lange kruisweg 12 | C122: Tradiro Services B.V. | D122: 2023-03-01 | F122: Onbepaalde tijd | G122: 0
A123: 0030 | B123: Curacaolaan 88 | C123: Tradiro Services B.V. | D123: 2026-01-14 | F123: Onbepaalde tijd | G123: 0
... A331: 0489 | B331: Woudseweg 146 | C331: Tradiro Services B.V. | D331: 2025-01-01 | F331: Onbepaalde tijd | G331: 0
A334: LEGENDA:
A335: < 30 dagen
A336: 30-60 dagen

Sheet Financieel
A1: FINANCIEEL OVERZICHT
A3: TOTALEN
A4: Totale Inhuur/maand: | B4: 405275.17 | C4: Jaarlijks: | D4: 4863302
A5: Totale Verhuur/maand: | B5: 687384.7 | D5: 8248616.4
A6: Totale Marge/maand: | B6: 282109.53 | D6: 3385314.4
A9: MARGE PER WONING
A10: Object | B10: Adres | C10: Inhuur | D10: Verhuur | E10: Marge/Maand | F10: Marge/Jaar | G10: Marge % | H10: Status
A11: 0291 | B11: Koperwerf 28 | D11: 41710 | E11: 41710 | F11: 500520 | H11: Verhuurd (onbepaald)
A12: 0474 | B12: Honselaarsdijk 27 | D12: 15163.2 | E12: 15163.2 | F12: 181958.4 | H12: Verhuurd (onbepaald)
A13: 0325 | B13: Hendriklaan 49 | D13: 6030 | E13: 6030 | F13: 72360 | H13: Beschikbaar
A14: 0409 | B14: Noordstraat 26 | D14: 5883.03 | E14: 5883.03 | F14: 70596.36 | H14: Verhuurd (onbepaald)
A15: 0205 | B15: Kreekrug 1 | D15: 4800 | E15: 4800 | F15: 57600 | H15: Verhuurd (onbepaald)
A16: 0383 | B16: Akkerweg 41 [huis 20] | D16: 4515 | E16: 4515 | F16: 54180 | H16: Inactief
A17: 0293 | B17: Akkerweg 41 [huis 14] | D17: 3885 | E17: 3885 | F17: 46620 | H17: Inactief
A18: 0009 | B18: Galgeweg 48-A | D18: 3643.5 | E18: 3643.5 | F18: 43722 | H18: Verhuurd (onbepaald)
A19: 0404 | B19: Europalaan 50 | D19: 3615.03 | E19: 3615.03 | F19: 43380.36 | H19: Verhuurd (onbepaald)
A20: 0139 | B20: Wilgensingel 63 | D20: 3457.68 | E20: 3457.68 | F20: 41492.16 | H20: Verhuurd (onbepaald)
A21: 0015 | B21: Maasdijk 69 | D21: 3400 | E21: 3400 | F21: 40800 | H21: Verhuurd (onbepaald)
A22: 0412 | B22: Hontenissestraat 162 | D22: 3347.25 | E22: 3347.25 | F22: 40167 | H22: Verhuurd (onbepaald)
... A59: 0156 | B59: Broersvest 74 c | D59: 2051.51 | E59: 2051.51 | F59: 24618.12 | H59: Verhuurd (onbepaald)
A60: 0067 | B60: Franz Liszstraat 5 | C60: 1665.6 | D60: 3643.5 | E60: 1977.9 | F60: 23734.8 | G60: 118.75 | H60: Verhuurd
A61: 0364 | B61: Rietdijkstraat 56B | D61: 1950 | E61: 1950 | F61: 23400 | H61: Verhuurd (onbepaald)
A62: 0279 | B62: Haagkamp 11 | D62: 1950 | E62: 1950 | F62: 23400 | H62: Verhuurd (onbepaald)
A63: 0174 | B63: Groeneweg 74 | D63: 1916 | E63: 1916 | F63: 22992 | H63: Verhuurd (onbepaald)
A64: 0005 | B64: Ringbaan Oost 327 | C64: 4300 | D64: 6210.93 | E64: 1910.93 | F64: 22931.16 | G64: 44.44 | H64: Verhuurd
A65: 0387 | B65: Verschansing 21 | C65: 2470 | D65: 4350 | E65: 1880 | F65: 22560 | G65: 76.11 | H65: Verhuurd
A66: 0210 | B66: Lorentzstraat 73 | D66: 1865.5 | E66: 1865.5 | F66: 22386 | H66: Verhuurd (onbepaald)
A67: 0173 | B67: Groeneweg 71 | D67: 1850 | E67: 1850 | F67: 22200 | H67: Verhuurd (onbepaald)
A68: 0021 | B68: Vaartweg 106C | D68: 1830.43 | E68: 1830.43 | F68: 21965.16 | H68: Verhuurd (onbepaald)
A69: 0002 | B69: Allard Piersonlaan 142 | D69: 1829.53 | E69: 1829.53 | F69: 21954.36 | H69: Verhuurd (onbepaald)
A70: 0001 | B70: Nunspeetlaan 14 | D70: 1829.53 | E70: 1829.53 | F70: 21954.36 | H70: Verhuurd (onbepaald)
A71: 0377 | B71: Rijpstraat 24 | D71: 1733.33 | E71: 1733.33 | F71: 20799.96 | H71: Verhuurd (onbepaald)
A72: 0020 | B72: Mr. Troelstrastraat 37 | D72: 1723.44 | E72: 1723.44 | F72: 20681.28 | H72: Verhuurd (onbepaald)
A73: 0057 | B73: Markt 5 | D73: 1715.6 | E73: 1715.6 | F73: 20587.2 | H73: Verhuurd (onbepaald)
A74: 0010 | B74: Kethelweg 1B | D74: 1708.41 | E74: 1708.41 | F74: 20500.92 | H74: Verhuurd (onbepaald)
A75: 0011 | B75: Kethelweg 1C | D75: 1708.41 | E75: 1708.41 | F75: 20500.92 | H75: Verhuurd (onbepaald)
A76: 0375 | B76: Cubalaan 25 | C76: 3600 | D76: 5300 | E76: 1700 | F76: 20400 | G76: 47.22 | H76: Verhuurd
A77: 0027 | B77: Buizerdstraat 210 | D77: 1677.89 | E77: 1677.89 | F77: 20134.68 | H77: Verhuurd (onbepaald)
A78: 0199 | B78: Kerstendijk 125 | C78: 1200 | D78: 2841.93 | E78: 1641.93 | F78: 19703.16 | G78: 136.83 | H78: Verhuurd (onbepaald)
A79: 0438 | B79: Franselaan 273-B | D79: 1641.12 | E79: 1641.12 | F79: 19693.44 | H79: Verhuurd (onbepaald)
...

Sheet Data
A1: object_id | B1: house_id | C1: adres | D1: postcode | E1: plaats | F1: woning_type | G1: oppervlakte_m2 | H1: aantal_slaapkamers | I1: capaciteit_personen | J1: huis_actief | K1: facturatie_type | L1: kluis_code_1 | M1: kluis_code_2 | N1: meterbeheerder | O1: gwe_leverancier | P1: sharepoint_folder | Q1: sharepoint_inhuur | R1: sharepoint_verhuur | S1: sharepoint_inhuur_overeenkomsten | T1: borg_standaard | U1: voorschot_gwe_standaard | V1: voorschot_schoonmaak_standaard | W1: eigenaar_id | X1: eigenaar_naam | Y1: eigenaar_type | Z1: eigenaar_contactpersoon | AA1: eigenaar_email | AB1: eigenaar_telefoon | AC1: eigenaar_adres | AD1: eigenaar_postcode | AE1: eigenaar_plaats | AF1: eigenaar_land | AG1: eigenaar_kvk | AH1: eigenaar_btw | AI1: eigenaar_iban | AJ1: inhuur_contract_id | AK1: inhuur_start | AL1: inhuur_eind | AM1: inhuur_status | AN1: inhuur_min_duur | AO1: inhuur_opzegtermijn | AP1: inhuur_hovk | AQ1: inhuur_rechtsvorm | AR1: inhuur_contract_link | AS1: inhuur_notities | AT1: inhuur_kale_huur | AU1: inhuur_totaal_excl_btw | AV1: inhuur_totaal_incl_btw | AW1: inhuur_btw_percentage | AX1: inhuur_borg | AY1: inhuur_voorschot_gwe | AZ1: inhuur_vve_kosten | BA1: inhuur_overige_kosten | BB1: inhuur_internet_kosten | BC1: huurder_id | BD1: huurder_naam | BE1: huurder_type | BF1: huurder_contactpersoon | BG1: huurder_email | BH1: huurder_telefoon | BI1: huurder_adres | BJ1: huurder_postcode | BK1: huurder_plaats | BL1: huurder_land | BM1: huurder_kvk | BN1: huurder_btw | BO1: huurder_iban | BP1: huurder_marge_max | BQ1: verhuur_contract_id | BR1: verhuur_start | BS1: verhuur_eind | BT1: verhuur_duur_maanden | BU1: verhuur_contract_type | BV1: verhuur_status | BW1: verhuur_kale_huur | BX1: verhuur_totaal_excl_btw | BY1: verhuur_totaal_incl_btw | BZ1: verhuur_btw_percentage | CA1: verhuur_voorschot_gwe | CB1: verhuur_overige_kosten | CC1: verhuur_eindschoonmaak | CD1: verhuur_borg | CE1: gwe_verantwoordelijk | CF1: incl_stoffering | CG1: incl_meubilering | CH1: incl_internet | CI1: incl_schoonmaak_kwartaal | CJ1: incl_bedlinnen | CK1: incl_tuinonderhoud | CL1: incl_eindschoonmaak | CM1: incl_afvalverwerking | CN1: schoonmaak_pakket | CO1: marge_maand_excl_btw | CP1: marge_jaar_excl_btw | CQ1: marge_percentage | CR1: beschikbaarheid_status | CS1: dagen_tot_beschikbaar
A2: 0001 | B2: 23 | C2: Nunspeetlaan 14 | D2: 2573 HG | E2: Den Haag | F2: Vakantiepark | H2: 3 | I2: 4 | J2: 1 | K2: Factuur | P2: https://ryanrent.sharepoint.com/sites/RyanRent/Gedeelde%20documenten/Forms/AllItems.aspx?id=%2Fsites%2FRyanRent%2FGedeelde%20documenten%2FGeneral%2F01%5FRyanRent%26Co%2F01%5FWoningen%2FNunspeetlaan%2014%20Den%20Haag | Q2: https://ryanrent.sharepoint.com/sites/RyanRent/Gedeelde%20documenten/Forms/AllItems.aspx?id=%2Fsites%2FRyanRent%2FGedeelde%20documenten%2FGeneral%2F01%5FRyanRent%26Co%2F01%5FWoningen%2FNunspeetlaan%2014%20Den%20Haag%2F2%5FInhuur | R2: https://ryanrent.sharepoint.com/sites/RyanRent/Gedeelde%20documenten/Forms/AllItems.aspx?id=%2Fsites%2FRyanRent%2FGedeelde%20documenten%2FGeneral%2F01%5FRyanRent%26Co%2F01%5FWoningen%2FNunspeetlaan%2014%20Den%20Haag%2F3%5FVerhuur | S2: https://ryanrent.sharepoint.com/sites/RyanRent/Gedeelde%20documenten/Forms/AllItems.aspx?id=%2Fsites%2FRyanRent%2FGedeelde%20documenten%2FGeneral%2F01%5FRyanRent%26Co%2F01%5FWoningen%2FNunspeetlaan%2014%20Den%20Haag%2F2%5FInhuur%2F2%5FInhuurovereenkomsten | T2: 1816.47 | U2: 300 | V2: 0 | AM2: Geen inhuur | BC2: 17 | BD2: Tradiro Services B.V. | BE2: particulier | BG2: facturen@tradiro.nl | BH2: null | BI2: Honderdland 960 | BJ2: 2678 PS | BK2: Maasdijk | BL2: Nederland | BM2: 59979135.0 | BO2: NL05 RABO 0154 0739 89 | BQ2: 443 | BR2: 2026-01-14 | BU2: bepaalde_tijd | BV2: Onbepaalde tijd | BW2: 1829.53 | BX2: 1829.53 | BY2: 1994.19 | BZ2: 0.09 | CA2: 0 | CB2: 22.82 | CC2: 0 | CD2: 1816.47 | CE2: ryanrent | CF2: 1 | CG2: 1 | CH2: 1 | CI2: 0 | CJ2: 0 | CK2: 0 | CL2: 0 | CM2: 0 | CO2: 1829.53 | CP2: 21954.36 | CR2: Verhuurd (onbepaald) | CS2: 0
A3: 0002 | B3: 24 | C3: Allard Piersonlaan 142 | D3: 2522 MT | E3: Den Haag | F3: Appartement | H3: 3 | I3: 4 | J3: 1 | K3: DS | P3: https://ryanrent.sharepoint.com/sites/RyanRent/Gedeelde%20documenten/Forms/AllItems.aspx?id=%2Fsites%2FRyanRent%2FGedeelde%20documenten%2FGeneral%2F01%5FRyanRent%26Co%2F01%5FWoningen%2FAllard%20Piersonlaan%20142%20Den%20Haag | Q3: https://ryanrent.sharepoint.com/sites/RyanRent/Gedeelde%20documenten/Forms/AllItems.aspx?id=%2Fsites%2FRyanRent%2FGedeelde%20documenten%2FGeneral%2F01%5FRyanRent%26Co%2F01%5FWoningen%2FAllard%20Piersonlaan%20142%20Den%20Haag%2F2%5FInhuur | R3: https://ryanrent.sharepoint.com/sites/RyanRent/Gedeelde%20documenten/Forms/AllItems.aspx?id=%2Fsites%2FRyanRent%2FGedeelde%20documenten%2FGeneral%2F01%5FRyanRent%26Co%2F01%5FWoningen%2FAllard%20Piersonlaan%20142%20Den%20Haag%2F3%5FVerhuur | S3: https://ryanrent.sharepoint.com/sites/RyanRent/Gedeelde%20documenten/Forms/AllItems.aspx?id=%2Fsites%2FRyanRent%2FGedeelde%20documenten%2FGeneral%2F01%5FRyanRent%26Co%2F01%5FWoningen%2FAllard%20Piersonlaan%20142%20Den%20Haag%2F2%5FInhuur%2F2%5FInhuurovereenkomsten | T3: 1929.41 | U3: 0 | V3: 0 | AM3: Geen inhuur | BC3: 17 | BD3: Tradiro Services B.V. | BE3: particulier | BG3: facturen@tradiro.nl | BH3: null | BI3: Honderdland 960 | BJ3: 2678 PS | BK3: Maasdijk | BL3: Nederland | BM3: 59979135.0 | BO3: NL05 RABO 0154 0739 89 | BQ3: 299 | BR3: 2026-01-14 | BU3: bepaalde_tijd | BV3: Onbepaalde tijd | BW3: 1829.53 | BX3: 1829.53 | BY3: 1994.19 | BZ3: 0.09 | CA3: 0 | CB3: 25.1 | CC3: 0 | CD3: 1929.41 | CE3: ryanrent | CF3: 0 | CG3: 0 | CH3: 0 | CI3: 0 | CJ3: 0 | CK3: 0 | CL3: 0 | CM3: 0 | CO3: 1829.53 | CP3: 21954.36 | CR3: Verhuurd (onbepaald) | CS3: 0
A4: 0003 | B4: 25 | C4: Acacia 2 | D4: 3224EB | E4: Hellevoetsluis | F4: Appartement | H4: 5 | I4: 5 | J4: 1 | K4: Factuur | L4: 4202 | M4: 1005 | P4: https://ryanrent.sharepoint.com/sites/RyanRent/Gedeelde%20documenten/Forms/AllItems.aspx?id=%2Fsites%2FRyanRent%2FGedeelde%20documenten%2FGeneral%2F01%5FRyanRent%26Co%2F01%5FWoningen%2FAcacia%202%2C%20Hellevoetsluis | Q4: https://ryanrent.sharepoint.com/sites/RyanRent/Gedeelde%20documenten/Forms/AllItems.aspx?id=%2Fsites%2FRyanRent%2FGedeelde%20documenten%2FGeneral%2F01%5FRyanRent%26Co%2F01%5FWoningen%2FAcacia%202%2C%20Hellevoetsluis%2F2%5FInhuur | R4: https://ryanrent.sharepoint.com/sites/RyanRent/Gedeelde%20documenten/Forms/AllItems.aspx?id=%2Fsites%2FRyanRent%2FGedeelde%20documenten%2FGeneral%2F01%5FRyanRent%26Co%2F01%5FWoningen%2FAcacia%202%2C%20Hellevoetsluis%2F3%5FVerhuur | S4: https://ryanrent.sharepoint.com/sites/RyanRent/Gedeelde%20documenten/Forms/AllItems.aspx?id=%2Fsites%2FRyanRent%2FGedeelde%20documenten%2FGeneral%2F01%5FRyanRent%26Co%2F01%5FWoningen%2FAcacia%202%2C%20Hellevoetsluis%2F2%5FInhuur%2F2%5FInhuurovereenkomsten | T4: 2022.35 | U4: 0 | V4: 0 | AM4: Geen inhuur | BV4: Leegstand | CD4: 2022.35 | CO4: 0 | CP4: 0 | CR4: Beschikbaar | CS4: 0
A5: 0004 | B5: 26 | C5: Broekweg 25 | D5: 3131 HC | E5: Vlaardingen | F5: Appartement | I5: 4 | J5: 1 | K5: Factuur | P5: https://ryanrent.sharepoint.com/sites/RyanRent/Gedeelde%20documenten/Forms/AllItems.aspx?id=%2Fsites%2FRyanRent%2FGedeelde%20documenten%2FGeneral%2F01%5FRyanRent%26Co%2F01%5FWoningen%2FBroekweg%2025%20Vlaardingen | Q5: https://ryanrent.sharepoint.com/sites/RyanRent/Gedeelde%20documenten/Forms/AllItems.aspx?id=%2Fsites%2FRyanRent%2FGedeelde%20documenten%2FGeneral%2F01%5FRyanRent%26Co%2F01%5FWoningen%2FBroekweg%2025%20Vlaardingen%2F2%5FInhuur | R5: https://ryanrent.sharepoint.com/sites/RyanRent/Gedeelde%20documenten/Forms/AllItems.aspx?id=%2Fsites%2FRyanRent%2FGedeelde%20documenten%2FGeneral%2F01%5FRyanRent%26Co%2F01%5FWoningen%2FBroekweg%2025%20Vlaardingen%2F3%5FVerhuur | S5: https://ryanrent.sharepoint.com/sites/RyanRent/Gedeelde%20documenten/Forms/AllItems.aspx?id=%2Fsites%2FRyanRent%2FGedeelde%20documenten%2FGeneral%2F01%5FRyanRent%26Co%2F01%5FWoningen%2FBroekweg%2025%20Vlaardingen%2F2%5FInhuur%2F2%5FInhuurovereenkomsten | T5: 2111.76 | U5: 260.15 | V5: 0 | AM5: Geen inhuur | BV5: Leegstand | CD5: 2111.76 | CO5: 0 | CP5: 0 | CR5: Beschikbaar | CS5: 0
A6: 0005 | B6: 27 | C6: Ringbaan Oost 327 | D6: 5014 GG | E6: Tilburg | F6: Appartement | H6: 8 | I6: 8 | J6: 1 | K6: Factuur | L6: 1908 | P6: https://ryanrent.sharepoint.com/sites/RyanRent/Gedeelde%20documenten/Forms/AllItems.aspx?id=%2Fsites%2FRyanRent%2FGedeelde%20documenten%2FGeneral%2F01%5FRyanRent%26Co%2F01%5FWoningen%2FRingbaan%20Oost%20327%20Tilburg | Q6: https://ryanrent.sharepoint.com/sites/RyanRent/Gedeelde%20documenten/Forms/AllItems.aspx?id=%2Fsites%2FRyanRent%2FGedeelde%20documenten%2FGeneral%2F01%5FRyanRent%26Co%2F01%5FWoningen%2FRingbaan%20Oost%20327%20Tilburg%2F2%5FInhuur | R6: https://ryanrent.sharepoint.com/sites/RyanRent/Gedeelde%20documenten/Forms/AllItems.aspx?id=%2Fsites%2FRyanRent%2FGedeelde%20documenten%2FGeneral%2F01%5FRyanRent%26Co%2F01%5FWoningen%2FRingbaan%20Oost%20327%20Tilburg%2F3%5FVerhuur | T6: 2076.47 | U6: 500 | V6: 0 | W6: 763 | X6: T. Eenhuistra/J. Pluimakers | Y6: particulier | AJ6: 724 | AK6: 2025-08-01 | AL6: 2027-08-01 | AM6: Actief | AO6: 1 | AT6: 4300 | AU6: 4300 | AV6: 4687 | AW6: 0.09 | AX6: 0 | AY6: 0 | AZ6: 0 | BA6: 0 | BB6: 0 | BC6: 237 | BD6: AKT Autoschade | BE6: particulier | BG6: facturen@aktautoschade.com | BH6: 06 33417286 | BI6: Goirkekanaaldijk 211-18 | BK6: Tilburg | BL6: Nederland | BQ6: 216 | BR6: 2025-08-01 | BS6: 2027-08-01 | BT6: 12 | BU6: bepaalde_tijd | BV6: Actief | BW6: 5710.93 | BX6: 6210.93 | BY6: 6769.91 | BZ6: 0.09 | CA6: 500 | CB6: 0 | CC6: 0 | CD6: 2076.47 | CE6: ryanrent | CF6: 0 | CG6: 0 | CH6: 0 | CI6: 0 | CJ6: 0 | CK6: 0 | CL6: 0 | CM6: 0 | CO6: 1910.93 | CP6: 22931.16 | CQ6: 44.44 | CR6: Verhuurd | CS6: 556
A7: 0006 | B7: 28 | C7: Enschotsestraat 163 | D7: 5014 DD | E7: Tilburg | F7: Appartement | H7: 8 | I7: 8 | J7: 1 | K7: Factuur | L7: 1908 | P7: https://ryanrent.sharepoint.com/sites/RyanRent/Gedeelde%20documenten/Forms/AllItems.aspx?id=%2Fsites%2FRyanRent%2FGedeelde%20documenten%2FGeneral%2F01%5FRyanRent%26Co%2F01%5FWoningen%2FEnschotsestraat%20163%20Tilburg | Q7: https://ryanrent.sharepoint.com/sites/RyanRent/Gedeelde%20documenten/Forms/AllItems.aspx?id=%2Fsites%2FRyanRent%2FGedeelde%20documenten%2FGeneral%2F01%5FRyanRent%26Co%2F01%5FWoningen%2FEnschotsestraat%20163%20Tilburg%2F2%5FInhuur | R7: https://ryanrent.sharepoint.com/sites/RyanRent/Gedeelde%20documenten/Forms/AllItems.aspx?id=%2Fsites%2FRyanRent%2FGedeelde%20documenten%2FGeneral%2F01%5FRyanRent%26Co%2F01%5FWoningen%2FEnschotsestraat%20163%20Tilburg%2F3%5FVerhuur | T7: 2192.94 | U7: 450 | V7: 0 | W7: 763 | X7: T. Eenhuistra/J. Pluimakers | Y7: particulier | AJ7: 586 | AK7: 2025-08-01 | AL7: 2027-08-01 | AM7: Actief | AO7: 1 | AT7: 4300 | AU7: 4300 | AV7: 4687 | AW7: 0.09 | AX7: 0 | AY7: 0 | AZ7: 0 | BA7: 0 | BB7: 0 | BC7: 353 | BD7: Optima Uitzendbureau B.V. | BE7: particulier | BG7: Financieel@optimauitzendburo.nl | BH7: 0184 675 489 | BI7: Kade 40 | BK7: Hardinxveld Giessendam | BL7: Nederland | BM7: 24403530.0 | BQ7: 71 | BR7: 2025-08-01 | BS7: 2027-08-01 | BT7: 12 | BU7: bepaalde_tijd | BV7: Actief | BW7: 4575 | BX7: 4575 | BY7: 4986.75 | BZ7: 0.09 | CA7: 0 | CB7: 0 | CC7: 375 | CD7: 2192.94 | CE7: eigen_beheer | CF7: 0 | CG7: 0 | CH7: 0 | CI7: 0 | CJ7: 0 | CK7: 0 | CL7: 1 | CM7: 0 | CN7: intensief | CO7: 275 | CP7: 3300 | CQ7: 6.4 | CR7: Verhuurd | CS7: 556
A8: 0007 | B8: 29 | C8: Adriaan Baasstraat 34 | D8: 7902HN | E8: Hoogeveen | F8: Appartement | H8: 4 | I8: 4 | J8: 1 | K8: DS | L8: 7902 | M8: 1005 | P8: https://ryanrent.sharepoint.com/sites/RyanRent/Gedeelde%20documenten/Forms/AllItems.aspx?id=%2Fsites%2FRyanRent%2FGedeelde%20documenten%2FGeneral%2F01%5FRyanRent%26Co%2F01%5FWoningen%2FAdriaan%20Baasstraat%2034%2C%20Hoogeveen | Q8: https://ryanrent.sharepoint.com/sites/RyanRent/Gedeelde%20documenten/Forms/AllItems.aspx?id=%2Fsites%2FRyanRent%2FGedeelde%20documenten%2FGeneral%2F01%5FRyanRent%26Co%2F01%5FWoningen%2FAdriaan%20Baasstraat%2034%2C%20Hoogeveen%2F2%5FInhuur | R8: https://ryanrent.sharepoint.com/sites/RyanRent/Gedeelde%20documenten/Forms/AllItems.aspx?id=%2Fsites%2FRyanRent%2FGedeelde%20documenten%2FGeneral%2F01%5FRyanRent%26Co%2F01%5FWoningen%2FAdriaan%20Baasstraat%2034%2C%20Hoogeveen%2F3%5FVerhuur | S8: https://ryanrent.sharepoint.com/sites/RyanRent/Gedeelde%20documenten/Forms/AllItems.aspx?id=%2Fsites%2FRyanRent%2FGedeelde%20documenten%2FGeneral%2F01%5FRyanRent%26Co%2F01%5FWoningen%2FAdriaan%20Baasstraat%2034%2C%20Hoogeveen%2F2%5FInhuur%2F2%5FInhuurovereenkomsten | T8: 2594.12 | U8: 250 | V8: 0 | AM8: Geen inhuur | BC8: 154 | BD8: InAxtion Vastgoed B.V. | BE8: particulier | BG8: Invoice.vastgoed@inaxtion.com | BH8: 06 43 36 18 85 | BI8: Wijnstraat 123 | BK8: Dordrecht | BL8: Nederland | BM8: 16074829.0 | BO8: NL68 ABNA 0427 9222 08 | BQ8: 8 | BR8: 2025-04-18 | BS8: 2026-04-17 | BT8: 12 | BU8: bepaalde_tijd | BV8: Actief | BW8: 2200 | BX8: 2480 | BY8: 2703.2 | BZ8: 0.09 | CA8: 250 | CB8: 30 | CC8: 250 | CD8: 2594.12 | CE8: ryanrent | CF8: 1 | CG8: 1 | CH8: 1 | CI8: 0 | CJ8: 1 | CK8: 0 | CL8: 1 | CM8: 0 | CN8: basis | CO8: 2480 | CP8: 29760 | CR8: Verhuurd | CS8: 85
A9: 0008 | B9: 30 | C9: Arkelse Onderweg 24a | D9: 4206AH | E9: Gorinchem | F9: Appartement | H9: 3 | I9: 10000 | J9: 1 | K9: Factuur | L9: 2324 | M9: 1908 | T9: 1780 | U9: 0 | V9: 0 | AM9: Geen inhuur | BV9: Leegstand | CD9: 1780 | CO9: 0 | CP9: 0 | CR9: Beschikbaar | CS9: 0
A10: 0009 | B10: 31 | C10: Galgeweg 48-A | D10: 2691MG | E10: s-Gravenzande | F10: Appartement | H10: 3 | I10: 6 | J10: 1 | K10: Factuur | T10: 2058.82 | U10: 95.2 | V10: 0 | AM10: Geen inhuur | BC10: 17 | BD10: Tradiro Services B.V. | BE10: particulier | BG10: facturen@tradiro.nl | BH10: null | BI10: Honderdland 960 | BJ10: 2678 PS | BK10: Maasdijk | BL10: Nederland | BM10: 59979135.0 | BO10: NL05 RABO 0154 0739 89 | BQ10: 300 | BR10: 2026-01-14 | BU10: bepaalde_tijd | BV10: Onbepaalde tijd | BW10: 0 | BX10: 3643.5 | BY10: 3971.42 | BZ10: 0.09 | CA10: 773.78 | CB10: 50.37 | CC10: 0 | CD10: 2058.82 | CE10: ryanrent | CF10: 0 | CG10: 0 | CH10: 0 | CI10: 0 | CJ10: 0 | CK10: 0 | CL10: 0 | CM10: 0 | CO10: 3643.5 | CP10: 43722 | CR10: Verhuurd (onbepaald) | CS10: 0
A11: 0010 | B11: 32 | C11: Kethelweg 1B | D11: 3135 GA | E11: Vlaardingen | F11: Vakantiepark | H11: 3 | I11: 5 | J11: 1 | K11: Factuur | P11: https://ryanrent.sharepoint.com/sites/RyanRent/Gedeelde%20documenten/Forms/AllItems.aspx?id=%2Fsites%2FRyanRent%2FGedeelde%20documenten%2FGeneral%2F01%5FRyanRent%26Co%2F01%5FWoningen%2FKethelweg%201B%20Vlaardingen | T11: 2444.71 | U11: 85.24 | V11: 0 | AM11: Geen inhuur | BC11: 17 | BD11: Tradiro Services B.V. | BE11: particulier | BG11: facturen@tradiro.nl | BH11: null | BI11: Honderdland 960 | BJ11: 2678 PS | BK11: Maasdijk | BL11: Nederland | BM11: 59979135.0 | BO11: NL05 RABO 0154 0739 89 | BQ11: 270 | BR11: 2023-02-01 | BU11: onbepaalde_tijd | BV11: Onbepaalde tijd | BW11: 1708.41 | BX11: 1708.41 | BY11: 1862.17 | BZ11: 0.09 | CA11: 0 | CB11: 0 | CC11: 0 | CD11: 2444.71 | CE11: ryanrent | CF11: 1 | CG11: 1 | CH11: 1 | CI11: 0 | CJ11: 0 | CK11: 0 | CL11: 0 | CM11: 0 | CO11: 1708.41 | CP11: 20500.92 | CR11: Verhuurd (onbepaald) | CS11: 0
A12: 0011 | B12: 33 | C12: Kethelweg 1C | D12: 3135 GA | E12: Vlaardingen | F12: Vakantiepark | H12: 3 | I12: 3 | J12: 1 | K12: Factuur | P12: https://ryanrent.sharepoint.com/sites/RyanRent/Gedeelde%20documenten/Forms/AllItems.aspx?id=%2Fsites%2FRyanRent%2FGedeelde%20documenten%2FGeneral%2F01%5FRyanRent%26Co%2F01%5FWoningen%2FKethelweg%201C%20Vlaardingen | Q12: https://ryanrent.sharepoint.com/sites/RyanRent/Gedeelde%20documenten/Forms/AllItems.aspx?id=%2Fsites%2FRyanRent%2FGedeelde%20documenten%2FGeneral%2F01%5FRyanRent%26Co%2F01%5FWoningen%2FKethelweg%201C%20Vlaardingen%2F2%5FInhuur | R12: https://ryanrent.sharepoint.com/sites/RyanRent/Gedeelde%20documenten/Forms/AllItems.aspx?id=%2Fsites%2FRyanRent%2FGedeelde%20documenten%2FGeneral%2F01%5FRyanRent%26Co%2F01%5FWoningen%2FKethelweg%201C%20Vlaardingen%2F3%5FVerhuur | T12: 1769.41 | U12: 32.11 | V12: 0 | AM12: Geen inhuur | BC12: 17 | BD12: Tradiro Services B.V. | BE12: particulier | BG12: facturen@tradiro.nl | BH12: null | BI12: Honderdland 960 | BJ12: 2678 PS | BK12: Maasdijk | BL12: Nederland | BM12: 59979135.0 | BO12: NL05 RABO 0154 0739 89 | BQ12: 271 | BR12: 2023-02-01 | BU12: onbepaalde_tijd | BV12: Onbepaalde tijd | BW12: 1708.41 | BX12: 1708.41 | BY12: 1862.17 | BZ12: 0.09 | CA12: 0 | CB12: 0 | CC12: 0 | CD12: 1769.41 | CE12: ryanrent | CF12: 0 | CG12: 0 | CH12: 0 | CI12: 0 | CJ12: 0 | CK12: 0 | CL12: 0 | CM12: 0 | CO12: 1708.41 | CP12: 20500.92 | CR12: Verhuurd (onbepaald) | CS12: 0
A13: 0012 | B13: 34 | C13: Baarlelaan 27 | D13: 7906GB | E13: Hoogeveen | F13: Appartement | H13: 4 | I13: 4 | J13: 1 | K13: DS | L13: 1975 | M13: 1005 | P13: https://ryanrent.sharepoint.com/sites/RyanRent/Gedeelde%20documenten/Forms/AllItems.aspx?id=%2Fsites%2FRyanRent%2FGedeelde%20documenten%2FGeneral%2F01%5FRyanRent%26Co%2F01%5FWoningen%2FBaarlelaan%2027%2C%20Hoogeveen | Q13: https://ryanrent.sharepoint.com/sites/RyanRent/Gedeelde%20documenten/Forms/AllItems.aspx?id=%2Fsites%2FRyanRent%2FGedeelde%20documenten%2FGeneral%2F01%5FRyanRent%26Co%2F01%5FWoningen%2FBaarlelaan%2027%2C%20Hoogeveen%2F2%5FInhuur | R13: https://ryanrent.sharepoint.com/sites/RyanRent/Gedeelde%20documenten/Forms/AllItems.aspx?id=%2Fsites%2FRyanRent%2FGedeelde%20documenten%2FGeneral%2F01%5FRyanRent%26Co%2F01%5FWoningen%2FBaarlelaan%2027%2C%20Hoogeveen%2F3%5FVerhuur | S13: https://ryanrent.sharepoint.com/sites/RyanRent/Gedeelde%20documenten/Forms/AllItems.aspx?id=%2Fsites%2FRyanRent%2FGedeelde%20documenten%2FGeneral%2F01%5FRyanRent%26Co%2F01%5FWoningen%2FBaarlelaan%2027%2C%20Hoogeveen%2F2%5FInhuur%2F2%5FInhuurovereenkomsten | T13: 1965.88 | U13: 240 | V13: 0 | AM13: Geen inhuur | BV13: Leegstand | CD13: 1965.88 | CO13: 0 | CP13: 0 | CR13: Beschikbaar | CS13: 0
A14: 0013 | B14: 35 | C14: Baarsveen 197 | D14: 3205 BB | E14: Spijkenisse | F14: Appartement | H14: 5 | I14: 5 | J14: 1 | K14: DS | L14: 9197 | M14: 1144 | P14: https://ryanrent.sharepoint.com/sites/RyanRent/Gedeelde%20documenten/Forms/AllItems.aspx?id=%2Fsites%2FRyanRent%2FGedeelde%20documenten%2FGeneral%2F01%5FRyanRent%26Co%2F01%5FWoningen%2FBaarsveen%20197%2C%20Spijkenisse | Q14: https://ryanrent.sharepoint.com/sites/RyanRent/Gedeelde%20documenten/Forms/AllItems.aspx?id=%2Fsites%2FRyanRent%2FGedeelde%20documenten%2FGeneral%2F01%5FRyanRent%26Co%2F01%5FWoningen%2FBaarsveen%20197%2C%20Spijkenisse%2F2%5FInhuur | R14: https://ryanrent.sharepoint.com/sites/RyanRent/Gedeelde%20documenten/Forms/AllItems.aspx?id=%2Fsites%2FRyanRent%2FGedeelde%20documenten%2FGeneral%2F01%5FRyanRent%26Co%2F01%5FWoningen%2FBaarsveen%20197%2C%20Spijkenisse%2F3%5FVerhuur | S14: https://ryanrent.sharepoint.com/sites/RyanRent/Gedeelde%20documenten/Forms/AllItems.aspx?id=%2Fsites%2FRyanRent%2FGedeelde%20documenten%2FGeneral%2F01%5FRyanRent%26Co%2F01%5FWoningen%2FBaarsveen%20197%2C%20Spijkenisse%2F2%5FInhuur%2F2%5FInhuurovereenkomsten | T14: 1864.71 | U14: 325 | V14: 0 | AM14: Geen inhuur | BV14: Leegstand | CD14: 1864.71 | CO14: 0 | CP14: 0 | CR14: Beschikbaar | CS14: 0
A15: 0014 | B15: 36 | C15: Abelenlaan 143 | D15: 3181WD | E15: Rozenburg | F15: Appartement | H15: 3 | I15: 6 | J15: 1 | K15: Factuur | L15: 3143 | M15: 1005 | T15: 1940 | U15: 300 | V15: 0 | AM15: Geen inhuur | BV15: Leegstand | CD15: 1940 | CO15: 0 | CP15: 0 | CR15: Beschikbaar | CS15: 0
A16: 0015 | B16: 37 | C16: Maasdijk 69 | D16: 2691NZ | E16: S-Gravenzande | F16: Vakantiepark | H16: 3 | I16: 4 | J16: 1 | K16: Factuur | T16: 1934.12 | U16: 2470.8 | V16: 0 | AM16: Geen inhuur | BC16: 17 | BD16: Tradiro Services B.V. | BE16: particulier | BG16: facturen@tradiro.nl | BH16: null | BI16: Honderdland 960 | BJ16: 2678 PS | BK16: Maasdijk | BL16: Nederland | BM16: 59979135.0 | BO16: NL05 RABO 0154 0739 89 | BQ16: 301 | BR16: 2026-01-14 | BU16: bepaalde_tijd | BV16: Onbepaalde tijd | BW16: 0 | BX16: 3400 | BY16: 3706 | BZ16: 0.09 | CA16: 2470.8 | CB16: 0 | CC16: 0 | CD16: 1934.12 | CE16: ryanrent | CF16: 0 | CG16: 0 | CH16: 0 | CI16: 0 | CJ16: 0 | CK16: 0 | CL16: 0 | CM16: 0 | CO16: 3400 | CP16: 40800 | CR16: Verhuurd (onbepaald) | CS16: 0
A17: 0016 | B17: 38 | C17: van Scorelstraat 73 | D17: 3141 TH | E17: Maassluis | F17: Appartement | H17: 3 | I17: 5 | J17: 1 | K17: Factuur | P17: https://ryanrent.sharepoint.com/sites/RyanRent/Gedeelde%20documenten/Forms/AllItems.aspx?id=%2Fsites%2FRyanRent%2FGedeelde%20documenten%2FGeneral%2F01%5FRyanRent%26Co%2F01%5FWoningen%2FVan%20Scorelstraat%2073%20Maassluis | Q17: https://ryanrent.sharepoint.com/sites/RyanRent/Gedeelde%20documenten/Forms/AllItems.aspx?id=%2Fsites%2FRyanRent%2FGedeelde%20documenten%2FGeneral%2F01%5FRyanRent%26Co%2F01%5FWoningen%2FVan%20Scorelstraat%2073%20Maassluis%2F2%5FInhuur | R17: https://ryanrent.sharepoint.com/sites/RyanRent/Gedeelde%20documenten/Forms/AllItems.aspx?id=%2Fsites%2FRyanRent%2FGedeelde%20documenten%2FGeneral%2F01%5FRyanRent%26Co%2F01%5FWoningen%2FVan%20Scorelstraat%2073%20Maassluis%2F3%5FVerhuur | S17: https://ryanrent.sharepoint.com/sites/RyanRent/Gedeelde%20documenten/Forms/AllItems.aspx?id=%2Fsites%2FRyanRent%2FGedeelde%20documenten%2FGeneral%2F01%5FRyanRent%26Co%2F01%5FWoningen%2FVan%20Scorelstraat%2073%20Maassluis%2F2%5FInhuur%2F2%5FInhuurovereenkomsten | T17: 2224.71 | U17: 218.11 | V17: 0 | AM17: Geen inhuur | BV17: Leegstand | CD17: 2224.71 | CO17: 0 | CP17: 0 | CR17: Beschikbaar | CS17: 0
A18: 0017 | B18: 39 | C18: G.A. Brederolaan 75B | D18: 3141 CD | E18: Maassluis | F18: Appartement | H18: 3 | I18: 4 | J18: 1 | K18: Factuur | P18: https://ryanrent.sharepoint.com/sites/RyanRent/Gedeelde%20documenten/Forms/AllItems.aspx?id=%2Fsites%2FRyanRent%2FGedeelde%20documenten%2FGeneral%2F01%5FRyanRent%26Co%2F01%5FWoningen%2FG.A.%20Brederolaan%2075B%20Maassluis | T18: 1702.35 | U18: 208.85 | V18: 0 | AM18: Geen inhuur | BV18: Leegstand | CD18: 1702.35 | CO18: 0 | CP18: 0 | CR18: Beschikbaar | CS18: 0
A19: 0018 | B19: 40 | C19: Meester G. Groen van Prinsterlaan 313 | D19: 1181TV | E19: Amstelveen | F19: Appartement | H19: 2 | I19: 3 | J19: 1 | K19: DS | P19: https://ryanrent.sharepoint.com/sites/RyanRent/Gedeelde%20documenten/Forms/AllItems.aspx?id=%2Fsites%2FRyanRent%2FGedeelde%20documenten%2FGeneral%2F01%5FRyanRent%26Co%2F01%5FWoningen%2FMeester%20G.%20groen%20van%20Prinsterlaan%20313%2C%20Amstelveen | Q19: https://ryanrent.sharepoint.com/sites/RyanRent/Gedeelde%20documenten/Forms/AllItems.aspx?id=%2Fsites%2FRyanRent%2FGedeelde%20documenten%2FGeneral%2F01%5FRyanRent%26Co%2F01%5FWoningen%2FMeester%20G.%20groen%20van%20Prinsterlaan%20313%2C%20Amstelveen%2F2%5FInhuur | R19: https://ryanrent.sharepoint.com/sites/RyanRent/Gedeelde%20documenten/Forms/AllItems.aspx?id=%2Fsites%2FRyanRent%2FGedeelde%20documenten%2FGeneral%2F01%5FRyanRent%26Co%2F01%5FWoningen%2FMeester%20G.%20groen%20van%20Prinsterlaan%20313%2C%20Amstelveen%2F3%5FVerhuur | S19: https://ryanrent.sharepoint.com/sites/RyanRent/Gedeelde%20documenten/Forms/AllItems.aspx?id=%2Fsites%2FRyanRent%2FGedeelde%20documenten%2FGeneral%2F01%5FRyanRent%26Co%2F01%5FWoningen%2FMeester%20G.%20groen%20van%20Prinsterlaan%20313%2C%20Amstelveen%2F2%5FInhuur%2F2%5FInhuurovereenkomsten | T19: 1861.18 | U19: 200 | V19: 0 | AM19: Geen inhuur | BV19: Leegstand | CD19: 1861.18 | CO19: 0 | CP19: 0 | CR19: Beschikbaar | CS19: 0
A20: 0019 | B20: 41 | C20: Franselaan 273B | D20: 3028 AC | E20: Rotterdam | F20: Appartement | H20: 8 | I20: 8 | J20: 1 | K20: Factuur | T20: 2052.94 | U20: 39.24 | V20: 0 | AM20: Geen inhuur | BV20: Leegstand | CD20: 2052.94 | CO20: 0 | CP20: 0 | CR20: Beschikbaar | CS20: 0
A21: 0020 | B21: 42 | C21: Mr. Troelstrastraat 37 | D21: 3131 HR | E21: Vlaardingen | F21: Vakantiepark | H21: 2 | I21: 3 | J21: 1 | K21: Factuur | P21: https://ryanrent.sharepoint.com/sites/RyanRent/Gedeelde%20documenten/Forms/AllItems.aspx?id=%2Fsites%2FRyanRent%2FGedeelde%20documenten%2FGeneral%2F01%5FRyanRent%26Co%2F01%5FWoningen%2FMr.%20Troelstrastraat%2037%20Vlaardingen | T21: 1783.53 | U21: 181.36 | V21: 0 | AM21: Geen inhuur | BC21: 17 | BD21: Tradiro Services B.V. | BE21: particulier | BG21: facturen@tradiro.nl | BH21: null | BI21: Honderdland 960 | BJ21: 2678 PS | BK21: Maasdijk | BL21: Nederland | BM21: 59979135.0 | BO21: NL05 RABO 0154 0739 89 | BQ21: 269 | BR21: 2023-02-01 | BU21: onbepaalde_tijd | BV21: Onbepaalde tijd | BW21: 1723.44 | BX21: 1723.44 | BY21: 1878.55 | BZ21: 0.09 | CA21: 0 | CB21: 0 | CC21: 0 | CD21: 1783.53 | CE21: ryanrent | CF21: 0 | CG21: 0 | CH21: 0 | CI21: 0 | CJ21: 0 | CK21: 0 | CL21: 0 | CM21: 0 | CO21: 1723.44 | CP21: 20681.28 | CR21: Verhuurd (onbepaald) | CS21: 0
A22: 0021 | B22: 43 | C22: Vaartweg 106C | D22: 3131 HV | E22: Vlaardingen | F22: Appartement | H22: 3 | I22: 5 | J22: 1 | K22: Factuur | P22: https://ryanrent.sharepoint.com/sites/RyanRent/Gedeelde%20documenten/Forms/AllItems.aspx?id=%2Fsites%2FRyanRent%2FGedeelde%20documenten%2FGeneral%2F01%5FRyanRent%26Co%2F01%5FWoningen%2FVaartweg%20106C%2C%20Vlaardingen | Q22: https://ryanrent.sharepoint.com/sites/RyanRent/Gedeelde%20documenten/Forms/AllItems.aspx?id=%2Fsites%2FRyanRent%2FGedeelde%20documenten%2FGeneral%2F01%5FRyanRent%26Co%2F01%5FWoningen%2FVaartweg%20106C%2C%20Vlaardingen%2F2%5FInhuur | R22: https://ryanrent.sharepoint.com/sites/RyanRent/Gedeelde%20documenten/Forms/AllItems.aspx?id=%2Fsites%2FRyanRent%2FGedeelde%20documenten%2FGeneral%2F01%5FRyanRent%26Co%2F01%5FWoningen%2FVaartweg%20106C%2C%20Vlaardingen%2F3%5FVerhuur | S22: https://ryanrent.sharepoint.com/sites/RyanRent/Gedeelde%20documenten/Forms/AllItems.aspx?id=%2Fsites%2FRyanRent%2FGedeelde%20documenten%2FGeneral%2F01%5FRyanRent%26Co%2F01%5FWoningen%2FVaartweg%20106C%2C%20Vlaardingen%2F2%5FInhuur%2F2%5FInhuurovereenkomsten | T22: 2016.47 | U22: 256.89 | V22: 0 | AM22: Geen inhuur | BC22: 17 | BD22: Tradiro Services B.V. | BE22: particulier | BG22: facturen@tradiro.nl | BH22: null | BI22: Honderdland 960 | BJ22: 2678 PS | BK22: Maasdijk | BL22: Nederland | BM22: 59979135.0 | BO22: NL05 RABO 0154 0739 89 | BQ22: 267 | BR22: 2023-02-01 | BU22: onbepaalde_tijd | BV22: Onbepaalde tijd | BW22: 1830.43 | BX22: 1830.43 | BY22: 1995.17 | BZ22: 0.09 | CA22: 0 | CB22: 0 | CC22: 0 | CD22: 2016.47 | CE22: ryanrent | CF22: 0 | CG22: 0 | CH22: 0 | CI22: 0 | CJ22: 0 | CK22: 0 | CL22: 0 | CM22: 0 | CO22: 1830.43 | CP22: 21965.16 | CR22: Verhuurd (onbepaald) | CS22: 0
A23: 0022 | B23: 44 | C23: 2e van Leydengaelstraat 6 | D23: 3134 LL | E23: Vlaardingen | F23: Vakantiepark | H23: 4 | I23: 8 | J23: 1 | K23: Factuur | P23: https://ryanrent.sharepoint.com/sites/RyanRent/Gedeelde%20documenten/Forms/AllItems.aspx?id=%2Fsites%2FRyanRent%2FGedeelde%20documenten%2FGeneral%2F01%5FRyanRent%26Co%2F01%5FWoningen%2F2e%20van%20leyden%20gaelstraat%206%20Vlaardingen | Q23: https://ryanrent.sharepoint.com/sites/RyanRent/Gedeelde%20documenten/Forms/AllItems.aspx?id=%2Fsites%2FRyanRent%2FGedeelde%20documenten%2FGeneral%2F01%5FRyanRent%26Co%2F01%5FWoningen%2F2e%20van%20leyden%20gaelstraat%206%20Vlaardingen%2F2%5FInhuur | R23: https://ryanrent.sharepoint.com/sites/RyanRent/Gedeelde%20documenten/Forms/AllItems.aspx?id=%2Fsites%2FRyanRent%2FGedeelde%20documenten%2FGeneral%2F01%5FRyanRent%26Co%2F01%5FWoningen%2F2e%20van%20leyden%20gaelstraat%206%20Vlaardingen%2F3%5FVerhuur | S23: https://ryanrent.sharepoint.com/sites/RyanRent/Gedeelde%20documenten/Forms/AllItems.aspx?id=%2Fsites%2FRyanRent%2FGedeelde%20documenten%2FGeneral%2F01%5FRyanRent%26Co%2F01%5FWoningen%2F2e%20van%20leyden%20gaelstraat%206%20Vlaardingen%2F2%5FInhuur%2F2%5FInhuurovereenkomsten | T23: 2271.76 | U23: 0 | V23: 0 | AM23: Geen inhuur | BV23: Leegstand | CD23: 2271.76 | CO23: 0 | CP23: 0 | CR23: Beschikbaar | CS23: 0
A24: 0023 | B24: 45 | C24: Desiree Geerartstraat 1B | D24: 5111CH | E24: Baarle-Nassau | F24: Vakantiepark | H24: 5 | I24: 8 | J24: 1 | K24: DS | L24: 0107 | T24: 2018.82 | U24: 0 | V24: 0 | W24: 326 | X24: S. Kleiren | Y24: particulier | AA24: sabine.kleiren@gmail.com | AF24: Nederland | AI24: NL20 RABO 0103 8768 98 | AJ24: 574 | AK24: 2024-10-18 | AL24: 2027-10-18 | AM24: Actief | AO24: 1 | AT24: 3519 | AU24: 3519 | AV24: 3835.71 | AW24: 0.09 | AX24: 0 | AY24: 0 | AZ24: 0 | BA24: 0 | BB24: 0 | BC24: 236 | BD24: NL Realty B.V. | BE24: particulier | BG24: administratie@nl-jobs.com | BH24: 06 22 040 775 | BI24: Honderdland 1 | BK24: MAASDIJK | BL24: Nederland | BO24: NL90 RABO 0346 4019 25 | BQ24: 60 | BR24: 2024-10-18 | BS24: 2027-10-18 | BT24: 6 | BU24: bepaalde_tijd | BV24: Actief | BW24: 4033.88 | BX24: 4033.88 | BY24: 4396.93 | BZ24: 0.09 | CA24: 0 | CB24: 0 | CC24: 0 | CD24: 2018.82 | CE24: eigen_beheer | CF24: 0 | CG24: 0 | CH24: 0 | CI24: 0 | CJ24: 0 | CK24: 0 | CL24: 0 | CM24: 0 | CO24: 514.88 | CP24: 6178.56 | CQ24: 14.63 | CR24: Verhuurd | CS24: 634
A25: 0024 | B25: 46 | C25: Desiree Geerartstraat 1C | D25: 5111CH | E25: Baarle-Nassau | F25: Vakantiepark | H25: 6 | I25: 8 | J25: 1 | K25: DS | L25: 0107 | T25: 2510.59 | U25: 0 | V25: 0 | W25: 326 | X25: S. Kleiren | Y25: particulier | AA25: sabine.kleiren@gmail.com | AF25: Nederland | AI25: NL20 RABO 0103 8768 98 | AJ25: 575 | AK25: 2024-10-18 | AL25: 2027-10-18 | AM25: Actief | AO25: 1 | AT25: 3519 | AU25: 3519 | AV25: 3835.71 | AW25: 0.09 | AX25: 0 | AY25: 0 | AZ25: 0 | BA25: 0 | BB25: 0 | BC25: 236 | BD25: NL Realty B.V. | BE25: particulier | BG25: administratie@nl-jobs.com | BH25: 06 22 040 775 | BI25: Honderdland 1 | BK25: MAASDIJK | BL25: Nederland | BO25: NL90 RABO 0346 4019 25 | BQ25: 61 | BR25: 2024-10-18 | BS25: 2027-10-18 | BT25: 6 | BU25: bepaalde_tijd | BV25: Actief | BW25: 4033.88 | BX25: 4033.88 | BY25: 4396.93 | BZ25: 0.09 | CA25: 0 | CB25: 0 | CC25: 0 | CD25: 2510.59 | CE25: eigen_beheer | CF25: 0 | CG25: 0 | CH25: 0 | CI25: 0 | CJ25: 0 | CK25: 0 | CL25: 0 | CM25: 0 | CO25: 514.88 | CP25: 6178.56 | CQ25: 14.63 | CR25: Verhuurd | CS25: 634
A26: 0025 | B26: 47 | C26: Groenelaan 30B | D26: 3114 CH | E26: Schiedam | F26: Appartement | H26: 3 | I26: 3 | J26: 1 | K26: Factuur | L26: 2206 | P26: https://ryanrent.sharepoint.com/sites/RyanRent/Gedeelde%20documenten/Forms/AllItems.aspx?id=%2Fsites%2FRyanRent%2FGedeelde%20documenten%2FGeneral%2F01%5FRyanRent%26Co%2F01%5FWoningen%2FGroenelaan%2030B%2C%20Schiedam | Q26: https://ryanrent.sharepoint.com/sites/RyanRent/Gedeelde%20documenten/Forms/AllItems.aspx?id=%2Fsites%2FRyanRent%2FGedeelde%20documenten%2FGeneral%2F01%5FRyanRent%26Co%2F01%5FWoningen%2FGroenelaan%2030B%2C%20Schiedam%2F2%5FInhuur | R26: https://ryanrent.sharepoint.com/sites/RyanRent/Gedeelde%20documenten/Forms/AllItems.aspx?id=%2Fsites%2FRyanRent%2FGedeelde%20documenten%2FGeneral%2F01%5FRyanRent%26Co%2F01%5FWoningen%2FGroenelaan%2030B%2C%20Schiedam%2F3%5FVerhuur | S26: https://ryanrent.sharepoint.com/sites/RyanRent/Gedeelde%20documenten/Forms/AllItems.aspx?id=%2Fsites%2FRyanRent%2FGedeelde%20documenten%2FGeneral%2F01%5FRyanRent%26Co%2F01%5FWoningen%2FGroenelaan%2030B%2C%20Schiedam%2F2%5FInhuur%2F2%5FInhuurovereenkomsten | T26: 2165.88 | U26: 190.22 | V26: 0 | AM26: Geen inhuur | BC26: 17 | BD26: Tradiro Services B.V. | BE26: particulier | BG26: facturen@tradiro.nl | BH26: null | BI26: Honderdland 960 | BJ26: 2678 PS | BK26: Maasdijk | BL26: Nederland | BM26: 59979135.0 | BO26: NL05 RABO 0154 0739 89 | BQ26: 275 | BR26: 2023-02-01 | BU26: onbepaalde_tijd | BV26: Onbepaalde tijd | BW26: 1430 | BX26: 1430 | BY26: 1558.7 | BZ26: 0.09 | CA26: 0 | CB26: 0 | CC26: 250 | CD26: 2165.88 | CE26: ryanrent | CF26: 0 | CG26: 0 | CH26: 0 | CI26: 0 | CJ26: 0 | CK26: 0 | CL26: 1 | CM26: 0 | CN26: basis | CO26: 1430 | CP26: 17160 | CR26: Verhuurd (onbepaald) | CS26: 0
A27: 0026 | B27: 48 | C27: Chopinstraat 39C | D27: 3131 DB | E27: Vlaardingen | F27: Vakantiepark | H27: 3 | I27: 6 | J27: 1 | K27: Factuur | P27: https://ryanrent.sharepoint.com/sites/RyanRent/Gedeelde%20documenten/Forms/AllItems.aspx?id=%2Fsites%2FRyanRent%2FGedeelde%20documenten%2FGeneral%2F01%5FRyanRent%26Co%2F01%5FWoningen%2FChopinstraat%2039C%20Vlaardingen | Q27: https://ryanrent.sharepoint.com/sites/RyanRent/Gedeelde%20documenten/Forms/AllItems.aspx?id=%2Fsites%2FRyanRent%2FGedeelde%20documenten%2FGeneral%2F01%5FRyanRent%26Co%2F01%5FWoningen%2FChopinstraat%2039C%20Vlaardingen%2F2%5FInhuur | R27: https://ryanrent.sharepoint.com/sites/RyanRent/Gedeelde%20documenten/Forms/AllItems.aspx?id=%2Fsites%2FRyanRent%2FGedeelde%20documenten%2FGeneral%2F01%5FRyanRent%26Co%2F01%5FWoningen%2FChopinstraat%2039C%20Vlaardingen%2F3%5FVerhuur | S27: https://ryanrent.sharepoint.com/sites/RyanRent/Gedeelde%20documenten/Forms/AllItems.aspx?id=%2Fsites%2FRyanRent%2FGedeelde%20documenten%2FGeneral%2F01%5FRyanRent%26Co%2F01%5FWoningen%2FChopinstraat%2039C%20Vlaardingen%2F2%5FInhuur%2F2%5FInhuurovereenkomsten | T27: 1763.53 | U27: 255.59 | V27: 0 | W27: 984 | X27: Park Wonen BV | Y27: bedrijf | AA27: info@parkwonen.nl | AB27: 010 — 844 25 52 | AC27: Kruisplein 488a | AD27: 3012 CC | AE27: Rotterdam | AG27: 64549836 | AI27: NLO4 RABO 0307 5644 79 | AJ27: 818 | AK27: 2019-09-16 | AM27: Onbepaalde tijd | AN27: 12 | AO27: 1 | AT27: 0 | AU27: 1600 | AV27: 1744 | AW27: 0.09 | AY27: 0 | BA27: 0 | BB27: 0 | BV27: Leegstand | CD27: 1763.53 | CO27: -1600 | CP27: -19200 | CQ27: -100 | CR27: Beschikbaar | CS27: 0
A28: 0027 | B28: 49 | C28: Buizerdstraat 210 | D28: 3145 AD | E28: Maassluis | F28: Appartement | H28: 5 | I28: 5 | J28: 1 | K28: Factuur | P28: https://ryanrent.sharepoint.com/sites/RyanRent/Gedeelde%20documenten/Forms/AllItems.aspx?id=%2Fsites%2FRyanRent%2FGedeelde%20documenten%2FGeneral%2F01%5FRyanRent%26Co%2F01%5FWoningen%2FBuizerdstraat%20210%20Maassluis | Q28: https://ryanrent.sharepoint.com/sites/RyanRent/Gedeelde%20documenten/Forms/AllItems.aspx?id=%2Fsites%2FRyanRent%2FGedeelde%20documenten%2FGeneral%2F01%5FRyanRent%26Co%2F01%5FWoningen%2FBuizerdstraat%20210%20Maassluis%2F2%5FInhuur | R28: https://ryanrent.sharepoint.com/sites/RyanRent/Gedeelde%20documenten/Forms/AllItems.aspx?id=%2Fsites%2FRyanRent%2FGedeelde%20documenten%2FGeneral%2F01%5FRyanRent%26Co%2F01%5FWoningen%2FBuizerdstraat%20210%20Maassluis%2F3%5FVerhuur | S28: https://ryanrent.sharepoint.com/sites/RyanRent/Gedeelde%20documenten/Forms/AllItems.aspx?id=%2Fsites%2FRyanRent%2FGedeelde%20documenten%2FGeneral%2F01%5FRyanRent%26Co%2F01%5FWoningen%2FBuizerdstraat%20210%20Maassluis%2F2%5FInhuur%2F2%5FInhuurovereenkomsten | T28: 1442.35 | U28: 142.75 | V28: 0 | AM28: Geen inhuur | BC28: 17 | BD28: Tradiro Services B.V. | BE28: particulier | BG28: facturen@tradiro.nl | BH28: null | BI28: Honderdland 960 | BJ28: 2678 PS | BK28: Maasdijk | BL28: Nederland | BM28: 59979135.0 | BO28: NL05 RABO 0154 0739 89 | BQ28: 276 | BR28: 2023-03-01 | BU28: onbepaalde_tijd | BV28: Onbepaalde tijd | BW28: 1677.89 | BX28: 1677.89 | BY28: 1828.9 | BZ28: 0.09 | CA28: 0 | CB28: 0 | CC28: 0 | CD28: 0 | CE28: ryanrent | CF28: 0 | CG28: 0 | CH28: 0 | CI28: 0 | CJ28: 0 | CK28: 0 | CL28: 0 | CM28: 0 | CO28: 1677.89 | CP28: 20134.68 | CR28: Verhuurd (onbepaald) | CS28: 0
A29: 0028 | B29: 50 | C29: Lange kruisweg 12 | D29: 2676 BL | E29: Maasdijk | F29: Appartement | H29: 4 | I29: 8 | J29: 1 | K29: DS | M29: 1005 | P29: https://ryanrent.sharepoint.com/sites/RyanRent/Gedeelde%20documenten/Forms/AllItems.aspx?id=%2Fsites%2FRyanRent%2FGedeelde%20documenten%2FGeneral%2F01%5FRyanRent%26Co%2F01%5FWoningen%2FLange%20Kruisweg%2012%20Maasdijk | T29: 1954.12 | U29: 272.64 | V29: 0 | AM29: Geen inhuur | BC29: 17 | BD29: Tradiro Services B.V. | BE29: particulier | BG29: facturen@tradiro.nl | BH29: null | BI29: Honderdland 960 | BJ29: 2678 PS | BK29: Maasdijk | BL29: Nederland | BM29: 59979135.0 | BO29: NL05 RABO 0154 0739 89 | BQ29: 273 | BR29: 2023-03-01 | BU29: onbepaalde_tijd | BV29: Onbepaalde tijd | BW29: 2928.69 | BX29: 2928.69 | BY29: 3192.27 | BZ29: 0.09 | CA29: 0 | CB29: 0 | CC29: 0 | CD29: 1954.12 | CE29: ryanrent | CF29: 0 | CG29: 0 | CH29: 0 | CI29: 0 | CJ29: 0 | CK29: 0 | CL29: 0 | CM29: 0 | CO29: 2928.69 | CP29: 35144.28 | CR29: Verhuurd (onbepaald) | CS29: 0
A30: 0029 | B30: 51 | C30: Madeliefstraat 46C | D30: 3083TJ | E30: Rotterdam | F30: Appartement | H30: 3 | I30: 3 | J30: 1 | K30: DS | P30: https://ryanrent.sharepoint.com/sites/RyanRent/Gedeelde%20documenten/Forms/AllItems.aspx?id=%2Fsites%2FRyanRent%2FGedeelde%20documenten%2FGeneral%2F01%5FRyanRent%26Co%2F01%5FWoningen%2FMadeliefstraat%2046c%20Rotterdam | Q30: https://ryanrent.sharepoint.com/sites/RyanRent/Gedeelde%20documenten/Forms/AllItems.aspx?id=%2Fsites%2FRyanRent%2FGedeelde%20documenten%2FGeneral%2F01%5FRyanRent%26Co%2F01%5FWoningen%2FMadeliefstraat%2046c%20Rotterdam%2F2%5FInhuur | R30: https://ryanrent.sharepoint.com/sites/RyanRent/Gedeelde%20documenten/Forms/AllItems.aspx?id=%2Fsites%2FRyanRent%2FGedeelde%20documenten%2FGeneral%2F01%5FRyanRent%26Co%2F01%5FWoningen%2FMadeliefstraat%2046c%20Rotterdam%2F3%5FVerhuur | S30: https://ryanrent.sharepoint.com/sites/RyanRent/Gedeelde%20documenten/Forms/AllItems.aspx?id=%2Fsites%2FRyanRent%2FGedeelde%20documenten%2FGeneral%2F01%5FRyanRent%26Co%2F01%5FWoningen%2FMadeliefstraat%2046c%20Rotterdam%2F2%5FInhuur%2F2%5FInhuurovereenkomsten | T30: 1877.65 | U30: 200 | V30: 0 | W30: 850 | X30: M. Kathiravelu | Y30: particulier | AJ30: 659 | AK30: 2024-10-01 | AL30: 2026-09-30 | AM30: Actief | AO30: 1 | AT30: 1350 | AU30: 1350 | AV30: 1471.5 | AW30: 0.09 | AX30: 0 | AY30: 0 | AZ30: 0 | BA30: 0 | BB30: 0 | BC30: 329 | BD30: RNDV Industries | BE30: particulier | BG30: laura.brackiene@rndv.eu | BH30: +37062054093 | BI30: Taikos pr. 52C | BK30: Klipeda | BL30: Litouwen | BM30: 1304203983 | BQ30: 146 | BR30: 2024-10-01 | BS30: 2026-09-30 | BT30: 12 | BU30: bepaalde_tijd | BV30: Actief | BW30: 1977.9 | BX30: 2212.9 | BY30: 2412.06 | BZ30: 0.09 | CA30: 200 | CB30: 35 | CC30: 0 | CD30: 1877.65 | CE30: ryanrent | CF30: 1 | CG30: 1 | CH30: 1 | CI30: 0 | CJ30: 0 | CK30: 0 | CL30: 0 | CM30: 0 | CO30: 862.9 | CP30: 10354.8 | CQ30: 63.92 | CR30: Verhuurd | CS30: 251
A31: 0030 | B31: 52 | C31: Curacaolaan 88 | D31: 3131 XD | E31: Vlaardingen | F31: Vakantiepark | H31: 2 | I31: 3 | J31: 1 | K31: Factuur | P31: https://ryanrent.sharepoint.com/sites/RyanRent/Gedeelde%20documenten/Forms/AllItems.aspx?id=%2Fsites%2FRyanRent%2FGedeelde%20documenten%2FGeneral%2F01%5FRyanRent%26Co%2F01%5FWoningen%2FCuracaolaan%2088%20Vlaardingen | T31: 2054.12 | U31: 297.55 | V31: 0 | AM31: Geen inhuur | BC31: 17 | BD31: Tradiro Services B.V. | BE31: particulier | BG31: facturen@tradiro.nl | BH31: null | BI31: Honderdland 960 | BJ31: 2678 PS | BK31: Maasdijk | BL31: Nederland | BM31: 59979135.0 | BO31: NL05 RABO 0154 0739 89 | BQ31: 302 | BR31: 2026-01-14 | BU31: bepaalde_tijd | BV31: Onbepaalde tijd | BW31: 0 | BX31: 895 | BY31: 975.55 | BZ31: 0.09 | CA31: 297.55 | CB31: 354.76 | CC31: 0 | CD31: 2054.12 | CE31: ryanrent | CF31: 0 | CG31: 0 | CH31: 0 | CI31: 0 | CJ31: 0 | CK31: 0 | CL31: 0 | CM31: 0 | CO31: 895 | CP31: 10740 | CR31: Verhuurd (onbepaald) | CS31: 0
A32: 0031 | B32: 53 | C32: Hogenbanweg 331 | D32: 3112 CK | E32: Schiedam | F32: Appartement | H32: 2 | I32: 3 | J32: 1 | K32: DS | P32: https://ryanrent.sharepoint.com/sites/RyanRent/Gedeelde%20documenten/Forms/AllItems.aspx?id=%2Fsites%2FRyanRent%2FGedeelde%20documenten%2FGeneral%2F01%5FRyanRent%26Co%2F01%5FWoningen%2FHogenbanweg%20331%20Schiedam | T32: 1974.12 | U32: 195.97 | V32: 0 | AM32: Geen inhuur | BV32: Leegstand | CD32: 1974.12 | CO32: 0 | CP32: 0 | CR32: Beschikbaar | CS32: 0
A33: 0032 | B33: 54 | C33: Jacob van offwegenlaan 26 | D33: 2282 HR | E33: Rijswijk | F33: Appartement | H33: 4 | I33: 4 | J33: 1 | K33: Factuur | P33: https://ryanrent.sharepoint.com/sites/RyanRent/Gedeelde%20documenten/Forms/AllItems.aspx?id=%2Fsites%2FRyanRent%2FGedeelde%20documenten%2FGeneral%2F01%5FRyanRent%26Co%2F01%5FWoningen%2FJacob%20van%20Lennepstraat%2013a | T33: 2065.88 | U33: 200 | V33: 0 | AM33: Geen inhuur | BV33: Leegstand | CD33: 2065.88 | CO33: 0 | CP33: 0 | CR33: Beschikbaar | CS33: 0
A34: 0033 | B34: 55 | C34: Kethelweg 66C | D34: 3135 GM | E34: Vlaardingen | F34: Vakantiepark | H34: 3 | I34: 5 | J34: 1 | K34: Factuur | P34: https://ryanrent.sharepoint.com/sites/RyanRent/Gedeelde%20documenten/Forms/AllItems.aspx?id=%2Fsites%2FRyanRent%2FGedeelde%20documenten%2FGeneral%2F01%5FRyanRent%26Co%2F01%5FWoningen%2FKethelweg%2066C%20Vlaardingen | T34: 2444.71 | U34: 370.02 | V34: 0 | AM34: Geen inhuur | BC34: 17 | BD34: Tradiro Services B.V. | BE34: particulier | BG34: facturen@tradiro.nl | BH34: null | BI34: Honderdland 960 | BJ34: 2678 PS | BK34: Maasdijk | BL34: Nederland | BM34: 59979135.0 | BO34: NL05 RABO 0154 0739 89 | BQ34: 268 | BR34: 2023-03-01 | BU34: onbepaalde_tijd | BV34: Onbepaalde tijd | BW34: 2082 | BX34: 2082 | BY34: 2269.38 | BZ34: 0.09 | CA34: 0 | CB34: 0 | CC34: 375 | CD34: 2000 | CE34: ryanrent | CF34: 0 | CG34: 0 | CH34: 0 | CI34: 0 | CJ34: 0 | CK34: 0 | CL34: 1 | CM34: 0 | CN34: intensief | CO34: 2082 | CP34: 24984 | CR34: Verhuurd (onbepaald) | CS34: 0
A35: 0034 | B35: 56 | C35: Kethelweg 68A | D35: 3135 GM | E35: Vlaardingen | F35: Vakantiepark | H35: 3 | I35: 5 | J35: 1 | K35: Factuur | P35: https://ryanrent.sharepoint.com/sites/RyanRent/Gedeelde%20documenten/Forms/AllItems.aspx?id=%2Fsites%2FRyanRent%2FGedeelde%20documenten%2FGeneral%2F01%5FRyanRent%26Co%2F01%5FWoningen%2FKethelweg%2068A%20Vlaardingen | T35: 2108.7 | U35: 491.73 | V35: 0 | AM35: Geen inhuur | BC35: 17 | BD35: Tradiro Services B.V. | BE35: particulier | BG35: facturen@tradiro.nl | BH35: null | BI35: Honderdland 960 | BJ35: 2678 PS | BK35: Maasdijk | BL35: Nederland | BM35: 59979135.0 | BO35: NL05 RABO 0154 0739 89 | BQ35: 274 | BR35: 2023-03-01 | BU35: onbepaalde_tijd | BV35: Onbepaalde tijd | BW35: 2082 | BX35: 2082 | BY35: 2269.38 | BZ35: 0.09 | CA35: 0 | CB35: 0 | CC35: 0 | CD35: 2000 | CE35: ryanrent | CF35: 0 | CG35: 0 | CH35: 0 | CI35: 0 | CJ35: 0 | CK35: 0 | CL35: 0 | CM35: 0 | CO35: 2082 | CP35: 24984 | CR35: Verhuurd (onbepaald) | CS35: 0
A36: 0035 | B36: 57 | C36: Messchaertplein 39 | D36: 3131 TG | E36: Vlaardingen | F36: Vakantiepark | H36: 2 | I36: 3 | J36: 1 | K36: Factuur | P36: https://ryanrent.sharepoint.com/sites/RyanRent/Gedeelde%20documenten/Forms/AllItems.aspx?id=%2Fsites%2FRyanRent%2FGedeelde%20documenten%2FGeneral%2F01%5FRyanRent%26Co%2F01%5FWoningen%2FMesschaertplein%2039%20Vlaardingen | T36: 2160 | U36: 160.42 | V36: 0 | W36: 984 | X36: Park Wonen BV | Y36: bedrijf | AA36: info@parkwonen.nl | AB36: 010 — 844 25 52 | AC36: Kruisplein 488a | AD36: 3012 CC | AE36: Rotterdam | AG36: 64549836 | AI36: NLO4 RABO 0307 5644 79 | AJ36: 814 | AK36: 2022-11-14 | AM36: Onbepaalde tijd | AN36: 12 | AO36: 1 | AT36: 0 | AU36: 1300 | AV36: 1417 | AW36: 0.09 | AX36: 1300 | AY36: 0 | BA36: 0 | BB36: 0 | BV36: Leegstand | CD36: 2160 | CO36: -1300 | CP36: -15600 | CQ36: -100 | CR36: Beschikbaar | CS36: 0
A37: 0036 | B37: 58 | C37: Messchaertplein 40 | D37: 3131 TG | E37: Vlaardingen | F37: Vakantiepark | H37: 3 | I37: 5 | J37: 1 | K37: Factuur | P37: https://ryanrent.sharepoint.com/sites/RyanRent/Gedeelde%20documenten/Forms/AllItems.aspx?id=%2Fsites%2FRyanRent%2FGedeelde%20documenten%2FGeneral%2F01%5FRyanRent%26Co%2F01%5FWoningen%2FMesschaertplein%2040%20Vlaardingen | T37: 2149.41 | U37: 332.55 | V37: 0 | W37: 984 | X37: Park Wonen BV | Y37: bedrijf | AA37: info@parkwonen.nl | AB37: 010 — 844 25 52 | AC37: Kruisplein 488a | AD37: 3012 CC | AE37: Rotterdam | AG37: 64549836 | AI37: NLO4 RABO 0307 5644 79 | AJ37: 805 | AK37: 2022-11-14 | AM37: Onbepaalde tijd | AN37: 12 | AO37: 1 | AT37: 0 | AU37: 1300 | AV37: 1417 | AW37: 0.09 | AX37: 1300 | AY37: 0 | BA37: 0 | BB37: 0 | BV37: Leegstand | CD37: 2149.41 | CO37: -1300 | CP37: -15600 | CQ37: -100 | CR37: Beschikbaar | CS37: 0
